Workbook

Sheet balance_sheet
A1: item | B1: 2018 | C1: 2019 | D1: 2020 | E1: 2021 | F1: 2022 | G1: 2023 | H1: 2024 | I1: 2025
A2: Tiền mặt, vàng bạc, đá quý | B2: 2606467000000 | C2: 4820627000000 | D2: 3663615000000 | E2: 3578643000000 | F2: 4215721000000 | G2: 3620695000000 | H2: 3384770000000 | I2: 4360821000000
A3: Tài sản cố định | B3: 1718596000000 | C3: 3207777000000 | D3: 4613423000000 | E3: 7224481000000 | F3: 8411382000000 | G3: 8892697000000 | H3: 12466885000000 | I3: 12122934000000
A4: Tài sản cố định hữu hình | B4: 788016000000 | C4: 793484000000 | D4: 1470942000000 | E4: 3628732000000 | F4: 3696812000000 | G4: 3527586000000 | H4: 6576699000000 | I4: 6343732000000
A5: Nguyên giá TSCĐ hữu hình | B5: 1835272000000 | C5: 1761468000000 | D5: 2416349000000 | E5: 4824092000000 | F5: 5156346000000 | G5: 5492566000000 | H5: 9080615000000 | I5: 9539276000000
A6: Hao mòn TSCĐ hữu hình | B6: -1047256000000 | C6: -967984000000 | D6: -945407000000 | E6: -1195360000000 | F6: -1459534000000 | G6: -1964980000000 | H6: -2503916000000 | I6: -3195544000000
A7: Tài sản cố định thuê tài chính | B7: 0 | C7: 0 | D7: 0 | E7: 0 | F7: 0 | G7: 0 | H7: 0 | I7: 0
A8: Nguyên giá TSCĐ thuê tài chính | B8: 0 | C8: 0 | D8: 0 | E8: 0 | F8: 0 | G8: 0 | H8: 0 | I8: 0
A9: Hao mòn TSCĐ thuê tài chính | B9: 0 | C9: 0 | D9: 0 | E9: 0 | F9: 0 | G9: 0 | H9: 0 | I9: 0
A10: Tài sản cố định vô hình | B10: 930580000000 | C10: 2414293000000 | D10: 3142481000000 | E10: 3595749000000 | F10: 4714570000000 | G10: 5365111000000 | H10: 5890186000000 | I10: 5779202000000
A11: Nguyên giá TSCĐ vô hình | B11: 1540037000000 | C11: 3086148000000 | D11: 3923203000000 | E11: 4541141000000 | F11: 5913538000000 | G11: 7198784000000 | H11: 8485022000000 | I11: 9535997000000
A12: Hao mòn TSCĐ vô hình | B12: -609457000000 | C12: -671855000000 | D12: -780722000000 | E12: -945392000000 | F12: -1198968000000 | G12: -1833673000000 | H12: -2594836000000 | I12: -3756795000000
A13: Bất động sản đầu tư | B13: 1196324000000 | C13: 1160524000000 | D13: 1124724000000 | E13: 1088924000000 | F13: 1053124000000 | G13: 0 | H13: 0 | I13: 0
... A35: Chứng khoán kinh doanh | B35: 7583090000000 | C35: 10052963000000 | D35: 8357447000000 | E35: 5074479000000 | F35: 961034000000 | G35: 4432778000000 | H35: 9000895000000 | I35: 4816831000000
A36: Chứng khoán kinh doanh | F36: 961034000000 | G36: 4432778000000 | H36: 9000895000000 | I36: 4816831000000
A37: Dự phòng giảm giá chứng khoán kinh doanh | B37: -10861000000 | C37: -11407000000 | D37: -9871000000 | E37: -3667000000 | F37: 0 | G37: 0 | H37: -251000000 | I37: -1054000000
A38: Các công cụ tài chính phái sinh và các tài sản tài chính khác | B38: 0 | C38: 0 | D38: 0 | E38: 293768000000 | F38: 0 | G38: 143611000000 | H38: 0 | I38: 0
A39: Cho vay khách hàng | B39: 159939217000000 | C39: 230802027000000 | D39: 277524615000000 | E39: 347341244000000 | F39: 420523705000000 | G39: 518641568000000 | H39: 631724964000000 | I39: 767617129000000
A40: Cho vay khách hàng | F40: 420523705000000 | G40: 518641568000000 | H40: 631724964000000 | I40: 767617129000000
A41: Dự phòng rủi ro cho vay khách hàng | B41: -2385114000000 | C41: -2916744000000 | D41: -2214248000000 | E41: -3735663000000 | F41: -4771449000000 | G41: -6127896000000 | H41: -8090693000000 | I41: -10498378000000
A42: Chứng khoán đầu tư | B42: 86512348000000 | C42: 66054597000000 | D42: 84447241000000 | E42: 97586088000000 | F42: 103651920000000 | G42: 104993945000000 | H42: 148623636000000 | I42: 145526404000000
A43: Chứng khoán đầu tư sẵn sàng để bán | B43: 66625261000000 | C43: 66158709000000 | D43: 84632952000000 | E43: 98092062000000 | F43: 104031921000000 | G43: 105356248000000 | H43: 142202792000000 | I43: 145942288000000
A44: Chứng khoán đầu tư giữ đến ngày đáo hạn | B44: 20236200000000 | C44: 202006000000 | D44: 200000000000 | E44: 200000000000 | F44: 0 | G44: 0 | H44: 6900000000000 | I44: 0
A45: Dự phòng giảm giá chứng khoán đầu tư | B45: -349113000000 | C45: -306118000000 | D45: -385711000000 | E45: -705974000000 | F45: -380001000000 | G45: -362303000000 | H45: -479156000000 | I45: -415884000000
A46: Tài sản Có khác | B46: 717481000000 | C46: 1055475000000 | D46: 1268562000000 | E46: 1448617000000 | F46: 1616735000000 | G46: 1650584000000 | H46: 1818676000000 | I46: 2070439000000
A47: Các khoản nợ chính phủ và NHNN Việt Nam | B47: 6025027000000 | C47: 0 | D47: 0 | E47: 842000000 | F47: 7826000000 | G47: 131000000 | H47: 11531000000 | I47: 4323867000000
A48: Tiền gửi và vay các Tổ chức tín dụng khác | B48: 36425560000000 | C48: 61266635000000 | D48: 47484812000000 | E48: 112458691000000 | F48: 167562969000000 | G48: 153173002000000 | H48: 132239088000000 | I48: 144982976000000
A49: Tiền gửi của khách hàng | B49: 201414532000000 | C49: 231296761000000 | D49: 277458651000000 | E49: 314752525000000 | F49: 358403785000000 | G49: 454660779000000 | H49: 533392350000000 | I49: 618911535000000
A50: Các công cụ tài chính phái sinh và các khoản nợ tài chính khác | B50: 310313000000 | C50: 434008000000 | D50: 266926000000 | E50: 0 | F50: 1851213000000 | G50: 0 | H50: 931231000000 | I50: 2416947000000
A51: Vốn tài trợ, uỷ thác đầu tư của Chính phủ và các tổ chức tín dụng khác | B51: 0 | C51: 0 | D51: 0 | E51: 0 | F51: 0 | G51: 0 | H51: 0 | I51: 0
A52: Phát hành giấy tờ có giá | B52: 13177959000000 | C52: 17460634000000 | D52: 27899640000000 | E52: 33679824000000 | F52: 34006619000000 | G52: 84703300000000 | H52: 140422321000000 | I52: 215330128000000
... A76: Tài sản thuế TNDN hoãn lại | B76: 0 | C76: 0 | D76: 0 | E76: 17460000000 | F76: 61050000000 | G76: 70409000000 | H76: 79856000000 | I76: 40487000000
A77: Tài sản Có khác | F77: 1616735000000 | G77: 1650584000000 | H77: 1818676000000 | I77: 2070439000000
A78: Trong đó: Lợi thế thương mại | B78: 0 | C78: 0 | D78: 0 | E78: 0 | F78: 0 | G78: 0 | H78: 0 | I78: 0
A79: Các khoản dự phòng rủi ro cho các tài sản Có nội bảng khác | B79: -75839000000 | C79: -228908000000 | D79: -189892000000 | E79: -680423000000 | F79: -798423000000 | G79: -692866000000 | H79: -64874000000 | I79: -8301000000
A80: Tiền gửi của các tổ chức tín dụng khác | B80: 28973455000000 | C80: 38632337000000 | D80: 21232089000000 | E80: 45606142000000 | F80: 61293738000000 | G80: 50619678000000 | H80: 72210834000000 | I80: 83014313000000
A81: Vay các tổ chức tín dụng khác | B81: 7452105000000 | C81: 22634298000000 | D81: 26252723000000 | E81: 66852549000000 | F81: 106269231000000 | G81: 102553324000000 | H81: 60028254000000 | I81: 61968663000000
A82: Các khoản lãi, phí phải trả | B82: 3424068000000 | C82: 3479310000000 | D82: 3252009000000 | E82: 3121881000000 | F82: 6144022000000 | G82: 9418750000000 | H82: 7281567000000 | I82: 9448719000000
A83: Thuế TNDN hoãn lại phải trả | B83: 0 | C83: 0 | D83: 0 | E83: 0 | F83: 0 | G83: 0 | H83: 0 | I83: 0
A84: Các khoản phải trả và công nợ khác | B84: 8428777000000 | C84: 7689346000000 | D84: 8626109000000 | E84: 11673715000000 | F84: 17631144000000 | G84: 15909985000000 | H84: 16580840000000 | I84: 17428523000000
...

Sheet income_statement
A1: item | B1: 2018 | C1: 2019 | D1: 2020 | E1: 2021 | F1: 2022 | G1: 2023 | H1: 2024 | I1: 2025
A2: Tổng lợi nhuận/lỗ trước thuế | B2: 10661016000000 | C2: 12838268000000 | D2: 15800296000000 | E2: 23238293000000 | F2: 25567768000000 | G2: 22888228000000 | H2: 27538368000000 | I2: 32538066000000
A3: Chi phí thuế TNDN hiện hành | B3: -2185246000000 | C3: -2612059000000 | D3: -3217829000000 | E3: -4840371000000 | F3: -5174932000000 | G3: -4706721000000 | H3: -5787711000000 | I3: -6544225000000
A4: Chi phí thuế TNDN hoãn lại | B4: -1773000000 | C4: 0 | D4: 0 | E4: 17460000000 | F4: 43590000000 | G4: 9359000000 | H4: 9447000000 | I4: -39369000000
A5: Chi phí thuế thu nhập doanh nghiệp | B5: -2187019000000 | C5: -2612059000000 | D5: -3217829000000 | E5: -4822911000000 | F5: -5131342000000 | G5: -4697362000000 | H5: -5778264000000 | I5: -6583594000000
A6: Lợi nhuận sau thuế | B6: 8473997000000 | C6: 10226209000000 | D6: 12582467000000 | E6: 18415382000000 | F6: 20436426000000 | G6: 18190866000000 | H6: 21760104000000 | I6: 25954472000000
A7: Lợi ích của cổ đông thiểu số | B7: -11222000000 | C7: -151070000000 | D7: -257476000000 | E7: -363132000000 | F7: -286049000000 | G7: -187064000000 | H7: -237176000000 | I7: -664242000000
A8: Cổ đông của Công ty mẹ | B8: 8462775000000 | C8: 10075139000000 | D8: 12324991000000 | E8: 18052250000000 | F8: 20150377000000 | G8: 18003802000000 | H8: 21522928000000 | I8: 25290230000000
A9: Lãi cơ bản trên cổ phiếu (VND) | B9: 3816 | C9: 2871 | D9: 3515 | E9: 5137 | F9: 5725 | G9: 2549 | H9: 3049 | I9: 3572
A10: Lãi trên cổ phiếu pha loãng (VND) | B10: 0 | C10: 0 | D10: 0 | E10: 0 | F10: 0 | G10: 0 | H10: 0 | I10: 0
A11: Thu nhập lãi và các khoản thu nhập tương tự | B11: 21413626000000 | C11: 25016341000000 | D11: 29001912000000 | E11: 35503251000000 | F11: 44752636000000 | G11: 56707759000000 | H11: 60089462000000 | I11: 68017450000000
A12: Chi phí lãi và các chi phí tương tự | B12: -10023687000000 | C12: -10758497000000 | D12: -10250703000000 | E12: -8804638000000 | F12: -14462861000000 | G12: -29016639000000 | H12: -24581499000000 | I12: -29862359000000
A13: Thu nhập lãi thuần | B13: 11389939000000 | C13: 14257844000000 | D13: 18751209000000 | E13: 26698613000000 | F13: 30289775000000 | G13: 27691120000000 | H13: 35507963000000 | I13: 38155091000000
... A27: Trích lập dự phòng tổn thất tín dụng | B27: -1846245000000 | C27: -917368000000 | D27: -2611035000000 | E27: -2664603000000 | F27: -1936294000000 | G27: -3921068000000 | H27: -4082294000000 | I27: -4420625000000

Sheet cash_flow
A1: item | B1: 2018 | C1: 2019 | D1: 2020 | E1: 2021 | F1: 2022 | G1: 2023 | H1: 2024 | I1: 2025
A2: Lưu chuyển tiền thuần từ hoạt động kinh doanh trước những thay đổi về tài sản và vốn lưu động | B2: 9926403000000 | C2: 13007909000000 | D2: 17631283000000 | E2: 23061616000000 | F2: 29013569000000 | G2: 24938816000000 | H2: 31037437000000 | I2: 33290586000000
A3: Thuế thu nhập doanh nghiệp đã trả | B3: 0 | C3: 0 | D3: 0 | E3: 0 | F3: 0 | G3: 0 | H3: 0 | I3: 0
A4: Lưu chuyển tiền thuần từ các hoạt động sản xuất kinh doanh | B4: 298932000000 | C4: 12631802000000 | D4: -10088467000000 | E4: 12828221000000 | F4: 55468501000000 | G4: 12053287000000 | H4: 42376555000000 | I4: 39923618000000
A5: Mua sắm TSCĐ | B5: -401574000000 | C5: -257620000000 | D5: -665860000000 | E5: -939995000000 | F5: -1110111000000 | G5: -1232358000000 | H5: -1618886000000 | I5: -657030000000
A6: Tiền thu được từ thanh lý, nhượng bán tài sản cố định | B6: 6097000000 | C6: 31428000000 | D6: 6837000000 | E6: 57506000000 | F6: 44111000000 | G6: 22156000000 | H6: 1741528000000 | I6: 3503000000
A7: Tiền chi đầu tư, góp vốn vào các đơn vị khác | B7: -799000000 | C7: 0 | D7: 0 | E7: -1497000000 | F7: 0 | G7: -3033432000000 | H7: -56278000000 | I7: -199836000000
A8: Tiền thu từ đầu tư, góp vốn vào các đơn vị khác | B8: 915560000000 | C8: 0 | D8: 0 | E8: 0 | F8: 0 | G8: 0 | H8: 0 | I8: 0
A9: Tiền thu cổ tức và lợi nhuận được chia từ các khoản đầu tư góp vốn dài hạn | B9: 275000000 | C9: 4216000000 | D9: 4191000000 | E9: 4043000000 | F9: 8776000000 | G9: 34756000000 | H9: 64561000000 | I9: 39938000000
A10: Lưu chuyển tiền thuần từ hoạt động đầu tư | B10: 519470000000 | C10: -222244000000 | D10: -655391000000 | E10: -879943000000 | F10: -1057275000000 | G10: -2912466000000 | H10: -382599000000 | I10: -816440000000
A11: Tăng vốn cổ phần từ góp vốn và/hoặc phát hành cổ phiếu | B11: 0 | C11: 35428000000 | D11: 47602000000 | E11: 60053000000 | F11: 65072000000 | G11: 52664000000 | H11: 200495000000 | I11: 12320661000000
A12: Cổ tức trả cho cổ đông, lợi nhuận đã chia | B12: 0 | C12: 0 | D12: -65086000000 | E12: 0 | F12: -74648000000 | G12: 854000000 | H12: -5210255000000 | I12: -7084911000000
A13: Lưu chuyển tiền thuần trong kỳ | B13: 13699378000000 | C13: -3094234000000 | D13: -174546000000 | E13: 60053000000 | F13: -709576000000 | G13: 53518000000 | H13: -5009760000000 | I13: 5235750000000
... A53: Chênh lệch số tiền thực thu/thực chi từ hoạt động kinh doanh | B53: 1310321000000 | C53: 1703869000000 | D53: 1897196000000 | E53: 2502188000000 | F53: -420995000000 | G53: 1168505000000 | H53: 3150018000000 | I53: 4478027000000

Sheet chi_so_tai_chinh
A1: Chỉ tiêu | B1: =balance_sheet!B1 | C1: =balance_sheet!C1 | D1: =balance_sheet!D1 | E1: =balance_sheet!E1 | F1: =balance_sheet!F1 | G1: =balance_sheet!G1 | H1: =balance_sheet!H1 | I1: =balance_sheet!I1 | J1: 2026
A2: ROE | C2: =IFERROR(C$60/AVERAGE(B$48,C$48),"n/a") | D2: =IFERROR(D$60/AVERAGE(C$48,D$48),"n/a") | E2: =IFERROR(E$60/AVERAGE(D$48,E$48),"n/a") | F2: =IFERROR(F$60/AVERAGE(E$48,F$48),"n/a") | G2: =IFERROR(G$60/AVERAGE(F$48,G$48),"n/a") | H2: =IFERROR(H$60/AVERAGE(G$48,H$48),"n/a") | I2: =IFERROR(I$60/AVERAGE(H$48,I$48),"n/a")
A3: Tăng trưởng LNST | C3: =IFERROR((C$60-B$60)/ABS(B$60),"n/a") | D3: =IFERROR((D$60-C$60)/ABS(C$60),"n/a") | E3: =IFERROR((E$60-D$60)/ABS(D$60),"n/a") | F3: =IFERROR((F$60-E$60)/ABS(E$60),"n/a") | G3: =IFERROR((G$60-F$60)/ABS(F$60),"n/a") | H3: =IFERROR((H$60-G$60)/ABS(G$60),"n/a") | I3: =IFERROR((I$60-H$60)/ABS(H$60),"n/a") | J3: =IFERROR((J$60-I$60)/ABS(I$60),"n/a")
A4: Tăng trưởng thu nhập hoạt động | C4: =IFERROR((C$54-B$54)/ABS(B$54),"n/a") | D4: =IFERROR((D$54-C$54)/ABS(C$54),"n/a") | E4: =IFERROR((E$54-D$54)/ABS(D$54),"n/a") | F4: =IFERROR((F$54-E$54)/ABS(E$54),"n/a") | G4: =IFERROR((G$54-F$54)/ABS(F$54),"n/a") | H4: =IFERROR((H$54-G$54)/ABS(G$54),"n/a") | I4: =IFERROR((I$54-H$54)/ABS(H$54),"n/a")
A5: % Dư nợ cho vay kinh doanh BĐS | B5: =IFERROR(B$36/#REF!,"n/a") | C5: =IFERROR(C$36/#REF!,"n/a") | D5: =IFERROR(D$36/#REF!,"n/a") | E5: =IFERROR(E$36/#REF!,"n/a") | F5: =IFERROR(F$36/#REF!,"n/a") | G5: =IFERROR(G$36/#REF!,"n/a") | H5: =IFERROR(H$36/#REF!,"n/a") | I5: =IFERROR(I$36/#REF!,"n/a")
A6: NIM | B6: =IFERROR(B$54/AVERAGE(B$42,A42),"n/a") | C6: =IFERROR(C$54/AVERAGE(C$42,B42),"n/a") | D6: =IFERROR(D$54/AVERAGE(D$42,C42),"n/a") | E6: =IFERROR(E$54/AVERAGE(E$42,D42),"n/a") | F6: =IFERROR(F$54/AVERAGE(F$42,E42),"n/a") | G6: =IFERROR(G$54/AVERAGE(G$42,F42),"n/a") | H6: =IFERROR(H$54/AVERAGE(H$42,G42),"n/a") | I6: =IFERROR(I$54/AVERAGE(I$42,H42),"n/a")
A7: CASA | C7: =IFERROR((B$45+C$45+B$47+C$47)/(B$44+C$44),"n/a") | D7: =IFERROR((C$45+D$45+C$47+D$47)/(C$44+D$44),"n/a") | E7: =IFERROR((D$45+E$45+D$47+E$47)/(D$44+E$44),"n/a") | F7: =IFERROR((E$45+F$45+E$47+F$47)/(E$44+F$44),"n/a") | G7: =IFERROR((F$45+G$45+F$47+G$47)/(F$44+G$44),"n/a") | H7: =IFERROR((G$45+H$45+G$47+H$47)/(G$44+H$44),"n/a") | I7: =IFERROR((H$45+I$45+H$47+I$47)/(H$44+I$44),"n/a")
A8: NPL | C8: =IFERROR((C$35/#REF!),"n/a") | D8: =IFERROR((D$35/#REF!),"n/a") | E8: =IFERROR((E$35/#REF!),"n/a") | F8: =IFERROR((F$35/#REF!),"n/a") | G8: =IFERROR((G$35/#REF!),"n/a") | H8: =IFERROR((H$35/#REF!),"n/a") | I8: =IFERROR((I$35/#REF!),"n/a")
A9: COF | C9: =IFERROR(ABS(C$53)/AVERAGE(C$42,B42),"n/a") | D9: =IFERROR(ABS(D$53)/AVERAGE(D$42,C42),"n/a") | E9: =IFERROR(ABS(E$53)/AVERAGE(E$42,D42),"n/a") | F9: =IFERROR(ABS(F$53)/AVERAGE(F$42,E42),"n/a") | G9: =IFERROR(ABS(G$53)/AVERAGE(G$42,F42),"n/a") | H9: =IFERROR(ABS(H$53)/AVERAGE(H$42,G42),"n/a") | I9: =IFERROR(ABS(I$53)/AVERAGE(I$42,H42),"n/a")
A10: LLR | B10: =IFERROR(ABS(B$37)/B$35,"n/a") | C10: =IFERROR(ABS(C$37)/C$35,"n/a") | D10: =IFERROR(ABS(D$37)/D$35,"n/a") | E10: =IFERROR(ABS(E$37)/E$35,"n/a") | F10: =IFERROR(ABS(F$37)/F$35,"n/a") | G10: =IFERROR(ABS(G$37)/G$35,"n/a") | H10: =IFERROR(ABS(H$37)/H$35,"n/a") | I10: =IFERROR(ABS(I$37)/I$35,"n/a")
A11: CAR
A12: LDR | B12: =IFERROR(B$29/B$44,"n/a") | C12: =IFERROR(C$29/C$44,"n/a") | D12: =IFERROR(D$29/D$44,"n/a") | E12: =IFERROR(E$29/E$44,"n/a") | F12: =IFERROR(F$29/F$44,"n/a") | G12: =IFERROR(G$29/G$44,"n/a") | H12: =IFERROR(H$29/H$44,"n/a") | I12: =IFERROR(I$29/I$44,"n/a")
A13: Tăng trưởng vốn huy động | C13: =IFERROR((C$44-B$44)/ABS(B$44),"n/a") | D13: =IFERROR((D$44-C$44)/ABS(C$44),"n/a") | E13: =IFERROR((E$44-D$44)/ABS(D$44),"n/a") | F13: =IFERROR((F$44-E$44)/ABS(E$44),"n/a") | G13: =IFERROR((G$44-F$44)/ABS(F$44),"n/a") | H13: =IFERROR((H$44-G$44)/ABS(G$44),"n/a") | I13: =IFERROR((I$44-H$44)/ABS(H$44),"n/a")
A14: Tăng trưởng tín dụng | C14: =IFERROR((C$29-B$29)/ABS(B$29),"n/a") | D14: =IFERROR((D$29-C$29)/ABS(C$29),"n/a") | E14: =IFERROR((E$29-D$29)/ABS(D$29),"n/a") | F14: =IFERROR((F$29-E$29)/ABS(E$29),"n/a") | G14: =IFERROR((G$29-F$29)/ABS(F$29),"n/a") | H14: =IFERROR((H$29-G$29)/ABS(G$29),"n/a") | I14: =IFERROR((I$29-H$29)/ABS(H$29),"n/a")
A15: CIR | B15: =IFERROR(ABS(B$57)/B$56,"n/a") | C15: =IFERROR(ABS(C$57)/C$56,"n/a") | D15: =IFERROR(ABS(D$57)/D$56,"n/a") | E15: =IFERROR(ABS(E$57)/E$56,"n/a") | F15: =IFERROR(ABS(F$57)/F$56,"n/a") | G15: =IFERROR(ABS(G$57)/G$56,"n/a") | H15: =IFERROR(ABS(H$57)/H$56,"n/a") | I15: =IFERROR(ABS(I$57)/I$56,"n/a")
A16: VCSH/Tổng tài sản | B16: =IFERROR(B$48/B$24,"n/a") | C16: =IFERROR(C$48/C$24,"n/a") | D16: =IFERROR(D$48/D$24,"n/a") | E16: =IFERROR(E$48/E$24,"n/a") | F16: =IFERROR(F$48/F$24,"n/a") | G16: =IFERROR(G$48/G$24,"n/a") | H16: =IFERROR(H$48/H$24,"n/a") | I16: =IFERROR(I$48/I$24,"n/a")
A17: Tỷ lệ lãi và phí phải thu/Thu nhập lãi | B17: =IFERROR(B58/B$52,"n/a") | C17: =IFERROR(C58/C$52,"n/a") | D17: =IFERROR(D58/D$52,"n/a") | E17: =IFERROR(E58/E$52,"n/a") | F17: =IFERROR(F58/F$52,"n/a") | G17: =IFERROR(G58/G$52,"n/a") | H17: =IFERROR(H58/H$52,"n/a") | I17: =IFERROR(I58/I$52,"n/a")
A18: Thu nhập ngoài lãi/Thu nhập hoạt động | B18: =IFERROR(B$55/B$56,"n/a") | C18: =IFERROR(C$55/C$56,"n/a") | D18: =IFERROR(D$55/D$56,"n/a") | E18: =IFERROR(E$55/E$56,"n/a") | F18: =IFERROR(F$55/F$56,"n/a") | G18: =IFERROR(G$55/G$56,"n/a") | H18: =IFERROR(H$55/H$56,"n/a") | I18: =IFERROR(I$55/I$56,"n/a")
A20: II. DỮ LIỆU TRÍCH XUẤT (tự động dò theo tên khoản mục)
A21: Khoản mục | B21: =balance_sheet!B1 | C21: =balance_sheet!C1 | D21: =balance_sheet!D1 | E21: =balance_sheet!E1 | F21: =balance_sheet!F1 | G21: =balance_sheet!G1 | H21: =balance_sheet!H1 | I21: =balance_sheet!I1
A22: CĐKT
A23: Tài sản
A24: TỔNG TÀI SẢN | B24: =IFERROR(INDEX(balance_sheet!$B:$I,MATCH("TỔNG TÀI SẢN",balance_sheet!$A:$A,0),MATCH(B$21,balance_sheet!$B$1:$I$1,0)),"") | C24: =IFERROR(INDEX(balance_sheet!$B:$I,MATCH("TỔNG TÀI SẢN",balance_sheet!$A:$A,0),MATCH(C$21,balance_sheet!$B$1:$I$1,0)),"") | D24: =IFERROR(INDEX(balance_sheet!$B:$I,MATCH("TỔNG TÀI SẢN",balance_sheet!$A:$A,0),MATCH(D$21,balance_sheet!$B$1:$I$1,0)),"") | E24: =IFERROR(INDEX(balance_sheet!$B:$I,MATCH("TỔNG TÀI SẢN",balance_sheet!$A:$A,0),MATCH(E$21,balance_sheet!$B$1:$I$1,0)),"") | F24: =IFERROR(INDEX(balance_sheet!$B:$I,MATCH("TỔNG TÀI SẢN",balance_sheet!$A:$A,0),MATCH(F$21,balance_sheet!$B$1:$I$1,0)),"") | G24: =IFERROR(INDEX(balance_sheet!$B:$I,MATCH("TỔNG TÀI SẢN",balance_sheet!$A:$A,0),MATCH(G$21,balance_sheet!$B$1:$I$1,0)),"") | H24: =IFERROR(INDEX(balance_sheet!$B:$I,MATCH("TỔNG TÀI SẢN",balance_sheet!$A:$A,0),MATCH(H$21,balance_sheet!$B$1:$I$1,0)),"") | I24: =IFERROR(INDEX(balance_sheet!$B:$I,MATCH("TỔNG TÀI SẢN",balance_sheet!$A:$A,0),MATCH(I$21,balance_sheet!$B$1:$I$1,0)),"")
A25: Tiền gửi tại Ngân hàng nhà nước Việt Nam | B25: =IFERROR(INDEX(balance_sheet!$B:$I,MATCH("Tiền gửi tại Ngân hàng nhà nước Việt Nam",balance_sheet!$A:$A,0),MATCH(B$21,balance_sheet!$B$1:$I$1,0)),"") | C25: =IFERROR(INDEX(balance_sheet!$B:$I,MATCH("Tiền gửi tại Ngân hàng nhà nước Việt Nam",balance_sheet!$A:$A,0),MATCH(C$21,balance_sheet!$B$1:$I$1,0)),"") | D25: =IFERROR(INDEX(balance_sheet!$B:$I,MATCH("Tiền gửi tại Ngân hàng nhà nước Việt Nam",balance_sheet!$A:$A,0),MATCH(D$21,balance_sheet!$B$1:$I$1,0)),"") | E25: =IFERROR(INDEX(balance_sheet!$B:$I,MATCH("Tiền gửi tại Ngân hàng nhà nước Việt Nam",balance_sheet!$A:$A,0),MATCH(E$21,balance_sheet!$B$1:$I$1,0)),"") | F25: =IFERROR(INDEX(balance_sheet!$B:$I,MATCH("Tiền gửi tại Ngân hàng nhà nước Việt Nam",balance_sheet!$A:$A,0),MATCH(F$21,balance_sheet!$B$1:$I$1,0)),"") | G25: =IFERROR(INDEX(balance_sheet!$B:$I,MATCH("Tiền gửi tại Ngân hàng nhà nước Việt Nam",balance_sheet!$A:$A,0),MATCH(G$21,balance_sheet!$B$1:$I$1,0)),"") | H25: =IFERROR(INDEX(balance_sheet!$B:$I,MATCH("Tiền gửi tại Ngân hàng nhà nước Việt Nam",balance_sheet!$A:$A,0),MATCH(H$21,balance_sheet!$B$1:$I$1,0)),"") | I25: =IFERROR(INDEX(balance_sheet!$B:$I,MATCH("Tiền gửi tại Ngân hàng nhà nước Việt Nam",balance_sheet!$A:$A,0),MATCH(I$21,balance_sheet!$B$1:$I$1,0)),"")
A26: Tiền gửi tại các TCTD khác và cho vay các TCTD khác | B26: =IFERROR(INDEX(balance_sheet!$B:$I,MATCH("Tiền gửi tại các TCTD khác và cho vay các TCTD khác",balance_sheet!$A:$A,0),MATCH(B$21,balance_sheet!$B$1:$I$1,0)),"") | C26: =IFERROR(INDEX(balance_sheet!$B:$I,MATCH("Tiền gửi tại các TCTD khác và cho vay các TCTD khác",balance_sheet!$A:$A,0),MATCH(C$21,balance_sheet!$B$1:$I$1,0)),"") | D26: =IFERROR(INDEX(balance_sheet!$B:$I,MATCH("Tiền gửi tại các TCTD khác và cho vay các TCTD khác",balance_sheet!$A:$A,0),MATCH(D$21,balance_sheet!$B$1:$I$1,0)),"") | E26: =IFERROR(INDEX(balance_sheet!$B:$I,MATCH("Tiền gửi tại các TCTD khác và cho vay các TCTD khác",balance_sheet!$A:$A,0),MATCH(E$21,balance_sheet!$B$1:$I$1,0)),"") | F26: =IFERROR(INDEX(balance_sheet!$B:$I,MATCH("Tiền gửi tại các TCTD khác và cho vay các TCTD khác",balance_sheet!$A:$A,0),MATCH(F$21,balance_sheet!$B$1:$I$1,0)),"") | G26: =IFERROR(INDEX(balance_sheet!$B:$I,MATCH("Tiền gửi tại các TCTD khác và cho vay các TCTD khác",balance_sheet!$A:$A,0),MATCH(G$21,balance_sheet!$B$1:$I$1,0)),"") | H26: =IFERROR(INDEX(balance_sheet!$B:$I,MATCH("Tiền gửi tại các TCTD khác và cho vay các TCTD khác",balance_sheet!$A:$A,0),MATCH(H$21,balance_sheet!$B$1:$I$1,0)),"") | I26: =IFERROR(INDEX(balance_sheet!$B:$I,MATCH("Tiền gửi tại các TCTD khác và cho vay các TCTD khác",balance_sheet!$A:$A,0),MATCH(I$21,balance_sheet!$B$1:$I$1,0)),"")
A27: Dự phòng rủi ro cho vay các TCTD khác | B27: =IFERROR(INDEX(balance_sheet!$B:$I,MATCH("Dự phòng rủi ro",balance_sheet!$A:$A,0),MATCH(B$21,balance_sheet!$B$1:$I$1,0)),"") | C27: =IFERROR(INDEX(balance_sheet!$B:$I,MATCH("Dự phòng rủi ro",balance_sheet!$A:$A,0),MATCH(C$21,balance_sheet!$B$1:$I$1,0)),"") | D27: =IFERROR(INDEX(balance_sheet!$B:$I,MATCH("Dự phòng rủi ro",balance_sheet!$A:$A,0),MATCH(D$21,balance_sheet!$B$1:$I$1,0)),"") | E27: =IFERROR(INDEX(balance_sheet!$B:$I,MATCH("Dự phòng rủi ro",balance_sheet!$A:$A,0),MATCH(E$21,balance_sheet!$B$1:$I$1,0)),"") | F27: =IFERROR(INDEX(balance_sheet!$B:$I,MATCH("Dự phòng rủi ro",balance_sheet!$A:$A,0),MATCH(F$21,balance_sheet!$B$1:$I$1,0)),"") | G27: =IFERROR(INDEX(balance_sheet!$B:$I,MATCH("Dự phòng rủi ro",balance_sheet!$A:$A,0),MATCH(G$21,balance_sheet!$B$1:$I$1,0)),"") | H27: =IFERROR(INDEX(balance_sheet!$B:$I,MATCH("Dự phòng rủi ro",balance_sheet!$A:$A,0),MATCH(H$21,balance_sheet!$B$1:$I$1,0)),"") | I27: =IFERROR(INDEX(balance_sheet!$B:$I,MATCH("Dự phòng rủi ro",balance_sheet!$A:$A,0),MATCH(I$21,balance_sheet!$B$1:$I$1,0)),"")
A28: Chứng khoán kinh doanh | B28: =IFERROR(INDEX(balance_sheet!$B:$I,MATCH("Chứng khoán kinh doanh",balance_sheet!$A:$A,0),MATCH(B$21,balance_sheet!$B$1:$I$1,0)),"") | C28: =IFERROR(INDEX(balance_sheet!$B:$I,MATCH("Chứng khoán kinh doanh",balance_sheet!$A:$A,0),MATCH(C$21,balance_sheet!$B$1:$I$1,0)),"") | D28: =IFERROR(INDEX(balance_sheet!$B:$I,MATCH("Chứng khoán kinh doanh",balance_sheet!$A:$A,0),MATCH(D$21,balance_sheet!$B$1:$I$1,0)),"") | E28: =IFERROR(INDEX(balance_sheet!$B:$I,MATCH("Chứng khoán kinh doanh",balance_sheet!$A:$A,0),MATCH(E$21,balance_sheet!$B$1:$I$1,0)),"") | F28: =IFERROR(INDEX(balance_sheet!$B:$I,MATCH("Chứng khoán kinh doanh",balance_sheet!$A:$A,0),MATCH(F$21,balance_sheet!$B$1:$I$1,0)),"") | G28: =IFERROR(INDEX(balance_sheet!$B:$I,MATCH("Chứng khoán kinh doanh",balance_sheet!$A:$A,0),MATCH(G$21,balance_sheet!$B$1:$I$1,0)),"") | H28: =IFERROR(INDEX(balance_sheet!$B:$I,MATCH("Chứng khoán kinh doanh",balance_sheet!$A:$A,0),MATCH(H$21,balance_sheet!$B$1:$I$1,0)),"") | I28: =IFERROR(INDEX(balance_sheet!$B:$I,MATCH("Chứng khoán kinh doanh",balance_sheet!$A:$A,0),MATCH(I$21,balance_sheet!$B$1:$I$1,0)),"")
A29: Cho vay khách hàng | B29: =IFERROR(INDEX(balance_sheet!$B:$I,MATCH("Cho vay khách hàng",balance_sheet!$A:$A,0),MATCH(B$21,balance_sheet!$B$1:$I$1,0)),"") | C29: =IFERROR(INDEX(balance_sheet!$B:$I,MATCH("Cho vay khách hàng",balance_sheet!$A:$A,0),MATCH(C$21,balance_sheet!$B$1:$I$1,0)),"") | D29: =IFERROR(INDEX(balance_sheet!$B:$I,MATCH("Cho vay khách hàng",balance_sheet!$A:$A,0),MATCH(D$21,balance_sheet!$B$1:$I$1,0)),"") | E29: =IFERROR(INDEX(balance_sheet!$B:$I,MATCH("Cho vay khách hàng",balance_sheet!$A:$A,0),MATCH(E$21,balance_sheet!$B$1:$I$1,0)),"") | F29: =IFERROR(INDEX(balance_sheet!$B:$I,MATCH("Cho vay khách hàng",balance_sheet!$A:$A,0),MATCH(F$21,balance_sheet!$B$1:$I$1,0)),"") | G29: =IFERROR(INDEX(balance_sheet!$B:$I,MATCH("Cho vay khách hàng",balance_sheet!$A:$A,0),MATCH(G$21,balance_sheet!$B$1:$I$1,0)),"") | H29: =IFERROR(INDEX(balance_sheet!$B:$I,MATCH("Cho vay khách hàng",balance_sheet!$A:$A,0),MATCH(H$21,balance_sheet!$B$1:$I$1,0)),"") | I29: =IFERROR(INDEX(balance_sheet!$B:$I,MATCH("Cho vay khách hàng",balance_sheet!$A:$A,0),MATCH(I$21,balance_sheet!$B$1:$I$1,0)),"")
A30: + Nợ đủ tiêu chuẩn | B30: 154548000000000 | C30: 225601000000000 | D30: 274424000000000 | E30: 342903000000000 | F30: 399403000000000 | G30: 491584000000000 | H30: 594272000000000 | I30: 711707000000000
A31: + Nợ cần chú ý | B31: 2588000000000 | C31: 2123000000000 | D31: 1806000000000 | E31: 2145000000000 | F31: 8733000000000 | G31: 4439000000000 | H31: 4441000000000 | I31: 3852000000000
A32: + Nợ dưới tiêu chuẩn | B32: 238000000000 | C32: 218000000000 | D32: 417000000000 | E32: 679000000000 | F32: 902000000000 | G32: 1857000000000 | H32: 1366000000000 | I32: 918000000000
A33: + Nợ nghi ngờ | B33: 86000000000 | C33: 31000000000 | D33: 534000000000 | E33: 860000000000 | F33: 1131000000000 | G33: 2762000000000 | H33: 2466000000000 | I33: 1339000000000
A34: + Nợ có khả năng mất vốn | B34: 1703000000000 | C34: 2555000000000 | D34: 344000000000 | E34: 755000000000 | F34: 1000000000000 | G34: 1380000000000 | H34: 3270000000000 | I34: 5941000000000
A35: Nợ xấu | B35: =SUM(B32:B34) | C35: =SUM(C32:C34) | D35: =SUM(D32:D34) | E35: =SUM(E32:E34) | F35: =SUM(F32:F34) | G35: =SUM(G32:G34) | H35: =SUM(H32:H34) | I35: =SUM(I32:I34)
A36: Cho vay KDBĐS | B36: 13555000000000 | C36: 50422000000000 | D36: 91361000000000 | E36: 95613000000000 | F36: 108805000000000 | G36: 176804000000000 | H36: 187100000000000 | I36: 207027000000000
A37: Dự phòng rủi ro cho vay khách hàng | B37: =IFERROR(INDEX(balance_sheet!$B:$I,MATCH("Dự phòng rủi ro cho vay khách hàng",balance_sheet!$A:$A,0),MATCH(B$21,balance_sheet!$B$1:$I$1,0)),"") | C37: =IFERROR(INDEX(balance_sheet!$B:$I,MATCH("Dự phòng rủi ro cho vay khách hàng",balance_sheet!$A:$A,0),MATCH(C$21,balance_sheet!$B$1:$I$1,0)),"") | D37: =IFERROR(INDEX(balance_sheet!$B:$I,MATCH("Dự phòng rủi ro cho vay khách hàng",balance_sheet!$A:$A,0),MATCH(D$21,balance_sheet!$B$1:$I$1,0)),"") | E37: =IFERROR(INDEX(balance_sheet!$B:$I,MATCH("Dự phòng rủi ro cho vay khách hàng",balance_sheet!$A:$A,0),MATCH(E$21,balance_sheet!$B$1:$I$1,0)),"") | F37: =IFERROR(INDEX(balance_sheet!$B:$I,MATCH("Dự phòng rủi ro cho vay khách hàng",balance_sheet!$A:$A,0),MATCH(F$21,balance_sheet!$B$1:$I$1,0)),"") | G37: =IFERROR(INDEX(balance_sheet!$B:$I,MATCH("Dự phòng rủi ro cho vay khách hàng",balance_sheet!$A:$A,0),MATCH(G$21,balance_sheet!$B$1:$I$1,0)),"") | H37: =IFERROR(INDEX(balance_sheet!$B:$I,MATCH("Dự phòng rủi ro cho vay khách hàng",balance_sheet!$A:$A,0),MATCH(H$21,balance_sheet!$B$1:$I$1,0)),"") | I37: =IFERROR(INDEX(balance_sheet!$B:$I,MATCH("Dự phòng rủi ro cho vay khách hàng",balance_sheet!$A:$A,0),MATCH(I$21,balance_sheet!$B$1:$I$1,0)),"")
A38: Chứng khoán đầu tư | B38: =IFERROR(INDEX(balance_sheet!$B:$I,MATCH("Chứng khoán đầu tư",balance_sheet!$A:$A,0),MATCH(B$21,balance_sheet!$B$1:$I$1,0)),"") | C38: =IFERROR(INDEX(balance_sheet!$B:$I,MATCH("Chứng khoán đầu tư",balance_sheet!$A:$A,0),MATCH(C$21,balance_sheet!$B$1:$I$1,0)),"") | D38: =IFERROR(INDEX(balance_sheet!$B:$I,MATCH("Chứng khoán đầu tư",balance_sheet!$A:$A,0),MATCH(D$21,balance_sheet!$B$1:$I$1,0)),"") | E38: =IFERROR(INDEX(balance_sheet!$B:$I,MATCH("Chứng khoán đầu tư",balance_sheet!$A:$A,0),MATCH(E$21,balance_sheet!$B$1:$I$1,0)),"") | F38: =IFERROR(INDEX(balance_sheet!$B:$I,MATCH("Chứng khoán đầu tư",balance_sheet!$A:$A,0),MATCH(F$21,balance_sheet!$B$1:$I$1,0)),"") | G38: =IFERROR(INDEX(balance_sheet!$B:$I,MATCH("Chứng khoán đầu tư",balance_sheet!$A:$A,0),MATCH(G$21,balance_sheet!$B$1:$I$1,0)),"") | H38: =IFERROR(INDEX(balance_sheet!$B:$I,MATCH("Chứng khoán đầu tư",balance_sheet!$A:$A,0),MATCH(H$21,balance_sheet!$B$1:$I$1,0)),"") | I38: =IFERROR(INDEX(balance_sheet!$B:$I,MATCH("Chứng khoán đầu tư",balance_sheet!$A:$A,0),MATCH(I$21,balance_sheet!$B$1:$I$1,0)),"")
A39: Dự phòng giảm giá chứng khoán đầu tư | B39: =IFERROR(INDEX(balance_sheet!$B:$I,MATCH("Dự phòng giảm giá chứng khoán đầu tư",balance_sheet!$A:$A,0),MATCH(B$21,balance_sheet!$B$1:$I$1,0)),"") | C39: =IFERROR(INDEX(balance_sheet!$B:$I,MATCH("Dự phòng giảm giá chứng khoán đầu tư",balance_sheet!$A:$A,0),MATCH(C$21,balance_sheet!$B$1:$I$1,0)),"") | D39: =IFERROR(INDEX(balance_sheet!$B:$I,MATCH("Dự phòng giảm giá chứng khoán đầu tư",balance_sheet!$A:$A,0),MATCH(D$21,balance_sheet!$B$1:$I$1,0)),"") | E39: =IFERROR(INDEX(balance_sheet!$B:$I,MATCH("Dự phòng giảm giá chứng khoán đầu tư",balance_sheet!$A:$A,0),MATCH(E$21,balance_sheet!$B$1:$I$1,0)),"") | F39: =IFERROR(INDEX(balance_sheet!$B:$I,MATCH("Dự phòng giảm giá chứng khoán đầu tư",balance_sheet!$A:$A,0),MATCH(F$21,balance_sheet!$B$1:$I$1,0)),"") | G39: =IFERROR(INDEX(balance_sheet!$B:$I,MATCH("Dự phòng giảm giá chứng khoán đầu tư",balance_sheet!$A:$A,0),MATCH(G$21,balance_sheet!$B$1:$I$1,0)),"") | H39: =IFERROR(INDEX(balance_sheet!$B:$I,MATCH("Dự phòng giảm giá chứng khoán đầu tư",balance_sheet!$A:$A,0),MATCH(H$21,balance_sheet!$B$1:$I$1,0)),"") | I39: =IFERROR(INDEX(balance_sheet!$B:$I,MATCH("Dự phòng giảm giá chứng khoán đầu tư",balance_sheet!$A:$A,0),MATCH(I$21,balance_sheet!$B$1:$I$1,0)),"")
A40: Góp vốn, đầu tư dài hạn | B40: =IFERROR(INDEX(balance_sheet!$B:$I,MATCH("Góp vốn, đầu tư dài hạn",balance_sheet!$A:$A,0),MATCH(B$21,balance_sheet!$B$1:$I$1,0)),"") | C40: =IFERROR(INDEX(balance_sheet!$B:$I,MATCH("Góp vốn, đầu tư dài hạn",balance_sheet!$A:$A,0),MATCH(C$21,balance_sheet!$B$1:$I$1,0)),"") | D40: =IFERROR(INDEX(balance_sheet!$B:$I,MATCH("Góp vốn, đầu tư dài hạn",balance_sheet!$A:$A,0),MATCH(D$21,balance_sheet!$B$1:$I$1,0)),"") | E40: =IFERROR(INDEX(balance_sheet!$B:$I,MATCH("Góp vốn, đầu tư dài hạn",balance_sheet!$A:$A,0),MATCH(E$21,balance_sheet!$B$1:$I$1,0)),"") | F40: =IFERROR(INDEX(balance_sheet!$B:$I,MATCH("Góp vốn, đầu tư dài hạn",balance_sheet!$A:$A,0),MATCH(F$21,balance_sheet!$B$1:$I$1,0)),"") | G40: =IFERROR(INDEX(balance_sheet!$B:$I,MATCH("Góp vốn, đầu tư dài hạn",balance_sheet!$A:$A,0),MATCH(G$21,balance_sheet!$B$1:$I$1,0)),"") | H40: =IFERROR(INDEX(balance_sheet!$B:$I,MATCH("Góp vốn, đầu tư dài hạn",balance_sheet!$A:$A,0),MATCH(H$21,balance_sheet!$B$1:$I$1,0)),"") | I40: =IFERROR(INDEX(balance_sheet!$B:$I,MATCH("Góp vốn, đầu tư dài hạn",balance_sheet!$A:$A,0),MATCH(I$21,balance_sheet!$B$1:$I$1,0)),"")
A41: Dự phòng giảm giá đầu tư dài hạn | B41: =IFERROR(INDEX(balance_sheet!$B:$I,MATCH("Dự phòng giảm giá đầu tư dài hạn",balance_sheet!$A:$A,0),MATCH(B$21,balance_sheet!$B$1:$I$1,0)),"") | C41: =IFERROR(INDEX(balance_sheet!$B:$I,MATCH("Dự phòng giảm giá đầu tư dài hạn",balance_sheet!$A:$A,0),MATCH(C$21,balance_sheet!$B$1:$I$1,0)),"") | D41: =IFERROR(INDEX(balance_sheet!$B:$I,MATCH("Dự phòng giảm giá đầu tư dài hạn",balance_sheet!$A:$A,0),MATCH(D$21,balance_sheet!$B$1:$I$1,0)),"") | E41: =IFERROR(INDEX(balance_sheet!$B:$I,MATCH("Dự phòng giảm giá đầu tư dài hạn",balance_sheet!$A:$A,0),MATCH(E$21,balance_sheet!$B$1:$I$1,0)),"") | F41: =IFERROR(INDEX(balance_sheet!$B:$I,MATCH("Dự phòng giảm giá đầu tư dài hạn",balance_sheet!$A:$A,0),MATCH(F$21,balance_sheet!$B$1:$I$1,0)),"") | G41: =IFERROR(INDEX(balance_sheet!$B:$I,MATCH("Dự phòng giảm giá đầu tư dài hạn",balance_sheet!$A:$A,0),MATCH(G$21,balance_sheet!$B$1:$I$1,0)),"") | H41: =IFERROR(INDEX(balance_sheet!$B:$I,MATCH("Dự phòng giảm giá đầu tư dài hạn",balance_sheet!$A:$A,0),MATCH(H$21,balance_sheet!$B$1:$I$1,0)),"") | I41: =IFERROR(INDEX(balance_sheet!$B:$I,MATCH("Dự phòng giảm giá đầu tư dài hạn",balance_sheet!$A:$A,0),MATCH(I$21,balance_sheet!$B$1:$I$1,0)),"")
...

Sheet Dự báo tăng trưởng
B1: Q1/2026 | C1: Q2/2026 | D1: Q3/2026 | E1: Q4/2026
A2: Số CP | B2: 7086240414 | C2: 7086240414 | D2: 7086240414 | E2: 7086240414
A3: Thị giá | B3: 31650 | C3: 31650 | D3: 31650 | E3: 31650
A4: Vốn hoá | B4: =B2*B3 | C4: =C2*C3 | D4: =D2*D3 | E4: =E2*E3
A6: VCSH | B6: 186683000000000 | C6: =B$6*(($E$6/$B$6)^(1/3)) | D6: =B$6*(($E$6/$B$6)^(2/3)) | E6: =chi_so_tai_chinh!J48
A7: LICĐKKS | B7: 9787000000000 | C7: =C6*0.02 | D7: =D6*0.02 | E7: =E6*0.02
A8: BV | B8: =B6-B7 | C8: =C6-C7 | D8: =D6-D7 | E8: =E6-E7
A9: BVPS | B9: =B8/B2 | C9: =C8/C2 | D9: =D8/D2 | E9: =E8/E2
A10: PB | B10: =B3/B9 | C10: =C3/C9 | D10: =D3/D9 | E10: =E3/E9

Sheet Hiệu quả thực hiện kế hoạch
A1: Chỉ tiêu | B1: 2022 | C1: 2023 | D1: 2024 | E1: 2025
A2: Lợi nhuận trước thuế kế hoạch | B2: 27000000 | C2: 22000000 | D2: 27100000 | E2: 31500000
A3: Lợi nhuận trước thuế thu nhập doanh nghiệp | B3: =chi_so_tai_chinh!F61/1000000 | C3: =chi_so_tai_chinh!G61/1000000 | D3: =chi_so_tai_chinh!H61/1000000 | E3: =chi_so_tai_chinh!I61/1000000
A4: %thực hiện | B4: =B3/B2 | C4: =C3/C2 | D4: =D3/D2 | E4: =E3/E2
A6: Trung vị %thực hiện LN trước thuế | B6: =MEDIAN(B4:E4)
A8: Tỷ lệ hoàn thành LNTT trên 95% | B8: =COUNTIF(B4:E4,">=95%")/COUNT(B4:D4)
