Workbook

Sheet balance_sheet
A1: item | B1: 2025 | C1: 2024 | D1: 2023 | E1: 2022
A2: Tiền mặt, vàng bạc, đá quý | B2: 4360821000000 | C2: 3384770000000 | D2: 3620695000000 | E2: 4215721000000
A3: Tài sản cố định | B3: 12122934000000 | C3: 12466885000000 | D3: 8892697000000 | E3: 8411382000000
A4: Tài sản cố định hữu hình | B4: 6343732000000 | C4: 6576699000000 | D4: 3527586000000 | E4: 3696812000000
A5: Nguyên giá TSCĐ hữu hình | B5: 9539276000000 | C5: 9080615000000 | D5: 5492566000000 | E5: 5156346000000
A6: Hao mòn TSCĐ hữu hình | B6: -3195544000000 | C6: -2503916000000 | D6: -1964980000000 | E6: -1459534000000
A7: Tài sản cố định thuê tài chính | B7: 0 | C7: 0 | D7: 0 | E7: 0
A8: Nguyên giá TSCĐ thuê tài chính | B8: 0 | C8: 0 | D8: 0 | E8: 0
A9: Hao mòn TSCĐ thuê tài chính | B9: 0 | C9: 0 | D9: 0 | E9: 0
A10: Tài sản cố định vô hình | B10: 5779202000000 | C10: 5890186000000 | D10: 5365111000000 | E10: 4714570000000
A11: Nguyên giá TSCĐ vô hình | B11: 9535997000000 | C11: 8485022000000 | D11: 7198784000000 | E11: 5913538000000
A12: Hao mòn TSCĐ vô hình | B12: -3756795000000 | C12: -2594836000000 | D12: -1833673000000 | E12: -1198968000000
A13: Bất động sản đầu tư | B13: 0 | C13: 0 | D13: 0 | E13: 1053124000000
... A87: Đầu tư vào công ty liên kết | B87: 32263000000 | C87: 0 | D87: 0 | E87: 0

Sheet income_statement
A1: item | B1: 2025 | C1: 2024 | D1: 2023 | E1: 2022
A2: Tổng lợi nhuận/lỗ trước thuế | B2: 32538066000000 | C2: 27538368000000 | D2: 22888228000000 | E2: 25567768000000
A3: Chi phí thuế TNDN hiện hành | B3: -6544225000000 | C3: -5787711000000 | D3: -4706721000000 | E3: -5174932000000
A4: Chi phí thuế TNDN hoãn lại | B4: -39369000000 | C4: 9447000000 | D4: 9359000000 | E4: 43590000000
A5: Chi phí thuế thu nhập doanh nghiệp | B5: -6583594000000 | C5: -5778264000000 | D5: -4697362000000 | E5: -5131342000000
A6: Lợi nhuận sau thuế | B6: 25954472000000 | C6: 21760104000000 | D6: 18190866000000 | E6: 20436426000000
A7: Lợi ích của cổ đông thiểu số | B7: -664242000000 | C7: -237176000000 | D7: -187064000000 | E7: -286049000000
A8: Cổ đông của Công ty mẹ | B8: 25290230000000 | C8: 21522928000000 | D8: 18003802000000 | E8: 20150377000000
A9: Lãi cơ bản trên cổ phiếu (VND) | B9: 3572 | C9: 3049 | D9: 2549 | E9: 5725
A10: Lãi trên cổ phiếu pha loãng (VND) | B10: 0 | C10: 0 | D10: 0 | E10: 0
A11: Thu nhập lãi và các khoản thu nhập tương tự | B11: 68017450000000 | C11: 60089462000000 | D11: 56707759000000 | E11: 44752636000000
A12: Chi phí lãi và các chi phí tương tự | B12: -29862359000000 | C12: -24581499000000 | D12: -29016639000000 | E12: -14462861000000
A13: Thu nhập lãi thuần | B13: 38155091000000 | C13: 35507963000000 | D13: 27691120000000 | E13: 30289775000000
... A27: Trích lập dự phòng tổn thất tín dụng | B27: -4420625000000 | C27: -4082294000000 | D27: -3921068000000 | E27: -1936294000000

Sheet cash_flow
A1: item | B1: 2025 | C1: 2024 | D1: 2023 | E1: 2022
A2: Lưu chuyển tiền thuần từ hoạt động kinh doanh trước những thay đổi về tài sản và vốn lưu động | B2: 33290586000000 | C2: 31037437000000 | D2: 24938816000000 | E2: 29013569000000
A3: Thuế thu nhập doanh nghiệp đã trả | B3: 0 | C3: 0 | D3: 0 | E3: 0
A4: Lưu chuyển tiền thuần từ các hoạt động sản xuất kinh doanh | B4: 39923618000000 | C4: 42376555000000 | D4: 12053287000000 | E4: 55468501000000
A5: Mua sắm TSCĐ | B5: -657030000000 | C5: -1618886000000 | D5: -1232358000000 | E5: -1110111000000
A6: Tiền thu được từ thanh lý, nhượng bán tài sản cố định | B6: 3503000000 | C6: 1741528000000 | D6: 22156000000 | E6: 44111000000
A7: Tiền chi đầu tư, góp vốn vào các đơn vị khác | B7: -199836000000 | C7: -56278000000 | D7: -3033432000000 | E7: 0
A8: Tiền thu từ đầu tư, góp vốn vào các đơn vị khác | B8: 0 | C8: 0 | D8: 0 | E8: 0
A9: Tiền thu cổ tức và lợi nhuận được chia từ các khoản đầu tư góp vốn dài hạn | B9: 39938000000 | C9: 64561000000 | D9: 34756000000 | E9: 8776000000
A10: Lưu chuyển tiền thuần từ hoạt động đầu tư | B10: -816440000000 | C10: -382599000000 | D10: -2912466000000 | E10: -1057275000000
A11: Tăng vốn cổ phần từ góp vốn và/hoặc phát hành cổ phiếu | B11: 12320661000000 | C11: 200495000000 | D11: 52664000000 | E11: 65072000000
A12: Cổ tức trả cho cổ đông, lợi nhuận đã chia | B12: -7084911000000 | C12: -5210255000000 | D12: 854000000 | E12: -74648000000
A13: Lưu chuyển tiền thuần trong kỳ | B13: 5235750000000 | C13: -5009760000000 | D13: 53518000000 | E13: -709576000000
... A53: Chênh lệch số tiền thực thu/thực chi từ hoạt động kinh doanh | B53: 4478027000000 | C53: 3150018000000 | D53: 1168505000000 | E53: -420995000000

Sheet chi_so_tai_chinh
A1: CHỈ SỐ TÀI CHÍNH — TCB
A2: Khối "CHỈ SỐ TÀI CHÍNH" tính bằng công thức từ khối "DỮ LIỆU TRÍCH XUẤT" bên dưới, không phải số nhập tay. Khối "DỮ LIỆU TRÍCH XUẤT" được dò tự động theo TÊN khoản mục (đúng theo tên gốc trong báo cáo) và theo NĂM từ 3 sheet balance_sheet / income_statement — không tham chiếu ô cố định. Có thể sửa nhãn khoản mục ở cột A khối này nếu công ty đổi tên dòng; công thức sẽ tự dò lại. Các năm được xếp tăng dần từ trái sang phải.
A3: Lưu ý: Đây là tổ chức tín dụng: báo cáo tài chính không có khái niệm hàng tồn kho / giá vốn hàng bán / phải thu-phải trả thương mại, và không tách vay ngắn hạn - dài hạn trên bảng cân đối. Các chỉ tiêu tương ứng hiển thị "n/a". Doanh thu dùng "Tổng thu nhập hoạt động" thay cho "Doanh thu thuần"; ROA/Biên lợi nhuận ròng dùng lợi nhuận sau thuế toàn ngân hàng.
A5: I. CHỈ SỐ TÀI CHÍNH
A6: Chỉ tiêu | B6: ='balance_sheet'!E1 | C6: ='balance_sheet'!D1 | D6: ='balance_sheet'!C1 | E6: ='balance_sheet'!B1
A7: 1. Khả năng sinh lời
A8: ROE (LNST CĐ Cty mẹ / VCSH bình quân) | B8: n/a | C8: =IFERROR(C$55/((C$40+B$40)/2),"n/a") | D8: =IFERROR(D$55/((D$40+C$40)/2),"n/a") | E8: =IFERROR(E$55/((E$40+D$40)/2),"n/a")
A9: ROA (LNST / Tổng tài sản bình quân) | B9: n/a | C9: =IFERROR(C$54/((C$41+B$41)/2),"n/a") | D9: =IFERROR(D$54/((D$41+C$41)/2),"n/a") | E9: =IFERROR(E$54/((E$41+D$41)/2),"n/a")
A10: Tăng trưởng LN Cổ đông Cty mẹ | B10: n/a | C10: =IFERROR((C$55-B$55)/ABS(B$55),"n/a") | D10: =IFERROR((D$55-C$55)/ABS(C$55),"n/a") | E10: =IFERROR((E$55-D$55)/ABS(D$55),"n/a")
A11: Tăng trưởng Doanh thu thuần | B11: n/a | C11: =IFERROR((C$47-B$47)/ABS(B$47),"n/a") | D11: =IFERROR((D$47-C$47)/ABS(C$47),"n/a") | E11: =IFERROR((E$47-D$47)/ABS(D$47),"n/a")
A13: 2. Biên lợi nhuận
A14: Biên lợi nhuận gộp | B14: =IFERROR(B$49/B$47,"n/a") | C14: =IFERROR(C$49/C$47,"n/a") | D14: =IFERROR(D$49/D$47,"n/a") | E14: =IFERROR(E$49/E$47,"n/a")
A15: Biên lợi nhuận ròng | B15: =IFERROR(B$54/B$47,"n/a") | C15: =IFERROR(C$54/C$47,"n/a") | D15: =IFERROR(D$54/D$47,"n/a") | E15: =IFERROR(E$54/E$47,"n/a")
A17: 3. Đòn bẩy tài chính
A18: D/E (Nợ vay / Vốn chủ sở hữu) | B18: =IFERROR((B$45+B$46)/B$40,"n/a") | C18: =IFERROR((C$45+C$46)/C$40,"n/a") | D18: =IFERROR((D$45+D$46)/D$40,"n/a") | E18: =IFERROR((E$45+E$46)/E$40,"n/a")
A19: - Nợ vay dài hạn/Vốn chủ sở hữu | B19: =IFERROR(B$46/B$40,"n/a") | C19: =IFERROR(C$46/C$40,"n/a") | D19: =IFERROR(D$46/D$40,"n/a") | E19: =IFERROR(E$46/E$40,"n/a")
A20: - Nợ vay ngắn hạn/Vốn chủ sở hữu | B20: =IFERROR(B$45/B$40,"n/a") | C20: =IFERROR(C$45/C$40,"n/a") | D20: =IFERROR(D$45/D$40,"n/a") | E20: =IFERROR(E$45/E$40,"n/a")
A21: Nợ phải trả/Vốn chủ sở hữu | B21: =IFERROR(B$42/B$40,"n/a") | C21: =IFERROR(C$42/C$40,"n/a") | D21: =IFERROR(D$42/D$40,"n/a") | E21: =IFERROR(E$42/E$40,"n/a")
A22: - Nợ dài hạn/Vốn chủ sở hữu | B22: =IFERROR(B$44/B$40,"n/a") | C22: =IFERROR(C$44/C$40,"n/a") | D22: =IFERROR(D$44/D$40,"n/a") | E22: =IFERROR(E$44/E$40,"n/a")
A23: - Nợ ngắn hạn/Vốn chủ sở hữu | B23: =IFERROR(B$43/B$40,"n/a") | C23: =IFERROR(C$43/C$40,"n/a") | D23: =IFERROR(D$43/D$40,"n/a") | E23: =IFERROR(E$43/E$40,"n/a")
A25: 4. Chi phí & khả năng trả lãi
A26: Chi phí bán hàng, quản lý/LN gộp | B26: =IFERROR((ABS(B$50)+ABS(B$51))/B$49,"n/a") | C26: =IFERROR((ABS(C$50)+ABS(C$51))/C$49,"n/a") | D26: =IFERROR((ABS(D$50)+ABS(D$51))/D$49,"n/a") | E26: =IFERROR((ABS(E$50)+ABS(E$51))/E$49,"n/a")
A27: Chi phí lãi vay/LN từ hoạt động kinh doanh | B27: =IFERROR(ABS(B$53)/B$52,"n/a") | C27: =IFERROR(ABS(C$53)/C$52,"n/a") | D27: =IFERROR(ABS(D$53)/D$52,"n/a") | E27: =IFERROR(ABS(E$53)/E$52,"n/a")
A29: 5. Chu kỳ hoạt động vốn lưu động
A30: Số ngày phải trả (DPO) | B30: n/a | C30: =IFERROR(((C$57+B$57)/2)/ABS(C$48)*365,"n/a") | D30: =IFERROR(((D$57+C$57)/2)/ABS(D$48)*365,"n/a") | E30: =IFERROR(((E$57+D$57)/2)/ABS(E$48)*365,"n/a")
A31: Số ngày phải thu (DSO) | B31: n/a | C31: =IFERROR(((C$56+B$56)/2)/C$47*365,"n/a") | D31: =IFERROR(((D$56+C$56)/2)/D$47*365,"n/a") | E31: =IFERROR(((E$56+D$56)/2)/E$47*365,"n/a")
A32: Số ngày tồn kho (DIO) | B32: n/a | C32: =IFERROR(((C$58+B$58)/2)/ABS(C$48)*365,"n/a") | D32: =IFERROR(((D$58+C$58)/2)/ABS(D$48)*365,"n/a") | E32: =IFERROR(((E$58+D$58)/2)/ABS(E$48)*365,"n/a")
A34: 6. Cơ cấu tài sản
A35: Tiền và tương đương tiền/Tài sản | B35: =IFERROR(B$59/B$41,"n/a") | C35: =IFERROR(C$59/C$41,"n/a") | D35: =IFERROR(D$59/D$41,"n/a") | E35: =IFERROR(E$59/E$41,"n/a")
A36: Hàng tồn kho/Tài sản | B36: =IFERROR(B$58/B$41,"n/a") | C36: =IFERROR(C$58/C$41,"n/a") | D36: =IFERROR(D$58/D$41,"n/a") | E36: =IFERROR(E$58/E$41,"n/a")
A38: II. DỮ LIỆU TRÍCH XUẤT (tự động dò theo tên khoản mục)
A39: Khoản mục | B39: ='balance_sheet'!E1 | C39: ='balance_sheet'!D1 | D39: ='balance_sheet'!C1 | E39: ='balance_sheet'!B1
A40: VỐN CHỦ SỞ HỮU | B40: =IFERROR(INDEX(balance_sheet!$B:$E,MATCH("VỐN CHỦ SỞ HỮU",balance_sheet!$A:$A,0),MATCH(B$39,balance_sheet!$B$1:$E$1,0)),"") | C40: =IFERROR(INDEX(balance_sheet!$B:$E,MATCH("VỐN CHỦ SỞ HỮU",balance_sheet!$A:$A,0),MATCH(C$39,balance_sheet!$B$1:$E$1,0)),"") | D40: =IFERROR(INDEX(balance_sheet!$B:$E,MATCH("VỐN CHỦ SỞ HỮU",balance_sheet!$A:$A,0),MATCH(D$39,balance_sheet!$B$1:$E$1,0)),"") | E40: =IFERROR(INDEX(balance_sheet!$B:$E,MATCH("VỐN CHỦ SỞ HỮU",balance_sheet!$A:$A,0),MATCH(E$39,balance_sheet!$B$1:$E$1,0)),"")
A41: TỔNG TÀI SẢN | B41: =IFERROR(INDEX(balance_sheet!$B:$E,MATCH("TỔNG TÀI SẢN",balance_sheet!$A:$A,0),MATCH(B$39,balance_sheet!$B$1:$E$1,0)),"") | C41: =IFERROR(INDEX(balance_sheet!$B:$E,MATCH("TỔNG TÀI SẢN",balance_sheet!$A:$A,0),MATCH(C$39,balance_sheet!$B$1:$E$1,0)),"") | D41: =IFERROR(INDEX(balance_sheet!$B:$E,MATCH("TỔNG TÀI SẢN",balance_sheet!$A:$A,0),MATCH(D$39,balance_sheet!$B$1:$E$1,0)),"") | E41: =IFERROR(INDEX(balance_sheet!$B:$E,MATCH("TỔNG TÀI SẢN",balance_sheet!$A:$A,0),MATCH(E$39,balance_sheet!$B$1:$E$1,0)),"")
A42: TỔNG NỢ PHẢI TRẢ | B42: =IFERROR(INDEX(balance_sheet!$B:$E,MATCH("TỔNG NỢ PHẢI TRẢ",balance_sheet!$A:$A,0),MATCH(B$39,balance_sheet!$B$1:$E$1,0)),"") | C42: =IFERROR(INDEX(balance_sheet!$B:$E,MATCH("TỔNG NỢ PHẢI TRẢ",balance_sheet!$A:$A,0),MATCH(C$39,balance_sheet!$B$1:$E$1,0)),"") | D42: =IFERROR(INDEX(balance_sheet!$B:$E,MATCH("TỔNG NỢ PHẢI TRẢ",balance_sheet!$A:$A,0),MATCH(D$39,balance_sheet!$B$1:$E$1,0)),"") | E42: =IFERROR(INDEX(balance_sheet!$B:$E,MATCH("TỔNG NỢ PHẢI TRẢ",balance_sheet!$A:$A,0),MATCH(E$39,balance_sheet!$B$1:$E$1,0)),"")
A43: Nợ ngắn hạn | B43: n/a | C43: n/a | D43: n/a | E43: n/a
A44: Nợ dài hạn | B44: n/a | C44: n/a | D44: n/a | E44: n/a
A45: Vay và nợ thuê tài chính ngắn hạn | B45: n/a | C45: n/a | D45: n/a | E45: n/a
A46: Vay và nợ thuê tài chính dài hạn | B46: n/a | C46: n/a | D46: n/a | E46: n/a
A47: Tổng thu nhập hoạt động | B47: =IFERROR(INDEX(income_statement!$B:$E,MATCH("Tổng thu nhập hoạt động",income_statement!$A:$A,0),MATCH(B$39,income_statement!$B$1:$E$1,0)),"") | C47: =IFERROR(INDEX(income_statement!$B:$E,MATCH("Tổng thu nhập hoạt động",income_statement!$A:$A,0),MATCH(C$39,income_statement!$B$1:$E$1,0)),"") | D47: =IFERROR(INDEX(income_statement!$B:$E,MATCH("Tổng thu nhập hoạt động",income_statement!$A:$A,0),MATCH(D$39,income_statement!$B$1:$E$1,0)),"") | E47: =IFERROR(INDEX(income_statement!$B:$E,MATCH("Tổng thu nhập hoạt động",income_statement!$A:$A,0),MATCH(E$39,income_statement!$B$1:$E$1,0)),"")
...
