Workbook

Sheet balance_sheet
A1: item | B1: 2018 | C1: 2019 | D1: 2020 | E1: 2021 | F1: 2022 | G1: 2023 | H1: 2024 | I1: 2025
A2: Tiền mặt, vàng bạc, đá quý | B2: 1736571000000 | C2: 2344291000000 | D2: 3109230000000 | E2: 3475341000000 | F2: 3744100000000 | G2: 3675394000000 | H2: 3349166000000 | I2: 4965786000000
A3: Tài sản cố định | B3: 2699314000000 | C3: 2798062000000 | D3: 4310919000000 | E3: 4678447000000 | F3: 5073508000000 | G3: 4854186000000 | H3: 5430416000000 | I3: 5616547000000
A4: Tài sản cố định hữu hình | B4: 1586152000000 | C4: 1642003000000 | D4: 3088524000000 | E4: 3213906000000 | F4: 3457561000000 | G4: 3194404000000 | H4: 3750696000000 | I4: 3805533000000
A5: Nguyên giá TSCĐ hữu hình | B5: 3268459000000 | C5: 3585813000000 | D5: 5387069000000 | E5: 6083517000000 | F5: 7110562000000 | G5: 7732608000000 | H5: 9014672000000 | I5: 9423236000000
A6: Hao mòn TSCĐ hữu hình | B6: -1682307000000 | C6: -1943810000000 | D6: -2298545000000 | E6: -2869611000000 | F6: -3653001000000 | G6: -4538204000000 | H6: -5263976000000 | I6: -5617703000000
A7: Tài sản cố định thuê tài chính | B7: 0 | C7: 0 | D7: 0 | E7: 0 | F7: 0 | G7: 0 | H7: 0 | I7: 0
A8: Nguyên giá TSCĐ thuê tài chính | B8: 0 | C8: 0 | D8: 0 | E8: 0 | F8: 0 | G8: 0 | H8: 0 | I8: 0
A9: Hao mòn TSCĐ thuê tài chính | B9: 0 | C9: 0 | D9: 0 | E9: 0 | F9: 0 | G9: 0 | H9: 0 | I9: 0
A10: Tài sản cố định vô hình | B10: 1113162000000 | C10: 1156059000000 | D10: 1222395000000 | E10: 1464541000000 | F10: 1615947000000 | G10: 1659782000000 | H10: 1679720000000 | I10: 1811014000000
A11: Nguyên giá TSCĐ vô hình | B11: 1823153000000 | C11: 1980168000000 | D11: 2277564000000 | E11: 2923616000000 | F11: 3565092000000 | G11: 4196144000000 | H11: 4976669000000 | I11: 5684904000000
A12: Hao mòn TSCĐ vô hình | B12: -709991000000 | C12: -824109000000 | D12: -1055169000000 | E12: -1459075000000 | F12: -1949145000000 | G12: -2536362000000 | H12: -3296949000000 | I12: -3873890000000
A13: Bất động sản đầu tư | B13: 30813000000 | C13: 30813000000 | D13: 247898000000 | E13: 268999000000 | F13: 236177000000 | G13: 240294000000 | H13: 234115000000 | I13: 222813000000
... A87: Đầu tư vào công ty liên kết | B87: 0 | C87: 0 | D87: 0 | E87: 0 | F87: 0 | G87: 0 | H87: 0 | I87: 0

Sheet income_statement
A1: item | B1: 2018 | C1: 2019 | D1: 2020 | E1: 2021 | F1: 2022 | G1: 2023 | H1: 2024 | I1: 2025
A2: Tổng lợi nhuận/lỗ trước thuế | B2: 7767373000000 | C2: 10036119000000 | D2: 10688276000000 | E2: 16527259000000 | F2: 22729320000000 | G2: 26306089000000 | H2: 28829328000000 | I2: 34268358000000
A3: Chi phí thuế TNDN hiện hành | B3: -1575157000000 | C3: -1959995000000 | D3: -2089420000000 | E3: -3307574000000 | F3: -4582973000000 | G3: -5269869000000 | H3: -5888266000000 | I3: -6876871000000
A4: Chi phí thuế TNDN hoãn lại | B4: -2315000000 | C4: -7520000000 | D4: 7183000000 | E4: 1752000000 | F4: 8838000000 | G4: 17572000000 | H4: 10202000000 | I4: -8509000000
A5: Chi phí thuế thu nhập doanh nghiệp | B5: -1577472000000 | C5: -1967515000000 | D5: -2082237000000 | E5: -3305822000000 | F5: -4574135000000 | G5: -5252297000000 | H5: -5878064000000 | I5: -6885380000000
A6: Lợi nhuận sau thuế | B6: 6189901000000 | C6: 8068604000000 | D6: 8606039000000 | E6: 13221437000000 | F6: 18155185000000 | G6: 21053792000000 | H6: 22951264000000 | I6: 27382978000000
A7: Lợi ích của cổ đông thiểu số | B7: -77187000000 | C7: -245831000000 | D7: -343380000000 | E7: -524362000000 | F7: -672450000000 | G7: -377004000000 | H7: -317507000000 | I7: -604039000000
A8: Cổ đông của Công ty mẹ | B8: 6112714000000 | C8: 7822773000000 | D8: 8262659000000 | E8: 12697075000000 | F8: 17482735000000 | G8: 20676788000000 | H8: 22633757000000 | I8: 26778939000000
A9: Lãi cơ bản trên cổ phiếu (VND) | B9: 2829 | C9: 3596 | D9: 2993 | E9: 3133 | F9: 3856 | G9: 3966 | H9: 3724 | I9: 3325
A10: Lãi trên cổ phiếu pha loãng (VND) | B10: 0 | C10: 0 | D10: 0 | E10: 0 | F10: 0 | G10: 0 | H10: 0 | I10: 0
A11: Thu nhập lãi và các khoản thu nhập tương tự | B11: 24824365000000 | C11: 31196604000000 | D11: 32767393000000 | E11: 38464932000000 | F11: 52485812000000 | G11: 69143043000000 | H11: 69061893000000 | I11: 89088116000000
A12: Chi phí lãi và các chi phí tương tự | B12: -10240868000000 | C12: -13196607000000 | D12: -12489598000000 | E12: -12265378000000 | F12: -16462690000000 | G12: -30459195000000 | H12: -27909674000000 | I12: -37477999000000
A13: Thu nhập lãi thuần | B13: 14583497000000 | C13: 17999997000000 | D13: 20277795000000 | E13: 26199554000000 | F13: 36023122000000 | G13: 38683848000000 | H13: 41152219000000 | I13: 51610117000000
... A27: Trích lập dự phòng tổn thất tín dụng | B27: -3035388000000 | C27: -4890623000000 | D27: -6118440000000 | E27: -8030051000000 | F27: -8047677000000 | G27: -6087032000000 | H27: -9576644000000 | I27: -13743504000000

Sheet cash_flow
A1: item | B1: 2018 | C1: 2019 | D1: 2020 | E1: 2021 | F1: 2022 | G1: 2023 | H1: 2024 | I1: 2025
A2: Lưu chuyển tiền thuần từ hoạt động kinh doanh trước những thay đổi về tài sản và vốn lưu động | B2: 9228303000000 | C2: 14987451000000 | D2: 15326289000000 | E2: 21229572000000 | F2: 29081781000000 | G2: 31334445000000 | H2: 29963896000000 | I2: 39713493000000
A3: Thuế thu nhập doanh nghiệp đã trả | B3: 0 | C3: 0 | D3: 0 | E3: 0 | F3: 0 | G3: 0 | H3: 0 | I3: 0
A4: Lưu chuyển tiền thuần từ các hoạt động sản xuất kinh doanh | B4: 2604652000000 | C4: 892883000000 | D4: 14739859000000 | E4: 4468298000000 | F4: 1876329000000 | G4: 41294612000000 | H4: -18576384000000 | I4: 137357399000000
A5: Mua sắm TSCĐ | B5: -483966000000 | C5: -701576000000 | D5: -823253000000 | E5: -1259868000000 | F5: -1748106000000 | G5: -1655386000000 | H5: -2301696000000 | I5: -1780261000000
A6: Tiền thu được từ thanh lý, nhượng bán tài sản cố định | B6: 5759000000 | C6: 2905000000 | D6: 4739000000 | E6: 7861000000 | F6: 2048000000 | G6: 3714000000 | H6: 6927000000 | I6: 231289000000
A7: Tiền chi đầu tư, góp vốn vào các đơn vị khác | B7: -1941000000 | C7: -9000000 | D7: -602000000 | E7: 0 | F7: -100091000000 | G7: -45500000000 | H7: -37651000000 | I7: -22024000000
A8: Tiền thu từ đầu tư, góp vốn vào các đơn vị khác | B8: 31925000000 | C8: 600000000 | D8: 7823000000 | E8: 13291000000 | F8: 271040000000 | G8: 34676000000 | H8: 41568000000 | I8: 2409280000000
A9: Tiền thu cổ tức và lợi nhuận được chia từ các khoản đầu tư góp vốn dài hạn | B9: 30178000000 | C9: 78227000000 | D9: 92511000000 | E9: 114835000000 | F9: 131941000000 | G9: 57083000000 | H9: 52643000000 | I9: 59336000000
A10: Lưu chuyển tiền thuần từ hoạt động đầu tư | B10: -418045000000 | C10: -619853000000 | D10: -718782000000 | E10: -1123881000000 | F10: -1443168000000 | G10: -1605413000000 | H10: -2238209000000 | I10: 904900000000
A11: Tăng vốn cổ phần từ góp vốn và/hoặc phát hành cổ phiếu | B11: 0 | C11: 432090000000 | D11: 1719922000000 | E11: 0 | F11: 0 | G11: 0 | H11: 2160445000000 | I11: 0
A12: Cổ tức trả cho cổ đông, lợi nhuận đã chia | B12: -1092592000000 | C12: -1304219000000 | D12: 0 | E12: 0 | F12: 0 | G12: -2266993000000 | H12: -2806251000000 | I12: -2072592000000
A13: Lưu chuyển tiền thuần trong kỳ | B13: -1092592000000 | C13: -1908841000000 | D13: 2292984000000 | E13: 0 | F13: 2120000000000 | G13: 1182007000000 | H13: 8759748000000 | I13: 3957417000000
... A53: Chênh lệch số tiền thực thu/thực chi từ hoạt động kinh doanh | B53: 754841000000 | C53: 1276978000000 | D53: 1607374000000 | E53: 3097962000000 | F53: 3231427000000 | G53: 2363720000000 | H53: 6277842000000 | I53: 3645303000000

Sheet chi_so_tai_chinh
A1: Chỉ tiêu | B1: =balance_sheet!B1 | C1: =balance_sheet!C1 | D1: =balance_sheet!D1 | E1: =balance_sheet!E1 | F1: =balance_sheet!F1 | G1: =balance_sheet!G1 | H1: =balance_sheet!H1 | I1: =balance_sheet!I1
A2: ROE | C2: =IFERROR(C$61/AVERAGE(B$49,C$49),"n/a") | D2: =IFERROR(D$61/AVERAGE(C$49,D$49),"n/a") | E2: =IFERROR(E$61/AVERAGE(D$49,E$49),"n/a") | F2: =IFERROR(F$61/AVERAGE(E$49,F$49),"n/a") | G2: =IFERROR(G$61/AVERAGE(F$49,G$49),"n/a") | H2: =IFERROR(H$61/AVERAGE(G$49,H$49),"n/a") | I2: =IFERROR(I$61/AVERAGE(H$49,I$49),"n/a")
A3: Tăng trưởng LNST | C3: =IFERROR((C$61-B$61)/ABS(B$61),"n/a") | D3: =IFERROR((D$61-C$61)/ABS(C$61),"n/a") | E3: =IFERROR((E$61-D$61)/ABS(D$61),"n/a") | F3: =IFERROR((F$61-E$61)/ABS(E$61),"n/a") | G3: =IFERROR((G$61-F$61)/ABS(F$61),"n/a") | H3: =IFERROR((H$61-G$61)/ABS(G$61),"n/a") | I3: =IFERROR((I$61-H$61)/ABS(H$61),"n/a")
A4: Tăng trưởng thu nhập hoạt động | C4: =IFERROR((C$55-B$55)/ABS(B$55),"n/a") | D4: =IFERROR((D$55-C$55)/ABS(C$55),"n/a") | E4: =IFERROR((E$55-D$55)/ABS(D$55),"n/a") | F4: =IFERROR((F$55-E$55)/ABS(E$55),"n/a") | G4: =IFERROR((G$55-F$55)/ABS(F$55),"n/a") | H4: =IFERROR((H$55-G$55)/ABS(G$55),"n/a") | I4: =IFERROR((I$55-H$55)/ABS(H$55),"n/a")
A5: % Dư nợ cho vay kinh doanh BĐS | B5: =IFERROR(B$36/#REF!,"n/a") | C5: =IFERROR(C$36/#REF!,"n/a") | D5: =IFERROR(D$36/#REF!,"n/a") | E5: =IFERROR(E$36/#REF!,"n/a") | F5: =IFERROR(F$36/#REF!,"n/a") | G5: =IFERROR(G$36/#REF!,"n/a") | H5: =IFERROR(H$36/#REF!,"n/a") | I5: =IFERROR(I$36/#REF!,"n/a")
A6: NIM | B6: =IFERROR(B$55/AVERAGE(B$42,A42),"n/a") | C6: =IFERROR(C$55/AVERAGE(C$42,B42),"n/a") | D6: =IFERROR(D$55/AVERAGE(D$42,C42),"n/a") | E6: =IFERROR(E$55/AVERAGE(E$42,D42),"n/a") | F6: =IFERROR(F$55/AVERAGE(F$42,E42),"n/a") | G6: =IFERROR(G$55/AVERAGE(G$42,F42),"n/a") | H6: =IFERROR(H$55/AVERAGE(H$42,G42),"n/a") | I6: =IFERROR(I$55/AVERAGE(I$42,H42),"n/a")
A7: CASA | E7: =IFERROR((D$45+E$45+D$48+E$48)/(D$44+E$44),"n/a") | F7: =IFERROR((E$45+F$45+E$48+F$48)/(E$44+F$44),"n/a") | G7: =IFERROR((F$45+G$45+F$48+G$48)/(F$44+G$44),"n/a") | H7: =IFERROR((G$45+H$45+G$48+H$48)/(G$44+H$44),"n/a") | I7: =IFERROR((H$45+I$45+H$48+I$48)/(H$44+I$44),"n/a")
A8: NPL | E8: =IFERROR((E$35/#REF!),"n/a") | F8: =IFERROR((F$35/#REF!),"n/a") | G8: =IFERROR((G$35/#REF!),"n/a") | H8: =IFERROR((H$35/#REF!),"n/a") | I8: =IFERROR((I$35/#REF!),"n/a")
A9: COF | C9: =IFERROR(ABS(C$54)/AVERAGE(C$42,B42),"n/a") | D9: =IFERROR(ABS(D$54)/AVERAGE(D$42,C42),"n/a") | E9: =IFERROR(ABS(E$54)/AVERAGE(E$42,D42),"n/a") | F9: =IFERROR(ABS(F$54)/AVERAGE(F$42,E42),"n/a") | G9: =IFERROR(ABS(G$54)/AVERAGE(G$42,F42),"n/a") | H9: =IFERROR(ABS(H$54)/AVERAGE(H$42,G42),"n/a") | I9: =IFERROR(ABS(I$54)/AVERAGE(I$42,H42),"n/a")
A10: LLR | B10: =IFERROR(ABS(B$37)/B$35,"n/a") | C10: =IFERROR(ABS(C$37)/C$35,"n/a") | D10: =IFERROR(ABS(D$37)/D$35,"n/a") | E10: =IFERROR(ABS(E$37)/E$35,"n/a") | F10: =IFERROR(ABS(F$37)/F$35,"n/a") | G10: =IFERROR(ABS(G$37)/G$35,"n/a") | H10: =IFERROR(ABS(H$37)/H$35,"n/a") | I10: =IFERROR(ABS(I$37)/I$35,"n/a")
A11: CAR
A12: LDR | B12: =IFERROR(B$29/B$44,"n/a") | C12: =IFERROR(C$29/C$44,"n/a") | D12: =IFERROR(D$29/D$44,"n/a") | E12: =IFERROR(E$29/E$44,"n/a") | F12: =IFERROR(F$29/F$44,"n/a") | G12: =IFERROR(G$29/G$44,"n/a") | H12: =IFERROR(H$29/H$44,"n/a") | I12: =IFERROR(I$29/I$44,"n/a")
A13: Tăng trưởng vốn huy động | C13: =IFERROR((C$44-B$44)/ABS(B$44),"n/a") | D13: =IFERROR((D$44-C$44)/ABS(C$44),"n/a") | E13: =IFERROR((E$44-D$44)/ABS(D$44),"n/a") | F13: =IFERROR((F$44-E$44)/ABS(E$44),"n/a") | G13: =IFERROR((G$44-F$44)/ABS(F$44),"n/a") | H13: =IFERROR((H$44-G$44)/ABS(G$44),"n/a") | I13: =IFERROR((I$44-H$44)/ABS(H$44),"n/a")
A14: Tăng trưởng tín dụng | C14: =IFERROR((C$29-B$29)/ABS(B$29),"n/a") | D14: =IFERROR((D$29-C$29)/ABS(C$29),"n/a") | E14: =IFERROR((E$29-D$29)/ABS(D$29),"n/a") | F14: =IFERROR((F$29-E$29)/ABS(E$29),"n/a") | G14: =IFERROR((G$29-F$29)/ABS(F$29),"n/a") | H14: =IFERROR((H$29-G$29)/ABS(G$29),"n/a") | I14: =IFERROR((I$29-H$29)/ABS(H$29),"n/a")
A15: CIR | B15: =IFERROR(ABS(B$58)/B$57,"n/a") | C15: =IFERROR(ABS(C$58)/C$57,"n/a") | D15: =IFERROR(ABS(D$58)/D$57,"n/a") | E15: =IFERROR(ABS(E$58)/E$57,"n/a") | F15: =IFERROR(ABS(F$58)/F$57,"n/a") | G15: =IFERROR(ABS(G$58)/G$57,"n/a") | H15: =IFERROR(ABS(H$58)/H$57,"n/a") | I15: =IFERROR(ABS(I$58)/I$57,"n/a")
A16: VCSH/Tổng tài sản | B16: =IFERROR(B$49/B$24,"n/a") | C16: =IFERROR(C$49/C$24,"n/a") | D16: =IFERROR(D$49/D$24,"n/a") | E16: =IFERROR(E$49/E$24,"n/a") | F16: =IFERROR(F$49/F$24,"n/a") | G16: =IFERROR(G$49/G$24,"n/a") | H16: =IFERROR(H$49/H$24,"n/a") | I16: =IFERROR(I$49/I$24,"n/a")
A17: Tỷ lệ lãi và phí phải thu/Thu nhập lãi | B17: =IFERROR(B59/B$53,"n/a") | C17: =IFERROR(C59/C$53,"n/a") | D17: =IFERROR(D59/D$53,"n/a") | E17: =IFERROR(E59/E$53,"n/a") | F17: =IFERROR(F59/F$53,"n/a") | G17: =IFERROR(G59/G$53,"n/a") | H17: =IFERROR(H59/H$53,"n/a") | I17: =IFERROR(I59/I$53,"n/a")
A18: Thu nhập ngoài lãi/Thu nhập hoạt động | B18: =IFERROR(B$56/B$57,"n/a") | C18: =IFERROR(C$56/C$57,"n/a") | D18: =IFERROR(D$56/D$57,"n/a") | E18: =IFERROR(E$56/E$57,"n/a") | F18: =IFERROR(F$56/F$57,"n/a") | G18: =IFERROR(G$56/G$57,"n/a") | H18: =IFERROR(H$56/H$57,"n/a") | I18: =IFERROR(I$56/I$57,"n/a")
A20: II. DỮ LIỆU TRÍCH XUẤT (tự động dò theo tên khoản mục)
A21: Khoản mục | B21: =balance_sheet!B1 | C21: =balance_sheet!C1 | D21: =balance_sheet!D1 | E21: =balance_sheet!E1 | F21: =balance_sheet!F1 | G21: =balance_sheet!G1 | H21: =balance_sheet!H1 | I21: =balance_sheet!I1
A22: CĐKT
A23: Tài sản
A24: TỔNG TÀI SẢN | B24: =IFERROR(INDEX(balance_sheet!$B:$I,MATCH("TỔNG TÀI SẢN",balance_sheet!$A:$A,0),MATCH(B$21,balance_sheet!$B$1:$I$1,0)),"") | C24: =IFERROR(INDEX(balance_sheet!$B:$I,MATCH("TỔNG TÀI SẢN",balance_sheet!$A:$A,0),MATCH(C$21,balance_sheet!$B$1:$I$1,0)),"") | D24: =IFERROR(INDEX(balance_sheet!$B:$I,MATCH("TỔNG TÀI SẢN",balance_sheet!$A:$A,0),MATCH(D$21,balance_sheet!$B$1:$I$1,0)),"") | E24: =IFERROR(INDEX(balance_sheet!$B:$I,MATCH("TỔNG TÀI SẢN",balance_sheet!$A:$A,0),MATCH(E$21,balance_sheet!$B$1:$I$1,0)),"") | F24: =IFERROR(INDEX(balance_sheet!$B:$I,MATCH("TỔNG TÀI SẢN",balance_sheet!$A:$A,0),MATCH(F$21,balance_sheet!$B$1:$I$1,0)),"") | G24: =IFERROR(INDEX(balance_sheet!$B:$I,MATCH("TỔNG TÀI SẢN",balance_sheet!$A:$A,0),MATCH(G$21,balance_sheet!$B$1:$I$1,0)),"") | H24: =IFERROR(INDEX(balance_sheet!$B:$I,MATCH("TỔNG TÀI SẢN",balance_sheet!$A:$A,0),MATCH(H$21,balance_sheet!$B$1:$I$1,0)),"") | I24: =IFERROR(INDEX(balance_sheet!$B:$I,MATCH("TỔNG TÀI SẢN",balance_sheet!$A:$A,0),MATCH(I$21,balance_sheet!$B$1:$I$1,0)),"")
A25: Tiền gửi tại Ngân hàng nhà nước Việt Nam | B25: =IFERROR(INDEX(balance_sheet!$B:$I,MATCH("Tiền gửi tại Ngân hàng nhà nước Việt Nam",balance_sheet!$A:$A,0),MATCH(B$21,balance_sheet!$B$1:$I$1,0)),"") | C25: =IFERROR(INDEX(balance_sheet!$B:$I,MATCH("Tiền gửi tại Ngân hàng nhà nước Việt Nam",balance_sheet!$A:$A,0),MATCH(C$21,balance_sheet!$B$1:$I$1,0)),"") | D25: =IFERROR(INDEX(balance_sheet!$B:$I,MATCH("Tiền gửi tại Ngân hàng nhà nước Việt Nam",balance_sheet!$A:$A,0),MATCH(D$21,balance_sheet!$B$1:$I$1,0)),"") | E25: =IFERROR(INDEX(balance_sheet!$B:$I,MATCH("Tiền gửi tại Ngân hàng nhà nước Việt Nam",balance_sheet!$A:$A,0),MATCH(E$21,balance_sheet!$B$1:$I$1,0)),"") | F25: =IFERROR(INDEX(balance_sheet!$B:$I,MATCH("Tiền gửi tại Ngân hàng nhà nước Việt Nam",balance_sheet!$A:$A,0),MATCH(F$21,balance_sheet!$B$1:$I$1,0)),"") | G25: =IFERROR(INDEX(balance_sheet!$B:$I,MATCH("Tiền gửi tại Ngân hàng nhà nước Việt Nam",balance_sheet!$A:$A,0),MATCH(G$21,balance_sheet!$B$1:$I$1,0)),"") | H25: =IFERROR(INDEX(balance_sheet!$B:$I,MATCH("Tiền gửi tại Ngân hàng nhà nước Việt Nam",balance_sheet!$A:$A,0),MATCH(H$21,balance_sheet!$B$1:$I$1,0)),"") | I25: =IFERROR(INDEX(balance_sheet!$B:$I,MATCH("Tiền gửi tại Ngân hàng nhà nước Việt Nam",balance_sheet!$A:$A,0),MATCH(I$21,balance_sheet!$B$1:$I$1,0)),"")
A26: Tiền gửi tại các TCTD khác và cho vay các TCTD khác | B26: =IFERROR(INDEX(balance_sheet!$B:$I,MATCH("Tiền gửi tại các TCTD khác và cho vay các TCTD khác",balance_sheet!$A:$A,0),MATCH(B$21,balance_sheet!$B$1:$I$1,0)),"") | C26: =IFERROR(INDEX(balance_sheet!$B:$I,MATCH("Tiền gửi tại các TCTD khác và cho vay các TCTD khác",balance_sheet!$A:$A,0),MATCH(C$21,balance_sheet!$B$1:$I$1,0)),"") | D26: =IFERROR(INDEX(balance_sheet!$B:$I,MATCH("Tiền gửi tại các TCTD khác và cho vay các TCTD khác",balance_sheet!$A:$A,0),MATCH(D$21,balance_sheet!$B$1:$I$1,0)),"") | E26: =IFERROR(INDEX(balance_sheet!$B:$I,MATCH("Tiền gửi tại các TCTD khác và cho vay các TCTD khác",balance_sheet!$A:$A,0),MATCH(E$21,balance_sheet!$B$1:$I$1,0)),"") | F26: =IFERROR(INDEX(balance_sheet!$B:$I,MATCH("Tiền gửi tại các TCTD khác và cho vay các TCTD khác",balance_sheet!$A:$A,0),MATCH(F$21,balance_sheet!$B$1:$I$1,0)),"") | G26: =IFERROR(INDEX(balance_sheet!$B:$I,MATCH("Tiền gửi tại các TCTD khác và cho vay các TCTD khác",balance_sheet!$A:$A,0),MATCH(G$21,balance_sheet!$B$1:$I$1,0)),"") | H26: =IFERROR(INDEX(balance_sheet!$B:$I,MATCH("Tiền gửi tại các TCTD khác và cho vay các TCTD khác",balance_sheet!$A:$A,0),MATCH(H$21,balance_sheet!$B$1:$I$1,0)),"") | I26: =IFERROR(INDEX(balance_sheet!$B:$I,MATCH("Tiền gửi tại các TCTD khác và cho vay các TCTD khác",balance_sheet!$A:$A,0),MATCH(I$21,balance_sheet!$B$1:$I$1,0)),"")
A27: Dự phòng rủi ro cho cay các TCTC khác | B27: =IFERROR(INDEX(balance_sheet!$B:$I,MATCH("Dự phòng rủi ro",balance_sheet!$A:$A,0),MATCH(B$21,balance_sheet!$B$1:$I$1,0)),"") | C27: =IFERROR(INDEX(balance_sheet!$B:$I,MATCH("Dự phòng rủi ro",balance_sheet!$A:$A,0),MATCH(C$21,balance_sheet!$B$1:$I$1,0)),"") | D27: =IFERROR(INDEX(balance_sheet!$B:$I,MATCH("Dự phòng rủi ro",balance_sheet!$A:$A,0),MATCH(D$21,balance_sheet!$B$1:$I$1,0)),"") | E27: =IFERROR(INDEX(balance_sheet!$B:$I,MATCH("Dự phòng rủi ro",balance_sheet!$A:$A,0),MATCH(E$21,balance_sheet!$B$1:$I$1,0)),"") | F27: =IFERROR(INDEX(balance_sheet!$B:$I,MATCH("Dự phòng rủi ro",balance_sheet!$A:$A,0),MATCH(F$21,balance_sheet!$B$1:$I$1,0)),"") | G27: =IFERROR(INDEX(balance_sheet!$B:$I,MATCH("Dự phòng rủi ro",balance_sheet!$A:$A,0),MATCH(G$21,balance_sheet!$B$1:$I$1,0)),"") | H27: =IFERROR(INDEX(balance_sheet!$B:$I,MATCH("Dự phòng rủi ro",balance_sheet!$A:$A,0),MATCH(H$21,balance_sheet!$B$1:$I$1,0)),"") | I27: =IFERROR(INDEX(balance_sheet!$B:$I,MATCH("Dự phòng rủi ro",balance_sheet!$A:$A,0),MATCH(I$21,balance_sheet!$B$1:$I$1,0)),"")
A28: Chứng khoán kinh doanh | B28: =IFERROR(INDEX(balance_sheet!$B:$I,MATCH("Chứng khoán kinh doanh",balance_sheet!$A:$A,0),MATCH(B$21,balance_sheet!$B$1:$I$1,0)),"") | C28: =IFERROR(INDEX(balance_sheet!$B:$I,MATCH("Chứng khoán kinh doanh",balance_sheet!$A:$A,0),MATCH(C$21,balance_sheet!$B$1:$I$1,0)),"") | D28: =IFERROR(INDEX(balance_sheet!$B:$I,MATCH("Chứng khoán kinh doanh",balance_sheet!$A:$A,0),MATCH(D$21,balance_sheet!$B$1:$I$1,0)),"") | E28: =IFERROR(INDEX(balance_sheet!$B:$I,MATCH("Chứng khoán kinh doanh",balance_sheet!$A:$A,0),MATCH(E$21,balance_sheet!$B$1:$I$1,0)),"") | F28: =IFERROR(INDEX(balance_sheet!$B:$I,MATCH("Chứng khoán kinh doanh",balance_sheet!$A:$A,0),MATCH(F$21,balance_sheet!$B$1:$I$1,0)),"") | G28: =IFERROR(INDEX(balance_sheet!$B:$I,MATCH("Chứng khoán kinh doanh",balance_sheet!$A:$A,0),MATCH(G$21,balance_sheet!$B$1:$I$1,0)),"") | H28: =IFERROR(INDEX(balance_sheet!$B:$I,MATCH("Chứng khoán kinh doanh",balance_sheet!$A:$A,0),MATCH(H$21,balance_sheet!$B$1:$I$1,0)),"") | I28: =IFERROR(INDEX(balance_sheet!$B:$I,MATCH("Chứng khoán kinh doanh",balance_sheet!$A:$A,0),MATCH(I$21,balance_sheet!$B$1:$I$1,0)),"")
A29: Cho vay khách hàng | B29: =IFERROR(INDEX(balance_sheet!$B:$I,MATCH("Cho vay khách hàng",balance_sheet!$A:$A,0),MATCH(B$21,balance_sheet!$B$1:$I$1,0)),"") | C29: =IFERROR(INDEX(balance_sheet!$B:$I,MATCH("Cho vay khách hàng",balance_sheet!$A:$A,0),MATCH(C$21,balance_sheet!$B$1:$I$1,0)),"") | D29: =IFERROR(INDEX(balance_sheet!$B:$I,MATCH("Cho vay khách hàng",balance_sheet!$A:$A,0),MATCH(D$21,balance_sheet!$B$1:$I$1,0)),"") | E29: =IFERROR(INDEX(balance_sheet!$B:$I,MATCH("Cho vay khách hàng",balance_sheet!$A:$A,0),MATCH(E$21,balance_sheet!$B$1:$I$1,0)),"") | F29: =IFERROR(INDEX(balance_sheet!$B:$I,MATCH("Cho vay khách hàng",balance_sheet!$A:$A,0),MATCH(F$21,balance_sheet!$B$1:$I$1,0)),"") | G29: =IFERROR(INDEX(balance_sheet!$B:$I,MATCH("Cho vay khách hàng",balance_sheet!$A:$A,0),MATCH(G$21,balance_sheet!$B$1:$I$1,0)),"") | H29: =IFERROR(INDEX(balance_sheet!$B:$I,MATCH("Cho vay khách hàng",balance_sheet!$A:$A,0),MATCH(H$21,balance_sheet!$B$1:$I$1,0)),"") | I29: =IFERROR(INDEX(balance_sheet!$B:$I,MATCH("Cho vay khách hàng",balance_sheet!$A:$A,0),MATCH(I$21,balance_sheet!$B$1:$I$1,0)),"")
A30: + Nợ đủ tiêu chuẩn | E30: 349223000000000 | F30: 443975000000000 | G30: 587326000000000 | H30: 751876000000000 | I30: 1.059782e+15
A31: + Nợ cần chú ý | E31: 3913000000000 | F31: 7809000000000 | G31: 13918000000000 | H31: 12197000000000 | I31: 10210000000000
A32: + Nợ dưới tiêu chuẩn | E32: 1433000000000 | F32: 1517000000000 | G32: 3211000000000 | H32: 3380000000000 | I32: 3276000000000
A33: + Nợ nghi ngờ | E33: 1015000000000 | F33: 1221000000000 | G33: 3704000000000 | H33: 4599000000000 | I33: 4330000000000
A34: + Nợ có khả năng mất vốn | E34: 819000000000 | F34: 2293000000000 | G34: 2890000000000 | H34: 4607000000000 | I34: 6421000000000
A35: Nợ xấu | B35: =SUM(B32:B34) | C35: =SUM(C32:C34) | D35: =SUM(D32:D34) | E35: =SUM(E32:E34) | F35: =SUM(F32:F34) | G35: =SUM(G32:G34) | H35: =SUM(H32:H34) | I35: =SUM(I32:I34)
A36: Cho vay KDBĐS | E36: 12632000000000 | F36: 21358000000000 | G36: 43268000000000 | H36: 64141000000000 | I36: 121189000000000
A37: Dự phòng rủi ro cho vay khách hàng | B37: =IFERROR(INDEX(balance_sheet!$B:$I,MATCH("Dự phòng rủi ro cho vay khách hàng",balance_sheet!$A:$A,0),MATCH(B$21,balance_sheet!$B$1:$I$1,0)),"") | C37: =IFERROR(INDEX(balance_sheet!$B:$I,MATCH("Dự phòng rủi ro cho vay khách hàng",balance_sheet!$A:$A,0),MATCH(C$21,balance_sheet!$B$1:$I$1,0)),"") | D37: =IFERROR(INDEX(balance_sheet!$B:$I,MATCH("Dự phòng rủi ro cho vay khách hàng",balance_sheet!$A:$A,0),MATCH(D$21,balance_sheet!$B$1:$I$1,0)),"") | E37: =IFERROR(INDEX(balance_sheet!$B:$I,MATCH("Dự phòng rủi ro cho vay khách hàng",balance_sheet!$A:$A,0),MATCH(E$21,balance_sheet!$B$1:$I$1,0)),"") | F37: =IFERROR(INDEX(balance_sheet!$B:$I,MATCH("Dự phòng rủi ro cho vay khách hàng",balance_sheet!$A:$A,0),MATCH(F$21,balance_sheet!$B$1:$I$1,0)),"") | G37: =IFERROR(INDEX(balance_sheet!$B:$I,MATCH("Dự phòng rủi ro cho vay khách hàng",balance_sheet!$A:$A,0),MATCH(G$21,balance_sheet!$B$1:$I$1,0)),"") | H37: =IFERROR(INDEX(balance_sheet!$B:$I,MATCH("Dự phòng rủi ro cho vay khách hàng",balance_sheet!$A:$A,0),MATCH(H$21,balance_sheet!$B$1:$I$1,0)),"") | I37: =IFERROR(INDEX(balance_sheet!$B:$I,MATCH("Dự phòng rủi ro cho vay khách hàng",balance_sheet!$A:$A,0),MATCH(I$21,balance_sheet!$B$1:$I$1,0)),"")
A38: Chứng khoán đầu tư | B38: =IFERROR(INDEX(balance_sheet!$B:$I,MATCH("Chứng khoán đầu tư",balance_sheet!$A:$A,0),MATCH(B$21,balance_sheet!$B$1:$I$1,0)),"") | C38: =IFERROR(INDEX(balance_sheet!$B:$I,MATCH("Chứng khoán đầu tư",balance_sheet!$A:$A,0),MATCH(C$21,balance_sheet!$B$1:$I$1,0)),"") | D38: =IFERROR(INDEX(balance_sheet!$B:$I,MATCH("Chứng khoán đầu tư",balance_sheet!$A:$A,0),MATCH(D$21,balance_sheet!$B$1:$I$1,0)),"") | E38: =IFERROR(INDEX(balance_sheet!$B:$I,MATCH("Chứng khoán đầu tư",balance_sheet!$A:$A,0),MATCH(E$21,balance_sheet!$B$1:$I$1,0)),"") | F38: =IFERROR(INDEX(balance_sheet!$B:$I,MATCH("Chứng khoán đầu tư",balance_sheet!$A:$A,0),MATCH(F$21,balance_sheet!$B$1:$I$1,0)),"") | G38: =IFERROR(INDEX(balance_sheet!$B:$I,MATCH("Chứng khoán đầu tư",balance_sheet!$A:$A,0),MATCH(G$21,balance_sheet!$B$1:$I$1,0)),"") | H38: =IFERROR(INDEX(balance_sheet!$B:$I,MATCH("Chứng khoán đầu tư",balance_sheet!$A:$A,0),MATCH(H$21,balance_sheet!$B$1:$I$1,0)),"") | I38: =IFERROR(INDEX(balance_sheet!$B:$I,MATCH("Chứng khoán đầu tư",balance_sheet!$A:$A,0),MATCH(I$21,balance_sheet!$B$1:$I$1,0)),"")
A39: Dự phòng giảm giá chứng khoán đầu tư | B39: =IFERROR(INDEX(balance_sheet!$B:$I,MATCH("Dự phòng giảm giá chứng khoán đầu tư",balance_sheet!$A:$A,0),MATCH(B$21,balance_sheet!$B$1:$I$1,0)),"") | C39: =IFERROR(INDEX(balance_sheet!$B:$I,MATCH("Dự phòng giảm giá chứng khoán đầu tư",balance_sheet!$A:$A,0),MATCH(C$21,balance_sheet!$B$1:$I$1,0)),"") | D39: =IFERROR(INDEX(balance_sheet!$B:$I,MATCH("Dự phòng giảm giá chứng khoán đầu tư",balance_sheet!$A:$A,0),MATCH(D$21,balance_sheet!$B$1:$I$1,0)),"") | E39: =IFERROR(INDEX(balance_sheet!$B:$I,MATCH("Dự phòng giảm giá chứng khoán đầu tư",balance_sheet!$A:$A,0),MATCH(E$21,balance_sheet!$B$1:$I$1,0)),"") | F39: =IFERROR(INDEX(balance_sheet!$B:$I,MATCH("Dự phòng giảm giá chứng khoán đầu tư",balance_sheet!$A:$A,0),MATCH(F$21,balance_sheet!$B$1:$I$1,0)),"") | G39: =IFERROR(INDEX(balance_sheet!$B:$I,MATCH("Dự phòng giảm giá chứng khoán đầu tư",balance_sheet!$A:$A,0),MATCH(G$21,balance_sheet!$B$1:$I$1,0)),"") | H39: =IFERROR(INDEX(balance_sheet!$B:$I,MATCH("Dự phòng giảm giá chứng khoán đầu tư",balance_sheet!$A:$A,0),MATCH(H$21,balance_sheet!$B$1:$I$1,0)),"") | I39: =IFERROR(INDEX(balance_sheet!$B:$I,MATCH("Dự phòng giảm giá chứng khoán đầu tư",balance_sheet!$A:$A,0),MATCH(I$21,balance_sheet!$B$1:$I$1,0)),"")
A40: Góp vốn, đầu tư dài hạn | B40: =IFERROR(INDEX(balance_sheet!$B:$I,MATCH("Góp vốn, đầu tư dài hạn",balance_sheet!$A:$A,0),MATCH(B$21,balance_sheet!$B$1:$I$1,0)),"") | C40: =IFERROR(INDEX(balance_sheet!$B:$I,MATCH("Góp vốn, đầu tư dài hạn",balance_sheet!$A:$A,0),MATCH(C$21,balance_sheet!$B$1:$I$1,0)),"") | D40: =IFERROR(INDEX(balance_sheet!$B:$I,MATCH("Góp vốn, đầu tư dài hạn",balance_sheet!$A:$A,0),MATCH(D$21,balance_sheet!$B$1:$I$1,0)),"") | E40: =IFERROR(INDEX(balance_sheet!$B:$I,MATCH("Góp vốn, đầu tư dài hạn",balance_sheet!$A:$A,0),MATCH(E$21,balance_sheet!$B$1:$I$1,0)),"") | F40: =IFERROR(INDEX(balance_sheet!$B:$I,MATCH("Góp vốn, đầu tư dài hạn",balance_sheet!$A:$A,0),MATCH(F$21,balance_sheet!$B$1:$I$1,0)),"") | G40: =IFERROR(INDEX(balance_sheet!$B:$I,MATCH("Góp vốn, đầu tư dài hạn",balance_sheet!$A:$A,0),MATCH(G$21,balance_sheet!$B$1:$I$1,0)),"") | H40: =IFERROR(INDEX(balance_sheet!$B:$I,MATCH("Góp vốn, đầu tư dài hạn",balance_sheet!$A:$A,0),MATCH(H$21,balance_sheet!$B$1:$I$1,0)),"") | I40: =IFERROR(INDEX(balance_sheet!$B:$I,MATCH("Góp vốn, đầu tư dài hạn",balance_sheet!$A:$A,0),MATCH(I$21,balance_sheet!$B$1:$I$1,0)),"")
A41: Dự phòng giảm giá đầu tư dài hạn | B41: =IFERROR(INDEX(balance_sheet!$B:$I,MATCH("Dự phòng giảm giá đầu tư dài hạn",balance_sheet!$A:$A,0),MATCH(B$21,balance_sheet!$B$1:$I$1,0)),"") | C41: =IFERROR(INDEX(balance_sheet!$B:$I,MATCH("Dự phòng giảm giá đầu tư dài hạn",balance_sheet!$A:$A,0),MATCH(C$21,balance_sheet!$B$1:$I$1,0)),"") | D41: =IFERROR(INDEX(balance_sheet!$B:$I,MATCH("Dự phòng giảm giá đầu tư dài hạn",balance_sheet!$A:$A,0),MATCH(D$21,balance_sheet!$B$1:$I$1,0)),"") | E41: =IFERROR(INDEX(balance_sheet!$B:$I,MATCH("Dự phòng giảm giá đầu tư dài hạn",balance_sheet!$A:$A,0),MATCH(E$21,balance_sheet!$B$1:$I$1,0)),"") | F41: =IFERROR(INDEX(balance_sheet!$B:$I,MATCH("Dự phòng giảm giá đầu tư dài hạn",balance_sheet!$A:$A,0),MATCH(F$21,balance_sheet!$B$1:$I$1,0)),"") | G41: =IFERROR(INDEX(balance_sheet!$B:$I,MATCH("Dự phòng giảm giá đầu tư dài hạn",balance_sheet!$A:$A,0),MATCH(G$21,balance_sheet!$B$1:$I$1,0)),"") | H41: =IFERROR(INDEX(balance_sheet!$B:$I,MATCH("Dự phòng giảm giá đầu tư dài hạn",balance_sheet!$A:$A,0),MATCH(H$21,balance_sheet!$B$1:$I$1,0)),"") | I41: =IFERROR(INDEX(balance_sheet!$B:$I,MATCH("Dự phòng giảm giá đầu tư dài hạn",balance_sheet!$A:$A,0),MATCH(I$21,balance_sheet!$B$1:$I$1,0)),"")
...

Sheet Dự báo tăng trưởng
B1: Q4/2025 | C1: Q1/2026 | D1: Q2/2026 | E1: Q3/2026 | F1: Q4/2026
A2: Số CP | B2: 8054999909 | C2: 8054999909 | D2: 8054999909 | E2: 8054999909 | F2: 8054999909
A3: Thị giá | B3: 75100 | C3: 75100 | D3: 75100 | E3: 75100 | F3: 75100
A4: Vốn hoá | B4: =B2*B3 | C4: =C2*C3 | D4: =D2*D3 | E4: =E2*E3 | F4: =F2*F3
A6: VCSH | B6: =chi_so_tai_chinh!I49 | C6: =B$6*(($F$6/$B$6)^(1/4)) | D6: =B$6*(($F$6/$B$6)^(2/4)) | E6: =B$6*(($F$6/$B$6)^(3/4)) | F6: =chi_so_tai_chinh!J49
A7: LICĐKKS | B7: =chi_so_tai_chinh!I51 | C7: =C6*0.05 | D7: =D6*0.05 | E7: =E6*0.05 | F7: =F6*0.05
A8: BV | B8: =B6-B7 | C8: =C6-C7 | D8: =D6-D7 | E8: =E6-E7 | F8: =F6-F7
A9: BVPS | B9: =B8/B2 | C9: =C8/C2 | D9: =D8/D2 | E9: =E8/E2 | F9: =F8/F2
A10: PB | B10: =$F$3/B9 | C10: =$F$3/C9 | D10: =$F$3/D9 | E10: =$F$3/E9 | F10: =$F$3/F9

Sheet Hiệu quả thực hiện kế hoạch
A1: Chỉ tiêu | B1: 2022 | C1: 2023 | D1: 2024 | E1: 2025
A2: Lợi nhuận trước thuế kế hoạch | B2: 20300000 | C2: 26138350 | D2: 28410000 | E2: 32000000
A3: Lợi nhuận trước thuế thu nhập doanh nghiệp | B3: =chi_so_tai_chinh!F62/1000000 | C3: =chi_so_tai_chinh!G62/1000000 | D3: =chi_so_tai_chinh!H62/1000000
A4: %thực hiện | B4: =B3/B2 | C4: =C3/C2 | D4: =D3/D2
A6: Trung vị %thực hiện LN trước thuế | B6: =MEDIAN(B4:D4)
A8: Tỷ lệ hoàn thành LNST trên 95% | B8: =COUNTIF(B4:D4,">=95%")/COUNT(B4:D4)
