Workbook

Sheet balance_sheet
A1: item | B1: 2018 | C1: 2019 | D1: 2020 | E1: 2021 | F1: 2022 | G1: 2023 | H1: 2024 | I1: 2025 | J1: 2018-Q1 | K1: 2018-Q2 | L1: 2018-Q3 | M1: 2018-Q4 | N1: 2024-Q3 | O1: 2024-Q4 | P1: 2025-Q1 | Q1: 2025-Q2 | R1: 2025-Q3 | S1: 2025-Q4 | T1: 2026-Q1 | U1: 2026-Q2
A2: Tiền mặt, vàng bạc, đá quý | B2: 1736571000000 | C2: 2344291000000 | D2: 3109230000000 | E2: 3475341000000 | F2: 3744100000000 | G2: 3675394000000 | H2: 3349166000000 | I2: 4965786000000 | J2: 2048473000000 | K2: 1946454000000 | L2: 1919151000000 | M2: 1736571000000 | N2: 3782282000000 | O2: 3349166000000 | P2: 4223983000000 | Q2: 5262525000000 | R2: 4421466000000 | S2: 4965786000000 | T2: 5741287000000 | U2: 5051244000000
A3: Tài sản cố định | B3: 2699314000000 | C3: 2798062000000 | D3: 4310919000000 | E3: 4678447000000 | F3: 5073508000000 | G3: 4854186000000 | H3: 5430416000000 | I3: 5616547000000 | J3: 2570955000000 | K3: 2538054000000 | L3: 2616548000000 | M3: 2699314000000 | N3: 4875798000000 | O3: 5430416000000 | P3: 5381759000000 | Q3: 5343331000000 | R3: 5121088000000 | S3: 5616547000000 | T3: 5500662000000 | U3: 5752320000000
A4: Tài sản cố định hữu hình | B4: 1586152000000 | C4: 1642003000000 | D4: 3088524000000 | E4: 3213906000000 | F4: 3457561000000 | G4: 3194404000000 | H4: 3750696000000 | I4: 3805533000000 | J4: 1552171000000 | K4: 1518666000000 | L4: 1583487000000 | M4: 1586152000000 | N4: 3268440000000 | O4: 3750696000000 | P4: 3772404000000 | Q4: 3713430000000 | R4: 3536030000000 | S4: 3805533000000 | T4: 3717028000000 | U4: 3940732000000
A5: Nguyên giá TSCĐ hữu hình | B5: 3268459000000 | C5: 3585813000000 | D5: 5387069000000 | E5: 6083517000000 | F5: 7110562000000 | G5: 7732608000000 | H5: 9014672000000 | I5: 9423236000000 | J5: 3104721000000 | K5: 3092406000000 | L5: 3218607000000 | M5: 3268459000000 | N5: 8340941000000 | O5: 9014672000000 | P5: 9160651000000 | Q5: 9174600000000 | R5: 9027999000000 | S5: 9423236000000 | T5: 9473484000000 | U5: 9805329000000
A6: Hao mòn TSCĐ hữu hình | B6: -1682307000000 | C6: -1943810000000 | D6: -2298545000000 | E6: -2869611000000 | F6: -3653001000000 | G6: -4538204000000 | H6: -5263976000000 | I6: -5617703000000 | J6: -1552550000000 | K6: -1573740000000 | L6: -1635120000000 | M6: -1682307000000 | N6: -5072501000000 | O6: -5263976000000 | P6: -5388247000000 | Q6: -5461170000000 | R6: -5491969000000 | S6: -5617703000000 | T6: -5756456000000 | U6: -5864597000000
A7: Tài sản cố định thuê tài chính | B7: 0 | C7: 0 | D7: 0 | E7: 0 | F7: 0 | G7: 0 | H7: 0 | I7: 0 | J7: 0 | K7: 0 | L7: 0 | M7: 0 | N7: 0 | O7: 0 | P7: 0 | Q7: 0 | R7: 0 | S7: 0 | T7: 0 | U7: 0
A8: Nguyên giá TSCĐ thuê tài chính | B8: 0 | C8: 0 | D8: 0 | E8: 0 | F8: 0 | G8: 0 | H8: 0 | I8: 0 | J8: 0 | K8: 0 | L8: 0 | M8: 0 | N8: 0 | O8: 0 | P8: 0 | Q8: 0 | R8: 0 | S8: 0 | T8: 0 | U8: 0
A9: Hao mòn TSCĐ thuê tài chính | B9: 0 | C9: 0 | D9: 0 | E9: 0 | F9: 0 | G9: 0 | H9: 0 | I9: 0 | J9: 0 | K9: 0 | L9: 0 | M9: 0 | N9: 0 | O9: 0 | P9: 0 | Q9: 0 | R9: 0 | S9: 0 | T9: 0 | U9: 0
A10: Tài sản cố định vô hình | B10: 1113162000000 | C10: 1156059000000 | D10: 1222395000000 | E10: 1464541000000 | F10: 1615947000000 | G10: 1659782000000 | H10: 1679720000000 | I10: 1811014000000 | J10: 1018784000000 | K10: 1019388000000 | L10: 1033061000000 | M10: 1113162000000 | N10: 1607358000000 | O10: 1679720000000 | P10: 1609355000000 | Q10: 1629901000000 | R10: 1585058000000 | S10: 1811014000000 | T10: 1783634000000 | U10: 1811588000000
A11: Nguyên giá TSCĐ vô hình | B11: 1823153000000 | C11: 1980168000000 | D11: 2277564000000 | E11: 2923616000000 | F11: 3565092000000 | G11: 4196144000000 | H11: 4976669000000 | I11: 5684904000000 | J11: 1629653000000 | K11: 1661526000000 | L11: 1710000000000 | M11: 1823153000000 | N11: 4679601000000 | O11: 4976669000000 | P11: 5006260000000 | Q11: 5180623000000 | R11: 5257810000000 | S11: 5684904000000 | T11: 5762160000000 | U11: 5929584000000
A12: Hao mòn TSCĐ vô hình | B12: -709991000000 | C12: -824109000000 | D12: -1055169000000 | E12: -1459075000000 | F12: -1949145000000 | G12: -2536362000000 | H12: -3296949000000 | I12: -3873890000000 | J12: -610869000000 | K12: -642138000000 | L12: -676939000000 | M12: -709991000000 | N12: -3072243000000 | O12: -3296949000000 | P12: -3396905000000 | Q12: -3550722000000 | R12: -3672752000000 | S12: -3873890000000 | T12: -3978526000000 | U12: -4117996000000
A13: Bất động sản đầu tư | B13: 30813000000 | C13: 30813000000 | D13: 247898000000 | E13: 268999000000 | F13: 236177000000 | G13: 240294000000 | H13: 234115000000 | I13: 222813000000 | J13: 92037000000 | K13: 88979000000 | L13: 88245000000 | M13: 30813000000 | N13: 235660000000 | O13: 234115000000 | P13: 232570000000 | Q13: 220898000000 | R13: 219370000000 | S13: 222813000000 | T13: 216314000000 | U13: 214786000000
... A35: Chứng khoán kinh doanh | B35: 684035000000 | C35: 1196887000000 | D35: 3102030000000 | E35: 7582673000000 | F35: 4107470000000 | G35: 44251400000000 | H35: 7931834000000 | I35: 4692622000000 | J35: 3461998000000 | K35: 3604722000000 | L35: 953306000000 | M35: 684035000000 | N35: 14324151000000 | O35: 7931834000000 | P35: 12509220000000 | Q35: 4618286000000 | R35: 3195873000000 | S35: 4692622000000 | T35: 5093432000000 | U35: 8888529000000
A36: Chứng khoán kinh doanh | F36: 4107470000000 | G36: 44251400000000 | H36: 7931834000000 | I36: 4692622000000
A37: Dự phòng giảm giá chứng khoán kinh doanh | B37: -106363000000 | C37: -29078000000 | D37: -16803000000 | E37: -7399000000 | F37: -1920000000 | G37: -612000000 | H37: -179000000 | I37: -39393000000 | J37: -51288000000 | K37: -92015000000 | L37: -48329000000 | M37: -106363000000 | N37: -209000000 | O37: -179000000 | P37: -27979000000 | Q37: -32610000000 | R37: -23700000000 | S37: -39393000000 | T37: -34663000000 | U37: -35170000000
A38: Các công cụ tài chính phái sinh và các tài sản tài chính khác | B38: 0 | C38: 14836000000 | D38: 37106000000 | E38: 274294000000 | F38: 69503000000 | G38: 141294000000 | H38: 0 | I38: 0 | J38: 146897000000 | K38: 0 | L38: 0 | M38: 36032000000 | N38: 111681000000 | O38: 0 | P38: 0 | Q38: 0 | R38: 0 | S38: 0 | T38: 0 | U38: 0
A39: Cho vay khách hàng | B39: 214685958000000 | C39: 250330623000000 | D39: 298296983000000 | E39: 363554778000000 | F39: 460574482000000 | G39: 611048830000000 | H39: 776657846000000 | I39: 1.0840194e+15 | J39: 193745724000000 | K39: 204829117000000 | L39: 204884876000000 | M39: 214685958000000 | N39: 702019545000000 | O39: 776657846000000 | P39: 797536715000000 | Q39: 879888513000000 | R39: 931498596000000 | S39: 1.0840194e+15 | T39: 1.1205625e+15 | U39: 1.2275545e+15
A40: Cho vay khách hàng | F40: 460574482000000 | G40: 611048830000000 | H40: 776657846000000 | I40: 1.0840194e+15
A41: Dự phòng rủi ro cho vay khách hàng | B41: -3211005000000 | C41: -3200913000000 | D41: -4354219000000 | E41: -8757684000000 | F41: -11975860000000 | G41: -11469563000000 | H41: -11609861000000 | I41: -13150593000000 | J41: -2483862000000 | K41: -2801694000000 | L41: -3409900000000 | M41: -3211005000000 | N41: -10786657000000 | O41: -11609861000000 | P41: -11049736000000 | Q41: -12548304000000 | R41: -13799595000000 | S41: -13150593000000 | T41: -14710330000000 | U41: -16662881000000
A42: Chứng khoán đầu tư | B42: 73731314000000 | C42: 85628999000000 | D42: 99713646000000 | E42: 128806244000000 | F42: 159580028000000 | G42: 147923205000000 | H42: 209637377000000 | I42: 225574850000000 | J42: 51337599000000 | K42: 52503841000000 | L42: 64526475000000 | M42: 73833564000000 | N42: 197206164000000 | O42: 209637377000000 | P42: 240234807000000 | Q42: 262474257000000 | R42: 235603615000000 | S42: 225574850000000 | T42: 262829936000000 | U42: 247070731000000
A43: Chứng khoán đầu tư sẵn sàng để bán | B43: 70467404000000 | C43: 82723727000000 | D43: 96775364000000 | E43: 124551916000000 | F43: 154506192000000 | G43: 143010711000000 | H43: 205507956000000 | I43: 221512464000000 | J43: 47298022000000 | K43: 48725373000000 | L43: 58934176000000 | M43: 70687988000000 | N43: 192578792000000 | O43: 205507956000000 | P43: 236771888000000 | Q43: 258676335000000 | R43: 232242770000000 | S43: 221512464000000 | T43: 259054739000000 | U43: 242744694000000
A44: Chứng khoán đầu tư giữ đến ngày đáo hạn | B44: 3522144000000 | C44: 3196877000000 | D44: 3374241000000 | E44: 4677084000000 | F44: 5475361000000 | G44: 5387952000000 | H44: 4612504000000 | I44: 4295125000000 | J44: 4373482000000 | K44: 4157952000000 | L44: 6036833000000 | M44: 3522144000000 | N44: 5422262000000 | O44: 4612504000000 | P44: 3969626000000 | Q44: 4255592000000 | R44: 4467417000000 | S44: 4295125000000 | T44: 4336559000000 | U44: 4573649000000
A45: Dự phòng giảm giá chứng khoán đầu tư | B45: -258234000000 | C45: -291605000000 | D45: -435959000000 | E45: -422756000000 | F45: -401525000000 | G45: -475458000000 | H45: -483083000000 | I45: -232739000000 | J45: -333905000000 | K45: -379484000000 | L45: -444534000000 | M45: -376568000000 | N45: -794890000000 | O45: -483083000000 | P45: -506707000000 | Q45: -457670000000 | R45: -1106572000000 | S45: -232739000000 | T45: -561362000000 | U45: -247612000000
A46: Tài sản Có khác | B46: 2267608000000 | C46: 2475062000000 | D46: 2280224000000 | E46: 3961963000000 | F46: 6174673000000 | G46: 6406669000000 | H46: 5873749000000 | I46: 7894091000000 | J46: 1384752000000 | K46: 1379112000000 | L46: 1506635000000 | M46: 2396048000000 | N46: 6453634000000 | O46: 5873749000000 | P46: 5725812000000 | Q46: 6156656000000 | R46: 6040196000000 | S46: 7894091000000 | T46: 6622398000000 | U46: 8297454000000
A47: Các khoản nợ chính phủ và NHNN Việt Nam | B47: 2632894000000 | C47: 16836000000 | D47: 15383000000 | E47: 262281000000 | F47: 31788000000 | G47: 8738000000 | H47: 8156285000000 | I47: 47474800000000 | J47: 4435673000000 | K47: 2981880000000 | L47: 2078022000000 | M47: 2632894000000 | N47: 5046988000000 | O47: 8156285000000 | P47: 5494421000000 | Q47: 20894064000000 | R47: 23155328000000 | S47: 47474800000000 | T47: 28346499000000 | U47: 22574102000000
A48: Tiền gửi và vay các Tổ chức tín dụng khác | B48: 60470881000000 | C48: 50314052000000 | D48: 50876472000000 | E48: 59560384000000 | F48: 65116779000000 | G48: 99810466000000 | H48: 110169585000000 | I48: 248017489000000 | J48: 36415087000000 | K48: 46107597000000 | L48: 58694829000000 | M48: 60470881000000 | N48: 118559598000000 | O48: 110169585000000 | P48: 109015683000000 | Q48: 130930943000000 | R48: 154325370000000 | S48: 248017489000000 | T48: 256891475000000 | U48: 285608719000000
A49: Tiền gửi của khách hàng | B49: 239964318000000 | C49: 272709512000000 | D49: 310960354000000 | E49: 384692155000000 | F49: 443605638000000 | G49: 567532577000000 | H49: 714154479000000 | I49: 921368132000000 | J49: 227017855000000 | K49: 234796072000000 | L49: 232638438000000 | M49: 239964318000000 | N49: 627567353000000 | O49: 714154479000000 | P49: 722622450000000 | Q49: 783291908000000 | R49: 788030328000000 | S49: 921368132000000 | T49: 905918332000000 | U49: 963815357000000
A50: Các công cụ tài chính phái sinh và các khoản nợ tài chính khác | B50: 5634000000 | C50: 0 | D50: 0 | E50: 0 | F50: 0 | G50: 0 | H50: 191545000000 | I50: 698507000000 | J50: 0 | K50: 144000000 | L50: 11437000000 | M50: 41666000000 | N50: 0 | O50: 191545000000 | P50: 526143000000 | Q50: 842870000000 | R50: 1228245000000 | S50: 698507000000 | T50: 661326000000 | U50: 571389000000
A51: Vốn tài trợ, uỷ thác đầu tư của Chính phủ và các tổ chức tín dụng khác | B51: 319963000000 | C51: 302126000000 | D51: 207341000000 | E51: 1998703000000 | F51: 2002722000000 | G51: 2799863000000 | H51: 2793453000000 | I51: 3912833000000 | J51: 266287000000 | K51: 275621000000 | L51: 285402000000 | M51: 319963000000 | N51: 3351982000000 | O51: 2793453000000 | P51: 3003072000000 | Q51: 3282236000000 | R51: 4048717000000 | S51: 3912833000000 | T51: 3247015000000 | U51: 2287529000000
A52: Phát hành giấy tờ có giá | B52: 11157638000000 | C52: 26288629000000 | D52: 50923563000000 | E52: 66886924000000 | F52: 96578125000000 | G52: 126463110000000 | H52: 128964033000000 | I52: 187236104000000 | J52: 6124181000000 | K52: 6087975000000 | L52: 6094172000000 | M52: 11157638000000 | N52: 119550968000000 | O52: 128964033000000 | P52: 146597114000000 | Q52: 170267177000000 | R52: 171610852000000 | S52: 187236104000000 | T52: 208816453000000 | U52: 233503962000000
... A76: Tài sản thuế TNDN hoãn lại | B76: 15777000000 | C76: 3699000000 | D76: 3436000000 | E76: 537000000 | F76: 10986000000 | G76: 28710000000 | H76: 38912000000 | I76: 34339000000 | J76: 13168000000 | K76: 15659000000 | L76: 12002000000 | M76: 15777000000 | N76: 35062000000 | O76: 38912000000 | P76: 39278000000 | Q76: 38316000000 | R76: 41863000000 | S76: 34339000000 | T76: 37793000000 | U76: 44326000000
A77: Tài sản Có khác | F77: 6174673000000 | G77: 6406669000000 | H77: 5873749000000 | I77: 7894091000000
A78: Trong đó: Lợi thế thương mại | B78: 66658000000 | C78: 57135000000 | D78: 47613000000 | E78: 38090000000 | F78: 28568000000 | G78: 19045000000 | H78: 9523000000 | I78: 0 | J78: 65982000000 | K78: 66658000000 | L78: 66658000000 | M78: 66658000000 | N78: 9523000000 | O78: 9523000000 | P78: 0 | Q78: 0 | R78: 0 | S78: 0 | T78: 0 | U78: 0
A79: Các khoản dự phòng rủi ro cho các tài sản Có nội bảng khác | B79: -301267000000 | C79: -274123000000 | D79: -46361000000 | E79: -59513000000 | F79: -231500000000 | G79: -174926000000 | H79: -193424000000 | I79: -71730000000 | J79: -904034000000 | K79: -860014000000 | L79: -692368000000 | M79: -301267000000 | N79: -153529000000 | O79: -193424000000 | P79: -146379000000 | Q79: -101652000000 | R79: -97963000000 | S79: -71730000000 | T79: -69380000000 | U79: -73454000000
A80: Tiền gửi của các tổ chức tín dụng khác | B80: 40692932000000 | C80: 29550155000000 | D80: 24984148000000 | E80: 13870641000000 | F80: 33059306000000 | G80: 68812883000000 | H80: 79515610000000 | I80: 183635325000000 | J80: 28691852000000 | K80: 37500079000000 | L80: 43480340000000 | M80: 40692932000000 | N80: 83303955000000 | O80: 79515610000000 | P80: 75655540000000 | Q80: 101565518000000 | R80: 99386298000000 | S80: 183635325000000 | T80: 184168441000000 | U80: 186637834000000
A81: Vay các tổ chức tín dụng khác | B81: 19777949000000 | C81: 20763897000000 | D81: 25892324000000 | E81: 45689743000000 | F81: 32057473000000 | G81: 30997583000000 | H81: 30653975000000 | I81: 64382164000000 | J81: 7723235000000 | K81: 8607518000000 | L81: 15214489000000 | M81: 19777949000000 | N81: 35255643000000 | O81: 30653975000000 | P81: 33360143000000 | Q81: 29365425000000 | R81: 54939072000000 | S81: 64382164000000 | T81: 72723034000000 | U81: 98970885000000
A82: Các khoản lãi, phí phải trả | B82: 2821056000000 | C82: 4598544000000 | D82: 4765744000000 | E82: 5077890000000 | F82: 7688257000000 | G82: 13390191000000 | H82: 9899902000000 | I82: 13245868000000 | J82: 2703389000000 | K82: 2880361000000 | L82: 2899934000000 | M82: 2821056000000 | N82: 8824156000000 | O82: 9899902000000 | P82: 11305751000000 | Q82: 11038072000000 | R82: 10698135000000 | S82: 13245868000000 | T82: 16185467000000 | U82: 19237642000000
A83: Thuế TNDN hoãn lại phải trả | B83: 16656000000 | C83: 12097000000 | D83: 4651000000 | E83: 0 | F83: 0 | G83: 0 | H83: 0 | I83: 0 | J83: 0 | K83: 0 | L83: 0 | M83: 16656000000 | N83: 0 | O83: 0 | P83: 0 | Q83: 0 | R83: 0 | S83: 0 | T83: 0 | U83: 0
A84: Các khoản phải trả và công nợ khác | B84: 10763164000000 | C84: 17359965000000 | D84: 27129159000000 | E84: 26176059000000 | F84: 33895818000000 | G84: 38236542000000 | H84: 37411147000000 | I84: 51785481000000 | J84: 8353390000000 | K84: 8742444000000 | L84: 7940421000000 | M84: 10763164000000 | N84: 35893971000000 | O84: 37411147000000 | P84: 34674850000000 | Q84: 41292416000000 | R84: 42370965000000 | S84: 51785481000000 | T84: 41408552000000 | U84: 48645739000000
...

Sheet income_statement
A1: item | B1: 2018 | C1: 2019 | D1: 2020 | E1: 2021 | F1: 2022 | G1: 2023 | H1: 2024 | I1: 2025 | J1: 2018-Q1 | K1: 2018-Q2 | L1: 2018-Q3 | M1: 2018-Q4 | N1: 2024-Q3 | O1: 2024-Q4 | P1: 2025-Q1 | Q1: 2025-Q2 | R1: 2025-Q3 | S1: 2025-Q4 | T1: 2026-Q1 | U1: 2026-Q2
A2: Tổng lợi nhuận/lỗ trước thuế | B2: 7767373000000 | C2: 10036119000000 | D2: 10688276000000 | E2: 16527259000000 | F2: 22729320000000 | G2: 26306089000000 | H2: 28829328000000 | I2: 34268358000000 | J2: 1918477000000 | K2: 1910987000000 | L2: 2185455000000 | M2: 1752454000000 | N2: 7307896000000 | O2: 8093120000000 | P2: 8386325000000 | Q2: 7502991000000 | R2: 7249920000000 | S2: 11129122000000 | T2: 9628386000000 | U2: 10559872000000
A3: Chi phí thuế TNDN hiện hành | B3: -1575157000000 | C3: -1959995000000 | D3: -2089420000000 | E3: -3307574000000 | F3: -4582973000000 | G3: -5269869000000 | H3: -5888266000000 | I3: -6876871000000 | J3: -381333000000 | K3: -422046000000 | L3: -420755000000 | M3: -351023000000 | N3: -1465240000000 | O3: -1715348000000 | P3: -1708859000000 | Q3: -1496624000000 | R3: -1452742000000 | S3: -2218646000000 | T3: -1929120000000 | U3: -2120910000000
A4: Chi phí thuế TNDN hoãn lại | B4: -2315000000 | C4: -7520000000 | D4: 7183000000 | E4: 1752000000 | F4: 8838000000 | G4: 17572000000 | H4: 10202000000 | I4: -8509000000 | J4: 11732000000 | K4: 2491000000 | L4: -3657000000 | M4: -12881000000 | N4: 787000000 | O4: 3850000000 | P4: -2587000000 | Q4: -1661000000 | R4: 3263000000 | S4: -7524000000 | T4: 3454000000 | U4: 6511000000
A5: Chi phí thuế thu nhập doanh nghiệp | B5: -1577472000000 | C5: -1967515000000 | D5: -2082237000000 | E5: -3305822000000 | F5: -4574135000000 | G5: -5252297000000 | H5: -5878064000000 | I5: -6885380000000 | J5: -369601000000 | K5: -419555000000 | L5: -424412000000 | M5: -363904000000 | N5: -1464453000000 | O5: -1711498000000 | P5: -1711446000000 | Q5: -1498285000000 | R5: -1449479000000 | S5: -2226170000000 | T5: -1925666000000 | U5: -2114399000000
A6: Lợi nhuận sau thuế | B6: 6189901000000 | C6: 8068604000000 | D6: 8606039000000 | E6: 13221437000000 | F6: 18155185000000 | G6: 21053792000000 | H6: 22951264000000 | I6: 27382978000000 | J6: 1548876000000 | K6: 1491432000000 | L6: 1761043000000 | M6: 1388550000000 | N6: 5843443000000 | O6: 6381622000000 | P6: 6674879000000 | Q6: 6004706000000 | R6: 5800441000000 | S6: 8902952000000 | T6: 7702720000000 | U6: 8445473000000
A7: Lợi ích của cổ đông thiểu số | B7: -77187000000 | C7: -245831000000 | D7: -343380000000 | E7: -524362000000 | F7: -672450000000 | G7: -377004000000 | H7: -317507000000 | I7: -604039000000 | J7: 0 | K7: -42100000000 | L7: 0 | M7: 0 | N7: -53287000000 | O7: -97468000000 | P7: -107139000000 | Q7: -127101000000 | R7: -229417000000 | S7: -140382000000 | T7: -187207000000 | U7: -216411000000
A8: Cổ đông của Công ty mẹ | B8: 6112714000000 | C8: 7822773000000 | D8: 8262659000000 | E8: 12697075000000 | F8: 17482735000000 | G8: 20676788000000 | H8: 22633757000000 | I8: 26778939000000 | J8: 1548876000000 | K8: 1449332000000 | L8: 1761043000000 | M8: 1388550000000 | N8: 5790156000000 | O8: 6284154000000 | P8: 6567740000000 | Q8: 5877605000000 | R8: 5571024000000 | S8: 8762570000000 | T8: 7515513000000 | U8: 8229062000000
A9: Lãi cơ bản trên cổ phiếu (VND) | B9: 2829 | C9: 3596 | D9: 2993 | E9: 3133 | F9: 3856 | G9: 3966 | H9: 3724 | I9: 3325 | J9: 0 | K9: 0 | L9: 0 | M9: 0 | N9: 0 | O9: 0 | P9: 0 | Q9: 0 | R9: 0 | S9: 0 | T9: 0 | U9: 0
A10: Lãi trên cổ phiếu pha loãng (VND) | B10: 0 | C10: 0 | D10: 0 | E10: 0 | F10: 0 | G10: 0 | H10: 0 | I10: 0 | J10: 0 | K10: 0 | L10: 0 | M10: 0 | N10: 0 | O10: 0 | P10: 0 | Q10: 0 | R10: 0 | S10: 0 | T10: 0 | U10: 0
A11: Thu nhập lãi và các khoản thu nhập tương tự | B11: 24824365000000 | C11: 31196604000000 | D11: 32767393000000 | E11: 38464932000000 | F11: 52485812000000 | G11: 69143043000000 | H11: 69061893000000 | I11: 89088116000000 | J11: 5616972000000 | K11: 6174345000000 | L11: 6363929000000 | M11: 6669119000000 | N11: 17396620000000 | O11: 18452076000000 | P11: 19590312000000 | Q11: 21099126000000 | R11: 22265897000000 | S11: 26132781000000 | T11: 28982071000000 | U11: 34006838000000
A12: Chi phí lãi và các chi phí tương tự | B12: -10240868000000 | C12: -13196607000000 | D12: -12489598000000 | E12: -12265378000000 | F12: -16462690000000 | G12: -30459195000000 | H12: -27909674000000 | I12: -37477999000000 | J12: -2323637000000 | K12: -2670497000000 | L12: -2731230000000 | M12: -2515504000000 | N12: -6979985000000 | O12: -7309898000000 | P12: -7898128000000 | Q12: -8727009000000 | R12: -9275373000000 | S12: -11577489000000 | T12: -14068954000000 | U12: -17113184000000
A13: Thu nhập lãi thuần | B13: 14583497000000 | C13: 17999997000000 | D13: 20277795000000 | E13: 26199554000000 | F13: 36023122000000 | G13: 38683848000000 | H13: 41152219000000 | I13: 51610117000000 | J13: 3293335000000 | K13: 3503848000000 | L13: 3632699000000 | M13: 4153615000000 | N13: 10416635000000 | O13: 11142178000000 | P13: 11692184000000 | Q13: 12372117000000 | R13: 12990524000000 | S13: 14555292000000 | T13: 14913117000000 | U13: 16893654000000
... A27: Trích lập dự phòng tổn thất tín dụng | B27: -3035388000000 | C27: -4890623000000 | D27: -6118440000000 | E27: -8030051000000 | F27: -8047677000000 | G27: -6087032000000 | H27: -9576644000000 | I27: -13743504000000 | J27: -692224000000 | K27: -952806000000 | L27: -645617000000 | M27: -747084000000 | N27: -1639970000000 | O27: -3223836000000 | P27: -2986414000000 | Q27: -4786217000000 | R27: -3801508000000 | S27: -2169365000000 | T27: -3454818000000 | U27: -4247083000000

Sheet cash_flow
A1: item | B1: 2018 | C1: 2019 | D1: 2020 | E1: 2021 | F1: 2022 | G1: 2023 | H1: 2024 | I1: 2025 | J1: 2018-Q1 | K1: 2018-Q2 | L1: 2018-Q3 | M1: 2018-Q4 | N1: 2024-Q3 | O1: 2024-Q4 | P1: 2025-Q1 | Q1: 2025-Q2 | R1: 2025-Q3 | S1: 2025-Q4 | T1: 2026-Q1 | U1: 2026-Q2
A2: Lưu chuyển tiền thuần từ hoạt động kinh doanh trước những thay đổi về tài sản và vốn lưu động | B2: 9228303000000 | C2: 14987451000000 | D2: 15326289000000 | E2: 21229572000000 | F2: 29081781000000 | G2: 31334445000000 | H2: 29963896000000 | I2: 39713493000000 | J2: 2609192000000 | K2: 2311489000000 | L2: 1773054000000 | M2: 2536911000000 | N2: 6610835000000 | O2: 12636013000000 | P2: 7431718000000 | Q2: 11324348000000 | R2: 9900748000000 | S2: 11056679000000 | T2: 7697852000000 | U2: 15569920000000
A3: Thuế thu nhập doanh nghiệp đã trả | B3: 0 | C3: 0 | D3: 0 | E3: 0 | F3: 0 | G3: 0 | H3: 0 | I3: 0 | J3: 0 | K3: 0 | L3: 0 | M3: 0 | N3: 0 | O3: 0 | P3: 0 | Q3: 0 | R3: 0 | S3: 0 | T3: 0 | U3: 0
A4: Lưu chuyển tiền thuần từ các hoạt động sản xuất kinh doanh | B4: 2604652000000 | C4: 892883000000 | D4: 14739859000000 | E4: 4468298000000 | F4: 1876329000000 | G4: 41294612000000 | H4: -18576384000000 | I4: 137357399000000 | J4: -10608607000000 | K4: 7053483000000 | L4: -433736000000 | M4: 6593512000000 | N4: -20490106000000 | O4: 15414261000000 | P4: -26075011000000 | Q4: 27591549000000 | R4: 10405047000000 | S4: 125435814000000 | T4: -64971848000000 | U4: 11770037000000
A5: Mua sắm TSCĐ | B5: -483966000000 | C5: -701576000000 | D5: -823253000000 | E5: -1259868000000 | F5: -1748106000000 | G5: -1655386000000 | H5: -2301696000000 | I5: -1780261000000 | J5: -60068000000 | K5: -52493000000 | L5: -190162000000 | M5: -181243000000 | N5: -532734000000 | O5: -910154000000 | P5: -105862000000 | Q5: -367960000000 | R5: -452322000000 | S5: -854117000000 | T5: -591985000000 | U5: -170606000000
A6: Tiền thu được từ thanh lý, nhượng bán tài sản cố định | B6: 5759000000 | C6: 2905000000 | D6: 4739000000 | E6: 7861000000 | F6: 2048000000 | G6: 3714000000 | H6: 6927000000 | I6: 231289000000 | J6: 1346000000 | K6: 26987000000 | L6: 31000000 | M6: -22605000000 | N6: 3036000000 | O6: 1713000000 | P6: 166000000 | Q6: 3035000000 | R6: 227573000000 | S6: 515000000 | T6: 1895000000 | U6: 5778000000
A7: Tiền chi đầu tư, góp vốn vào các đơn vị khác | B7: -1941000000 | C7: -9000000 | D7: -602000000 | E7: 0 | F7: -100091000000 | G7: -45500000000 | H7: -37651000000 | I7: -22024000000 | J7: -246986000000 | K7: 245503000000 | L7: 290766000000 | M7: -259299000000 | N7: 0 | O7: -37651000000 | P7: -71299000000 | Q7: 56245000000 | R7: -506943000000 | S7: 499973000000 | T7: 0 | U7: -3300000000
A8: Tiền thu từ đầu tư, góp vốn vào các đơn vị khác | B8: 31925000000 | C8: 600000000 | D8: 7823000000 | E8: 13291000000 | F8: 271040000000 | G8: 34676000000 | H8: 41568000000 | I8: 2409280000000 | J8: 0 | K8: 0 | L8: 0 | M8: 0 | N8: 4337000000 | O8: 4209000000 | P8: 0 | Q8: 57485000000 | R8: -57485000000 | S8: 2409280000000 | T8: 490000000 | U8: 1470000000
A9: Tiền thu cổ tức và lợi nhuận được chia từ các khoản đầu tư góp vốn dài hạn | B9: 30178000000 | C9: 78227000000 | D9: 92511000000 | E9: 114835000000 | F9: 131941000000 | G9: 57083000000 | H9: 52643000000 | I9: 59336000000 | J9: 9224000000 | K9: 30843000000 | L9: 2601000000 | M9: -12490000000 | N9: -3507000000 | O9: 32861000000 | P9: 40000000 | Q9: 27174000000 | R9: 12470000000 | S9: 19652000000 | T9: 30000000 | U9: 24346000000
A10: Lưu chuyển tiền thuần từ hoạt động đầu tư | B10: -418045000000 | C10: -619853000000 | D10: -718782000000 | E10: -1123881000000 | F10: -1443168000000 | G10: -1605413000000 | H10: -2238209000000 | I10: 904900000000 | J10: -295839000000 | K10: 250195000000 | L10: 103236000000 | M10: -475637000000 | N10: -528868000000 | O10: -909022000000 | P10: -176955000000 | Q10: -224021000000 | R10: -776707000000 | S10: 2082583000000 | T10: -589570000000 | U10: -142312000000
A11: Tăng vốn cổ phần từ góp vốn và/hoặc phát hành cổ phiếu | B11: 0 | C11: 432090000000 | D11: 1719922000000 | E11: 0 | F11: 0 | G11: 0 | H11: 2160445000000 | I11: 0 | J11: 0 | K11: 0 | L11: 0 | M11: 0 | N11: 0 | O11: 995438000000 | P11: 0 | Q11: 0 | R11: 0 | S11: 0 | T11: 85922000000 | U11: 1087532000000
A12: Cổ tức trả cho cổ đông, lợi nhuận đã chia | B12: -1092592000000 | C12: -1304219000000 | D12: 0 | E12: 0 | F12: 0 | G12: -2266993000000 | H12: -2806251000000 | I12: -2072592000000 | J12: -1089303000000 | K12: -3289000000 | L12: 0 | M12: 0 | N12: 0 | O12: -162709000000 | P12: 0 | Q12: 0 | R12: -2072592000000 | S12: 0 | T12: 0 | U12: 0
A13: Lưu chuyển tiền thuần trong kỳ | B13: -1092592000000 | C13: -1908841000000 | D13: 2292984000000 | E13: 0 | F13: 2120000000000 | G13: 1182007000000 | H13: 8759748000000 | I13: 3957417000000 | J13: -1089303000000 | K13: -3289000000 | L13: 0 | M13: 0 | N13: 395103000000 | O13: 4992180000000 | P13: 2198563000000 | Q13: 3500000000000 | R13: 2072408000000 | S13: -3813554000000 | T13: -3712641000000 | U13: 5736532000000
... A53: Chênh lệch số tiền thực thu/thực chi từ hoạt động kinh doanh | B53: 754841000000 | C53: 1276978000000 | D53: 1607374000000 | E53: 3097962000000 | F53: 3231427000000 | G53: 2363720000000 | H53: 6277842000000 | I53: 3645303000000 | J53: 341364000000 | K53: 130650000000 | L53: 98369000000 | M53: 184458000000 | N53: 664929000000 | O53: 2959020000000 | P53: 1274291000000 | Q53: 1472901000000 | R53: 696540000000 | S53: 201571000000 | T53: 166721000000 | U53: 471367000000

Sheet chi_so_tai_chinh
A1: Chỉ tiêu | B1: =balance_sheet!J1 | C1: =balance_sheet!K1 | D1: =balance_sheet!L1 | E1: =balance_sheet!M1 | F1: =balance_sheet!N1 | G1: =balance_sheet!O1 | H1: =balance_sheet!P1 | I1: =balance_sheet!Q1
A2: ROE | B2: =IFERROR(B$65/AVERAGE(#REF!,B$53),"n/a") | C2: =IFERROR(C$65/AVERAGE(B$53,C$53),"n/a") | D2: =IFERROR(D$65/AVERAGE(C$53,D$53),"n/a") | E2: =IFERROR(E$65/AVERAGE(D$53,E$53),"n/a") | F2: =IFERROR(F$65/AVERAGE(E$53,F$53),"n/a") | G2: =IFERROR(G$65/AVERAGE(F$53,G$53),"n/a") | H2: =IFERROR(H$65/AVERAGE(G$53,H$53),"n/a") | I2: =IFERROR(I$65/AVERAGE(H$53,I$53),"n/a")
A3: Tăng trưởng LNST QQ | B3: =IFERROR((B$65-#REF!)/ABS(#REF!),"n/a") | C3: =IFERROR((C$65-B$65)/ABS(B$65),"n/a") | D3: =IFERROR((D$65-C$65)/ABS(C$65),"n/a") | E3: =IFERROR((E$65-D$65)/ABS(D$65),"n/a") | F3: =IFERROR((F$65-E$65)/ABS(E$65),"n/a") | G3: =IFERROR((G$65-F$65)/ABS(F$65),"n/a") | H3: =IFERROR((H$65-G$65)/ABS(G$65),"n/a") | I3: =IFERROR((I$65-H$65)/ABS(H$65),"n/a")
A4: Tăng trưởng LNST YY | F4: =IFERROR((F$65-B$65)/ABS(B$65),"n/a") | G4: =IFERROR((G$65-C$65)/ABS(C$65),"n/a") | H4: =IFERROR((H$65-D$65)/ABS(D$65),"n/a") | I4: =IFERROR((I$65-E$65)/ABS(E$65),"n/a")
A5: Tăng trưởng thu nhập hoạt động QQ | B5: =IFERROR((B$59-#REF!)/ABS(#REF!),"n/a") | C5: =IFERROR((C$59-B$59)/ABS(B$59),"n/a") | D5: =IFERROR((D$59-C$59)/ABS(C$59),"n/a") | E5: =IFERROR((E$59-D$59)/ABS(D$59),"n/a") | F5: =IFERROR((F$59-E$59)/ABS(E$59),"n/a") | G5: =IFERROR((G$59-F$59)/ABS(F$59),"n/a") | H5: =IFERROR((H$59-G$59)/ABS(G$59),"n/a") | I5: =IFERROR((I$59-H$59)/ABS(H$59),"n/a")
A6: Tăng trưởng thu nhập hoạt động YY | F6: =IFERROR((F$59-B$59)/ABS(B$59),"n/a") | G6: =IFERROR((G$59-C$59)/ABS(C$59),"n/a") | H6: =IFERROR((H$59-D$59)/ABS(D$59),"n/a") | I6: =IFERROR((I$59-E$59)/ABS(E$59),"n/a")
A7: % Dư nợ cho vay kinh doanh BĐS | B7: =IFERROR(B$40/#REF!,"n/a") | C7: =IFERROR(C$40/#REF!,"n/a") | D7: =IFERROR(D$40/#REF!,"n/a") | E7: =IFERROR(E$40/#REF!,"n/a") | F7: =IFERROR(F$40/#REF!,"n/a") | G7: =IFERROR(G$40/#REF!,"n/a") | H7: =IFERROR(H$40/#REF!,"n/a") | I7: =IFERROR(I$40/#REF!,"n/a")
A8: NIM | B8: =IFERROR(B$59/AVERAGE(B$46,#REF!),"n/a") | C8: =IFERROR(C$59/AVERAGE(C$46,B46),"n/a") | D8: =IFERROR(D$59/AVERAGE(D$46,C46),"n/a") | E8: =IFERROR(E$59/AVERAGE(E$46,D46),"n/a") | F8: =IFERROR(F$59/AVERAGE(F$46,E46),"n/a") | G8: =IFERROR(G$59/AVERAGE(G$46,F46),"n/a") | H8: =IFERROR(H$59/AVERAGE(H$46,G46),"n/a") | I8: =IFERROR(I$59/AVERAGE(I$46,H46),"n/a")
A9: CASA | B9: =IFERROR((#REF!+B$49+#REF!+B$52)/(#REF!+B$48),"n/a") | C9: =IFERROR((B$49+C$49+B$52+C$52)/(B$48+C$48),"n/a") | D9: =IFERROR((C$49+D$49+C$52+D$52)/(C$48+D$48),"n/a") | E9: =IFERROR((D$49+E$49+D$52+E$52)/(D$48+E$48),"n/a") | F9: =IFERROR((E$49+F$49+E$52+F$52)/(E$48+F$48),"n/a") | G9: =IFERROR((F$49+G$49+F$52+G$52)/(F$48+G$48),"n/a") | H9: =IFERROR((G$49+H$49+G$52+H$52)/(G$48+H$48),"n/a") | I9: =IFERROR((H$49+I$49+H$52+I$52)/(H$48+I$48),"n/a")
A10: NPL | B10: =IFERROR((B$39/#REF!),"n/a") | C10: =IFERROR((C$39/#REF!),"n/a") | D10: =IFERROR((D$39/#REF!),"n/a") | E10: =IFERROR((E$39/#REF!),"n/a") | F10: =IFERROR((F$39/#REF!),"n/a") | G10: =IFERROR((G$39/#REF!),"n/a") | H10: =IFERROR((H$39/#REF!),"n/a") | I10: =IFERROR((I$39/#REF!),"n/a")
A11: COF | B11: =IFERROR(ABS(B$58)/AVERAGE(B$46,#REF!),"n/a") | C11: =IFERROR(ABS(C$58)/AVERAGE(C$46,B46),"n/a") | D11: =IFERROR(ABS(D$58)/AVERAGE(D$46,C46),"n/a") | E11: =IFERROR(ABS(E$58)/AVERAGE(E$46,D46),"n/a") | F11: =IFERROR(ABS(F$58)/AVERAGE(F$46,E46),"n/a") | G11: =IFERROR(ABS(G$58)/AVERAGE(G$46,F46),"n/a") | H11: =IFERROR(ABS(H$58)/AVERAGE(H$46,G46),"n/a") | I11: =IFERROR(ABS(I$58)/AVERAGE(I$46,H46),"n/a")
A12: LLR | B12: =IFERROR(ABS(B$41)/B$39,"n/a") | C12: =IFERROR(ABS(C$41)/C$39,"n/a") | D12: =IFERROR(ABS(D$41)/D$39,"n/a") | E12: =IFERROR(ABS(E$41)/E$39,"n/a") | F12: =IFERROR(ABS(F$41)/F$39,"n/a") | G12: =IFERROR(ABS(G$41)/G$39,"n/a") | H12: =IFERROR(ABS(H$41)/H$39,"n/a") | I12: =IFERROR(ABS(I$41)/I$39,"n/a")
A13: CAR
A14: LDR | B14: =IFERROR(B$33/B$48,"n/a") | C14: =IFERROR(C$33/C$48,"n/a") | D14: =IFERROR(D$33/D$48,"n/a") | E14: =IFERROR(E$33/E$48,"n/a") | F14: =IFERROR(F$33/F$48,"n/a") | G14: =IFERROR(G$33/G$48,"n/a") | H14: =IFERROR(H$33/H$48,"n/a") | I14: =IFERROR(I$33/I$48,"n/a")
A15: Tăng trưởng vốn huy động QQ | B15: =IFERROR((B$48-#REF!)/ABS(#REF!),"n/a") | C15: =IFERROR((C$48-B$48)/ABS(B$48),"n/a") | D15: =IFERROR((D$48-C$48)/ABS(C$48),"n/a") | E15: =IFERROR((E$48-D$48)/ABS(D$48),"n/a") | F15: =IFERROR((F$48-E$48)/ABS(E$48),"n/a") | G15: =IFERROR((G$48-F$48)/ABS(F$48),"n/a") | H15: =IFERROR((H$48-G$48)/ABS(G$48),"n/a") | I15: =IFERROR((I$48-H$48)/ABS(H$48),"n/a")
A16: Tăng trưởng vốn huy động YY | F16: =IFERROR((F$48-B$48)/ABS(B$48),"n/a") | G16: =IFERROR((G$48-C$48)/ABS(C$48),"n/a") | H16: =IFERROR((H$48-D$48)/ABS(D$48),"n/a") | I16: =IFERROR((I$48-E$48)/ABS(E$48),"n/a")
A17: Tăng trưởng tín dụng QQ | B17: =IFERROR((B$33-#REF!)/ABS(#REF!),"n/a") | C17: =IFERROR((C$33-B$33)/ABS(B$33),"n/a") | D17: =IFERROR((D$33-C$33)/ABS(C$33),"n/a") | E17: =IFERROR((E$33-D$33)/ABS(D$33),"n/a") | F17: =IFERROR((F$33-E$33)/ABS(E$33),"n/a") | G17: =IFERROR((G$33-F$33)/ABS(F$33),"n/a") | H17: =IFERROR((H$33-G$33)/ABS(G$33),"n/a") | I17: =IFERROR((I$33-H$33)/ABS(H$33),"n/a")
A18: Tăng trưởng tín dụng YY | F18: =IFERROR((F$33-B$33)/ABS(B$33),"n/a") | G18: =IFERROR((G$33-C$33)/ABS(C$33),"n/a") | H18: =IFERROR((H$33-D$33)/ABS(D$33),"n/a") | I18: =IFERROR((I$33-E$33)/ABS(E$33),"n/a")
A19: CIR | B19: =IFERROR(ABS(B$62)/B$61,"n/a") | C19: =IFERROR(ABS(C$62)/C$61,"n/a") | D19: =IFERROR(ABS(D$62)/D$61,"n/a") | E19: =IFERROR(ABS(E$62)/E$61,"n/a") | F19: =IFERROR(ABS(F$62)/F$61,"n/a") | G19: =IFERROR(ABS(G$62)/G$61,"n/a") | H19: =IFERROR(ABS(H$62)/H$61,"n/a") | I19: =IFERROR(ABS(I$62)/I$61,"n/a")
A20: VCSH/Tổng tài sản | B20: =IFERROR(B$53/B$28,"n/a") | C20: =IFERROR(C$53/C$28,"n/a") | D20: =IFERROR(D$53/D$28,"n/a") | E20: =IFERROR(E$53/E$28,"n/a") | F20: =IFERROR(F$53/F$28,"n/a") | G20: =IFERROR(G$53/G$28,"n/a") | H20: =IFERROR(H$53/H$28,"n/a") | I20: =IFERROR(I$53/I$28,"n/a")
A21: Tỷ lệ lãi và phí phải thu/Thu nhập lãi | B21: =IFERROR(B63/B$57,"n/a") | C21: =IFERROR(C63/C$57,"n/a") | D21: =IFERROR(D63/D$57,"n/a") | E21: =IFERROR(E63/E$57,"n/a") | F21: =IFERROR(F63/F$57,"n/a") | G21: =IFERROR(G63/G$57,"n/a") | H21: =IFERROR(H63/H$57,"n/a") | I21: =IFERROR(I63/I$57,"n/a")
A22: Thu nhập ngoài lãi/Thu nhập hoạt động | B22: =IFERROR(B$60/B$61,"n/a") | C22: =IFERROR(C$60/C$61,"n/a") | D22: =IFERROR(D$60/D$61,"n/a") | E22: =IFERROR(E$60/E$61,"n/a") | F22: =IFERROR(F$60/F$61,"n/a") | G22: =IFERROR(G$60/G$61,"n/a") | H22: =IFERROR(H$60/H$61,"n/a") | I22: =IFERROR(I$60/I$61,"n/a")
A24: II. DỮ LIỆU TRÍCH XUẤT (tự động dò theo tên khoản mục)
A25: Khoản mục | B25: =balance_sheet!J1 | C25: =balance_sheet!K1 | D25: =balance_sheet!L1 | E25: =balance_sheet!M1 | F25: =balance_sheet!N1 | G25: =balance_sheet!O1 | H25: =balance_sheet!P1 | I25: =balance_sheet!Q1
A26: CĐKT
A27: Tài sản
A28: TỔNG TÀI SẢN | B28: =IFERROR(INDEX(balance_sheet!$B:$XFD,MATCH("TỔNG TÀI SẢN",balance_sheet!$A:$A,0),MATCH(B$25,balance_sheet!$B$1:$XFD$1,0)),"") | C28: =IFERROR(INDEX(balance_sheet!$B:$XFD,MATCH("TỔNG TÀI SẢN",balance_sheet!$A:$A,0),MATCH(C$25,balance_sheet!$B$1:$XFD$1,0)),"") | D28: =IFERROR(INDEX(balance_sheet!$B:$XFD,MATCH("TỔNG TÀI SẢN",balance_sheet!$A:$A,0),MATCH(D$25,balance_sheet!$B$1:$XFD$1,0)),"") | E28: =IFERROR(INDEX(balance_sheet!$B:$XFD,MATCH("TỔNG TÀI SẢN",balance_sheet!$A:$A,0),MATCH(E$25,balance_sheet!$B$1:$XFD$1,0)),"") | F28: =IFERROR(INDEX(balance_sheet!$B:$XFD,MATCH("TỔNG TÀI SẢN",balance_sheet!$A:$A,0),MATCH(F$25,balance_sheet!$B$1:$XFD$1,0)),"") | G28: =IFERROR(INDEX(balance_sheet!$B:$XFD,MATCH("TỔNG TÀI SẢN",balance_sheet!$A:$A,0),MATCH(G$25,balance_sheet!$B$1:$XFD$1,0)),"") | H28: =IFERROR(INDEX(balance_sheet!$B:$XFD,MATCH("TỔNG TÀI SẢN",balance_sheet!$A:$A,0),MATCH(H$25,balance_sheet!$B$1:$XFD$1,0)),"") | I28: =IFERROR(INDEX(balance_sheet!$B:$XFD,MATCH("TỔNG TÀI SẢN",balance_sheet!$A:$A,0),MATCH(I$25,balance_sheet!$B$1:$XFD$1,0)),"")
A29: Tiền gửi tại Ngân hàng nhà nước Việt Nam | B29: =IFERROR(INDEX(balance_sheet!$B:$XFD,MATCH("Tiền gửi tại Ngân hàng nhà nước Việt Nam",balance_sheet!$A:$A,0),MATCH(B$25,balance_sheet!$B$1:$XFD$1,0)),"") | C29: =IFERROR(INDEX(balance_sheet!$B:$XFD,MATCH("Tiền gửi tại Ngân hàng nhà nước Việt Nam",balance_sheet!$A:$A,0),MATCH(C$25,balance_sheet!$B$1:$XFD$1,0)),"") | D29: =IFERROR(INDEX(balance_sheet!$B:$XFD,MATCH("Tiền gửi tại Ngân hàng nhà nước Việt Nam",balance_sheet!$A:$A,0),MATCH(D$25,balance_sheet!$B$1:$XFD$1,0)),"") | E29: =IFERROR(INDEX(balance_sheet!$B:$XFD,MATCH("Tiền gửi tại Ngân hàng nhà nước Việt Nam",balance_sheet!$A:$A,0),MATCH(E$25,balance_sheet!$B$1:$XFD$1,0)),"") | F29: =IFERROR(INDEX(balance_sheet!$B:$XFD,MATCH("Tiền gửi tại Ngân hàng nhà nước Việt Nam",balance_sheet!$A:$A,0),MATCH(F$25,balance_sheet!$B$1:$XFD$1,0)),"") | G29: =IFERROR(INDEX(balance_sheet!$B:$XFD,MATCH("Tiền gửi tại Ngân hàng nhà nước Việt Nam",balance_sheet!$A:$A,0),MATCH(G$25,balance_sheet!$B$1:$XFD$1,0)),"") | H29: =IFERROR(INDEX(balance_sheet!$B:$XFD,MATCH("Tiền gửi tại Ngân hàng nhà nước Việt Nam",balance_sheet!$A:$A,0),MATCH(H$25,balance_sheet!$B$1:$XFD$1,0)),"") | I29: =IFERROR(INDEX(balance_sheet!$B:$XFD,MATCH("Tiền gửi tại Ngân hàng nhà nước Việt Nam",balance_sheet!$A:$A,0),MATCH(I$25,balance_sheet!$B$1:$XFD$1,0)),"")
A30: Tiền gửi tại các TCTD khác và cho vay các TCTD khác | B30: =IFERROR(INDEX(balance_sheet!$B:$XFD,MATCH("Tiền gửi tại các TCTD khác và cho vay các TCTD khác",balance_sheet!$A:$A,0),MATCH(B$25,balance_sheet!$B$1:$XFD$1,0)),"") | C30: =IFERROR(INDEX(balance_sheet!$B:$XFD,MATCH("Tiền gửi tại các TCTD khác và cho vay các TCTD khác",balance_sheet!$A:$A,0),MATCH(C$25,balance_sheet!$B$1:$XFD$1,0)),"") | D30: =IFERROR(INDEX(balance_sheet!$B:$XFD,MATCH("Tiền gửi tại các TCTD khác và cho vay các TCTD khác",balance_sheet!$A:$A,0),MATCH(D$25,balance_sheet!$B$1:$XFD$1,0)),"") | E30: =IFERROR(INDEX(balance_sheet!$B:$XFD,MATCH("Tiền gửi tại các TCTD khác và cho vay các TCTD khác",balance_sheet!$A:$A,0),MATCH(E$25,balance_sheet!$B$1:$XFD$1,0)),"") | F30: =IFERROR(INDEX(balance_sheet!$B:$XFD,MATCH("Tiền gửi tại các TCTD khác và cho vay các TCTD khác",balance_sheet!$A:$A,0),MATCH(F$25,balance_sheet!$B$1:$XFD$1,0)),"") | G30: =IFERROR(INDEX(balance_sheet!$B:$XFD,MATCH("Tiền gửi tại các TCTD khác và cho vay các TCTD khác",balance_sheet!$A:$A,0),MATCH(G$25,balance_sheet!$B$1:$XFD$1,0)),"") | H30: =IFERROR(INDEX(balance_sheet!$B:$XFD,MATCH("Tiền gửi tại các TCTD khác và cho vay các TCTD khác",balance_sheet!$A:$A,0),MATCH(H$25,balance_sheet!$B$1:$XFD$1,0)),"") | I30: =IFERROR(INDEX(balance_sheet!$B:$XFD,MATCH("Tiền gửi tại các TCTD khác và cho vay các TCTD khác",balance_sheet!$A:$A,0),MATCH(I$25,balance_sheet!$B$1:$XFD$1,0)),"")
A31: Dự phòng rủi ro cho cay các TCTC khác | B31: =IFERROR(INDEX(balance_sheet!$B:$XFD,MATCH("Dự phòng rủi ro",balance_sheet!$A:$A,0),MATCH(B$25,balance_sheet!$B$1:$XFD$1,0)),"") | C31: =IFERROR(INDEX(balance_sheet!$B:$XFD,MATCH("Dự phòng rủi ro",balance_sheet!$A:$A,0),MATCH(C$25,balance_sheet!$B$1:$XFD$1,0)),"") | D31: =IFERROR(INDEX(balance_sheet!$B:$XFD,MATCH("Dự phòng rủi ro",balance_sheet!$A:$A,0),MATCH(D$25,balance_sheet!$B$1:$XFD$1,0)),"") | E31: =IFERROR(INDEX(balance_sheet!$B:$XFD,MATCH("Dự phòng rủi ro",balance_sheet!$A:$A,0),MATCH(E$25,balance_sheet!$B$1:$XFD$1,0)),"") | F31: =IFERROR(INDEX(balance_sheet!$B:$XFD,MATCH("Dự phòng rủi ro",balance_sheet!$A:$A,0),MATCH(F$25,balance_sheet!$B$1:$XFD$1,0)),"") | G31: =IFERROR(INDEX(balance_sheet!$B:$XFD,MATCH("Dự phòng rủi ro",balance_sheet!$A:$A,0),MATCH(G$25,balance_sheet!$B$1:$XFD$1,0)),"") | H31: =IFERROR(INDEX(balance_sheet!$B:$XFD,MATCH("Dự phòng rủi ro",balance_sheet!$A:$A,0),MATCH(H$25,balance_sheet!$B$1:$XFD$1,0)),"") | I31: =IFERROR(INDEX(balance_sheet!$B:$XFD,MATCH("Dự phòng rủi ro",balance_sheet!$A:$A,0),MATCH(I$25,balance_sheet!$B$1:$XFD$1,0)),"")
A32: Chứng khoán kinh doanh | B32: =IFERROR(INDEX(balance_sheet!$B:$XFD,MATCH("Chứng khoán kinh doanh",balance_sheet!$A:$A,0),MATCH(B$25,balance_sheet!$B$1:$XFD$1,0)),"") | C32: =IFERROR(INDEX(balance_sheet!$B:$XFD,MATCH("Chứng khoán kinh doanh",balance_sheet!$A:$A,0),MATCH(C$25,balance_sheet!$B$1:$XFD$1,0)),"") | D32: =IFERROR(INDEX(balance_sheet!$B:$XFD,MATCH("Chứng khoán kinh doanh",balance_sheet!$A:$A,0),MATCH(D$25,balance_sheet!$B$1:$XFD$1,0)),"") | E32: =IFERROR(INDEX(balance_sheet!$B:$XFD,MATCH("Chứng khoán kinh doanh",balance_sheet!$A:$A,0),MATCH(E$25,balance_sheet!$B$1:$XFD$1,0)),"") | F32: =IFERROR(INDEX(balance_sheet!$B:$XFD,MATCH("Chứng khoán kinh doanh",balance_sheet!$A:$A,0),MATCH(F$25,balance_sheet!$B$1:$XFD$1,0)),"") | G32: =IFERROR(INDEX(balance_sheet!$B:$XFD,MATCH("Chứng khoán kinh doanh",balance_sheet!$A:$A,0),MATCH(G$25,balance_sheet!$B$1:$XFD$1,0)),"") | H32: =IFERROR(INDEX(balance_sheet!$B:$XFD,MATCH("Chứng khoán kinh doanh",balance_sheet!$A:$A,0),MATCH(H$25,balance_sheet!$B$1:$XFD$1,0)),"") | I32: =IFERROR(INDEX(balance_sheet!$B:$XFD,MATCH("Chứng khoán kinh doanh",balance_sheet!$A:$A,0),MATCH(I$25,balance_sheet!$B$1:$XFD$1,0)),"")
A33: Cho vay khách hàng | B33: =IFERROR(INDEX(balance_sheet!$B:$XFD,MATCH("Cho vay khách hàng",balance_sheet!$A:$A,0),MATCH(B$25,balance_sheet!$B$1:$XFD$1,0)),"") | C33: =IFERROR(INDEX(balance_sheet!$B:$XFD,MATCH("Cho vay khách hàng",balance_sheet!$A:$A,0),MATCH(C$25,balance_sheet!$B$1:$XFD$1,0)),"") | D33: =IFERROR(INDEX(balance_sheet!$B:$XFD,MATCH("Cho vay khách hàng",balance_sheet!$A:$A,0),MATCH(D$25,balance_sheet!$B$1:$XFD$1,0)),"") | E33: =IFERROR(INDEX(balance_sheet!$B:$XFD,MATCH("Cho vay khách hàng",balance_sheet!$A:$A,0),MATCH(E$25,balance_sheet!$B$1:$XFD$1,0)),"") | F33: =IFERROR(INDEX(balance_sheet!$B:$XFD,MATCH("Cho vay khách hàng",balance_sheet!$A:$A,0),MATCH(F$25,balance_sheet!$B$1:$XFD$1,0)),"") | G33: =IFERROR(INDEX(balance_sheet!$B:$XFD,MATCH("Cho vay khách hàng",balance_sheet!$A:$A,0),MATCH(G$25,balance_sheet!$B$1:$XFD$1,0)),"") | H33: =IFERROR(INDEX(balance_sheet!$B:$XFD,MATCH("Cho vay khách hàng",balance_sheet!$A:$A,0),MATCH(H$25,balance_sheet!$B$1:$XFD$1,0)),"") | I33: =IFERROR(INDEX(balance_sheet!$B:$XFD,MATCH("Cho vay khách hàng",balance_sheet!$A:$A,0),MATCH(I$25,balance_sheet!$B$1:$XFD$1,0)),"")
A34: + Nợ đủ tiêu chuẩn
A35: + Nợ cần chú ý
A36: + Nợ dưới tiêu chuẩn
A37: + Nợ nghi ngờ
A38: + Nợ có khả năng mất vốn
A39: Nợ xấu | B39: =SUM(B36:B38) | C39: =SUM(C36:C38) | D39: =SUM(D36:D38) | E39: =SUM(E36:E38) | F39: =SUM(F36:F38) | G39: =SUM(G36:G38) | H39: =SUM(H36:H38) | I39: =SUM(I36:I38)
A40: Cho vay KDBĐS
A41: Dự phòng rủi ro cho vay khách hàng | B41: =IFERROR(INDEX(balance_sheet!$B:$XFD,MATCH("Dự phòng rủi ro cho vay khách hàng",balance_sheet!$A:$A,0),MATCH(B$25,balance_sheet!$B$1:$XFD$1,0)),"") | C41: =IFERROR(INDEX(balance_sheet!$B:$XFD,MATCH("Dự phòng rủi ro cho vay khách hàng",balance_sheet!$A:$A,0),MATCH(C$25,balance_sheet!$B$1:$XFD$1,0)),"") | D41: =IFERROR(INDEX(balance_sheet!$B:$XFD,MATCH("Dự phòng rủi ro cho vay khách hàng",balance_sheet!$A:$A,0),MATCH(D$25,balance_sheet!$B$1:$XFD$1,0)),"") | E41: =IFERROR(INDEX(balance_sheet!$B:$XFD,MATCH("Dự phòng rủi ro cho vay khách hàng",balance_sheet!$A:$A,0),MATCH(E$25,balance_sheet!$B$1:$XFD$1,0)),"") | F41: =IFERROR(INDEX(balance_sheet!$B:$XFD,MATCH("Dự phòng rủi ro cho vay khách hàng",balance_sheet!$A:$A,0),MATCH(F$25,balance_sheet!$B$1:$XFD$1,0)),"") | G41: =IFERROR(INDEX(balance_sheet!$B:$XFD,MATCH("Dự phòng rủi ro cho vay khách hàng",balance_sheet!$A:$A,0),MATCH(G$25,balance_sheet!$B$1:$XFD$1,0)),"") | H41: =IFERROR(INDEX(balance_sheet!$B:$XFD,MATCH("Dự phòng rủi ro cho vay khách hàng",balance_sheet!$A:$A,0),MATCH(H$25,balance_sheet!$B$1:$XFD$1,0)),"") | I41: =IFERROR(INDEX(balance_sheet!$B:$XFD,MATCH("Dự phòng rủi ro cho vay khách hàng",balance_sheet!$A:$A,0),MATCH(I$25,balance_sheet!$B$1:$XFD$1,0)),"")
...
