Workbook

Sheet balance_sheet
A1: item | B1: 2018 | C1: 2019 | D1: 2020 | E1: 2021 | F1: 2022 | G1: 2023 | H1: 2024 | I1: 2025
A2: TÀI SẢN NGẮN HẠN | B2: 18406087226041 | C2: 18979176128930 | D2: 25265933056476 | E2: 35118372900846 | F2: 30937711076141 | G2: 36705751751876 | H2: 45535942846453 | I2: 58137438254908
A3: Tiền và tương đương tiền | B3: 3925727206293 | C3: 3453388617569 | D3: 4686191374038 | E3: 5417845293242 | F3: 6440177174322 | G3: 8279156683221 | H3: 9315440438884 | I3: 10522105729992
A4: Tiền | B4: 2682437141849 | C4: 2611644417963 | D4: 2216742790757 | E4: 3447377491137 | F4: 3880860111180 | G4: 5975127685903 | H4: 6725619929289 | I4: 8084751080186
A5: Các khoản tương đương tiền | B5: 1243290064444 | C5: 841744199606 | D5: 2469448583281 | E5: 1970467802105 | F5: 2559317063142 | G5: 2304028997318 | H5: 2589820509595 | I5: 2437354649806
A6: Đầu tư ngắn hạn | B6: 5568623727137 | C6: 6708978162325 | D6: 12435918124269 | E6: 20730720735456 | F6: 0 | G6: 0 | H6: 0 | I6: 0
A7: Đầu tư ngắn hạn | B7: 0 | C7: 0 | D7: 0 | E7: 0 | F7: 0 | G7: 0 | H7: 0 | I7: 0
A8: Dự phòng giảm giá | B8: 0 | C8: 0 | D8: 0 | E8: 0 | F8: 0 | G8: 0 | H8: 0 | I8: 0
A9: Các khoản phải thu | B9: 6426946279074 | C9: 6536251148622 | D9: 6265411863371 | E9: 6882182894987 | F9: 8502895161839 | G9: 9674343237344 | H9: 11381523992803 | I9: 14402017450105
A10: Phải thu khách hàng | B10: 5561545801834 | C10: 5812938112346 | D10: 5564392191491 | E10: 6211956510246 | F10: 7990076948983 | G10: 9057647206985 | H10: 10537019113380 | I10: 12734600596550
A11: Trả trước người bán | B11: 218427501076 | C11: 274779131899 | D11: 459336196478 | E11: 400707131836 | F11: 292916357080 | G11: 482074732731 | H11: 610379845664 | I11: 952737932722
A12: Phải thu nội bộ | B12: 0 | C12: 0 | D12: 0 | E12: 0 | F12: 0 | G12: 0 | H12: 0 | I12: 0
A13: Phải thu hợp đồng xây dựng đang thực hiện | B13: 251954356007 | C13: 318339389202 | D13: 197972680487 | E13: 168939964952 | F13: 199252243559 | G13: 176770894412 | H13: 136097256629 | I13: 200405269967
... A123: Nguồn kinh phí đã hình thành TSCĐ | B123: 0 | C123: 0 | D123: 0 | E123: 0 | F123: 0 | G123: 0 | H123: 0 | I123: 0

Sheet income_statement
A1: item | B1: 2018 | C1: 2019 | D1: 2020 | E1: 2021 | F1: 2022 | G1: 2023 | H1: 2024 | I1: 2025
A2: Doanh thu bán hàng và cung cấp dịch vụ | B2: 23259126277266 | C2: 27791982176829 | D2: 29921698144296 | E2: 35671052233610 | F2: 44023010881275 | G2: 52625174861333 | H2: 62962652134635 | I2: 70207688944553
A3: Các khoản giảm trừ doanh thu | B3: -45589419541 | C3: -75022024554 | D3: -91297617472 | E3: -13789688583 | F3: -13483200364 | G3: -7274033948 | H3: -113857783268 | I3: -94863843843
A4: Doanh thu thuần | B4: 23213536857725 | C4: 27716960152275 | D4: 29830400526824 | E4: 35657262545027 | F4: 44009527680911 | G4: 52617900827385 | H4: 62848794351367 | I4: 70112825100710
A5: Giá vốn hàng bán | B5: -14490657872236 | C5: -17004910529153 | D5: -18016743052097 | E5: -22025298308249 | F5: -26842249039713 | G5: -32298347382703 | H5: -39150445981451 | I5: -44224295588297
A6: Lợi nhuận gộp | B6: 8722878985489 | C6: 10712049623122 | D6: 11813657474727 | E6: 13631964236778 | F6: 17167278641198 | G6: 20319553444682 | H6: 23698348369916 | I6: 25888529512413
A7: Doanh thu hoạt động tài chính | B7: 600093309692 | C7: 650494541199 | D7: 821896424782 | E7: 1270789386267 | F7: 1998503979865 | G7: 2336069089819 | H7: 1935749115305 | I7: 2977156356773
A8: Chi phí tài chính | B8: -361046565710 | C8: -592386050061 | D8: -548165211617 | E8: -1144187446845 | F8: -1687369701824 | G8: -1718298463710 | H8: -1811547381981 | I8: -1672048701466
A9: Chi phí lãi vay | B9: -238344431747 | C9: -358987537452 | D9: -385337754896 | E9: -483995846804 | F9: -645725556308 | G9: -832648611261 | H9: -551639361786 | I9: -809759601156
A10: Chi phí bán hàng | B10: -2047833577540 | C10: -2345957646507 | D10: -2713561338553 | E10: -3604610784981 | F10: -4526440691815 | G10: -5242551906960 | H10: -6115961971783 | I10: -7562660640454
A11: Chi phí quản lý doanh nghiệp | B11: -3553288111032 | C11: -4219254770652 | D11: -4495366457586 | E11: -4612325935574 | F11: -5846280653514 | G11: -6625373638359 | H11: -7074038614774 | I11: -7337325397804
A12: Lãi/(lỗ) từ hoạt động kinh doanh | B12: 3799831155588 | C12: 4609873163414 | D12: 5190654463931 | E12: 6228494136764 | F12: 7589289622311 | G12: 9111745534433 | H12: 11025080772955 | I12: 12951675964776
A13: Thu nhập khác | B13: 60448926027 | C13: 112683563071 | D13: 131401186949 | E13: 133219177622 | F13: 184323926142 | G13: 200956010920 | H13: 175450599740 | I13: 142892570480
... A26: Lãi/(lỗ) từ công ty liên doanh (từ năm 2015) | B26: 439027114689 | C26: 404927466313 | D26: 312193572178 | E26: 686864681119 | F26: 483598048401 | G26: 42347008961 | H26: 392531256272 | I26: 658024835314

Sheet cash_flow
A1: item | B1: 2018 | C1: 2019 | D1: 2020 | E1: 2021 | F1: 2022 | G1: 2023 | H1: 2024 | I1: 2025
A2: Lợi nhuận/(lỗ) trước thuế | B2: 3857602555206 | C2: 4664530511706 | D2: 5263456629967 | E2: 6337206440958 | F2: 7662282959880 | G2: 9203006098570 | H2: 11069666417819 | I2: 13043632833797
A3: Khấu hao TSCĐ và BĐSĐT | B3: 1164692003074 | C3: 1354613458881 | D3: 1490607476892 | E3: 1643915685332 | F3: 1833064499128 | G3: 2286514158688 | H3: 2535298475665 | I3: 2914178360732
A4: Chi phí dự phòng | B4: 120544469503 | C4: 287785755015 | D4: 313851138486 | E4: 352207924154 | F4: 880253740252 | G4: 677928749053 | H4: 1148951390915 | I4: 651406282654
A5: Lãi/lỗ chênh lệch tỷ giá hối đoái do đánh giá lại các khoản mục tiền tệ có gốc ngoại tệ | B5: 18627355032 | C5: 9525407416 | D5: -3386721059 | E5: -63913432668 | F5: 7652847077 | G5: -34070358211 | H5: 46311803197 | I5: -27776460391
A6: Lãi/(lỗ) từ thanh lý tài sản cố định | B6: 0 | C6: 0 | D6: 0 | E6: 0 | F6: 0 | G6: 0 | H6: 0 | I6: 0
A7: (Lãi)/lỗ từ hoạt động đầu tư | B7: -761304152101 | C7: -903441404801 | D7: -1039617856401 | E7: -1700489438802 | F7: -1986715685147 | G7: -1976268355482 | H7: -1725022480893 | I7: -2575840046010
A8: Chi phí lãi vay | B8: 238344431747 | C8: 358987537452 | D8: 385337754896 | E8: 483995846804 | F8: 645725556308 | G8: 832648611261 | H8: 551639361786 | I8: 809759601156
A9: Thu lãi và cổ tức | B9: 0 | C9: 0 | D9: 0 | E9: 0 | F9: 0 | G9: 0 | H9: 0 | I9: 0
A10: Lợi nhuận/(lỗ) từ hoạt động kinh doanh trước những thay đổi vốn lưu động | B10: 4638506662461 | C10: 5772001265669 | D10: 6410248422781 | E10: 7052923025778 | F10: 9042263917498 | G10: 10989758903879 | H10: 13626844968489 | I10: 14815360571938
A11: (Tăng)/giảm các khoản phải thu | B11: -159344472867 | C11: -481202921282 | D11: 311571475172 | E11: -693503200106 | F11: -1949023327296 | G11: -1163209212196 | H11: -1913663012505 | I11: -2874821969471
A12: (Tăng)/giảm hàng tồn kho | B12: -229108218690 | C12: 256058829417 | D12: -55124600922 | E12: -218231826239 | F12: -497802711008 | G12: 396161114891 | H12: -265267561842 | I12: -335071616492
A13: Tăng/(giảm) các khoản phải trả | B13: 644985031490 | C13: 305737668001 | D13: 1060519849887 | E13: 1910090001449 | F13: 1299834862339 | G13: 1380255770889 | H13: 2875571263689 | I13: 2556427255416
... A42: (Tăng)/giảm chứng khoán kinh doanh | B42: 0 | C42: 0 | D42: 0 | E42: 0 | F42: 0 | G42: 0 | H42: 0 | I42: 0

Sheet chi_so_tai_chinh
A1: Chỉ tiêu | B1: =balance_sheet!B1 | C1: =balance_sheet!C1 | D1: =balance_sheet!D1 | E1: =balance_sheet!E1 | F1: =balance_sheet!F1 | G1: =balance_sheet!G1 | H1: =balance_sheet!H1 | I1: =balance_sheet!I1 | J1: 2026
A2: ROE | B2: n/a | C2: =IFERROR(C$51/((C$39+B$39)/2),"n/a") | D2: =IFERROR(D$51/((D$39+C$39)/2),"n/a") | E2: =IFERROR(E$51/((E$39+D$39)/2),"n/a") | F2: =IFERROR(F$51/((F$39+E$39)/2),"n/a") | G2: =IFERROR(G$51/((G$39+F$39)/2),"n/a") | H2: =IFERROR(H$51/((H$39+G$39)/2),"n/a") | I2: =IFERROR(I$51/((I$39+H$39)/2),"n/a")
A3: ROA | B3: =IFERROR(B$51/((B$31+A$31)/2),"n/a") | C3: =IFERROR(C$51/((C$31+B$31)/2),"n/a") | D3: =IFERROR(D$51/((D$31+C$31)/2),"n/a") | E3: =IFERROR(E$51/((E$31+D$31)/2),"n/a") | F3: =IFERROR(F$51/((F$31+E$31)/2),"n/a") | G3: =IFERROR(G$51/((G$31+F$31)/2),"n/a") | H3: =IFERROR(H$51/((H$31+G$31)/2),"n/a") | I3: =IFERROR(I$51/((I$31+H$31)/2),"n/a")
A4: Tăng trưởng LN Cổ đông Cty mẹ | B4: n/a | C4: =IFERROR((C$51-B$51)/ABS(B$51),"n/a") | D4: =IFERROR((D$51-C$51)/ABS(C$51),"n/a") | E4: =IFERROR((E$51-D$51)/ABS(D$51),"n/a") | F4: =IFERROR((F$51-E$51)/ABS(E$51),"n/a") | G4: =IFERROR((G$51-F$51)/ABS(F$51),"n/a") | H4: =IFERROR((H$51-G$51)/ABS(G$51),"n/a") | I4: =IFERROR((I$51-H$51)/ABS(H$51),"n/a") | J4: 0.15
A5: Tăng trưởng Doanh thu thuần | B5: n/a | C5: =IFERROR((C$42-B$42)/ABS(B$42),"n/a") | D5: =IFERROR((D$42-C$42)/ABS(C$42),"n/a") | E5: =IFERROR((E$42-D$42)/ABS(D$42),"n/a") | F5: =IFERROR((F$42-E$42)/ABS(E$42),"n/a") | G5: =IFERROR((G$42-F$42)/ABS(F$42),"n/a") | H5: =IFERROR((H$42-G$42)/ABS(G$42),"n/a") | I5: =IFERROR((I$42-H$42)/ABS(H$42),"n/a") | J5: 0.16
A6: Biên lợi nhuận gộp | B6: =IFERROR(B$44/B$42,"n/a") | C6: =IFERROR(C$44/C$42,"n/a") | D6: =IFERROR(D$44/D$42,"n/a") | E6: =IFERROR(E$44/E$42,"n/a") | F6: =IFERROR(F$44/F$42,"n/a") | G6: =IFERROR(G$44/G$42,"n/a") | H6: =IFERROR(H$44/H$42,"n/a") | I6: =IFERROR(I$44/I$42,"n/a")
A7: Biên lợi nhuận ròng | B7: =IFERROR(B$51/B$42,"n/a") | C7: =IFERROR(C$51/C$42,"n/a") | D7: =IFERROR(D$51/D$42,"n/a") | E7: =IFERROR(E$51/E$42,"n/a") | F7: =IFERROR(F$51/F$42,"n/a") | G7: =IFERROR(G$51/G$42,"n/a") | H7: =IFERROR(H$51/H$42,"n/a") | I7: =IFERROR(I$51/I$42,"n/a") | J7: =IFERROR(J$51/J$42,"n/a")
A8: D/E (Nợ vay / Vốn chủ sở hữu) | B8: =IFERROR((B$34+B$36)/B$39,"n/a") | C8: =IFERROR((C$34+C$36)/C$39,"n/a") | D8: =IFERROR((D$34+D$36)/D$39,"n/a") | E8: =IFERROR((E$34+E$36)/E$39,"n/a") | F8: =IFERROR((F$34+F$36)/F$39,"n/a") | G8: =IFERROR((G$34+G$36)/G$39,"n/a") | H8: =IFERROR((H$34+H$36)/H$39,"n/a") | I8: =IFERROR((I$34+I$36)/I$39,"n/a")
A9: - Nợ vay dài hạn/Vốn chủ sở hữu | B9: =IFERROR(B$36/B$39,"n/a") | C9: =IFERROR(C$36/C$39,"n/a") | D9: =IFERROR(D$36/D$39,"n/a") | E9: =IFERROR(E$36/E$39,"n/a") | F9: =IFERROR(F$36/F$39,"n/a") | G9: =IFERROR(G$36/G$39,"n/a") | H9: =IFERROR(H$36/H$39,"n/a") | I9: =IFERROR(I$36/I$39,"n/a")
A10: - Nợ vay ngắn hạn/Vốn chủ sở hữu | B10: =IFERROR(B$34/B$39,"n/a") | C10: =IFERROR(C$34/C$39,"n/a") | D10: =IFERROR(D$34/D$39,"n/a") | E10: =IFERROR(E$34/E$39,"n/a") | F10: =IFERROR(F$34/F$39,"n/a") | G10: =IFERROR(G$34/G$39,"n/a") | H10: =IFERROR(H$34/H$39,"n/a") | I10: =IFERROR(I$34/I$39,"n/a")
A11: Nợ phải trả/Vốn chủ sở hữu | B11: =IFERROR(B$38/B$39,"n/a") | C11: =IFERROR(C$38/C$39,"n/a") | D11: =IFERROR(D$38/D$39,"n/a") | E11: =IFERROR(E$38/E$39,"n/a") | F11: =IFERROR(F$38/F$39,"n/a") | G11: =IFERROR(G$38/G$39,"n/a") | H11: =IFERROR(H$38/H$39,"n/a") | I11: =IFERROR(I$38/I$39,"n/a")
A12: - Nợ dài hạn/Vốn chủ sở hữu | B12: =IFERROR(B$37/B$39,"n/a") | C12: =IFERROR(C$37/C$39,"n/a") | D12: =IFERROR(D$37/D$39,"n/a") | E12: =IFERROR(E$37/E$39,"n/a") | F12: =IFERROR(F$37/F$39,"n/a") | G12: =IFERROR(G$37/G$39,"n/a") | H12: =IFERROR(H$37/H$39,"n/a") | I12: =IFERROR(I$37/I$39,"n/a")
A13: - Nợ ngắn hạn/Vốn chủ sở hữu | B13: =IFERROR(B$35/B$39,"n/a") | C13: =IFERROR(C$35/C$39,"n/a") | D13: =IFERROR(D$35/D$39,"n/a") | E13: =IFERROR(E$35/E$39,"n/a") | F13: =IFERROR(F$35/F$39,"n/a") | G13: =IFERROR(G$35/G$39,"n/a") | H13: =IFERROR(H$35/H$39,"n/a") | I13: =IFERROR(I$35/I$39,"n/a")
A14: Chi phí bán hàng, quản lý/LN gộp | B14: =IFERROR((ABS(B$45)+ABS(B$46))/B$44,"n/a") | C14: =IFERROR((ABS(C$45)+ABS(C$46))/C$44,"n/a") | D14: =IFERROR((ABS(D$45)+ABS(D$46))/D$44,"n/a") | E14: =IFERROR((ABS(E$45)+ABS(E$46))/E$44,"n/a") | F14: =IFERROR((ABS(F$45)+ABS(F$46))/F$44,"n/a") | G14: =IFERROR((ABS(G$45)+ABS(G$46))/G$44,"n/a") | H14: =IFERROR((ABS(H$45)+ABS(H$46))/H$44,"n/a") | I14: =IFERROR((ABS(I$45)+ABS(I$46))/I$44,"n/a")
A15: Chi phí lãi vay/LN từ hoạt động kinh doanh | B15: =IFERROR(ABS(B$48)/B$47,"n/a") | C15: =IFERROR(ABS(C$48)/C$47,"n/a") | D15: =IFERROR(ABS(D$48)/D$47,"n/a") | E15: =IFERROR(ABS(E$48)/E$47,"n/a") | F15: =IFERROR(ABS(F$48)/F$47,"n/a") | G15: =IFERROR(ABS(G$48)/G$47,"n/a") | H15: =IFERROR(ABS(H$48)/H$47,"n/a") | I15: =IFERROR(ABS(I$48)/I$47,"n/a")
A16: Số ngày phải trả (DPO) | B16: n/a | C16: =IFERROR(((C$33+B$33)/2)/ABS(C$43)*365,"n/a") | D16: =IFERROR(((D$33+C$33)/2)/ABS(D$43)*365,"n/a") | E16: =IFERROR(((E$33+D$33)/2)/ABS(E$43)*365,"n/a") | F16: =IFERROR(((F$33+E$33)/2)/ABS(F$43)*365,"n/a") | G16: =IFERROR(((G$33+F$33)/2)/ABS(G$43)*365,"n/a") | H16: =IFERROR(((H$33+G$33)/2)/ABS(H$43)*365,"n/a") | I16: =IFERROR(((I$33+H$33)/2)/ABS(I$43)*365,"n/a")
A17: Số ngày phải thu (DSO) | B17: n/a | C17: =IFERROR(((C$27+B$27)/2)/C$42*365,"n/a") | D17: =IFERROR(((D$27+C$27)/2)/D$42*365,"n/a") | E17: =IFERROR(((E$27+D$27)/2)/E$42*365,"n/a") | F17: =IFERROR(((F$27+E$27)/2)/F$42*365,"n/a") | G17: =IFERROR(((G$27+F$27)/2)/G$42*365,"n/a") | H17: =IFERROR(((H$27+G$27)/2)/H$42*365,"n/a") | I17: =IFERROR(((I$27+H$27)/2)/I$42*365,"n/a")
A18: Số ngày tồn kho (DIO) | B18: n/a | C18: =IFERROR(((C$28+B$28)/2)/ABS(C$43)*365,"n/a") | D18: =IFERROR(((D$28+C$28)/2)/ABS(D$43)*365,"n/a") | E18: =IFERROR(((E$28+D$28)/2)/ABS(E$43)*365,"n/a") | F18: =IFERROR(((F$28+E$28)/2)/ABS(F$43)*365,"n/a") | G18: =IFERROR(((G$28+F$28)/2)/ABS(G$43)*365,"n/a") | H18: =IFERROR(((H$28+G$28)/2)/ABS(H$43)*365,"n/a") | I18: =IFERROR(((I$28+H$28)/2)/ABS(I$43)*365,"n/a")
A19: Tiền và tương đương tiền/Tài sản | B19: =IFERROR(B$26/B$31,"n/a") | C19: =IFERROR(C$26/C$31,"n/a") | D19: =IFERROR(D$26/D$31,"n/a") | E19: =IFERROR(E$26/E$31,"n/a") | F19: =IFERROR(F$26/F$31,"n/a") | G19: =IFERROR(G$26/G$31,"n/a") | H19: =IFERROR(H$26/H$31,"n/a") | I19: =IFERROR(I$26/I$31,"n/a")
A20: Hàng tồn kho/Tài sản | B20: =IFERROR(B$28/B$31,"n/a") | C20: =IFERROR(C$28/C$31,"n/a") | D20: =IFERROR(D$28/D$31,"n/a") | E20: =IFERROR(E$28/E$31,"n/a") | F20: =IFERROR(F$28/F$31,"n/a") | G20: =IFERROR(G$28/G$31,"n/a") | H20: =IFERROR(H$28/H$31,"n/a") | I20: =IFERROR(I$28/I$31,"n/a")
A22: II. DỮ LIỆU TRÍCH XUẤT (tự động dò theo tên khoản mục)
A23: Khoản mục | B23: =balance_sheet!B1 | C23: =balance_sheet!C1 | D23: =balance_sheet!D1 | E23: =balance_sheet!E1 | F23: =balance_sheet!F1 | G23: =balance_sheet!G1 | H23: =balance_sheet!H1 | I23: =balance_sheet!I1
A24: CĐKT
A25: Tài sản
A26: Tiền và tương đương tiền | B26: =IFERROR(INDEX(balance_sheet!$B:$I,MATCH("Tiền và tương đương tiền",balance_sheet!$A:$A,0),MATCH(B$23,balance_sheet!$B$1:$I$1,0)),"") | C26: =IFERROR(INDEX(balance_sheet!$B:$I,MATCH("Tiền và tương đương tiền",balance_sheet!$A:$A,0),MATCH(C$23,balance_sheet!$B$1:$I$1,0)),"") | D26: =IFERROR(INDEX(balance_sheet!$B:$I,MATCH("Tiền và tương đương tiền",balance_sheet!$A:$A,0),MATCH(D$23,balance_sheet!$B$1:$I$1,0)),"") | E26: =IFERROR(INDEX(balance_sheet!$B:$I,MATCH("Tiền và tương đương tiền",balance_sheet!$A:$A,0),MATCH(E$23,balance_sheet!$B$1:$I$1,0)),"") | F26: =IFERROR(INDEX(balance_sheet!$B:$I,MATCH("Tiền và tương đương tiền",balance_sheet!$A:$A,0),MATCH(F$23,balance_sheet!$B$1:$I$1,0)),"") | G26: =IFERROR(INDEX(balance_sheet!$B:$I,MATCH("Tiền và tương đương tiền",balance_sheet!$A:$A,0),MATCH(G$23,balance_sheet!$B$1:$I$1,0)),"") | H26: =IFERROR(INDEX(balance_sheet!$B:$I,MATCH("Tiền và tương đương tiền",balance_sheet!$A:$A,0),MATCH(H$23,balance_sheet!$B$1:$I$1,0)),"") | I26: =IFERROR(INDEX(balance_sheet!$B:$I,MATCH("Tiền và tương đương tiền",balance_sheet!$A:$A,0),MATCH(I$23,balance_sheet!$B$1:$I$1,0)),"")
A27: Phải thu khách hàng | B27: =IFERROR(INDEX(balance_sheet!$B:$I,MATCH("Phải thu khách hàng",balance_sheet!$A:$A,0),MATCH(B$23,balance_sheet!$B$1:$I$1,0)),"") | C27: =IFERROR(INDEX(balance_sheet!$B:$I,MATCH("Phải thu khách hàng",balance_sheet!$A:$A,0),MATCH(C$23,balance_sheet!$B$1:$I$1,0)),"") | D27: =IFERROR(INDEX(balance_sheet!$B:$I,MATCH("Phải thu khách hàng",balance_sheet!$A:$A,0),MATCH(D$23,balance_sheet!$B$1:$I$1,0)),"") | E27: =IFERROR(INDEX(balance_sheet!$B:$I,MATCH("Phải thu khách hàng",balance_sheet!$A:$A,0),MATCH(E$23,balance_sheet!$B$1:$I$1,0)),"") | F27: =IFERROR(INDEX(balance_sheet!$B:$I,MATCH("Phải thu khách hàng",balance_sheet!$A:$A,0),MATCH(F$23,balance_sheet!$B$1:$I$1,0)),"") | G27: =IFERROR(INDEX(balance_sheet!$B:$I,MATCH("Phải thu khách hàng",balance_sheet!$A:$A,0),MATCH(G$23,balance_sheet!$B$1:$I$1,0)),"") | H27: =IFERROR(INDEX(balance_sheet!$B:$I,MATCH("Phải thu khách hàng",balance_sheet!$A:$A,0),MATCH(H$23,balance_sheet!$B$1:$I$1,0)),"") | I27: =IFERROR(INDEX(balance_sheet!$B:$I,MATCH("Phải thu khách hàng",balance_sheet!$A:$A,0),MATCH(I$23,balance_sheet!$B$1:$I$1,0)),"")
A28: Hàng tồn kho, ròng | B28: =IFERROR(INDEX(balance_sheet!$B:$I,MATCH("Hàng tồn kho, ròng",balance_sheet!$A:$A,0),MATCH(B$23,balance_sheet!$B$1:$I$1,0)),"") | C28: =IFERROR(INDEX(balance_sheet!$B:$I,MATCH("Hàng tồn kho, ròng",balance_sheet!$A:$A,0),MATCH(C$23,balance_sheet!$B$1:$I$1,0)),"") | D28: =IFERROR(INDEX(balance_sheet!$B:$I,MATCH("Hàng tồn kho, ròng",balance_sheet!$A:$A,0),MATCH(D$23,balance_sheet!$B$1:$I$1,0)),"") | E28: =IFERROR(INDEX(balance_sheet!$B:$I,MATCH("Hàng tồn kho, ròng",balance_sheet!$A:$A,0),MATCH(E$23,balance_sheet!$B$1:$I$1,0)),"") | F28: =IFERROR(INDEX(balance_sheet!$B:$I,MATCH("Hàng tồn kho, ròng",balance_sheet!$A:$A,0),MATCH(F$23,balance_sheet!$B$1:$I$1,0)),"") | G28: =IFERROR(INDEX(balance_sheet!$B:$I,MATCH("Hàng tồn kho, ròng",balance_sheet!$A:$A,0),MATCH(G$23,balance_sheet!$B$1:$I$1,0)),"") | H28: =IFERROR(INDEX(balance_sheet!$B:$I,MATCH("Hàng tồn kho, ròng",balance_sheet!$A:$A,0),MATCH(H$23,balance_sheet!$B$1:$I$1,0)),"") | I28: =IFERROR(INDEX(balance_sheet!$B:$I,MATCH("Hàng tồn kho, ròng",balance_sheet!$A:$A,0),MATCH(I$23,balance_sheet!$B$1:$I$1,0)),"")
A29: TÀI SẢN NGẮN HẠN | B29: =IFERROR(INDEX(balance_sheet!$B:$I,MATCH("TÀI SẢN NGẮN HẠN",balance_sheet!$A:$A,0),MATCH(B$23,balance_sheet!$B$1:$I$1,0)),"") | C29: =IFERROR(INDEX(balance_sheet!$B:$I,MATCH("TÀI SẢN NGẮN HẠN",balance_sheet!$A:$A,0),MATCH(C$23,balance_sheet!$B$1:$I$1,0)),"") | D29: =IFERROR(INDEX(balance_sheet!$B:$I,MATCH("TÀI SẢN NGẮN HẠN",balance_sheet!$A:$A,0),MATCH(D$23,balance_sheet!$B$1:$I$1,0)),"") | E29: =IFERROR(INDEX(balance_sheet!$B:$I,MATCH("TÀI SẢN NGẮN HẠN",balance_sheet!$A:$A,0),MATCH(E$23,balance_sheet!$B$1:$I$1,0)),"") | F29: =IFERROR(INDEX(balance_sheet!$B:$I,MATCH("TÀI SẢN NGẮN HẠN",balance_sheet!$A:$A,0),MATCH(F$23,balance_sheet!$B$1:$I$1,0)),"") | G29: =IFERROR(INDEX(balance_sheet!$B:$I,MATCH("TÀI SẢN NGẮN HẠN",balance_sheet!$A:$A,0),MATCH(G$23,balance_sheet!$B$1:$I$1,0)),"") | H29: =IFERROR(INDEX(balance_sheet!$B:$I,MATCH("TÀI SẢN NGẮN HẠN",balance_sheet!$A:$A,0),MATCH(H$23,balance_sheet!$B$1:$I$1,0)),"") | I29: =IFERROR(INDEX(balance_sheet!$B:$I,MATCH("TÀI SẢN NGẮN HẠN",balance_sheet!$A:$A,0),MATCH(I$23,balance_sheet!$B$1:$I$1,0)),"")
A30: GTCL tài sản cố định vô hình | B30: =IFERROR(INDEX(balance_sheet!$B:$I,MATCH("GTCL tài sản cố định vô hình",balance_sheet!$A:$A,0),MATCH(B$23,balance_sheet!$B$1:$I$1,0)),"") | C30: =IFERROR(INDEX(balance_sheet!$B:$I,MATCH("GTCL tài sản cố định vô hình",balance_sheet!$A:$A,0),MATCH(C$23,balance_sheet!$B$1:$I$1,0)),"") | D30: =IFERROR(INDEX(balance_sheet!$B:$I,MATCH("GTCL tài sản cố định vô hình",balance_sheet!$A:$A,0),MATCH(D$23,balance_sheet!$B$1:$I$1,0)),"") | E30: =IFERROR(INDEX(balance_sheet!$B:$I,MATCH("GTCL tài sản cố định vô hình",balance_sheet!$A:$A,0),MATCH(E$23,balance_sheet!$B$1:$I$1,0)),"") | F30: =IFERROR(INDEX(balance_sheet!$B:$I,MATCH("GTCL tài sản cố định vô hình",balance_sheet!$A:$A,0),MATCH(F$23,balance_sheet!$B$1:$I$1,0)),"") | G30: =IFERROR(INDEX(balance_sheet!$B:$I,MATCH("GTCL tài sản cố định vô hình",balance_sheet!$A:$A,0),MATCH(G$23,balance_sheet!$B$1:$I$1,0)),"") | H30: =IFERROR(INDEX(balance_sheet!$B:$I,MATCH("GTCL tài sản cố định vô hình",balance_sheet!$A:$A,0),MATCH(H$23,balance_sheet!$B$1:$I$1,0)),"") | I30: =IFERROR(INDEX(balance_sheet!$B:$I,MATCH("GTCL tài sản cố định vô hình",balance_sheet!$A:$A,0),MATCH(I$23,balance_sheet!$B$1:$I$1,0)),"")
A31: TỔNG CỘNG TÀI SẢN | B31: =IFERROR(INDEX(balance_sheet!$B:$I,MATCH("TỔNG CỘNG TÀI SẢN",balance_sheet!$A:$A,0),MATCH(B$23,balance_sheet!$B$1:$I$1,0)),"") | C31: =IFERROR(INDEX(balance_sheet!$B:$I,MATCH("TỔNG CỘNG TÀI SẢN",balance_sheet!$A:$A,0),MATCH(C$23,balance_sheet!$B$1:$I$1,0)),"") | D31: =IFERROR(INDEX(balance_sheet!$B:$I,MATCH("TỔNG CỘNG TÀI SẢN",balance_sheet!$A:$A,0),MATCH(D$23,balance_sheet!$B$1:$I$1,0)),"") | E31: =IFERROR(INDEX(balance_sheet!$B:$I,MATCH("TỔNG CỘNG TÀI SẢN",balance_sheet!$A:$A,0),MATCH(E$23,balance_sheet!$B$1:$I$1,0)),"") | F31: =IFERROR(INDEX(balance_sheet!$B:$I,MATCH("TỔNG CỘNG TÀI SẢN",balance_sheet!$A:$A,0),MATCH(F$23,balance_sheet!$B$1:$I$1,0)),"") | G31: =IFERROR(INDEX(balance_sheet!$B:$I,MATCH("TỔNG CỘNG TÀI SẢN",balance_sheet!$A:$A,0),MATCH(G$23,balance_sheet!$B$1:$I$1,0)),"") | H31: =IFERROR(INDEX(balance_sheet!$B:$I,MATCH("TỔNG CỘNG TÀI SẢN",balance_sheet!$A:$A,0),MATCH(H$23,balance_sheet!$B$1:$I$1,0)),"") | I31: =IFERROR(INDEX(balance_sheet!$B:$I,MATCH("TỔNG CỘNG TÀI SẢN",balance_sheet!$A:$A,0),MATCH(I$23,balance_sheet!$B$1:$I$1,0)),"")
A32: Nguồn vốn
A33: Phải trả người bán | B33: =IFERROR(INDEX(balance_sheet!$B:$I,MATCH("Phải trả người bán",balance_sheet!$A:$A,0),MATCH(B$23,balance_sheet!$B$1:$I$1,0)),"") | C33: =IFERROR(INDEX(balance_sheet!$B:$I,MATCH("Phải trả người bán",balance_sheet!$A:$A,0),MATCH(C$23,balance_sheet!$B$1:$I$1,0)),"") | D33: =IFERROR(INDEX(balance_sheet!$B:$I,MATCH("Phải trả người bán",balance_sheet!$A:$A,0),MATCH(D$23,balance_sheet!$B$1:$I$1,0)),"") | E33: =IFERROR(INDEX(balance_sheet!$B:$I,MATCH("Phải trả người bán",balance_sheet!$A:$A,0),MATCH(E$23,balance_sheet!$B$1:$I$1,0)),"") | F33: =IFERROR(INDEX(balance_sheet!$B:$I,MATCH("Phải trả người bán",balance_sheet!$A:$A,0),MATCH(F$23,balance_sheet!$B$1:$I$1,0)),"") | G33: =IFERROR(INDEX(balance_sheet!$B:$I,MATCH("Phải trả người bán",balance_sheet!$A:$A,0),MATCH(G$23,balance_sheet!$B$1:$I$1,0)),"") | H33: =IFERROR(INDEX(balance_sheet!$B:$I,MATCH("Phải trả người bán",balance_sheet!$A:$A,0),MATCH(H$23,balance_sheet!$B$1:$I$1,0)),"") | I33: =IFERROR(INDEX(balance_sheet!$B:$I,MATCH("Phải trả người bán",balance_sheet!$A:$A,0),MATCH(I$23,balance_sheet!$B$1:$I$1,0)),"")
A34: Vay ngắn hạn | B34: =IFERROR(INDEX(balance_sheet!$B:$I,MATCH("Vay ngắn hạn",balance_sheet!$A:$A,0),MATCH(B$23,balance_sheet!$B$1:$I$1,0)),"") | C34: =IFERROR(INDEX(balance_sheet!$B:$I,MATCH("Vay ngắn hạn",balance_sheet!$A:$A,0),MATCH(C$23,balance_sheet!$B$1:$I$1,0)),"") | D34: =IFERROR(INDEX(balance_sheet!$B:$I,MATCH("Vay ngắn hạn",balance_sheet!$A:$A,0),MATCH(D$23,balance_sheet!$B$1:$I$1,0)),"") | E34: =IFERROR(INDEX(balance_sheet!$B:$I,MATCH("Vay ngắn hạn",balance_sheet!$A:$A,0),MATCH(E$23,balance_sheet!$B$1:$I$1,0)),"") | F34: =IFERROR(INDEX(balance_sheet!$B:$I,MATCH("Vay ngắn hạn",balance_sheet!$A:$A,0),MATCH(F$23,balance_sheet!$B$1:$I$1,0)),"") | G34: =IFERROR(INDEX(balance_sheet!$B:$I,MATCH("Vay ngắn hạn",balance_sheet!$A:$A,0),MATCH(G$23,balance_sheet!$B$1:$I$1,0)),"") | H34: =IFERROR(INDEX(balance_sheet!$B:$I,MATCH("Vay ngắn hạn",balance_sheet!$A:$A,0),MATCH(H$23,balance_sheet!$B$1:$I$1,0)),"") | I34: =IFERROR(INDEX(balance_sheet!$B:$I,MATCH("Vay ngắn hạn",balance_sheet!$A:$A,0),MATCH(I$23,balance_sheet!$B$1:$I$1,0)),"")
A35: Nợ ngắn hạn | B35: =IFERROR(INDEX(balance_sheet!$B:$I,MATCH("Nợ ngắn hạn",balance_sheet!$A:$A,0),MATCH(B$23,balance_sheet!$B$1:$I$1,0)),"") | C35: =IFERROR(INDEX(balance_sheet!$B:$I,MATCH("Nợ ngắn hạn",balance_sheet!$A:$A,0),MATCH(C$23,balance_sheet!$B$1:$I$1,0)),"") | D35: =IFERROR(INDEX(balance_sheet!$B:$I,MATCH("Nợ ngắn hạn",balance_sheet!$A:$A,0),MATCH(D$23,balance_sheet!$B$1:$I$1,0)),"") | E35: =IFERROR(INDEX(balance_sheet!$B:$I,MATCH("Nợ ngắn hạn",balance_sheet!$A:$A,0),MATCH(E$23,balance_sheet!$B$1:$I$1,0)),"") | F35: =IFERROR(INDEX(balance_sheet!$B:$I,MATCH("Nợ ngắn hạn",balance_sheet!$A:$A,0),MATCH(F$23,balance_sheet!$B$1:$I$1,0)),"") | G35: =IFERROR(INDEX(balance_sheet!$B:$I,MATCH("Nợ ngắn hạn",balance_sheet!$A:$A,0),MATCH(G$23,balance_sheet!$B$1:$I$1,0)),"") | H35: =IFERROR(INDEX(balance_sheet!$B:$I,MATCH("Nợ ngắn hạn",balance_sheet!$A:$A,0),MATCH(H$23,balance_sheet!$B$1:$I$1,0)),"") | I35: =IFERROR(INDEX(balance_sheet!$B:$I,MATCH("Nợ ngắn hạn",balance_sheet!$A:$A,0),MATCH(I$23,balance_sheet!$B$1:$I$1,0)),"")
A36: Vay dài hạn | B36: =IFERROR(INDEX(balance_sheet!$B:$I,MATCH("Vay dài hạn",balance_sheet!$A:$A,0),MATCH(B$23,balance_sheet!$B$1:$I$1,0)),"") | C36: =IFERROR(INDEX(balance_sheet!$B:$I,MATCH("Vay dài hạn",balance_sheet!$A:$A,0),MATCH(C$23,balance_sheet!$B$1:$I$1,0)),"") | D36: =IFERROR(INDEX(balance_sheet!$B:$I,MATCH("Vay dài hạn",balance_sheet!$A:$A,0),MATCH(D$23,balance_sheet!$B$1:$I$1,0)),"") | E36: =IFERROR(INDEX(balance_sheet!$B:$I,MATCH("Vay dài hạn",balance_sheet!$A:$A,0),MATCH(E$23,balance_sheet!$B$1:$I$1,0)),"") | F36: =IFERROR(INDEX(balance_sheet!$B:$I,MATCH("Vay dài hạn",balance_sheet!$A:$A,0),MATCH(F$23,balance_sheet!$B$1:$I$1,0)),"") | G36: =IFERROR(INDEX(balance_sheet!$B:$I,MATCH("Vay dài hạn",balance_sheet!$A:$A,0),MATCH(G$23,balance_sheet!$B$1:$I$1,0)),"") | H36: =IFERROR(INDEX(balance_sheet!$B:$I,MATCH("Vay dài hạn",balance_sheet!$A:$A,0),MATCH(H$23,balance_sheet!$B$1:$I$1,0)),"") | I36: =IFERROR(INDEX(balance_sheet!$B:$I,MATCH("Vay dài hạn",balance_sheet!$A:$A,0),MATCH(I$23,balance_sheet!$B$1:$I$1,0)),"")
A37: Nợ dài hạn | B37: =IFERROR(INDEX(balance_sheet!$B:$I,MATCH("Nợ dài hạn",balance_sheet!$A:$A,0),MATCH(B$23,balance_sheet!$B$1:$I$1,0)),"") | C37: =IFERROR(INDEX(balance_sheet!$B:$I,MATCH("Nợ dài hạn",balance_sheet!$A:$A,0),MATCH(C$23,balance_sheet!$B$1:$I$1,0)),"") | D37: =IFERROR(INDEX(balance_sheet!$B:$I,MATCH("Nợ dài hạn",balance_sheet!$A:$A,0),MATCH(D$23,balance_sheet!$B$1:$I$1,0)),"") | E37: =IFERROR(INDEX(balance_sheet!$B:$I,MATCH("Nợ dài hạn",balance_sheet!$A:$A,0),MATCH(E$23,balance_sheet!$B$1:$I$1,0)),"") | F37: =IFERROR(INDEX(balance_sheet!$B:$I,MATCH("Nợ dài hạn",balance_sheet!$A:$A,0),MATCH(F$23,balance_sheet!$B$1:$I$1,0)),"") | G37: =IFERROR(INDEX(balance_sheet!$B:$I,MATCH("Nợ dài hạn",balance_sheet!$A:$A,0),MATCH(G$23,balance_sheet!$B$1:$I$1,0)),"") | H37: =IFERROR(INDEX(balance_sheet!$B:$I,MATCH("Nợ dài hạn",balance_sheet!$A:$A,0),MATCH(H$23,balance_sheet!$B$1:$I$1,0)),"") | I37: =IFERROR(INDEX(balance_sheet!$B:$I,MATCH("Nợ dài hạn",balance_sheet!$A:$A,0),MATCH(I$23,balance_sheet!$B$1:$I$1,0)),"")
A38: NỢ PHẢI TRẢ | B38: =IFERROR(INDEX(balance_sheet!$B:$I,MATCH("NỢ PHẢI TRẢ",balance_sheet!$A:$A,0),MATCH(B$23,balance_sheet!$B$1:$I$1,0)),"") | C38: =IFERROR(INDEX(balance_sheet!$B:$I,MATCH("NỢ PHẢI TRẢ",balance_sheet!$A:$A,0),MATCH(C$23,balance_sheet!$B$1:$I$1,0)),"") | D38: =IFERROR(INDEX(balance_sheet!$B:$I,MATCH("NỢ PHẢI TRẢ",balance_sheet!$A:$A,0),MATCH(D$23,balance_sheet!$B$1:$I$1,0)),"") | E38: =IFERROR(INDEX(balance_sheet!$B:$I,MATCH("NỢ PHẢI TRẢ",balance_sheet!$A:$A,0),MATCH(E$23,balance_sheet!$B$1:$I$1,0)),"") | F38: =IFERROR(INDEX(balance_sheet!$B:$I,MATCH("NỢ PHẢI TRẢ",balance_sheet!$A:$A,0),MATCH(F$23,balance_sheet!$B$1:$I$1,0)),"") | G38: =IFERROR(INDEX(balance_sheet!$B:$I,MATCH("NỢ PHẢI TRẢ",balance_sheet!$A:$A,0),MATCH(G$23,balance_sheet!$B$1:$I$1,0)),"") | H38: =IFERROR(INDEX(balance_sheet!$B:$I,MATCH("NỢ PHẢI TRẢ",balance_sheet!$A:$A,0),MATCH(H$23,balance_sheet!$B$1:$I$1,0)),"") | I38: =IFERROR(INDEX(balance_sheet!$B:$I,MATCH("NỢ PHẢI TRẢ",balance_sheet!$A:$A,0),MATCH(I$23,balance_sheet!$B$1:$I$1,0)),"")
A39: Vốn chủ sở hữu | B39: =IFERROR(INDEX(balance_sheet!$B:$I,MATCH("Vốn chủ sở hữu",balance_sheet!$A:$A,0),MATCH(B$23,balance_sheet!$B$1:$I$1,0)),"") | C39: =IFERROR(INDEX(balance_sheet!$B:$I,MATCH("Vốn chủ sở hữu",balance_sheet!$A:$A,0),MATCH(C$23,balance_sheet!$B$1:$I$1,0)),"") | D39: =IFERROR(INDEX(balance_sheet!$B:$I,MATCH("Vốn chủ sở hữu",balance_sheet!$A:$A,0),MATCH(D$23,balance_sheet!$B$1:$I$1,0)),"") | E39: =IFERROR(INDEX(balance_sheet!$B:$I,MATCH("Vốn chủ sở hữu",balance_sheet!$A:$A,0),MATCH(E$23,balance_sheet!$B$1:$I$1,0)),"") | F39: =IFERROR(INDEX(balance_sheet!$B:$I,MATCH("Vốn chủ sở hữu",balance_sheet!$A:$A,0),MATCH(F$23,balance_sheet!$B$1:$I$1,0)),"") | G39: =IFERROR(INDEX(balance_sheet!$B:$I,MATCH("Vốn chủ sở hữu",balance_sheet!$A:$A,0),MATCH(G$23,balance_sheet!$B$1:$I$1,0)),"") | H39: =IFERROR(INDEX(balance_sheet!$B:$I,MATCH("Vốn chủ sở hữu",balance_sheet!$A:$A,0),MATCH(H$23,balance_sheet!$B$1:$I$1,0)),"") | I39: =IFERROR(INDEX(balance_sheet!$B:$I,MATCH("Vốn chủ sở hữu",balance_sheet!$A:$A,0),MATCH(I$23,balance_sheet!$B$1:$I$1,0)),"")
A40: Lợi ích cổ đông không kiểm soát | B40: =IFERROR(INDEX(balance_sheet!$B:$I,MATCH("Lợi ích cổ đông không kiểm soát",balance_sheet!$A:$A,0),MATCH(B$23,balance_sheet!$B$1:$I$1,0)),"") | C40: =IFERROR(INDEX(balance_sheet!$B:$I,MATCH("Lợi ích cổ đông không kiểm soát",balance_sheet!$A:$A,0),MATCH(C$23,balance_sheet!$B$1:$I$1,0)),"") | D40: =IFERROR(INDEX(balance_sheet!$B:$I,MATCH("Lợi ích cổ đông không kiểm soát",balance_sheet!$A:$A,0),MATCH(D$23,balance_sheet!$B$1:$I$1,0)),"") | E40: =IFERROR(INDEX(balance_sheet!$B:$I,MATCH("Lợi ích cổ đông không kiểm soát",balance_sheet!$A:$A,0),MATCH(E$23,balance_sheet!$B$1:$I$1,0)),"") | F40: =IFERROR(INDEX(balance_sheet!$B:$I,MATCH("Lợi ích cổ đông không kiểm soát",balance_sheet!$A:$A,0),MATCH(F$23,balance_sheet!$B$1:$I$1,0)),"") | G40: =IFERROR(INDEX(balance_sheet!$B:$I,MATCH("Lợi ích cổ đông không kiểm soát",balance_sheet!$A:$A,0),MATCH(G$23,balance_sheet!$B$1:$I$1,0)),"") | H40: =IFERROR(INDEX(balance_sheet!$B:$I,MATCH("Lợi ích cổ đông không kiểm soát",balance_sheet!$A:$A,0),MATCH(H$23,balance_sheet!$B$1:$I$1,0)),"") | I40: =IFERROR(INDEX(balance_sheet!$B:$I,MATCH("Lợi ích cổ đông không kiểm soát",balance_sheet!$A:$A,0),MATCH(I$23,balance_sheet!$B$1:$I$1,0)),"")
A41: Kết quả hoạt động kinh doanh
...

Sheet Dự báo tăng trưởng
B1: Q1/2026 | C1: Q2/2026 | D1: Q3/2026 | E1: Q4/2026
A2: Số CP | B2: 1714326422 | C2: 1714326422 | D2: 1714326422 | E2: 1714326422
A3: Thị giá | B3: 66400 | C3: 66400 | D3: 66400 | E3: 66400
A4: Vốn hoá | B4: =B2*B3 | C4: =C2*C3 | D4: =D2*D3 | E4: =E2*E3
A6: VCSH | B6: 40122000000000 | C6: 40996000000000 | D6: =$C$6*(($E$6/$C$6)^(1/2)) | E6: 46100000000000
A7: LICĐKKS | B7: 1170000000000 | C7: 1144000000000 | D7: =D6*0.03 | E7: =E6*0.03
A8: BV | B8: =B6-B7 | C8: =C6-C7 | D8: =D6-D7 | E8: =E6-E7
A9: BVPS | B9: =B8/B2 | C9: =C8/C2 | D9: =D8/D2 | E9: =E8/E2
A10: PB | B10: =B4/B8 | C10: =C4/C8 | D10: =D4/D8 | E10: =E4/E8
A12: Trailing Earning | C12: =(2568+2487+2503+2435)*1000000000 | D12: =$C$12*(($E$12/$C$12)^(1/2)) | E12: =chi_so_tai_chinh!J51
A13: EPS | B13: 5687 | C13: =C12/C2 | D13: =$C$13*(($E$13/$C$13)^(1/2)) | E13: =E12/E2
A14: PE | B14: =$E$3/B13 | C14: =$E$3/C13 | D14: =$E$3/D13 | E14: =$E$3/E13

Sheet Hiệu quả thực hiện kế hoạch
B1: 2020 | C1: 2021 | D1: 2022 | E1: 2023 | F1: 2024 | G1: 2025 | H1: 2026
A2: Doanh thu kế hoạch | B2: 32450 | C2: 34720 | D2: 42420 | E2: 52289 | F2: 61850 | G2: 75400 | H2: 58580
A3: Doanh thu thuần | B3: =chi_so_tai_chinh!D42/1000000000 | C3: =chi_so_tai_chinh!E42/1000000000 | D3: =chi_so_tai_chinh!F42/1000000000 | E3: =chi_so_tai_chinh!G42/1000000000 | F3: =chi_so_tai_chinh!H42/1000000000 | G3: =chi_so_tai_chinh!I42/1000000000 | H3: =12486+13810
A4: % thực hiện | B4: =B3/B2 | C4: =C3/C2 | D4: =D3/D2 | E4: =E3/E2 | F4: =F3/F2 | G4: =G3/G2 | H4: =H3/H2
A5: Lợi nhuận trước thuế kế hoạch | B5: 5510 | C5: 6210 | D5: 7618 | E5: 9055 | F5: 10875 | G5: 13395 | H5: 11629
A6: Tổng lợi nhuận kế toán trước thuế | B6: =chi_so_tai_chinh!D49/1000000000 | C6: =chi_so_tai_chinh!E49/1000000000 | D6: =chi_so_tai_chinh!F49/1000000000 | E6: =chi_so_tai_chinh!G49/1000000000 | F6: =chi_so_tai_chinh!H49/1000000000 | G6: =chi_so_tai_chinh!I49/1000000000 | H6: =2804+2910
A7: % thực hiện | B7: =B6/B5 | C7: =C6/C5 | D7: =D6/D5 | E7: =E6/E5 | F7: =F6/F5 | G7: =G6/G5 | H7: =H6/H5
A9: Trung vị thực hiện DT | B9: =MEDIAN(B4:F4)
A10: Trung vị thực hiện LNKTTT | B10: =MEDIAN(B7:F7)
A12: Tỷ lệ hoàn thành DT trên 95% | B12: =COUNTIF(B4:G4,">=95%")/COUNT(B4:G4)
A13: Tỷ lệ hoàn thành LNTT trên 95% | B13: =COUNTIF(B7:G7,">=95%")/COUNT(B7:G7)
