Workbook

Sheet balance_sheet
A1: item | B1: 2018 | C1: 2019 | D1: 2020 | E1: 2021 | F1: 2022 | G1: 2023 | H1: 2024 | I1: 2025
A2: TÀI SẢN NGẮN HẠN | B2: 23371994756394 | C2: 35011896908246 | D2: 37317233970267 | E2: 51955257770657 | F2: 44577607228189 | G2: 51950337976047 | H2: 65836422620040 | I2: 77201650782966
A3: Tiền và tương đương tiền | B3: 3749550258212 | C3: 3115236816468 | D3: 7347857397925 | E3: 4142015762555 | F3: 5061020547422 | G3: 5365704857172 | H3: 4897331540730 | I3: 4999925717187
A4: Tiền | B4: 3363717276954 | C4: 2024347938868 | D4: 2243274466174 | E4: 2606672264502 | F4: 3846020547422 | G4: 4795636583222 | H4: 4697331540730 | I4: 4960375717187
A5: Các khoản tương đương tiền | B5: 385832981258 | C5: 1090888877600 | D5: 5104582931751 | E5: 1535343498053 | F5: 1215000000000 | G5: 570068273950 | H5: 200000000000 | I5: 39550000000
A6: Đầu tư ngắn hạn | B6: 0 | C6: 0 | D6: 0 | E6: 0 | F6: 0 | G6: 0 | H6: 0 | I6: 0
A7: Đầu tư ngắn hạn | F7: 0 | G7: 0 | H7: 0 | I7: 0
A8: Dự phòng giảm giá | B8: 0 | C8: 0 | D8: 0 | E8: 0 | F8: 0 | G8: 0 | H8: 0 | I8: 0
A9: Các khoản phải thu | B9: 1542529736073 | C9: 1815085561979 | D9: 1595251018496 | E9: 3162121971586 | F9: 3000817466182 | G9: 5158853337785 | H9: 8825896224771 | I9: 10182835978469
A10: Phải thu khách hàng | B10: 369573657457 | C10: 262268362817 | D10: 196394545434 | E10: 384236578232 | F10: 178061365251 | G10: 308474343927 | H10: 241405396887 | I10: 253358838280
A11: Trả trước người bán | B11: 21007291749 | C11: 195016846986 | D11: 287913331552 | E11: 390738782756 | F11: 403669438496 | G11: 95981093251 | H11: 115888383111 | I11: 141627187798
A12: Phải thu nội bộ | B12: 0 | C12: 0 | D12: 0 | E12: 0 | F12: 0 | G12: 0 | H12: 0 | I12: 0
A13: Phải thu hợp đồng xây dựng đang thực hiện | B13: 0 | C13: 0 | D13: 0 | E13: 0 | F13: 0 | G13: 0 | H13: 0 | I13: 0
A14: Phải thu khác | B14: 1151948786867 | C14: 1357800352176 | D14: 1030943141510 | E14: 1425228912960 | F14: 2402168964797 | G14: 2668480202969 | H14: 2430887848672 | I14: 2877349952391
A15: Dự phòng nợ khó đòi | B15: 0 | C15: 0 | D15: 0 | E15: 0 | F15: 0 | G15: 0 | H15: 0 | I15: 0
A16: Hàng tồn kho, ròng | B16: 17446005298981 | C16: 25745428436580 | D16: 19422177452674 | E16: 29167232293922 | F16: 25696077735282 | G16: 21824235626176 | H16: 22244676326705 | I16: 27266851974258
A17: Hàng tồn kho | B17: 17821137643753 | C17: 26195934673884 | D17: 19926363502365 | E17: 29850068817719 | F17: 26058131396686 | G17: 22028684523096 | H17: 22667774012643 | I17: 27876446129267
A18: Dự phòng giảm giá hàng tồn kho | B18: -375132344772 | C18: -450506237304 | D18: -504186049691 | E18: -682836523797 | F18: -362053661404 | G18: -204448896920 | H18: -423097685938 | I18: -609594155009
A19: Tài sản lưu động khác | B19: 0 | C19: 0 | D19: 0 | E19: 0 | F19: 0 | G19: 0 | H19: 0 | I19: 0
... A22: Phải thu thuế khác | B22: 1842948927 | C22: 2890365291 | D22: 4751687467 | E22: 41984411029 | F22: 28637906590 | G22: 23473930964 | H22: 32630294575 | I22: 44293494912
A23: Tài sản lưu động khác | F23: 0 | G23: 0 | H23: 0 | I23: 0
A24: TÀI SẢN DÀI HẠN | B24: 4750536730462 | C24: 6696198636637 | D24: 8713645982187 | E24: 11016147044285 | F24: 11256488385860 | G24: 8160899236677 | H24: 4601353101564 | I24: 6743968829068
A25: Phải thu dài hạn | B25: 313775645332 | C25: 374563598474 | D25: 439493257757 | E25: 482389179464 | F25: 503486573563 | G25: 457569986630 | H25: 389707802472 | I25: 403823784845
A26: Phải thu khách hàng dài hạn | B26: 0 | C26: 0 | D26: 0 | E26: 0 | F26: 0 | G26: 0 | H26: 0 | I26: 0
A27: Phải thu nội bộ dài hạn | B27: 0 | C27: 0 | D27: 0 | E27: 0 | F27: 0 | G27: 0 | H27: 0 | I27: 0
A28: Phải thu dài hạn khác | B28: 313775645332 | C28: 374563598474 | D28: 439493257757 | E28: 482389179464 | F28: 493741850234 | G28: 448325013301 | H28: 389707802472 | I28: 403823784845
A29: Dự phòng phải thu dài hạn | B29: 0 | C29: 0 | D29: 0 | E29: 0 | F29: 0 | G29: 0 | H29: 0 | I29: 0
A30: Tài sản cố định | B30: 3333147659602 | C30: 5403776988921 | D30: 7294961666136 | E30: 9647168873232 | F30: 9727502911440 | G30: 6500135608914 | H30: 3586628664045 | I30: 2598189217583
A31: GTCL TSCĐ hữu hình | B31: 3304923529470 | C31: 5375279172974 | D31: 7267319287908 | E31: 9566954933220 | F31: 9653330005976 | G31: 6431315373113 | H31: 3523161097906 | I31: 2540074321107
A32: Nguyên giá TSCĐ hữu hình | B32: 5788326331676 | C32: 9148455989525 | D32: 12963311412901 | E32: 17987087849355 | F32: 20841513609195 | G32: 20139282722977 | H32: 19174626383752 | I32: 19478200234864
A33: Khấu hao lũy kế TSCĐ hữu hình | B33: -2483402802206 | C33: -3773176816551 | D33: -5695992124993 | E33: -8420132916135 | F33: -11188183603219 | G33: -13707967349864 | H33: -15651465285846 | I33: -16938125913757
A34: GTCL tài sản thuê tài chính | B34: 0 | C34: 0 | D34: 0 | E34: 0 | F34: 0 | G34: 0 | H34: 0 | I34: 0
A35: Nguyên giá tài sản thuê tài chính | B35: 0 | C35: 0 | D35: 0 | E35: 0 | F35: 0 | G35: 0 | H35: 0 | I35: 0
... A72: Vay dài hạn | B72: 1208167140389 | C72: 1122136666657 | D72: 1126676666653 | E72: 0 | F72: 5901250000000 | G72: 5985250000000 | H72: 0 | I72: 0
A73: Thuế thu nhập hoãn lại | F73: 0 | G73: 1168691414 | H73: 0 | I73: 0
A74: Dự phòng trợ cấp thôi việc | B74: 0 | C74: 0 | D74: 0 | E74: 0 | F74: 0 | G74: 0 | H74: 0 | I74: 0
A75: Dự phòng các khoản nợ dài hạn | B75: 0 | C75: 0 | D75: 0 | E75: 0 | F75: 0 | G75: 0 | H75: 0 | I75: 0
A76: Doanh thu chưa thực hiện | B76: 0 | C76: 0 | D76: 0 | E76: 0 | F76: 0 | G76: 0 | H76: 0 | I76: 0
A77: Quỹ phát triển khoa học công nghệ | B77: 0 | C77: 0 | D77: 0 | E77: 0 | F77: 0 | G77: 0 | H77: 0 | I77: 0
A78: Vốn chủ sở hữu | B78: 8983035331342 | C78: 12143592194353 | D78: 15481689846432 | E78: 20378245999846 | F78: 23932581517576 | G78: 23359557967338 | H78: 28121576823855 | I78: 33176117374577
...

Sheet income_statement
A1: item | B1: 2018 | C1: 2019 | D1: 2020 | E1: 2021 | F1: 2022 | G1: 2023 | H1: 2024 | I1: 2025
A2: Doanh thu bán hàng và cung cấp dịch vụ | B2: 87738378978636 | C2: 103485046672447 | D2: 109801253690656 | E2: 124141525689948 | F2: 134722248887557 | G2: 119234184825086 | H2: 135225101298992 | I2: 156836115054975
A3: Các khoản giảm trừ doanh thu | B3: -1222091976137 | C3: -1310802695724 | D3: -1255234025244 | E3: -1183419586774 | F3: -1317471297033 | G3: -954396369644 | H3: -883948450190 | I3: -907969435608
A4: Doanh thu thuần | B4: 86516287002499 | C4: 102174243976723 | D4: 108546019665412 | E4: 122958106103174 | F4: 133404777590524 | G4: 118279788455442 | H4: 134341152848802 | I4: 155928145619367
A5: Giá vốn hàng bán | B5: -71224159239435 | C5: -82686444673012 | D5: -84591522392949 | E5: -95325974107640 | F5: -102542735094343 | G5: -95759175291712 | H5: -106841942771781 | I5: -124926268219546
A6: Lợi nhuận gộp | B6: 15292127763064 | C6: 19487799303711 | D6: 23954497272463 | E6: 27632131995534 | F6: 30862042496181 | G6: 22520613163730 | H6: 27499210077021 | I6: 31001877399821
A7: Doanh thu hoạt động tài chính | B7: 342083875229 | C7: 631177854351 | D7: 794121782667 | E7: 1287956026163 | F7: 1313137304323 | G7: 2166963715091 | H7: 2376502605263 | I7: 3107348733939
A8: Chi phí tài chính | B8: -436573150236 | C8: -569754844844 | D8: -594151513751 | E8: -714707225745 | F8: -1382620454532 | G8: -1556146106982 | H8: -1188465609510 | I8: -1542518673463
A9: Chi phí lãi vay | B9: -436416577674 | C9: -568136717134 | D9: -594003821021 | E9: -674427746189 | F9: -1362143909103 | G9: -1447718354797 | H9: -1137236129748 | I9: -1470675593604
A10: Chi phí bán hàng | B10: -9659741188756 | C10: -12437282718212 | D10: -15333798830787 | E10: -17914173302345 | F10: -22336838067678 | G10: -20916710755306 | H10: -19849837609882 | I10: -19330903536858
A11: Chi phí quản lý doanh nghiệp | B11: -1761613900080 | C11: -2073782880058 | D11: -3404431838167 | E11: -3823390074765 | F11: -1881027579714 | G11: -1167651662536 | H11: -3565767583102 | I11: -4596074513172
A12: Lãi/(lỗ) từ hoạt động kinh doanh | B12: 3774182412336 | C12: 5034683431577 | D12: 5412529932954 | E12: 6465606918356 | F12: 6574693698580 | G12: 1047068353997 | H12: 5227045424891 | I12: 8664080489454
A13: Thu nhập khác | B13: 33233337382 | C13: 41557041541 | D13: 43512695471 | E13: 54872797433 | F13: 61606712681 | G13: 36883419051 | H13: 25743895664 | I13: 52777770887
... A26: Lãi/(lỗ) từ công ty liên doanh (từ năm 2015) | B26: -2100986885 | C26: -3473283371 | D26: -3706939471 | E26: -2210500486 | F26: 0 | G26: 0 | H26: -44596454899 | I26: 24351079187

Sheet cash_flow
A1: item | B1: 2018 | C1: 2019 | D1: 2020 | E1: 2021 | F1: 2022 | G1: 2023 | H1: 2024 | I1: 2025
A2: Lợi nhuận/(lỗ) trước thuế | B2: 3786318568918 | C2: 5053447204696 | D2: 5409735407353 | E2: 6471583750543 | F2: 6056355373558 | G2: 689692367896 | H2: 4825763013078 | I2: 8633067583426
A3: Khấu hao TSCĐ và BĐSĐT | B3: 1222868683717 | C3: 1442826938954 | D3: 2195583071035 | E3: 2920713608410 | F3: 3540324726294 | G3: 3351314267883 | H3: 2913419081483 | I3: 1890882108632
A4: Chi phí dự phòng | B4: 126083626828 | C4: 90495782206 | D4: 58366659386 | E4: 179550717177 | F4: -321799366884 | G4: -165930068132 | H4: 220952651591 | I4: 205754863290
A5: Lãi/lỗ chênh lệch tỷ giá hối đoái do đánh giá lại các khoản mục tiền tệ có gốc ngoại tệ | B5: -107059306 | C5: -27160364 | D5: -36874578 | E5: -146653994 | F5: 284374414 | G5: 83631272202 | H5: 25689580954 | I5: 48281410640
A6: Lãi/(lỗ) từ thanh lý tài sản cố định | B6: 0 | C6: 0 | D6: 0 | E6: 0 | F6: 0 | G6: 0 | H6: 0 | I6: 0
A7: (Lãi)/lỗ từ hoạt động đầu tư | B7: -84857279584 | C7: -341194613832 | D7: -557627148536 | E7: -959323580633 | F7: -348599792355 | G7: -1509203341265 | H7: -1729164103487 | I7: -2908766491708
A8: Chi phí lãi vay | B8: 436416577674 | C8: 568136717134 | D8: 594003821021 | E8: 674427746189 | F8: 1362143909103 | G8: 1447718354797 | H8: 1137236129748 | I8: 1470675593604
A9: Thu lãi và cổ tức | B9: 0 | C9: 0 | D9: 0 | E9: 0 | F9: 0 | G9: 0 | H9: 0 | I9: 0
A10: Lợi nhuận/(lỗ) từ hoạt động kinh doanh trước những thay đổi vốn lưu động | B10: 5486723118247 | C10: 6813684868794 | D10: 7700024935681 | E10: 9286805587692 | F10: 10288709224130 | G10: 3897222853381 | H10: 7393896353367 | I10: 9339895067884
A11: (Tăng)/giảm các khoản phải thu | B11: 1246646823981 | C11: -675979882201 | D11: 850493238036 | E11: -827596105467 | F11: -588827639446 | G11: 672440536688 | H11: 151205190961 | I11: -308618709954
A12: (Tăng)/giảm hàng tồn kho | B12: -4672944194460 | C12: -8374797030131 | D12: 6269571171519 | E12: -9923705315353 | F12: 3791937421033 | G12: 4169031757473 | H12: -636927914305 | I12: -5207942331422
A13: Tăng/(giảm) các khoản phải trả | B13: 1331042865781 | C13: 2823942311184 | D13: -1894206905085 | E13: 3781614904801 | F13: -2286756979213 | G13: -3136706601092 | H13: 3581806724649 | I13: 5339106069277
... A42: (Tăng)/giảm chứng khoán kinh doanh | B42: 0 | C42: 0 | D42: 0 | E42: 0 | F42: 0 | G42: 0 | H42: 0 | I42: 0

Sheet chi_so_tai_chinh
A1: Chỉ tiêu | B1: =balance_sheet!B1 | C1: =balance_sheet!C1 | D1: =balance_sheet!D1 | E1: =balance_sheet!E1 | F1: =balance_sheet!F1 | G1: =balance_sheet!G1 | H1: =balance_sheet!H1 | I1: =balance_sheet!I1 | J1: 2026
A2: ROE (LNST CĐ Cty mẹ / VCSH bình quân) | B2: n/a | C2: =IFERROR(C$51/((C$39+B$39)/2),"n/a") | D2: =IFERROR(D$51/((D$39+C$39)/2),"n/a") | E2: =IFERROR(E$51/((E$39+D$39)/2),"n/a") | F2: =IFERROR(F$51/((F$39+E$39)/2),"n/a") | G2: =IFERROR(G$51/((G$39+F$39)/2),"n/a") | H2: =IFERROR(H$51/((H$39+G$39)/2),"n/a") | I2: =IFERROR(I$51/((I$39+H$39)/2),"n/a") | J2: =IFERROR(J$51/((J$39+I$39)/2),"n/a")
A3: ROA (LNST / Tổng tài sản bình quân) | B3: n/a | C3: =IFERROR(C$50/((C$31+B$31)/2),"n/a") | D3: =IFERROR(D$50/((D$31+C$31)/2),"n/a") | E3: =IFERROR(E$50/((E$31+D$31)/2),"n/a") | F3: =IFERROR(F$50/((F$31+E$31)/2),"n/a") | G3: =IFERROR(G$50/((G$31+F$31)/2),"n/a") | H3: =IFERROR(H$50/((H$31+G$31)/2),"n/a") | I3: =IFERROR(I$50/((I$31+H$31)/2),"n/a")
A4: Tăng trưởng LN Cổ đông Cty mẹ | B4: n/a | C4: =IFERROR((C$51-B$51)/ABS(B$51),"n/a") | D4: =IFERROR((D$51-C$51)/ABS(C$51),"n/a") | E4: =IFERROR((E$51-D$51)/ABS(D$51),"n/a") | F4: =IFERROR((F$51-E$51)/ABS(E$51),"n/a") | G4: =IFERROR((G$51-F$51)/ABS(F$51),"n/a") | H4: =IFERROR((H$51-G$51)/ABS(G$51),"n/a") | I4: =IFERROR((I$51-H$51)/ABS(H$51),"n/a") | J4: =IFERROR((J$51-I$51)/ABS(I$51),"n/a")
A5: Tăng trưởng Doanh thu thuần | B5: n/a | C5: =IFERROR((C$43-B$43)/ABS(B$43),"n/a") | D5: =IFERROR((D$43-C$43)/ABS(C$43),"n/a") | E5: =IFERROR((E$43-D$43)/ABS(D$43),"n/a") | F5: =IFERROR((F$43-E$43)/ABS(E$43),"n/a") | G5: =IFERROR((G$43-F$43)/ABS(F$43),"n/a") | H5: =IFERROR((H$43-G$43)/ABS(G$43),"n/a") | I5: =IFERROR((I$43-H$43)/ABS(H$43),"n/a") | J5: =IFERROR((J$43-I$43)/ABS(I$43),"n/a")
A6: Biên lợi nhuận gộp | B6: =IFERROR(B$45/B$43,"n/a") | C6: =IFERROR(C$45/C$43,"n/a") | D6: =IFERROR(D$45/D$43,"n/a") | E6: =IFERROR(E$45/E$43,"n/a") | F6: =IFERROR(F$45/F$43,"n/a") | G6: =IFERROR(G$45/G$43,"n/a") | H6: =IFERROR(H$45/H$43,"n/a") | I6: =IFERROR(I$45/I$43,"n/a")
A7: Biên lợi nhuận ròng | B7: =IFERROR(B$51/B$43,"n/a") | C7: =IFERROR(C$51/C$43,"n/a") | D7: =IFERROR(D$51/D$43,"n/a") | E7: =IFERROR(E$51/E$43,"n/a") | F7: =IFERROR(F$51/F$43,"n/a") | G7: =IFERROR(G$51/G$43,"n/a") | H7: =IFERROR(H$51/H$43,"n/a") | I7: =IFERROR(I$51/I$43,"n/a") | J7: =IFERROR(J$51/J$43,"n/a")
A8: D/E (Nợ vay / Vốn chủ sở hữu) | B8: =IFERROR((B$34+B$36)/B$39,"n/a") | C8: =IFERROR((C$34+C$36)/C$39,"n/a") | D8: =IFERROR((D$34+D$36)/D$39,"n/a") | E8: =IFERROR((E$34+E$36)/E$39,"n/a") | F8: =IFERROR((F$34+F$36)/F$39,"n/a") | G8: =IFERROR((G$34+G$36)/G$39,"n/a") | H8: =IFERROR((H$34+H$36)/H$39,"n/a") | I8: =IFERROR((I$34+I$36)/I$39,"n/a")
A9: - Nợ vay dài hạn/Vốn chủ sở hữu | B9: =IFERROR(B$36/B$39,"n/a") | C9: =IFERROR(C$36/C$39,"n/a") | D9: =IFERROR(D$36/D$39,"n/a") | E9: =IFERROR(E$36/E$39,"n/a") | F9: =IFERROR(F$36/F$39,"n/a") | G9: =IFERROR(G$36/G$39,"n/a") | H9: =IFERROR(H$36/H$39,"n/a") | I9: =IFERROR(I$36/I$39,"n/a")
A10: - Nợ vay ngắn hạn/Vốn chủ sở hữu | B10: =IFERROR(B$34/B$39,"n/a") | C10: =IFERROR(C$34/C$39,"n/a") | D10: =IFERROR(D$34/D$39,"n/a") | E10: =IFERROR(E$34/E$39,"n/a") | F10: =IFERROR(F$34/F$39,"n/a") | G10: =IFERROR(G$34/G$39,"n/a") | H10: =IFERROR(H$34/H$39,"n/a") | I10: =IFERROR(I$34/I$39,"n/a")
A11: Nợ phải trả/Vốn chủ sở hữu | B11: =IFERROR(B$38/B$39,"n/a") | C11: =IFERROR(C$38/C$39,"n/a") | D11: =IFERROR(D$38/D$39,"n/a") | E11: =IFERROR(E$38/E$39,"n/a") | F11: =IFERROR(F$38/F$39,"n/a") | G11: =IFERROR(G$38/G$39,"n/a") | H11: =IFERROR(H$38/H$39,"n/a") | I11: =IFERROR(I$38/I$39,"n/a")
A12: - Nợ dài hạn/Vốn chủ sở hữu | B12: =IFERROR(B$37/B$39,"n/a") | C12: =IFERROR(C$37/C$39,"n/a") | D12: =IFERROR(D$37/D$39,"n/a") | E12: =IFERROR(E$37/E$39,"n/a") | F12: =IFERROR(F$37/F$39,"n/a") | G12: =IFERROR(G$37/G$39,"n/a") | H12: =IFERROR(H$37/H$39,"n/a") | I12: =IFERROR(I$37/I$39,"n/a")
A13: - Nợ ngắn hạn/Vốn chủ sở hữu | B13: =IFERROR(B$35/B$39,"n/a") | C13: =IFERROR(C$35/C$39,"n/a") | D13: =IFERROR(D$35/D$39,"n/a") | E13: =IFERROR(E$35/E$39,"n/a") | F13: =IFERROR(F$35/F$39,"n/a") | G13: =IFERROR(G$35/G$39,"n/a") | H13: =IFERROR(H$35/H$39,"n/a") | I13: =IFERROR(I$35/I$39,"n/a")
A14: Chi phí bán hàng, quản lý/LN gộp | B14: =IFERROR((ABS(B$46)+ABS(B$47))/B$45,"n/a") | C14: =IFERROR((ABS(C$46)+ABS(C$47))/C$45,"n/a") | D14: =IFERROR((ABS(D$46)+ABS(D$47))/D$45,"n/a") | E14: =IFERROR((ABS(E$46)+ABS(E$47))/E$45,"n/a") | F14: =IFERROR((ABS(F$46)+ABS(F$47))/F$45,"n/a") | G14: =IFERROR((ABS(G$46)+ABS(G$47))/G$45,"n/a") | H14: =IFERROR((ABS(H$46)+ABS(H$47))/H$45,"n/a") | I14: =IFERROR((ABS(I$46)+ABS(I$47))/I$45,"n/a")
A15: Chi phí lãi vay/LN từ hoạt động kinh doanh | B15: =IFERROR(ABS(B$49)/B$48,"n/a") | C15: =IFERROR(ABS(C$49)/C$48,"n/a") | D15: =IFERROR(ABS(D$49)/D$48,"n/a") | E15: =IFERROR(ABS(E$49)/E$48,"n/a") | F15: =IFERROR(ABS(F$49)/F$48,"n/a") | G15: =IFERROR(ABS(G$49)/G$48,"n/a") | H15: =IFERROR(ABS(H$49)/H$48,"n/a") | I15: =IFERROR(ABS(I$49)/I$48,"n/a")
A16: Số ngày phải trả (DPO) | B16: n/a | C16: =IFERROR(((C$33+B$33)/2)/ABS(C$44)*365,"n/a") | D16: =IFERROR(((D$33+C$33)/2)/ABS(D$44)*365,"n/a") | E16: =IFERROR(((E$33+D$33)/2)/ABS(E$44)*365,"n/a") | F16: =IFERROR(((F$33+E$33)/2)/ABS(F$44)*365,"n/a") | G16: =IFERROR(((G$33+F$33)/2)/ABS(G$44)*365,"n/a") | H16: =IFERROR(((H$33+G$33)/2)/ABS(H$44)*365,"n/a") | I16: =IFERROR(((I$33+H$33)/2)/ABS(I$44)*365,"n/a")
A17: Số ngày phải thu (DSO) | B17: n/a | C17: =IFERROR(((C$27+B$27)/2)/C$43*365,"n/a") | D17: =IFERROR(((D$27+C$27)/2)/D$43*365,"n/a") | E17: =IFERROR(((E$27+D$27)/2)/E$43*365,"n/a") | F17: =IFERROR(((F$27+E$27)/2)/F$43*365,"n/a") | G17: =IFERROR(((G$27+F$27)/2)/G$43*365,"n/a") | H17: =IFERROR(((H$27+G$27)/2)/H$43*365,"n/a") | I17: =IFERROR(((I$27+H$27)/2)/I$43*365,"n/a")
A18: Số ngày tồn kho (DIO) | B18: n/a | C18: =IFERROR(((C$28+B$28)/2)/ABS(C$44)*365,"n/a") | D18: =IFERROR(((D$28+C$28)/2)/ABS(D$44)*365,"n/a") | E18: =IFERROR(((E$28+D$28)/2)/ABS(E$44)*365,"n/a") | F18: =IFERROR(((F$28+E$28)/2)/ABS(F$44)*365,"n/a") | G18: =IFERROR(((G$28+F$28)/2)/ABS(G$44)*365,"n/a") | H18: =IFERROR(((H$28+G$28)/2)/ABS(H$44)*365,"n/a") | I18: =IFERROR(((I$28+H$28)/2)/ABS(I$44)*365,"n/a")
A19: Tiền và tương đương tiền/Tài sản | B19: =IFERROR(B$26/B$31,"n/a") | C19: =IFERROR(C$26/C$31,"n/a") | D19: =IFERROR(D$26/D$31,"n/a") | E19: =IFERROR(E$26/E$31,"n/a") | F19: =IFERROR(F$26/F$31,"n/a") | G19: =IFERROR(G$26/G$31,"n/a") | H19: =IFERROR(H$26/H$31,"n/a") | I19: =IFERROR(I$26/I$31,"n/a")
A20: Hàng tồn kho/Tài sản | B20: =IFERROR(B$28/B$31,"n/a") | C20: =IFERROR(C$28/C$31,"n/a") | D20: =IFERROR(D$28/D$31,"n/a") | E20: =IFERROR(E$28/E$31,"n/a") | F20: =IFERROR(F$28/F$31,"n/a") | G20: =IFERROR(G$28/G$31,"n/a") | H20: =IFERROR(H$28/H$31,"n/a") | I20: =IFERROR(I$28/I$31,"n/a")
A22: II. DỮ LIỆU TRÍCH XUẤT (tự động dò theo tên khoản mục)
A23: Khoản mục | B23: =balance_sheet!B1 | C23: =balance_sheet!C1 | D23: =balance_sheet!D1 | E23: =balance_sheet!E1 | F23: =balance_sheet!F1 | G23: =balance_sheet!G1 | H23: =balance_sheet!H1 | I23: =balance_sheet!I1
A24: CĐKT
A25: Tài sản
A26: Tiền và tương đương tiền | B26: =IFERROR(INDEX(balance_sheet!$B:$XFD,MATCH("Tiền và tương đương tiền",balance_sheet!$A:$A,0),MATCH(B$23,balance_sheet!$B$1:$XFD$1,0)),"") | C26: =IFERROR(INDEX(balance_sheet!$B:$XFD,MATCH("Tiền và tương đương tiền",balance_sheet!$A:$A,0),MATCH(C$23,balance_sheet!$B$1:$XFD$1,0)),"") | D26: =IFERROR(INDEX(balance_sheet!$B:$XFD,MATCH("Tiền và tương đương tiền",balance_sheet!$A:$A,0),MATCH(D$23,balance_sheet!$B$1:$XFD$1,0)),"") | E26: =IFERROR(INDEX(balance_sheet!$B:$XFD,MATCH("Tiền và tương đương tiền",balance_sheet!$A:$A,0),MATCH(E$23,balance_sheet!$B$1:$XFD$1,0)),"") | F26: =IFERROR(INDEX(balance_sheet!$B:$XFD,MATCH("Tiền và tương đương tiền",balance_sheet!$A:$A,0),MATCH(F$23,balance_sheet!$B$1:$XFD$1,0)),"") | G26: =IFERROR(INDEX(balance_sheet!$B:$XFD,MATCH("Tiền và tương đương tiền",balance_sheet!$A:$A,0),MATCH(G$23,balance_sheet!$B$1:$XFD$1,0)),"") | H26: =IFERROR(INDEX(balance_sheet!$B:$XFD,MATCH("Tiền và tương đương tiền",balance_sheet!$A:$A,0),MATCH(H$23,balance_sheet!$B$1:$XFD$1,0)),"") | I26: =IFERROR(INDEX(balance_sheet!$B:$XFD,MATCH("Tiền và tương đương tiền",balance_sheet!$A:$A,0),MATCH(I$23,balance_sheet!$B$1:$XFD$1,0)),"")
A27: Phải thu khách hàng | B27: =IFERROR(INDEX(balance_sheet!$B:$XFD,MATCH("Phải thu khách hàng",balance_sheet!$A:$A,0),MATCH(B$23,balance_sheet!$B$1:$XFD$1,0)),"") | C27: =IFERROR(INDEX(balance_sheet!$B:$XFD,MATCH("Phải thu khách hàng",balance_sheet!$A:$A,0),MATCH(C$23,balance_sheet!$B$1:$XFD$1,0)),"") | D27: =IFERROR(INDEX(balance_sheet!$B:$XFD,MATCH("Phải thu khách hàng",balance_sheet!$A:$A,0),MATCH(D$23,balance_sheet!$B$1:$XFD$1,0)),"") | E27: =IFERROR(INDEX(balance_sheet!$B:$XFD,MATCH("Phải thu khách hàng",balance_sheet!$A:$A,0),MATCH(E$23,balance_sheet!$B$1:$XFD$1,0)),"") | F27: =IFERROR(INDEX(balance_sheet!$B:$XFD,MATCH("Phải thu khách hàng",balance_sheet!$A:$A,0),MATCH(F$23,balance_sheet!$B$1:$XFD$1,0)),"") | G27: =IFERROR(INDEX(balance_sheet!$B:$XFD,MATCH("Phải thu khách hàng",balance_sheet!$A:$A,0),MATCH(G$23,balance_sheet!$B$1:$XFD$1,0)),"") | H27: =IFERROR(INDEX(balance_sheet!$B:$XFD,MATCH("Phải thu khách hàng",balance_sheet!$A:$A,0),MATCH(H$23,balance_sheet!$B$1:$XFD$1,0)),"") | I27: =IFERROR(INDEX(balance_sheet!$B:$XFD,MATCH("Phải thu khách hàng",balance_sheet!$A:$A,0),MATCH(I$23,balance_sheet!$B$1:$XFD$1,0)),"")
A28: Hàng tồn kho, ròng | B28: =IFERROR(INDEX(balance_sheet!$B:$XFD,MATCH("Hàng tồn kho, ròng",balance_sheet!$A:$A,0),MATCH(B$23,balance_sheet!$B$1:$XFD$1,0)),"") | C28: =IFERROR(INDEX(balance_sheet!$B:$XFD,MATCH("Hàng tồn kho, ròng",balance_sheet!$A:$A,0),MATCH(C$23,balance_sheet!$B$1:$XFD$1,0)),"") | D28: =IFERROR(INDEX(balance_sheet!$B:$XFD,MATCH("Hàng tồn kho, ròng",balance_sheet!$A:$A,0),MATCH(D$23,balance_sheet!$B$1:$XFD$1,0)),"") | E28: =IFERROR(INDEX(balance_sheet!$B:$XFD,MATCH("Hàng tồn kho, ròng",balance_sheet!$A:$A,0),MATCH(E$23,balance_sheet!$B$1:$XFD$1,0)),"") | F28: =IFERROR(INDEX(balance_sheet!$B:$XFD,MATCH("Hàng tồn kho, ròng",balance_sheet!$A:$A,0),MATCH(F$23,balance_sheet!$B$1:$XFD$1,0)),"") | G28: =IFERROR(INDEX(balance_sheet!$B:$XFD,MATCH("Hàng tồn kho, ròng",balance_sheet!$A:$A,0),MATCH(G$23,balance_sheet!$B$1:$XFD$1,0)),"") | H28: =IFERROR(INDEX(balance_sheet!$B:$XFD,MATCH("Hàng tồn kho, ròng",balance_sheet!$A:$A,0),MATCH(H$23,balance_sheet!$B$1:$XFD$1,0)),"") | I28: =IFERROR(INDEX(balance_sheet!$B:$XFD,MATCH("Hàng tồn kho, ròng",balance_sheet!$A:$A,0),MATCH(I$23,balance_sheet!$B$1:$XFD$1,0)),"")
A29: TÀI SẢN NGẮN HẠN | B29: =IFERROR(INDEX(balance_sheet!$B:$XFD,MATCH("TÀI SẢN NGẮN HẠN",balance_sheet!$A:$A,0),MATCH(B$23,balance_sheet!$B$1:$XFD$1,0)),"") | C29: =IFERROR(INDEX(balance_sheet!$B:$XFD,MATCH("TÀI SẢN NGẮN HẠN",balance_sheet!$A:$A,0),MATCH(C$23,balance_sheet!$B$1:$XFD$1,0)),"") | D29: =IFERROR(INDEX(balance_sheet!$B:$XFD,MATCH("TÀI SẢN NGẮN HẠN",balance_sheet!$A:$A,0),MATCH(D$23,balance_sheet!$B$1:$XFD$1,0)),"") | E29: =IFERROR(INDEX(balance_sheet!$B:$XFD,MATCH("TÀI SẢN NGẮN HẠN",balance_sheet!$A:$A,0),MATCH(E$23,balance_sheet!$B$1:$XFD$1,0)),"") | F29: =IFERROR(INDEX(balance_sheet!$B:$XFD,MATCH("TÀI SẢN NGẮN HẠN",balance_sheet!$A:$A,0),MATCH(F$23,balance_sheet!$B$1:$XFD$1,0)),"") | G29: =IFERROR(INDEX(balance_sheet!$B:$XFD,MATCH("TÀI SẢN NGẮN HẠN",balance_sheet!$A:$A,0),MATCH(G$23,balance_sheet!$B$1:$XFD$1,0)),"") | H29: =IFERROR(INDEX(balance_sheet!$B:$XFD,MATCH("TÀI SẢN NGẮN HẠN",balance_sheet!$A:$A,0),MATCH(H$23,balance_sheet!$B$1:$XFD$1,0)),"") | I29: =IFERROR(INDEX(balance_sheet!$B:$XFD,MATCH("TÀI SẢN NGẮN HẠN",balance_sheet!$A:$A,0),MATCH(I$23,balance_sheet!$B$1:$XFD$1,0)),"")
A30: GTCL tài sản cố định vô hình | B30: =IFERROR(INDEX(balance_sheet!$B:$XFD,MATCH("GTCL tài sản cố định vô hình",balance_sheet!$A:$A,0),MATCH(B$23,balance_sheet!$B$1:$XFD$1,0)),"") | C30: =IFERROR(INDEX(balance_sheet!$B:$XFD,MATCH("GTCL tài sản cố định vô hình",balance_sheet!$A:$A,0),MATCH(C$23,balance_sheet!$B$1:$XFD$1,0)),"") | D30: =IFERROR(INDEX(balance_sheet!$B:$XFD,MATCH("GTCL tài sản cố định vô hình",balance_sheet!$A:$A,0),MATCH(D$23,balance_sheet!$B$1:$XFD$1,0)),"") | E30: =IFERROR(INDEX(balance_sheet!$B:$XFD,MATCH("GTCL tài sản cố định vô hình",balance_sheet!$A:$A,0),MATCH(E$23,balance_sheet!$B$1:$XFD$1,0)),"") | F30: =IFERROR(INDEX(balance_sheet!$B:$XFD,MATCH("GTCL tài sản cố định vô hình",balance_sheet!$A:$A,0),MATCH(F$23,balance_sheet!$B$1:$XFD$1,0)),"") | G30: =IFERROR(INDEX(balance_sheet!$B:$XFD,MATCH("GTCL tài sản cố định vô hình",balance_sheet!$A:$A,0),MATCH(G$23,balance_sheet!$B$1:$XFD$1,0)),"") | H30: =IFERROR(INDEX(balance_sheet!$B:$XFD,MATCH("GTCL tài sản cố định vô hình",balance_sheet!$A:$A,0),MATCH(H$23,balance_sheet!$B$1:$XFD$1,0)),"") | I30: =IFERROR(INDEX(balance_sheet!$B:$XFD,MATCH("GTCL tài sản cố định vô hình",balance_sheet!$A:$A,0),MATCH(I$23,balance_sheet!$B$1:$XFD$1,0)),"")
A31: TỔNG CỘNG TÀI SẢN | B31: =IFERROR(INDEX(balance_sheet!$B:$XFD,MATCH("TỔNG CỘNG TÀI SẢN",balance_sheet!$A:$A,0),MATCH(B$23,balance_sheet!$B$1:$XFD$1,0)),"") | C31: =IFERROR(INDEX(balance_sheet!$B:$XFD,MATCH("TỔNG CỘNG TÀI SẢN",balance_sheet!$A:$A,0),MATCH(C$23,balance_sheet!$B$1:$XFD$1,0)),"") | D31: =IFERROR(INDEX(balance_sheet!$B:$XFD,MATCH("TỔNG CỘNG TÀI SẢN",balance_sheet!$A:$A,0),MATCH(D$23,balance_sheet!$B$1:$XFD$1,0)),"") | E31: =IFERROR(INDEX(balance_sheet!$B:$XFD,MATCH("TỔNG CỘNG TÀI SẢN",balance_sheet!$A:$A,0),MATCH(E$23,balance_sheet!$B$1:$XFD$1,0)),"") | F31: =IFERROR(INDEX(balance_sheet!$B:$XFD,MATCH("TỔNG CỘNG TÀI SẢN",balance_sheet!$A:$A,0),MATCH(F$23,balance_sheet!$B$1:$XFD$1,0)),"") | G31: =IFERROR(INDEX(balance_sheet!$B:$XFD,MATCH("TỔNG CỘNG TÀI SẢN",balance_sheet!$A:$A,0),MATCH(G$23,balance_sheet!$B$1:$XFD$1,0)),"") | H31: =IFERROR(INDEX(balance_sheet!$B:$XFD,MATCH("TỔNG CỘNG TÀI SẢN",balance_sheet!$A:$A,0),MATCH(H$23,balance_sheet!$B$1:$XFD$1,0)),"") | I31: =IFERROR(INDEX(balance_sheet!$B:$XFD,MATCH("TỔNG CỘNG TÀI SẢN",balance_sheet!$A:$A,0),MATCH(I$23,balance_sheet!$B$1:$XFD$1,0)),"")
A32: Nguồn vốn
A33: Phải trả người bán | B33: =IFERROR(INDEX(balance_sheet!$B:$XFD,MATCH("Phải trả người bán",balance_sheet!$A:$A,0),MATCH(B$23,balance_sheet!$B$1:$XFD$1,0)),"") | C33: =IFERROR(INDEX(balance_sheet!$B:$XFD,MATCH("Phải trả người bán",balance_sheet!$A:$A,0),MATCH(C$23,balance_sheet!$B$1:$XFD$1,0)),"") | D33: =IFERROR(INDEX(balance_sheet!$B:$XFD,MATCH("Phải trả người bán",balance_sheet!$A:$A,0),MATCH(D$23,balance_sheet!$B$1:$XFD$1,0)),"") | E33: =IFERROR(INDEX(balance_sheet!$B:$XFD,MATCH("Phải trả người bán",balance_sheet!$A:$A,0),MATCH(E$23,balance_sheet!$B$1:$XFD$1,0)),"") | F33: =IFERROR(INDEX(balance_sheet!$B:$XFD,MATCH("Phải trả người bán",balance_sheet!$A:$A,0),MATCH(F$23,balance_sheet!$B$1:$XFD$1,0)),"") | G33: =IFERROR(INDEX(balance_sheet!$B:$XFD,MATCH("Phải trả người bán",balance_sheet!$A:$A,0),MATCH(G$23,balance_sheet!$B$1:$XFD$1,0)),"") | H33: =IFERROR(INDEX(balance_sheet!$B:$XFD,MATCH("Phải trả người bán",balance_sheet!$A:$A,0),MATCH(H$23,balance_sheet!$B$1:$XFD$1,0)),"") | I33: =IFERROR(INDEX(balance_sheet!$B:$XFD,MATCH("Phải trả người bán",balance_sheet!$A:$A,0),MATCH(I$23,balance_sheet!$B$1:$XFD$1,0)),"")
A34: Vay ngắn hạn | B34: =IFERROR(INDEX(balance_sheet!$B:$XFD,MATCH("Vay ngắn hạn",balance_sheet!$A:$A,0),MATCH(B$23,balance_sheet!$B$1:$XFD$1,0)),"") | C34: =IFERROR(INDEX(balance_sheet!$B:$XFD,MATCH("Vay ngắn hạn",balance_sheet!$A:$A,0),MATCH(C$23,balance_sheet!$B$1:$XFD$1,0)),"") | D34: =IFERROR(INDEX(balance_sheet!$B:$XFD,MATCH("Vay ngắn hạn",balance_sheet!$A:$A,0),MATCH(D$23,balance_sheet!$B$1:$XFD$1,0)),"") | E34: =IFERROR(INDEX(balance_sheet!$B:$XFD,MATCH("Vay ngắn hạn",balance_sheet!$A:$A,0),MATCH(E$23,balance_sheet!$B$1:$XFD$1,0)),"") | F34: =IFERROR(INDEX(balance_sheet!$B:$XFD,MATCH("Vay ngắn hạn",balance_sheet!$A:$A,0),MATCH(F$23,balance_sheet!$B$1:$XFD$1,0)),"") | G34: =IFERROR(INDEX(balance_sheet!$B:$XFD,MATCH("Vay ngắn hạn",balance_sheet!$A:$A,0),MATCH(G$23,balance_sheet!$B$1:$XFD$1,0)),"") | H34: =IFERROR(INDEX(balance_sheet!$B:$XFD,MATCH("Vay ngắn hạn",balance_sheet!$A:$A,0),MATCH(H$23,balance_sheet!$B$1:$XFD$1,0)),"") | I34: =IFERROR(INDEX(balance_sheet!$B:$XFD,MATCH("Vay ngắn hạn",balance_sheet!$A:$A,0),MATCH(I$23,balance_sheet!$B$1:$XFD$1,0)),"")
A35: Nợ ngắn hạn | B35: =IFERROR(INDEX(balance_sheet!$B:$XFD,MATCH("Nợ ngắn hạn",balance_sheet!$A:$A,0),MATCH(B$23,balance_sheet!$B$1:$XFD$1,0)),"") | C35: =IFERROR(INDEX(balance_sheet!$B:$XFD,MATCH("Nợ ngắn hạn",balance_sheet!$A:$A,0),MATCH(C$23,balance_sheet!$B$1:$XFD$1,0)),"") | D35: =IFERROR(INDEX(balance_sheet!$B:$XFD,MATCH("Nợ ngắn hạn",balance_sheet!$A:$A,0),MATCH(D$23,balance_sheet!$B$1:$XFD$1,0)),"") | E35: =IFERROR(INDEX(balance_sheet!$B:$XFD,MATCH("Nợ ngắn hạn",balance_sheet!$A:$A,0),MATCH(E$23,balance_sheet!$B$1:$XFD$1,0)),"") | F35: =IFERROR(INDEX(balance_sheet!$B:$XFD,MATCH("Nợ ngắn hạn",balance_sheet!$A:$A,0),MATCH(F$23,balance_sheet!$B$1:$XFD$1,0)),"") | G35: =IFERROR(INDEX(balance_sheet!$B:$XFD,MATCH("Nợ ngắn hạn",balance_sheet!$A:$A,0),MATCH(G$23,balance_sheet!$B$1:$XFD$1,0)),"") | H35: =IFERROR(INDEX(balance_sheet!$B:$XFD,MATCH("Nợ ngắn hạn",balance_sheet!$A:$A,0),MATCH(H$23,balance_sheet!$B$1:$XFD$1,0)),"") | I35: =IFERROR(INDEX(balance_sheet!$B:$XFD,MATCH("Nợ ngắn hạn",balance_sheet!$A:$A,0),MATCH(I$23,balance_sheet!$B$1:$XFD$1,0)),"")
A36: Vay dài hạn | B36: =IFERROR(INDEX(balance_sheet!$B:$XFD,MATCH("Vay dài hạn",balance_sheet!$A:$A,0),MATCH(B$23,balance_sheet!$B$1:$XFD$1,0)),"") | C36: =IFERROR(INDEX(balance_sheet!$B:$XFD,MATCH("Vay dài hạn",balance_sheet!$A:$A,0),MATCH(C$23,balance_sheet!$B$1:$XFD$1,0)),"") | D36: =IFERROR(INDEX(balance_sheet!$B:$XFD,MATCH("Vay dài hạn",balance_sheet!$A:$A,0),MATCH(D$23,balance_sheet!$B$1:$XFD$1,0)),"") | E36: =IFERROR(INDEX(balance_sheet!$B:$XFD,MATCH("Vay dài hạn",balance_sheet!$A:$A,0),MATCH(E$23,balance_sheet!$B$1:$XFD$1,0)),"") | F36: =IFERROR(INDEX(balance_sheet!$B:$XFD,MATCH("Vay dài hạn",balance_sheet!$A:$A,0),MATCH(F$23,balance_sheet!$B$1:$XFD$1,0)),"") | G36: =IFERROR(INDEX(balance_sheet!$B:$XFD,MATCH("Vay dài hạn",balance_sheet!$A:$A,0),MATCH(G$23,balance_sheet!$B$1:$XFD$1,0)),"") | H36: =IFERROR(INDEX(balance_sheet!$B:$XFD,MATCH("Vay dài hạn",balance_sheet!$A:$A,0),MATCH(H$23,balance_sheet!$B$1:$XFD$1,0)),"") | I36: =IFERROR(INDEX(balance_sheet!$B:$XFD,MATCH("Vay dài hạn",balance_sheet!$A:$A,0),MATCH(I$23,balance_sheet!$B$1:$XFD$1,0)),"")
A37: Nợ dài hạn | B37: =IFERROR(INDEX(balance_sheet!$B:$XFD,MATCH("Nợ dài hạn",balance_sheet!$A:$A,0),MATCH(B$23,balance_sheet!$B$1:$XFD$1,0)),"") | C37: =IFERROR(INDEX(balance_sheet!$B:$XFD,MATCH("Nợ dài hạn",balance_sheet!$A:$A,0),MATCH(C$23,balance_sheet!$B$1:$XFD$1,0)),"") | D37: =IFERROR(INDEX(balance_sheet!$B:$XFD,MATCH("Nợ dài hạn",balance_sheet!$A:$A,0),MATCH(D$23,balance_sheet!$B$1:$XFD$1,0)),"") | E37: =IFERROR(INDEX(balance_sheet!$B:$XFD,MATCH("Nợ dài hạn",balance_sheet!$A:$A,0),MATCH(E$23,balance_sheet!$B$1:$XFD$1,0)),"") | F37: =IFERROR(INDEX(balance_sheet!$B:$XFD,MATCH("Nợ dài hạn",balance_sheet!$A:$A,0),MATCH(F$23,balance_sheet!$B$1:$XFD$1,0)),"") | G37: =IFERROR(INDEX(balance_sheet!$B:$XFD,MATCH("Nợ dài hạn",balance_sheet!$A:$A,0),MATCH(G$23,balance_sheet!$B$1:$XFD$1,0)),"") | H37: =IFERROR(INDEX(balance_sheet!$B:$XFD,MATCH("Nợ dài hạn",balance_sheet!$A:$A,0),MATCH(H$23,balance_sheet!$B$1:$XFD$1,0)),"") | I37: =IFERROR(INDEX(balance_sheet!$B:$XFD,MATCH("Nợ dài hạn",balance_sheet!$A:$A,0),MATCH(I$23,balance_sheet!$B$1:$XFD$1,0)),"")
A38: NỢ PHẢI TRẢ | B38: =IFERROR(INDEX(balance_sheet!$B:$XFD,MATCH("NỢ PHẢI TRẢ",balance_sheet!$A:$A,0),MATCH(B$23,balance_sheet!$B$1:$XFD$1,0)),"") | C38: =IFERROR(INDEX(balance_sheet!$B:$XFD,MATCH("NỢ PHẢI TRẢ",balance_sheet!$A:$A,0),MATCH(C$23,balance_sheet!$B$1:$XFD$1,0)),"") | D38: =IFERROR(INDEX(balance_sheet!$B:$XFD,MATCH("NỢ PHẢI TRẢ",balance_sheet!$A:$A,0),MATCH(D$23,balance_sheet!$B$1:$XFD$1,0)),"") | E38: =IFERROR(INDEX(balance_sheet!$B:$XFD,MATCH("NỢ PHẢI TRẢ",balance_sheet!$A:$A,0),MATCH(E$23,balance_sheet!$B$1:$XFD$1,0)),"") | F38: =IFERROR(INDEX(balance_sheet!$B:$XFD,MATCH("NỢ PHẢI TRẢ",balance_sheet!$A:$A,0),MATCH(F$23,balance_sheet!$B$1:$XFD$1,0)),"") | G38: =IFERROR(INDEX(balance_sheet!$B:$XFD,MATCH("NỢ PHẢI TRẢ",balance_sheet!$A:$A,0),MATCH(G$23,balance_sheet!$B$1:$XFD$1,0)),"") | H38: =IFERROR(INDEX(balance_sheet!$B:$XFD,MATCH("NỢ PHẢI TRẢ",balance_sheet!$A:$A,0),MATCH(H$23,balance_sheet!$B$1:$XFD$1,0)),"") | I38: =IFERROR(INDEX(balance_sheet!$B:$XFD,MATCH("NỢ PHẢI TRẢ",balance_sheet!$A:$A,0),MATCH(I$23,balance_sheet!$B$1:$XFD$1,0)),"")
A39: Vốn chủ sở hữu | B39: =IFERROR(INDEX(balance_sheet!$B:$XFD,MATCH("Vốn chủ sở hữu",balance_sheet!$A:$A,0),MATCH(B$23,balance_sheet!$B$1:$XFD$1,0)),"") | C39: =IFERROR(INDEX(balance_sheet!$B:$XFD,MATCH("Vốn chủ sở hữu",balance_sheet!$A:$A,0),MATCH(C$23,balance_sheet!$B$1:$XFD$1,0)),"") | D39: =IFERROR(INDEX(balance_sheet!$B:$XFD,MATCH("Vốn chủ sở hữu",balance_sheet!$A:$A,0),MATCH(D$23,balance_sheet!$B$1:$XFD$1,0)),"") | E39: =IFERROR(INDEX(balance_sheet!$B:$XFD,MATCH("Vốn chủ sở hữu",balance_sheet!$A:$A,0),MATCH(E$23,balance_sheet!$B$1:$XFD$1,0)),"") | F39: =IFERROR(INDEX(balance_sheet!$B:$XFD,MATCH("Vốn chủ sở hữu",balance_sheet!$A:$A,0),MATCH(F$23,balance_sheet!$B$1:$XFD$1,0)),"") | G39: =IFERROR(INDEX(balance_sheet!$B:$XFD,MATCH("Vốn chủ sở hữu",balance_sheet!$A:$A,0),MATCH(G$23,balance_sheet!$B$1:$XFD$1,0)),"") | H39: =IFERROR(INDEX(balance_sheet!$B:$XFD,MATCH("Vốn chủ sở hữu",balance_sheet!$A:$A,0),MATCH(H$23,balance_sheet!$B$1:$XFD$1,0)),"") | I39: =IFERROR(INDEX(balance_sheet!$B:$XFD,MATCH("Vốn chủ sở hữu",balance_sheet!$A:$A,0),MATCH(I$23,balance_sheet!$B$1:$XFD$1,0)),"") | J39: =I39+0.8*J51
A40: Tăng VCSH/LN cổ đông cty mẹ | C40: =(C39-B39)/C51 | D40: =(D39-C39)/D51 | E40: =(E39-D39)/E51 | F40: =(F39-E39)/F51 | G40: =(G39-F39)/G51 | H40: =(H39-G39)/H51 | I40: =(I39-H39)/I51
A41: Lợi ích cổ đông không kiểm soát | B41: =IFERROR(INDEX(balance_sheet!$B:$XFD,MATCH("Lợi ích cổ đông không kiểm soát",balance_sheet!$A:$A,0),MATCH(B$23,balance_sheet!$B$1:$XFD$1,0)),"") | C41: =IFERROR(INDEX(balance_sheet!$B:$XFD,MATCH("Lợi ích cổ đông không kiểm soát",balance_sheet!$A:$A,0),MATCH(C$23,balance_sheet!$B$1:$XFD$1,0)),"") | D41: =IFERROR(INDEX(balance_sheet!$B:$XFD,MATCH("Lợi ích cổ đông không kiểm soát",balance_sheet!$A:$A,0),MATCH(D$23,balance_sheet!$B$1:$XFD$1,0)),"") | E41: =IFERROR(INDEX(balance_sheet!$B:$XFD,MATCH("Lợi ích cổ đông không kiểm soát",balance_sheet!$A:$A,0),MATCH(E$23,balance_sheet!$B$1:$XFD$1,0)),"") | F41: =IFERROR(INDEX(balance_sheet!$B:$XFD,MATCH("Lợi ích cổ đông không kiểm soát",balance_sheet!$A:$A,0),MATCH(F$23,balance_sheet!$B$1:$XFD$1,0)),"") | G41: =IFERROR(INDEX(balance_sheet!$B:$XFD,MATCH("Lợi ích cổ đông không kiểm soát",balance_sheet!$A:$A,0),MATCH(G$23,balance_sheet!$B$1:$XFD$1,0)),"") | H41: =IFERROR(INDEX(balance_sheet!$B:$XFD,MATCH("Lợi ích cổ đông không kiểm soát",balance_sheet!$A:$A,0),MATCH(H$23,balance_sheet!$B$1:$XFD$1,0)),"") | I41: =IFERROR(INDEX(balance_sheet!$B:$XFD,MATCH("Lợi ích cổ đông không kiểm soát",balance_sheet!$A:$A,0),MATCH(I$23,balance_sheet!$B$1:$XFD$1,0)),"")
...

Sheet Dự báo tăng trưởng
B1: Q1/2026 | C1: Q2/2026 | D1: Q3/2026 | E1: Q4/2026
A2: Số CP | B2: 1475765646 | C2: 1475765646 | D2: 1475765646 | E2: 1475765646
A3: Thị giá | B3: 75100 | C3: 75100 | D3: 75100 | E3: 75100
A4: Vốn hoá | B4: =B2*B3 | C4: =C2*C3 | D4: =D2*D3 | E4: =E2*E3
A6: VCSH | B6: 35933000000000 | C6: 36351000000000 | D6: =B6*(($E$6/B6)^(2/3)) | E6: =chi_so_tai_chinh!J39
A7: LICĐTS | B7: 619000000000 | C7: 672000000000 | D7: =D6*0.02 | E7: =E6*0.02
A8: BV | B8: =B6-B7 | C8: =C6-C7 | D8: =D6-D7 | E8: =E6-E7
A9: BVPS | B9: =B8/B2 | C9: =C8/C2 | D9: =D8/D2 | E9: =E8/E2
A10: PB | B10: =B3/B9 | C10: =C3/C9 | D10: =D3/D9 | E10: =E3/E9
