Workbook

Sheet balance_sheet
A1: item | B1: 2018 | C1: 2019 | D1: 2020 | E1: 2021 | F1: 2022 | G1: 2023 | H1: 2024 | I1: 2025 | J1: 2018-Q1 | K1: 2018-Q2 | L1: 2018-Q3 | M1: 2018-Q4 | N1: 2024-Q3 | O1: 2024-Q4 | P1: 2025-Q1 | Q1: 2025-Q2 | R1: 2025-Q3 | S1: 2025-Q4 | T1: 2026-Q1 | U1: 2026-Q2
A2: TÀI SẢN NGẮN HẠN | B2: 23371994756394 | C2: 35011896908246 | D2: 37317233970267 | E2: 51955257770657 | F2: 44577607228189 | G2: 51950337976047 | H2: 65836422620040 | I2: 77201650782966 | J2: 18987675255015 | K2: 19674745908177 | L2: 20874017598029 | M2: 23389569670395 | N2: 61074953380269 | O2: 65836422620040 | P2: 68350202307085 | Q2: 75933600138863 | R2: 75125383121673 | S2: 77201650782966 | T2: 76834611871316 | U2: 97732971951408
A3: Tiền và tương đương tiền | B3: 3749550258212 | C3: 3115236816468 | D3: 7347857397925 | E3: 4142015762555 | F3: 5061020547422 | G3: 5365704857172 | H3: 4897331540730 | I3: 4999925717187 | J3: 2344357965889 | K3: 2904599435150 | L3: 5069778230756 | M3: 3749550258212 | N3: 9752339611719 | O3: 4897331540730 | P3: 2658218136149 | Q3: 6030067748439 | R3: 5510816169528 | S3: 4999925717187 | T3: 4553652582201 | U3: 4678600961443
A4: Tiền | B4: 3363717276954 | C4: 2024347938868 | D4: 2243274466174 | E4: 2606672264502 | F4: 3846020547422 | G4: 4795636583222 | H4: 4697331540730 | I4: 4960375717187 | J4: 1393331705506 | K4: 2059221030725 | L4: 2584448230756 | M4: 3363717276954 | N4: 3283839611719 | O4: 4697331540730 | P4: 2658218136149 | Q4: 5730067748439 | R4: 5510816169528 | S4: 4960375717187 | T4: 4553652582201 | U4: 4678600961443
A5: Các khoản tương đương tiền | B5: 385832981258 | C5: 1090888877600 | D5: 5104582931751 | E5: 1535343498053 | F5: 1215000000000 | G5: 570068273950 | H5: 200000000000 | I5: 39550000000 | J5: 951026260383 | K5: 845378404425 | L5: 2485330000000 | M5: 385832981258 | N5: 6468500000000 | O5: 200000000000 | P5: 0 | Q5: 300000000000 | R5: 0 | S5: 39550000000 | T5: 0 | U5: 0
A6: Đầu tư ngắn hạn | B6: 0 | C6: 0 | D6: 0 | E6: 0 | F6: 0 | G6: 0 | H6: 0 | I6: 0 | J6: 0 | K6: 0 | L6: 0 | M6: 0 | N6: 0 | O6: 0 | P6: 0 | Q6: 0 | R6: 0 | S6: 0 | T6: 0 | U6: 0
A7: Đầu tư ngắn hạn | F7: 0 | G7: 0 | H7: 0 | I7: 0
A8: Dự phòng giảm giá | B8: 0 | C8: 0 | D8: 0 | E8: 0 | F8: 0 | G8: 0 | H8: 0 | I8: 0 | J8: 0 | K8: 0 | L8: 0 | M8: 0 | N8: 0 | O8: 0 | P8: 0 | Q8: 0 | R8: 0 | S8: 0 | T8: 0 | U8: 0
A9: Các khoản phải thu | B9: 1542529736073 | C9: 1815085561979 | D9: 1595251018496 | E9: 3162121971586 | F9: 3000817466182 | G9: 5158853337785 | H9: 8825896224771 | I9: 10182835978469 | J9: 1730824187579 | K9: 1433869348388 | L9: 1505154445936 | M9: 1560104650074 | N9: 7355271408055 | O9: 8825896224771 | P9: 9862532179881 | Q9: 11374184436260 | R9: 11515134739245 | S9: 10182835978469 | T9: 2121015956014 | U9: 2434312355641
A10: Phải thu khách hàng | B10: 369573657457 | C10: 262268362817 | D10: 196394545434 | E10: 384236578232 | F10: 178061365251 | G10: 308474343927 | H10: 241405396887 | I10: 253358838280 | J10: 337929921139 | K10: 389783195002 | L10: 417878278560 | M10: 380144545257 | N10: 232971309862 | O10: 241405396887 | P10: 238308586301 | Q10: 307952455563 | R10: 203255755385 | S10: 253358838280 | T10: 255239898353 | U10: 421858877183
A11: Trả trước người bán | B11: 21007291749 | C11: 195016846986 | D11: 287913331552 | E11: 390738782756 | F11: 403669438496 | G11: 95981093251 | H11: 115888383111 | I11: 141627187798 | J11: 40635659294 | K11: 83457888055 | L11: 85909526091 | M11: 21007291749 | N11: 99504470546 | O11: 115888383111 | P11: 62660193813 | Q11: 38235583466 | R11: 34907414898 | S11: 141627187798 | T11: 162975645383 | U11: 80803683167
A12: Phải thu nội bộ | B12: 0 | C12: 0 | D12: 0 | E12: 0 | F12: 0 | G12: 0 | H12: 0 | I12: 0 | J12: 0 | K12: 0 | L12: 0 | M12: 0 | N12: 0 | O12: 0 | P12: 0 | Q12: 0 | R12: 0 | S12: 0 | T12: 0 | U12: 0
A13: Phải thu hợp đồng xây dựng đang thực hiện | B13: 0 | C13: 0 | D13: 0 | E13: 0 | F13: 0 | G13: 0 | H13: 0 | I13: 0 | J13: 0 | K13: 0 | L13: 0 | M13: 0 | N13: 0 | O13: 0 | P13: 0 | Q13: 0 | R13: 0 | S13: 0 | T13: 0 | U13: 0
A14: Phải thu khác | B14: 1151948786867 | C14: 1357800352176 | D14: 1030943141510 | E14: 1425228912960 | F14: 2402168964797 | G14: 2668480202969 | H14: 2430887848672 | I14: 2877349952391 | J14: 1352258607146 | K14: 960628265331 | L14: 1001366641285 | M14: 1158952813068 | N14: 2486351627647 | O14: 2430887848672 | P14: 2589563399767 | Q14: 3098996397231 | R14: 3397471568962 | S14: 2877349952391 | T14: 1702800412278 | U14: 1931649795291
A15: Dự phòng nợ khó đòi | B15: 0 | C15: 0 | D15: 0 | E15: 0 | F15: 0 | G15: 0 | H15: 0 | I15: 0 | J15: 0 | K15: 0 | L15: 0 | M15: 0 | N15: 0 | O15: 0 | P15: 0 | Q15: 0 | R15: 0 | S15: 0 | T15: 0 | U15: 0
A16: Hàng tồn kho, ròng | B16: 17446005298981 | C16: 25745428436580 | D16: 19422177452674 | E16: 29167232293922 | F16: 25696077735282 | G16: 21824235626176 | H16: 22244676326705 | I16: 27266851974258 | J16: 14417399343964 | K16: 14275184170658 | L16: 13304860681973 | M16: 17446005298981 | N16: 21853578009429 | O16: 22244676326705 | P16: 22808478321986 | Q16: 23691724133318 | R16: 24101279307428 | S16: 27266851974258 | T16: 27600707843304 | U16: 30874909197649
A17: Hàng tồn kho | B17: 17821137643753 | C17: 26195934673884 | D17: 19926363502365 | E17: 29850068817719 | F17: 26058131396686 | G17: 22028684523096 | H17: 22667774012643 | I17: 27876446129267 | J17: 14735000448428 | K17: 14635272065949 | L17: 13667536889135 | M17: 17821137643753 | N17: 22212929474722 | O17: 22667774012643 | P17: 23243566847543 | Q17: 24132788913496 | R17: 24645125687618 | S17: 27876446129267 | T17: 28349740199616 | U17: 31599182640982
A18: Dự phòng giảm giá hàng tồn kho | B18: -375132344772 | C18: -450506237304 | D18: -504186049691 | E18: -682836523797 | F18: -362053661404 | G18: -204448896920 | H18: -423097685938 | I18: -609594155009 | J18: -317601104464 | K18: -360087895291 | L18: -362676207162 | M18: -375132344772 | N18: -359351465293 | O18: -423097685938 | P18: -435088525557 | Q18: -441064780178 | R18: -543846380190 | S18: -609594155009 | T18: -749032356312 | U18: -724273443333
A19: Tài sản lưu động khác | B19: 0 | C19: 0 | D19: 0 | E19: 0 | F19: 0 | G19: 0 | H19: 0 | I19: 0 | J19: 0 | K19: 0 | L19: 0 | M19: 0 | N19: 0 | O19: 0 | P19: 0 | Q19: 0 | R19: 0 | S19: 0 | T19: 0 | U19: 13315080000000
... A22: Phải thu thuế khác | B22: 1842948927 | C22: 2890365291 | D22: 4751687467 | E22: 41984411029 | F22: 28637906590 | G22: 23473930964 | H22: 32630294575 | I22: 44293494912 | J22: 965019135 | K22: 10076273881 | L22: 1221330389 | M22: 1842948927 | N22: 21369067834 | O22: 32630294575 | P22: 30098399501 | Q22: 13710817808 | R22: 13802454253 | S22: 44293494912 | T22: 43418120537 | U22: 56140913335
A23: Tài sản lưu động khác | F23: 0 | G23: 0 | H23: 0 | I23: 0
A24: TÀI SẢN DÀI HẠN | B24: 4750536730462 | C24: 6696198636637 | D24: 8713645982187 | E24: 11016147044285 | F24: 11256488385860 | G24: 8160899236677 | H24: 4601353101564 | I24: 6743968829068 | J24: 4671211025166 | K24: 4667942946620 | L24: 4672413937653 | M24: 4750536730462 | N24: 5825089761066 | O24: 4601353101564 | P24: 4329022407862 | Q24: 5067799108905 | R24: 5163114770393 | S24: 6743968829068 | T24: 7159946601011 | U24: 7181991691663
A25: Phải thu dài hạn | B25: 313775645332 | C25: 374563598474 | D25: 439493257757 | E25: 482389179464 | F25: 503486573563 | G25: 457569986630 | H25: 389707802472 | I25: 403823784845 | J25: 302365145533 | K25: 303035864435 | L25: 310311155448 | M25: 313775645332 | N25: 397943974045 | O25: 389707802472 | P25: 398376958399 | Q25: 392831179367 | R25: 394958296709 | S25: 403823784845 | T25: 420693031855 | U25: 428065660316
A26: Phải thu khách hàng dài hạn | B26: 0 | C26: 0 | D26: 0 | E26: 0 | F26: 0 | G26: 0 | H26: 0 | I26: 0 | J26: 0 | K26: 0 | L26: 0 | M26: 0 | N26: 0 | O26: 0 | P26: 0 | Q26: 0 | R26: 0 | S26: 0 | T26: 0 | U26: 0
A27: Phải thu nội bộ dài hạn | B27: 0 | C27: 0 | D27: 0 | E27: 0 | F27: 0 | G27: 0 | H27: 0 | I27: 0 | J27: 0 | K27: 0 | L27: 0 | M27: 0 | N27: 0 | O27: 0 | P27: 0 | Q27: 0 | R27: 0 | S27: 0 | T27: 0 | U27: 0
A28: Phải thu dài hạn khác | B28: 313775645332 | C28: 374563598474 | D28: 439493257757 | E28: 482389179464 | F28: 493741850234 | G28: 448325013301 | H28: 389707802472 | I28: 403823784845 | J28: 302365145533 | K28: 303035864435 | L28: 310311155448 | M28: 313775645332 | N28: 397943974045 | O28: 389707802472 | P28: 398376958399 | Q28: 392831179367 | R28: 394958296709 | S28: 403823784845 | T28: 420693031855 | U28: 428065660316
A29: Dự phòng phải thu dài hạn | B29: 0 | C29: 0 | D29: 0 | E29: 0 | F29: 0 | G29: 0 | H29: 0 | I29: 0 | J29: 0 | K29: 0 | L29: 0 | M29: 0 | N29: 0 | O29: 0 | P29: 0 | Q29: 0 | R29: 0 | S29: 0 | T29: 0 | U29: 0
A30: Tài sản cố định | B30: 3333147659602 | C30: 5403776988921 | D30: 7294961666136 | E30: 9647168873232 | F30: 9727502911440 | G30: 6500135608914 | H30: 3586628664045 | I30: 2598189217583 | J30: 3500311717421 | K30: 3418127368371 | L30: 3330857563330 | M30: 3333147659602 | N30: 4172053614940 | O30: 3586628664045 | P30: 3233901626643 | Q30: 2977795755305 | R30: 2606757399459 | S30: 2598189217583 | T30: 2418447401463 | U30: 2482116748592
A31: GTCL TSCĐ hữu hình | B31: 3304923529470 | C31: 5375279172974 | D31: 7267319287908 | E31: 9566954933220 | F31: 9653330005976 | G31: 6431315373113 | H31: 3523161097906 | I31: 2540074321107 | J31: 3469295441563 | K31: 3386769615191 | L31: 3300153689070 | M31: 3304923529470 | N31: 4107247881385 | O31: 3523161097906 | P31: 3171772227920 | Q31: 2917004523997 | R31: 2547304335567 | S31: 2540074321107 | T31: 2361670672403 | U31: 2426678186947
A32: Nguyên giá TSCĐ hữu hình | B32: 5788326331676 | C32: 9148455989525 | D32: 12963311412901 | E32: 17987087849355 | F32: 20841513609195 | G32: 20139282722977 | H32: 19174626383752 | I32: 19478200234864 | J32: 5189241896878 | K32: 5360563477467 | L32: 5542951542435 | M32: 5788326331676 | N32: 19064454816619 | O32: 19174626383752 | P32: 19305596081131 | Q32: 19477127305514 | R32: 19496422101808 | S32: 19478200234864 | T32: 19648285497537 | U32: 20004114064471
A33: Khấu hao lũy kế TSCĐ hữu hình | B33: -2483402802206 | C33: -3773176816551 | D33: -5695992124993 | E33: -8420132916135 | F33: -11188183603219 | G33: -13707967349864 | H33: -15651465285846 | I33: -16938125913757 | J33: -1719946455315 | K33: -1973793862276 | L33: -2242797853365 | M33: -2483402802206 | N33: -14957206935234 | O33: -15651465285846 | P33: -16133823853211 | Q33: -16560122781517 | R33: -16949117766241 | S33: -16938125913757 | T33: -17286614825134 | U33: -17577435877524
A34: GTCL tài sản thuê tài chính | B34: 0 | C34: 0 | D34: 0 | E34: 0 | F34: 0 | G34: 0 | H34: 0 | I34: 0 | J34: 0 | K34: 0 | L34: 0 | M34: 0 | N34: 0 | O34: 0 | P34: 0 | Q34: 0 | R34: 0 | S34: 0 | T34: 0 | U34: 0
A35: Nguyên giá tài sản thuê tài chính | B35: 0 | C35: 0 | D35: 0 | E35: 0 | F35: 0 | G35: 0 | H35: 0 | I35: 0 | J35: 0 | K35: 0 | L35: 0 | M35: 0 | N35: 0 | O35: 0 | P35: 0 | Q35: 0 | R35: 0 | S35: 0 | T35: 0 | U35: 0
... A72: Vay dài hạn | B72: 1208167140389 | C72: 1122136666657 | D72: 1126676666653 | E72: 0 | F72: 5901250000000 | G72: 5985250000000 | H72: 0 | I72: 0 | J72: 1362046386664 | K72: 1339471247194 | L72: 1296366150251 | M72: 1247995997257 | N72: 6151875000000 | O72: 0 | P72: 0 | Q72: 0 | R72: 0 | S72: 0 | T72: 0 | U72: 0
A73: Thuế thu nhập hoãn lại | F73: 0 | G73: 1168691414 | H73: 0 | I73: 0
A74: Dự phòng trợ cấp thôi việc | B74: 0 | C74: 0 | D74: 0 | E74: 0 | F74: 0 | G74: 0 | H74: 0 | I74: 0 | J74: 0 | K74: 0 | L74: 0 | M74: 0 | N74: 0 | O74: 0 | P74: 0 | Q74: 0 | R74: 0 | S74: 0 | T74: 0 | U74: 0
A75: Dự phòng các khoản nợ dài hạn | B75: 0 | C75: 0 | D75: 0 | E75: 0 | F75: 0 | G75: 0 | H75: 0 | I75: 0 | J75: 0 | K75: 0 | L75: 0 | M75: 0 | N75: 0 | O75: 0 | P75: 0 | Q75: 0 | R75: 0 | S75: 0 | T75: 0 | U75: 0
A76: Doanh thu chưa thực hiện | B76: 0 | C76: 0 | D76: 0 | E76: 0 | F76: 0 | G76: 0 | H76: 0 | I76: 0 | J76: 0 | K76: 0 | L76: 0 | M76: 0 | N76: 0 | O76: 0 | P76: 0 | Q76: 0 | R76: 0 | S76: 0 | T76: 0 | U76: 493714455488
A77: Quỹ phát triển khoa học công nghệ | B77: 0 | C77: 0 | D77: 0 | E77: 0 | F77: 0 | G77: 0 | H77: 0 | I77: 0 | J77: 0 | K77: 0 | L77: 0 | M77: 0 | N77: 0 | O77: 0 | P77: 0 | Q77: 0 | R77: 0 | S77: 0 | T77: 0 | U77: 0
A78: Vốn chủ sở hữu | B78: 8983035331342 | C78: 12143592194353 | D78: 15481689846432 | E78: 20378245999846 | F78: 23932581517576 | G78: 23359557967338 | H78: 28121576823855 | I78: 33176117374577 | J78: 7267996594125 | K78: 7515367410874 | L78: 8162767661816 | M78: 8983035331342 | N78: 27275564730745 | O78: 28121576823855 | P78: 29669133577791 | Q78: 30016164896852 | R78: 31797199621877 | S78: 33176117374577 | T78: 35933342055104 | U78: 36351326250442
...

Sheet income_statement
A1: item | B1: 2018 | C1: 2019 | D1: 2020 | E1: 2021 | F1: 2022 | G1: 2023 | H1: 2024 | I1: 2025 | J1: 2018-Q1 | K1: 2018-Q2 | L1: 2018-Q3 | M1: 2018-Q4 | N1: 2024-Q3 | O1: 2024-Q4 | P1: 2025-Q1 | Q1: 2025-Q2 | R1: 2025-Q3 | S1: 2025-Q4 | T1: 2026-Q1 | U1: 2026-Q2
A2: Doanh thu bán hàng và cung cấp dịch vụ | B2: 87738378978636 | C2: 103485046672447 | D2: 109801253690656 | E2: 124141525689948 | F2: 134722248887557 | G2: 119234184825086 | H2: 135225101298992 | I2: 156836115054975 | J2: 23073465470685 | K2: 22127707569982 | L2: 21211714779754 | M2: 21325491158215 | N2: 34361569620937 | O2: 34793923302149 | P2: 36332913479242 | Q2: 37844160678840 | R2: 40091343632319 | S2: 42567697264574 | T2: 46709163270992 | U2: 49034501493892
A3: Các khoản giảm trừ doanh thu | B3: -1222091976137 | C3: -1310802695724 | D3: -1255234025244 | E3: -1183419586774 | F3: -1317471297033 | G3: -954396369644 | H3: -883948450190 | I3: -907969435608 | J3: -309945720115 | K3: -320773748245 | L3: -304132083712 | M3: -287240424065 | N3: -214900932986 | O3: -220002524817 | P3: -197955061033 | Q3: -224192018870 | R3: -238836479673 | S3: -246985876032 | T3: -247211244219 | U3: -283217941935
A4: Doanh thu thuần | B4: 86516287002499 | C4: 102174243976723 | D4: 108546019665412 | E4: 122958106103174 | F4: 133404777590524 | G4: 118279788455442 | H4: 134341152848802 | I4: 155928145619367 | J4: 22763519750570 | K4: 21806933821737 | L4: 20907582696042 | M4: 21038250734150 | N4: 34146668687951 | O4: 34573920777332 | P4: 36134958418209 | Q4: 37619968659970 | R4: 39852507152646 | S4: 42320711388542 | T4: 46461952026773 | U4: 48751283551957
A5: Giá vốn hàng bán | B5: -71224159239435 | C5: -82686444673012 | D5: -84591522392949 | E5: -95325974107640 | F5: -102542735094343 | G5: -95759175291712 | H5: -106841942771781 | I5: -124926268219546 | J5: -18788756341782 | K5: -17945292260387 | L5: -17205031495334 | M5: -17285079141932 | N5: -27254757625648 | O5: -27986951875213 | P5: -28934547803004 | Q5: -30051267999814 | R5: -32374320274746 | S5: -33566132141982 | T5: -36751850587457 | U5: -37942073479846
A6: Lợi nhuận gộp | B6: 15292127763064 | C6: 19487799303711 | D6: 23954497272463 | E6: 27632131995534 | F6: 30862042496181 | G6: 22520613163730 | H6: 27499210077021 | I6: 31001877399821 | J6: 3974763408788 | K6: 3861641561350 | L6: 3702551200708 | M6: 3753171592218 | N6: 6891911062303 | O6: 6586968902119 | P6: 7200410615205 | Q6: 7568700660156 | R6: 7478186877900 | S6: 8754579246560 | T6: 9710101439316 | U6: 10809210072111
A7: Doanh thu hoạt động tài chính | B7: 342083875229 | C7: 631177854351 | D7: 794121782667 | E7: 1287956026163 | F7: 1313137304323 | G7: 2166963715091 | H7: 2376502605263 | I7: 3107348733939 | J7: 76259503803 | K7: 71909377837 | L7: 86456996199 | M7: 107457997390 | N7: 575388786548 | O7: 635695584388 | P7: 693293667931 | Q7: 768832246965 | R7: 809068897431 | S7: 836153921612 | T7: 857866587527 | U7: 957393431151
A8: Chi phí tài chính | B8: -436573150236 | C8: -569754844844 | D8: -594151513751 | E8: -714707225745 | F8: -1382620454532 | G8: -1556146106982 | H8: -1188465609510 | I8: -1542518673463 | J8: -114960070907 | K8: -105700047545 | L8: -104974336364 | M8: -110938695420 | N8: -330440626256 | O8: -189071963171 | P8: -339023162705 | Q8: -402454468644 | R8: -410743275636 | S8: -390297766478 | T8: -421767358286 | U8: -453084595743
A9: Chi phí lãi vay | B9: -436416577674 | C9: -568136717134 | D9: -594003821021 | E9: -674427746189 | F9: -1362143909103 | G9: -1447718354797 | H9: -1137236129748 | I9: -1470675593604 | J9: -112795317948 | K9: -105346054241 | L9: -107492002949 | M9: -110783202536 | N9: -303696061820 | O9: -323470486929 | P9: -322792850500 | Q9: -375178482038 | R9: -388038374707 | S9: -384665886359 | T9: -415448904085 | U9: -436321054832
A10: Chi phí bán hàng | B10: -9659741188756 | C10: -12437282718212 | D10: -15333798830787 | E10: -17914173302345 | F10: -22336838067678 | G10: -20916710755306 | H10: -19849837609882 | I10: -19330903536858 | J10: -2308808752645 | K10: -2464220418793 | L10: -2436749840647 | M10: -2449962176671 | N10: -4848950073481 | O10: -5123108197082 | P10: -4403006343750 | Q10: -4703283205201 | R10: -4570833491508 | S10: -5653780496399 | T10: -5284908877085 | U10: -5980272600628
A11: Chi phí quản lý doanh nghiệp | B11: -1761613900080 | C11: -2073782880058 | D11: -3404431838167 | E11: -3823390074765 | F11: -1881027579714 | G11: -1167651662536 | H11: -3565767583102 | I11: -4596074513172 | J11: -588469226877 | K11: -397865044350 | L11: -390396333632 | M11: -384883295221 | N11: -967618855194 | O11: -916356723640 | P11: -1214599786616 | Q11: -1201666094080 | R11: -1119414262509 | S11: -1060394369967 | T11: -1523180115533 | U11: -1317458502119
A12: Lãi/(lỗ) từ hoạt động kinh doanh | B12: 3774182412336 | C12: 5034683431577 | D12: 5412529932954 | E12: 6465606918356 | F12: 6574693698580 | G12: 1047068353997 | H12: 5227045424891 | I12: 8664080489454 | J12: 1038784862162 | K12: 965030927222 | L12: 854343455912 | M12: 916023167040 | N12: 1320438170928 | O12: 996550122732 | P12: 1940204764365 | Q12: 2041250769970 | R12: 2190441447033 | S12: 2492183508086 | T12: 3347123417867 | U12: 4034437503929
A13: Thu nhập khác | B13: 33233337382 | C13: 41557041541 | D13: 43512695471 | E13: 54872797433 | F13: 61606712681 | G13: 36883419051 | H13: 25743895664 | I13: 52777770887 | J13: 8064141763 | K13: 6487958421 | L13: 8770935444 | M13: 9910301754 | N13: 6069253262 | O13: 8777694085 | P13: 12087549570 | Q13: 1186376818 | R13: 6915715579 | S13: 32588128920 | T13: 12428594028 | U13: 6297681218
... A26: Lãi/(lỗ) từ công ty liên doanh (từ năm 2015) | B26: -2100986885 | C26: -3473283371 | D26: -3706939471 | E26: -2210500486 | F26: 0 | G26: 0 | H26: -44596454899 | I26: 24351079187 | J26: 0 | K26: -734501277 | L26: -2544230352 | M26: 1177744744 | N26: 147877008 | O26: 2422520118 | P26: 3129774300 | Q26: 11121630774 | R26: 4176701355 | S26: 5922972758 | T26: 9011741928 | U26: 18649699157

Sheet cash_flow
A1: item | B1: 2018 | C1: 2019 | D1: 2020 | E1: 2021 | F1: 2022 | G1: 2023 | H1: 2024 | I1: 2025 | J1: 2018-Q1 | K1: 2018-Q2 | L1: 2018-Q3 | M1: 2018-Q4 | N1: 2024-Q3 | O1: 2024-Q4 | P1: 2025-Q1 | Q1: 2025-Q2 | R1: 2025-Q3 | S1: 2025-Q4 | T1: 2026-Q1 | U1: 2026-Q2
A2: Lợi nhuận/(lỗ) trước thuế | B2: 3786318568918 | C2: 5053447204696 | D2: 5409735407353 | E2: 6471583750543 | F2: 6056355373558 | G2: 689692367896 | H2: 4825763013078 | I2: 8633067583426 | J2: 1042985027628 | K2: 968242972018 | L2: 856152481258 | M2: 918938088015 | N2: 1068045400607 | O2: 1035471253998 | P2: 1934661387220 | Q2: 2028204755376 | R2: 2172351166079 | S2: 2497850274751 | T2: 3327584299891 | U2: 4032996498033
A3: Khấu hao TSCĐ và BĐSĐT | B3: 1222868683717 | C3: 1442826938954 | D3: 2195583071035 | E3: 2920713608410 | F3: 3540324726294 | G3: 3351314267883 | H3: 2913419081483 | I3: 1890882108632 | J3: 275195696006 | K3: 288375292601 | L3: 322218177564 | M3: 337080211991 | N3: 709538513762 | O3: 806163942588 | P3: 508919466750 | Q3: 489299387395 | R3: 459321401160 | S3: 433341853327 | T3: 393929975265 | U3: 360693855102
A4: Chi phí dự phòng | B4: 126083626828 | C4: 90495782206 | D4: 58366659386 | E4: 179550717177 | F4: -321799366884 | G4: -165930068132 | H4: 220952651591 | I4: 205754863290 | J4: 61484098224 | K4: 48212881818 | L4: 227862314 | M4: 16158784472 | N4: 80430663127 | O4: 66918985373 | P4: 11990839619 | Q4: 13861998805 | R4: 102781600012 | S4: 77120424854 | T4: 148321568633 | U4: -16391785057
A5: Lãi/lỗ chênh lệch tỷ giá hối đoái do đánh giá lại các khoản mục tiền tệ có gốc ngoại tệ | B5: -107059306 | C5: -27160364 | D5: -36874578 | E5: -146653994 | F5: 284374414 | G5: 83631272202 | H5: 25689580954 | I5: 48281410640 | J5: 3123787796 | K5: -296246332 | L5: -2851609274 | M5: -82991496 | N5: 20090137067 | O5: -141025314729 | P5: 10006964390 | Q5: 20285050148 | R5: 17804103606 | S5: 185292496 | T5: -1038495565 | U5: 839017483
A6: Lãi/(lỗ) từ thanh lý tài sản cố định | B6: 0 | C6: 0 | D6: 0 | E6: 0 | F6: 0 | G6: 0 | H6: 0 | I6: 0 | J6: 0 | K6: 0 | L6: 0 | M6: 0 | N6: 0 | O6: 0 | P6: 0 | Q6: 0 | R6: 0 | S6: 0 | T6: 0 | U6: 0
A7: (Lãi)/lỗ từ hoạt động đầu tư | B7: -84857279584 | C7: -341194613832 | D7: -557627148536 | E7: -959323580633 | F7: -348599792355 | G7: -1509203341265 | H7: -1729164103487 | I7: -2908766491708 | J7: -4400592798 | K7: -15137961548 | L7: -30111340870 | M7: -35207384368 | N7: -283114817875 | O7: -627238602343 | P7: -637707361482 | Q7: -721876708932 | R7: -763715309306 | S7: -785467111988 | T7: -803187924707 | U7: -902130463700
A8: Chi phí lãi vay | B8: 436416577674 | C8: 568136717134 | D8: 594003821021 | E8: 674427746189 | F8: 1362143909103 | G8: 1447718354797 | H8: 1137236129748 | I8: 1470675593604 | J8: 112795317948 | K8: 105346054241 | L8: 107492002949 | M8: 110783202536 | N8: 303696061820 | O8: 323470486929 | P8: 322792850500 | Q8: 375178482038 | R8: 388038374707 | S8: 384665886359 | T8: 415448904085 | U8: 436321054832
A9: Thu lãi và cổ tức | B9: 0 | C9: 0 | D9: 0 | E9: 0 | F9: 0 | G9: 0 | H9: 0 | I9: 0 | J9: 0 | K9: 0 | L9: 0 | M9: 0 | N9: 0 | O9: 0 | P9: 0 | Q9: 0 | R9: 0 | S9: 0 | T9: 0 | U9: 0
A10: Lợi nhuận/(lỗ) từ hoạt động kinh doanh trước những thay đổi vốn lưu động | B10: 5486723118247 | C10: 6813684868794 | D10: 7700024935681 | E10: 9286805587692 | F10: 10288709224130 | G10: 3897222853381 | H10: 7393896353367 | I10: 9339895067884 | J10: 1491183334804 | K10: 1394742992798 | L10: 1253127573941 | M10: 1347669911150 | N10: 1898685958508 | O10: 1463760751816 | P10: 2150664146997 | Q10: 2204952964830 | R10: 2376581336258 | S10: 2607696619799 | T10: 3481058327602 | U10: 3912328176693
A11: (Tăng)/giảm các khoản phải thu | B11: 1246646823981 | C11: -675979882201 | D11: 850493238036 | E11: -827596105467 | F11: -588827639446 | G11: 672440536688 | H11: 151205190961 | I11: -308618709954 | J11: 1156728740090 | K11: 378964388367 | L11: -24911405961 | M11: -281709747071 | N11: 325328320498 | O11: 38470643956 | P11: -20551258 | Q11: -251635229938 | R11: -83919351041 | S11: 26956422283 | T11: 168304248946 | U11: -13650520988769
A12: (Tăng)/giảm hàng tồn kho | B12: -4672944194460 | C12: -8374797030131 | D12: 6269571171519 | E12: -9923705315353 | F12: 3791937421033 | G12: 4169031757473 | H12: -636927914305 | I12: -5207942331422 | J12: -1586806999135 | K12: 99728382479 | L12: 967735176814 | M12: -4153600754618 | N12: -892284242431 | O12: -454321055722 | P12: -575792834900 | Q12: -888492280751 | R12: -512336774122 | S12: -3231320441649 | T12: -473294070349 | U12: -3249442441366
A13: Tăng/(giảm) các khoản phải trả | B13: 1331042865781 | C13: 2823942311184 | D13: -1894206905085 | E13: 3781614904801 | F13: -2286756979213 | G13: -3136706601092 | H13: 3581806724649 | I13: 5339106069277 | J13: -2691311201860 | K13: 614010121595 | L13: -77902747024 | M13: 3503821607071 | N13: 193484688240 | O13: -325910980822 | P13: 1748346307159 | Q13: 994923531151 | R13: 1930842466387 | S13: 664993764580 | T13: -776569297738 | U13: 16306823873210
... A42: (Tăng)/giảm chứng khoán kinh doanh | B42: 0 | C42: 0 | D42: 0 | E42: 0 | F42: 0 | G42: 0 | H42: 0 | I42: 0 | J42: 0 | K42: 0 | L42: 0 | M42: 0 | N42: 0 | O42: 0 | P42: 0 | Q42: 0 | R42: 0 | S42: 0 | T42: 0 | U42: 0

Sheet chi_so_tai_chinh
A1: Chỉ tiêu | B1: =balance_sheet!J1 | C1: =balance_sheet!K1 | D1: =balance_sheet!L1 | E1: =balance_sheet!M1 | F1: =balance_sheet!N1 | G1: =balance_sheet!O1 | H1: =balance_sheet!P1 | I1: =balance_sheet!Q1
A2: ROE (LNST CĐ Cty mẹ / VCSH bình quân) | B2: =IFERROR(B$53/((B$41+#REF!)/2),"n/a") | C2: =IFERROR(C$53/((C$41+B$41)/2),"n/a") | D2: =IFERROR(D$53/((D$41+C$41)/2),"n/a") | E2: =IFERROR(E$53/((E$41+D$41)/2),"n/a") | F2: =IFERROR(F$53/((F$41+E$41)/2),"n/a") | G2: =IFERROR(G$53/((G$41+F$41)/2),"n/a") | H2: =IFERROR(H$53/((H$41+G$41)/2),"n/a") | I2: =IFERROR(I$53/((I$41+H$41)/2),"n/a")
A3: ROA (LNST / Tổng tài sản bình quân) | B3: =IFERROR(B$52/((B$33+#REF!)/2),"n/a") | C3: =IFERROR(C$52/((C$33+B$33)/2),"n/a") | D3: =IFERROR(D$52/((D$33+C$33)/2),"n/a") | E3: =IFERROR(E$52/((E$33+D$33)/2),"n/a") | F3: =IFERROR(F$52/((F$33+E$33)/2),"n/a") | G3: =IFERROR(G$52/((G$33+F$33)/2),"n/a") | H3: =IFERROR(H$52/((H$33+G$33)/2),"n/a") | I3: =IFERROR(I$52/((I$33+H$33)/2),"n/a")
A4: Tăng trưởng LN Cổ đông Cty mẹ QQ | B4: =IFERROR((B$53-#REF!)/ABS(#REF!),"n/a") | C4: =IFERROR((C$53-B$53)/ABS(B$53),"n/a") | D4: =IFERROR((D$53-C$53)/ABS(C$53),"n/a") | E4: =IFERROR((E$53-D$53)/ABS(D$53),"n/a") | F4: =IFERROR((F$53-E$53)/ABS(E$53),"n/a") | G4: =IFERROR((G$53-F$53)/ABS(F$53),"n/a") | H4: =IFERROR((H$53-G$53)/ABS(G$53),"n/a") | I4: =IFERROR((I$53-H$53)/ABS(H$53),"n/a")
A5: Tăng trưởng LN Cổ đông Cty mẹ YY | F5: =IFERROR((F$53-B$53)/ABS(B$53),"n/a") | G5: =IFERROR((G$53-C$53)/ABS(C$53),"n/a") | H5: =IFERROR((H$53-D$53)/ABS(D$53),"n/a") | I5: =IFERROR((I$53-E$53)/ABS(E$53),"n/a")
A6: Tăng trưởng Doanh thu thuần QQ | B6: =IFERROR((B$45-#REF!)/ABS(#REF!),"n/a") | C6: =IFERROR((C$45-B$45)/ABS(B$45),"n/a") | D6: =IFERROR((D$45-C$45)/ABS(C$45),"n/a") | E6: =IFERROR((E$45-D$45)/ABS(D$45),"n/a") | F6: =IFERROR((F$45-E$45)/ABS(E$45),"n/a") | G6: =IFERROR((G$45-F$45)/ABS(F$45),"n/a") | H6: =IFERROR((H$45-G$45)/ABS(G$45),"n/a") | I6: =IFERROR((I$45-H$45)/ABS(H$45),"n/a")
A7: Tăng trưởng Doanh thu thuần YY | F7: =IFERROR((F$45-B$45)/ABS(B$45),"n/a") | G7: =IFERROR((G$45-C$45)/ABS(C$45),"n/a") | H7: =IFERROR((H$45-D$45)/ABS(D$45),"n/a") | I7: =IFERROR((I$45-E$45)/ABS(E$45),"n/a")
A8: Biên lợi nhuận gộp | B8: =IFERROR(B$47/B$45,"n/a") | C8: =IFERROR(C$47/C$45,"n/a") | D8: =IFERROR(D$47/D$45,"n/a") | E8: =IFERROR(E$47/E$45,"n/a") | F8: =IFERROR(F$47/F$45,"n/a") | G8: =IFERROR(G$47/G$45,"n/a") | H8: =IFERROR(H$47/H$45,"n/a") | I8: =IFERROR(I$47/I$45,"n/a")
A9: Biên lợi nhuận ròng | B9: =IFERROR(B$53/B$45,"n/a") | C9: =IFERROR(C$53/C$45,"n/a") | D9: =IFERROR(D$53/D$45,"n/a") | E9: =IFERROR(E$53/E$45,"n/a") | F9: =IFERROR(F$53/F$45,"n/a") | G9: =IFERROR(G$53/G$45,"n/a") | H9: =IFERROR(H$53/H$45,"n/a") | I9: =IFERROR(I$53/I$45,"n/a")
A10: D/E (Nợ vay / Vốn chủ sở hữu) | B10: =IFERROR((B$36+B$38)/B$41,"n/a") | C10: =IFERROR((C$36+C$38)/C$41,"n/a") | D10: =IFERROR((D$36+D$38)/D$41,"n/a") | E10: =IFERROR((E$36+E$38)/E$41,"n/a") | F10: =IFERROR((F$36+F$38)/F$41,"n/a") | G10: =IFERROR((G$36+G$38)/G$41,"n/a") | H10: =IFERROR((H$36+H$38)/H$41,"n/a") | I10: =IFERROR((I$36+I$38)/I$41,"n/a")
A11: - Nợ vay dài hạn/Vốn chủ sở hữu | B11: =IFERROR(B$38/B$41,"n/a") | C11: =IFERROR(C$38/C$41,"n/a") | D11: =IFERROR(D$38/D$41,"n/a") | E11: =IFERROR(E$38/E$41,"n/a") | F11: =IFERROR(F$38/F$41,"n/a") | G11: =IFERROR(G$38/G$41,"n/a") | H11: =IFERROR(H$38/H$41,"n/a") | I11: =IFERROR(I$38/I$41,"n/a")
A12: - Nợ vay ngắn hạn/Vốn chủ sở hữu | B12: =IFERROR(B$36/B$41,"n/a") | C12: =IFERROR(C$36/C$41,"n/a") | D12: =IFERROR(D$36/D$41,"n/a") | E12: =IFERROR(E$36/E$41,"n/a") | F12: =IFERROR(F$36/F$41,"n/a") | G12: =IFERROR(G$36/G$41,"n/a") | H12: =IFERROR(H$36/H$41,"n/a") | I12: =IFERROR(I$36/I$41,"n/a")
A13: Nợ phải trả/Vốn chủ sở hữu | B13: =IFERROR(B$40/B$41,"n/a") | C13: =IFERROR(C$40/C$41,"n/a") | D13: =IFERROR(D$40/D$41,"n/a") | E13: =IFERROR(E$40/E$41,"n/a") | F13: =IFERROR(F$40/F$41,"n/a") | G13: =IFERROR(G$40/G$41,"n/a") | H13: =IFERROR(H$40/H$41,"n/a") | I13: =IFERROR(I$40/I$41,"n/a")
A14: - Nợ dài hạn/Vốn chủ sở hữu | B14: =IFERROR(B$39/B$41,"n/a") | C14: =IFERROR(C$39/C$41,"n/a") | D14: =IFERROR(D$39/D$41,"n/a") | E14: =IFERROR(E$39/E$41,"n/a") | F14: =IFERROR(F$39/F$41,"n/a") | G14: =IFERROR(G$39/G$41,"n/a") | H14: =IFERROR(H$39/H$41,"n/a") | I14: =IFERROR(I$39/I$41,"n/a")
A15: - Nợ ngắn hạn/Vốn chủ sở hữu | B15: =IFERROR(B$37/B$41,"n/a") | C15: =IFERROR(C$37/C$41,"n/a") | D15: =IFERROR(D$37/D$41,"n/a") | E15: =IFERROR(E$37/E$41,"n/a") | F15: =IFERROR(F$37/F$41,"n/a") | G15: =IFERROR(G$37/G$41,"n/a") | H15: =IFERROR(H$37/H$41,"n/a") | I15: =IFERROR(I$37/I$41,"n/a")
A16: Chi phí bán hàng, quản lý/LN gộp | B16: =IFERROR((ABS(B$48)+ABS(B$49))/B$47,"n/a") | C16: =IFERROR((ABS(C$48)+ABS(C$49))/C$47,"n/a") | D16: =IFERROR((ABS(D$48)+ABS(D$49))/D$47,"n/a") | E16: =IFERROR((ABS(E$48)+ABS(E$49))/E$47,"n/a") | F16: =IFERROR((ABS(F$48)+ABS(F$49))/F$47,"n/a") | G16: =IFERROR((ABS(G$48)+ABS(G$49))/G$47,"n/a") | H16: =IFERROR((ABS(H$48)+ABS(H$49))/H$47,"n/a") | I16: =IFERROR((ABS(I$48)+ABS(I$49))/I$47,"n/a")
A17: Chi phí lãi vay/LN từ hoạt động kinh doanh | B17: =IFERROR(ABS(B$51)/B$50,"n/a") | C17: =IFERROR(ABS(C$51)/C$50,"n/a") | D17: =IFERROR(ABS(D$51)/D$50,"n/a") | E17: =IFERROR(ABS(E$51)/E$50,"n/a") | F17: =IFERROR(ABS(F$51)/F$50,"n/a") | G17: =IFERROR(ABS(G$51)/G$50,"n/a") | H17: =IFERROR(ABS(H$51)/H$50,"n/a") | I17: =IFERROR(ABS(I$51)/I$50,"n/a")
A18: Số ngày phải trả (DPO) | B18: =IFERROR(((B$35+#REF!)/2)/ABS(B$46)*365,"n/a") | C18: =IFERROR(((C$35+B$35)/2)/ABS(C$46)*365,"n/a") | D18: =IFERROR(((D$35+C$35)/2)/ABS(D$46)*365,"n/a") | E18: =IFERROR(((E$35+D$35)/2)/ABS(E$46)*365,"n/a") | F18: =IFERROR(((F$35+E$35)/2)/ABS(F$46)*365,"n/a") | G18: =IFERROR(((G$35+F$35)/2)/ABS(G$46)*365,"n/a") | H18: =IFERROR(((H$35+G$35)/2)/ABS(H$46)*365,"n/a") | I18: =IFERROR(((I$35+H$35)/2)/ABS(I$46)*365,"n/a")
A19: Số ngày phải thu (DSO) | B19: =IFERROR(((B$29+#REF!)/2)/B$45*365,"n/a") | C19: =IFERROR(((C$29+B$29)/2)/C$45*365,"n/a") | D19: =IFERROR(((D$29+C$29)/2)/D$45*365,"n/a") | E19: =IFERROR(((E$29+D$29)/2)/E$45*365,"n/a") | F19: =IFERROR(((F$29+E$29)/2)/F$45*365,"n/a") | G19: =IFERROR(((G$29+F$29)/2)/G$45*365,"n/a") | H19: =IFERROR(((H$29+G$29)/2)/H$45*365,"n/a") | I19: =IFERROR(((I$29+H$29)/2)/I$45*365,"n/a")
A20: Số ngày tồn kho (DIO) | B20: =IFERROR(((B$30+#REF!)/2)/ABS(B$46)*365,"n/a") | C20: =IFERROR(((C$30+B$30)/2)/ABS(C$46)*365,"n/a") | D20: =IFERROR(((D$30+C$30)/2)/ABS(D$46)*365,"n/a") | E20: =IFERROR(((E$30+D$30)/2)/ABS(E$46)*365,"n/a") | F20: =IFERROR(((F$30+E$30)/2)/ABS(F$46)*365,"n/a") | G20: =IFERROR(((G$30+F$30)/2)/ABS(G$46)*365,"n/a") | H20: =IFERROR(((H$30+G$30)/2)/ABS(H$46)*365,"n/a") | I20: =IFERROR(((I$30+H$30)/2)/ABS(I$46)*365,"n/a")
A21: Tiền và tương đương tiền/Tài sản | B21: =IFERROR(B$28/B$33,"n/a") | C21: =IFERROR(C$28/C$33,"n/a") | D21: =IFERROR(D$28/D$33,"n/a") | E21: =IFERROR(E$28/E$33,"n/a") | F21: =IFERROR(F$28/F$33,"n/a") | G21: =IFERROR(G$28/G$33,"n/a") | H21: =IFERROR(H$28/H$33,"n/a") | I21: =IFERROR(I$28/I$33,"n/a")
A22: Hàng tồn kho/Tài sản | B22: =IFERROR(B$30/B$33,"n/a") | C22: =IFERROR(C$30/C$33,"n/a") | D22: =IFERROR(D$30/D$33,"n/a") | E22: =IFERROR(E$30/E$33,"n/a") | F22: =IFERROR(F$30/F$33,"n/a") | G22: =IFERROR(G$30/G$33,"n/a") | H22: =IFERROR(H$30/H$33,"n/a") | I22: =IFERROR(I$30/I$33,"n/a")
A24: II. DỮ LIỆU TRÍCH XUẤT (tự động dò theo tên khoản mục)
A25: Khoản mục | B25: =balance_sheet!J1 | C25: =balance_sheet!K1 | D25: =balance_sheet!L1 | E25: =balance_sheet!M1 | F25: =balance_sheet!N1 | G25: =balance_sheet!O1 | H25: =balance_sheet!P1 | I25: =balance_sheet!Q1
A26: CĐKT
A27: Tài sản
A28: Tiền và tương đương tiền | B28: =IFERROR(INDEX(balance_sheet!$B:$XFD,MATCH("Tiền và tương đương tiền",balance_sheet!$A:$A,0),MATCH(B$25,balance_sheet!$B$1:$XFD$1,0)),"") | C28: =IFERROR(INDEX(balance_sheet!$B:$XFD,MATCH("Tiền và tương đương tiền",balance_sheet!$A:$A,0),MATCH(C$25,balance_sheet!$B$1:$XFD$1,0)),"") | D28: =IFERROR(INDEX(balance_sheet!$B:$XFD,MATCH("Tiền và tương đương tiền",balance_sheet!$A:$A,0),MATCH(D$25,balance_sheet!$B$1:$XFD$1,0)),"") | E28: =IFERROR(INDEX(balance_sheet!$B:$XFD,MATCH("Tiền và tương đương tiền",balance_sheet!$A:$A,0),MATCH(E$25,balance_sheet!$B$1:$XFD$1,0)),"") | F28: =IFERROR(INDEX(balance_sheet!$B:$XFD,MATCH("Tiền và tương đương tiền",balance_sheet!$A:$A,0),MATCH(F$25,balance_sheet!$B$1:$XFD$1,0)),"") | G28: =IFERROR(INDEX(balance_sheet!$B:$XFD,MATCH("Tiền và tương đương tiền",balance_sheet!$A:$A,0),MATCH(G$25,balance_sheet!$B$1:$XFD$1,0)),"") | H28: =IFERROR(INDEX(balance_sheet!$B:$XFD,MATCH("Tiền và tương đương tiền",balance_sheet!$A:$A,0),MATCH(H$25,balance_sheet!$B$1:$XFD$1,0)),"") | I28: =IFERROR(INDEX(balance_sheet!$B:$XFD,MATCH("Tiền và tương đương tiền",balance_sheet!$A:$A,0),MATCH(I$25,balance_sheet!$B$1:$XFD$1,0)),"")
A29: Phải thu khách hàng | B29: =IFERROR(INDEX(balance_sheet!$B:$XFD,MATCH("Phải thu khách hàng",balance_sheet!$A:$A,0),MATCH(B$25,balance_sheet!$B$1:$XFD$1,0)),"") | C29: =IFERROR(INDEX(balance_sheet!$B:$XFD,MATCH("Phải thu khách hàng",balance_sheet!$A:$A,0),MATCH(C$25,balance_sheet!$B$1:$XFD$1,0)),"") | D29: =IFERROR(INDEX(balance_sheet!$B:$XFD,MATCH("Phải thu khách hàng",balance_sheet!$A:$A,0),MATCH(D$25,balance_sheet!$B$1:$XFD$1,0)),"") | E29: =IFERROR(INDEX(balance_sheet!$B:$XFD,MATCH("Phải thu khách hàng",balance_sheet!$A:$A,0),MATCH(E$25,balance_sheet!$B$1:$XFD$1,0)),"") | F29: =IFERROR(INDEX(balance_sheet!$B:$XFD,MATCH("Phải thu khách hàng",balance_sheet!$A:$A,0),MATCH(F$25,balance_sheet!$B$1:$XFD$1,0)),"") | G29: =IFERROR(INDEX(balance_sheet!$B:$XFD,MATCH("Phải thu khách hàng",balance_sheet!$A:$A,0),MATCH(G$25,balance_sheet!$B$1:$XFD$1,0)),"") | H29: =IFERROR(INDEX(balance_sheet!$B:$XFD,MATCH("Phải thu khách hàng",balance_sheet!$A:$A,0),MATCH(H$25,balance_sheet!$B$1:$XFD$1,0)),"") | I29: =IFERROR(INDEX(balance_sheet!$B:$XFD,MATCH("Phải thu khách hàng",balance_sheet!$A:$A,0),MATCH(I$25,balance_sheet!$B$1:$XFD$1,0)),"")
A30: Hàng tồn kho, ròng | B30: =IFERROR(INDEX(balance_sheet!$B:$XFD,MATCH("Hàng tồn kho, ròng",balance_sheet!$A:$A,0),MATCH(B$25,balance_sheet!$B$1:$XFD$1,0)),"") | C30: =IFERROR(INDEX(balance_sheet!$B:$XFD,MATCH("Hàng tồn kho, ròng",balance_sheet!$A:$A,0),MATCH(C$25,balance_sheet!$B$1:$XFD$1,0)),"") | D30: =IFERROR(INDEX(balance_sheet!$B:$XFD,MATCH("Hàng tồn kho, ròng",balance_sheet!$A:$A,0),MATCH(D$25,balance_sheet!$B$1:$XFD$1,0)),"") | E30: =IFERROR(INDEX(balance_sheet!$B:$XFD,MATCH("Hàng tồn kho, ròng",balance_sheet!$A:$A,0),MATCH(E$25,balance_sheet!$B$1:$XFD$1,0)),"") | F30: =IFERROR(INDEX(balance_sheet!$B:$XFD,MATCH("Hàng tồn kho, ròng",balance_sheet!$A:$A,0),MATCH(F$25,balance_sheet!$B$1:$XFD$1,0)),"") | G30: =IFERROR(INDEX(balance_sheet!$B:$XFD,MATCH("Hàng tồn kho, ròng",balance_sheet!$A:$A,0),MATCH(G$25,balance_sheet!$B$1:$XFD$1,0)),"") | H30: =IFERROR(INDEX(balance_sheet!$B:$XFD,MATCH("Hàng tồn kho, ròng",balance_sheet!$A:$A,0),MATCH(H$25,balance_sheet!$B$1:$XFD$1,0)),"") | I30: =IFERROR(INDEX(balance_sheet!$B:$XFD,MATCH("Hàng tồn kho, ròng",balance_sheet!$A:$A,0),MATCH(I$25,balance_sheet!$B$1:$XFD$1,0)),"")
A31: TÀI SẢN NGẮN HẠN | B31: =IFERROR(INDEX(balance_sheet!$B:$XFD,MATCH("TÀI SẢN NGẮN HẠN",balance_sheet!$A:$A,0),MATCH(B$25,balance_sheet!$B$1:$XFD$1,0)),"") | C31: =IFERROR(INDEX(balance_sheet!$B:$XFD,MATCH("TÀI SẢN NGẮN HẠN",balance_sheet!$A:$A,0),MATCH(C$25,balance_sheet!$B$1:$XFD$1,0)),"") | D31: =IFERROR(INDEX(balance_sheet!$B:$XFD,MATCH("TÀI SẢN NGẮN HẠN",balance_sheet!$A:$A,0),MATCH(D$25,balance_sheet!$B$1:$XFD$1,0)),"") | E31: =IFERROR(INDEX(balance_sheet!$B:$XFD,MATCH("TÀI SẢN NGẮN HẠN",balance_sheet!$A:$A,0),MATCH(E$25,balance_sheet!$B$1:$XFD$1,0)),"") | F31: =IFERROR(INDEX(balance_sheet!$B:$XFD,MATCH("TÀI SẢN NGẮN HẠN",balance_sheet!$A:$A,0),MATCH(F$25,balance_sheet!$B$1:$XFD$1,0)),"") | G31: =IFERROR(INDEX(balance_sheet!$B:$XFD,MATCH("TÀI SẢN NGẮN HẠN",balance_sheet!$A:$A,0),MATCH(G$25,balance_sheet!$B$1:$XFD$1,0)),"") | H31: =IFERROR(INDEX(balance_sheet!$B:$XFD,MATCH("TÀI SẢN NGẮN HẠN",balance_sheet!$A:$A,0),MATCH(H$25,balance_sheet!$B$1:$XFD$1,0)),"") | I31: =IFERROR(INDEX(balance_sheet!$B:$XFD,MATCH("TÀI SẢN NGẮN HẠN",balance_sheet!$A:$A,0),MATCH(I$25,balance_sheet!$B$1:$XFD$1,0)),"")
A32: GTCL tài sản cố định vô hình | B32: =IFERROR(INDEX(balance_sheet!$B:$XFD,MATCH("GTCL tài sản cố định vô hình",balance_sheet!$A:$A,0),MATCH(B$25,balance_sheet!$B$1:$XFD$1,0)),"") | C32: =IFERROR(INDEX(balance_sheet!$B:$XFD,MATCH("GTCL tài sản cố định vô hình",balance_sheet!$A:$A,0),MATCH(C$25,balance_sheet!$B$1:$XFD$1,0)),"") | D32: =IFERROR(INDEX(balance_sheet!$B:$XFD,MATCH("GTCL tài sản cố định vô hình",balance_sheet!$A:$A,0),MATCH(D$25,balance_sheet!$B$1:$XFD$1,0)),"") | E32: =IFERROR(INDEX(balance_sheet!$B:$XFD,MATCH("GTCL tài sản cố định vô hình",balance_sheet!$A:$A,0),MATCH(E$25,balance_sheet!$B$1:$XFD$1,0)),"") | F32: =IFERROR(INDEX(balance_sheet!$B:$XFD,MATCH("GTCL tài sản cố định vô hình",balance_sheet!$A:$A,0),MATCH(F$25,balance_sheet!$B$1:$XFD$1,0)),"") | G32: =IFERROR(INDEX(balance_sheet!$B:$XFD,MATCH("GTCL tài sản cố định vô hình",balance_sheet!$A:$A,0),MATCH(G$25,balance_sheet!$B$1:$XFD$1,0)),"") | H32: =IFERROR(INDEX(balance_sheet!$B:$XFD,MATCH("GTCL tài sản cố định vô hình",balance_sheet!$A:$A,0),MATCH(H$25,balance_sheet!$B$1:$XFD$1,0)),"") | I32: =IFERROR(INDEX(balance_sheet!$B:$XFD,MATCH("GTCL tài sản cố định vô hình",balance_sheet!$A:$A,0),MATCH(I$25,balance_sheet!$B$1:$XFD$1,0)),"")
A33: TỔNG CỘNG TÀI SẢN | B33: =IFERROR(INDEX(balance_sheet!$B:$XFD,MATCH("TỔNG CỘNG TÀI SẢN",balance_sheet!$A:$A,0),MATCH(B$25,balance_sheet!$B$1:$XFD$1,0)),"") | C33: =IFERROR(INDEX(balance_sheet!$B:$XFD,MATCH("TỔNG CỘNG TÀI SẢN",balance_sheet!$A:$A,0),MATCH(C$25,balance_sheet!$B$1:$XFD$1,0)),"") | D33: =IFERROR(INDEX(balance_sheet!$B:$XFD,MATCH("TỔNG CỘNG TÀI SẢN",balance_sheet!$A:$A,0),MATCH(D$25,balance_sheet!$B$1:$XFD$1,0)),"") | E33: =IFERROR(INDEX(balance_sheet!$B:$XFD,MATCH("TỔNG CỘNG TÀI SẢN",balance_sheet!$A:$A,0),MATCH(E$25,balance_sheet!$B$1:$XFD$1,0)),"") | F33: =IFERROR(INDEX(balance_sheet!$B:$XFD,MATCH("TỔNG CỘNG TÀI SẢN",balance_sheet!$A:$A,0),MATCH(F$25,balance_sheet!$B$1:$XFD$1,0)),"") | G33: =IFERROR(INDEX(balance_sheet!$B:$XFD,MATCH("TỔNG CỘNG TÀI SẢN",balance_sheet!$A:$A,0),MATCH(G$25,balance_sheet!$B$1:$XFD$1,0)),"") | H33: =IFERROR(INDEX(balance_sheet!$B:$XFD,MATCH("TỔNG CỘNG TÀI SẢN",balance_sheet!$A:$A,0),MATCH(H$25,balance_sheet!$B$1:$XFD$1,0)),"") | I33: =IFERROR(INDEX(balance_sheet!$B:$XFD,MATCH("TỔNG CỘNG TÀI SẢN",balance_sheet!$A:$A,0),MATCH(I$25,balance_sheet!$B$1:$XFD$1,0)),"")
A34: Nguồn vốn
A35: Phải trả người bán | B35: =IFERROR(INDEX(balance_sheet!$B:$XFD,MATCH("Phải trả người bán",balance_sheet!$A:$A,0),MATCH(B$25,balance_sheet!$B$1:$XFD$1,0)),"") | C35: =IFERROR(INDEX(balance_sheet!$B:$XFD,MATCH("Phải trả người bán",balance_sheet!$A:$A,0),MATCH(C$25,balance_sheet!$B$1:$XFD$1,0)),"") | D35: =IFERROR(INDEX(balance_sheet!$B:$XFD,MATCH("Phải trả người bán",balance_sheet!$A:$A,0),MATCH(D$25,balance_sheet!$B$1:$XFD$1,0)),"") | E35: =IFERROR(INDEX(balance_sheet!$B:$XFD,MATCH("Phải trả người bán",balance_sheet!$A:$A,0),MATCH(E$25,balance_sheet!$B$1:$XFD$1,0)),"") | F35: =IFERROR(INDEX(balance_sheet!$B:$XFD,MATCH("Phải trả người bán",balance_sheet!$A:$A,0),MATCH(F$25,balance_sheet!$B$1:$XFD$1,0)),"") | G35: =IFERROR(INDEX(balance_sheet!$B:$XFD,MATCH("Phải trả người bán",balance_sheet!$A:$A,0),MATCH(G$25,balance_sheet!$B$1:$XFD$1,0)),"") | H35: =IFERROR(INDEX(balance_sheet!$B:$XFD,MATCH("Phải trả người bán",balance_sheet!$A:$A,0),MATCH(H$25,balance_sheet!$B$1:$XFD$1,0)),"") | I35: =IFERROR(INDEX(balance_sheet!$B:$XFD,MATCH("Phải trả người bán",balance_sheet!$A:$A,0),MATCH(I$25,balance_sheet!$B$1:$XFD$1,0)),"")
A36: Vay ngắn hạn | B36: =IFERROR(INDEX(balance_sheet!$B:$XFD,MATCH("Vay ngắn hạn",balance_sheet!$A:$A,0),MATCH(B$25,balance_sheet!$B$1:$XFD$1,0)),"") | C36: =IFERROR(INDEX(balance_sheet!$B:$XFD,MATCH("Vay ngắn hạn",balance_sheet!$A:$A,0),MATCH(C$25,balance_sheet!$B$1:$XFD$1,0)),"") | D36: =IFERROR(INDEX(balance_sheet!$B:$XFD,MATCH("Vay ngắn hạn",balance_sheet!$A:$A,0),MATCH(D$25,balance_sheet!$B$1:$XFD$1,0)),"") | E36: =IFERROR(INDEX(balance_sheet!$B:$XFD,MATCH("Vay ngắn hạn",balance_sheet!$A:$A,0),MATCH(E$25,balance_sheet!$B$1:$XFD$1,0)),"") | F36: =IFERROR(INDEX(balance_sheet!$B:$XFD,MATCH("Vay ngắn hạn",balance_sheet!$A:$A,0),MATCH(F$25,balance_sheet!$B$1:$XFD$1,0)),"") | G36: =IFERROR(INDEX(balance_sheet!$B:$XFD,MATCH("Vay ngắn hạn",balance_sheet!$A:$A,0),MATCH(G$25,balance_sheet!$B$1:$XFD$1,0)),"") | H36: =IFERROR(INDEX(balance_sheet!$B:$XFD,MATCH("Vay ngắn hạn",balance_sheet!$A:$A,0),MATCH(H$25,balance_sheet!$B$1:$XFD$1,0)),"") | I36: =IFERROR(INDEX(balance_sheet!$B:$XFD,MATCH("Vay ngắn hạn",balance_sheet!$A:$A,0),MATCH(I$25,balance_sheet!$B$1:$XFD$1,0)),"")
A37: Nợ ngắn hạn | B37: =IFERROR(INDEX(balance_sheet!$B:$XFD,MATCH("Nợ ngắn hạn",balance_sheet!$A:$A,0),MATCH(B$25,balance_sheet!$B$1:$XFD$1,0)),"") | C37: =IFERROR(INDEX(balance_sheet!$B:$XFD,MATCH("Nợ ngắn hạn",balance_sheet!$A:$A,0),MATCH(C$25,balance_sheet!$B$1:$XFD$1,0)),"") | D37: =IFERROR(INDEX(balance_sheet!$B:$XFD,MATCH("Nợ ngắn hạn",balance_sheet!$A:$A,0),MATCH(D$25,balance_sheet!$B$1:$XFD$1,0)),"") | E37: =IFERROR(INDEX(balance_sheet!$B:$XFD,MATCH("Nợ ngắn hạn",balance_sheet!$A:$A,0),MATCH(E$25,balance_sheet!$B$1:$XFD$1,0)),"") | F37: =IFERROR(INDEX(balance_sheet!$B:$XFD,MATCH("Nợ ngắn hạn",balance_sheet!$A:$A,0),MATCH(F$25,balance_sheet!$B$1:$XFD$1,0)),"") | G37: =IFERROR(INDEX(balance_sheet!$B:$XFD,MATCH("Nợ ngắn hạn",balance_sheet!$A:$A,0),MATCH(G$25,balance_sheet!$B$1:$XFD$1,0)),"") | H37: =IFERROR(INDEX(balance_sheet!$B:$XFD,MATCH("Nợ ngắn hạn",balance_sheet!$A:$A,0),MATCH(H$25,balance_sheet!$B$1:$XFD$1,0)),"") | I37: =IFERROR(INDEX(balance_sheet!$B:$XFD,MATCH("Nợ ngắn hạn",balance_sheet!$A:$A,0),MATCH(I$25,balance_sheet!$B$1:$XFD$1,0)),"")
A38: Vay dài hạn | B38: =IFERROR(INDEX(balance_sheet!$B:$XFD,MATCH("Vay dài hạn",balance_sheet!$A:$A,0),MATCH(B$25,balance_sheet!$B$1:$XFD$1,0)),"") | C38: =IFERROR(INDEX(balance_sheet!$B:$XFD,MATCH("Vay dài hạn",balance_sheet!$A:$A,0),MATCH(C$25,balance_sheet!$B$1:$XFD$1,0)),"") | D38: =IFERROR(INDEX(balance_sheet!$B:$XFD,MATCH("Vay dài hạn",balance_sheet!$A:$A,0),MATCH(D$25,balance_sheet!$B$1:$XFD$1,0)),"") | E38: =IFERROR(INDEX(balance_sheet!$B:$XFD,MATCH("Vay dài hạn",balance_sheet!$A:$A,0),MATCH(E$25,balance_sheet!$B$1:$XFD$1,0)),"") | F38: =IFERROR(INDEX(balance_sheet!$B:$XFD,MATCH("Vay dài hạn",balance_sheet!$A:$A,0),MATCH(F$25,balance_sheet!$B$1:$XFD$1,0)),"") | G38: =IFERROR(INDEX(balance_sheet!$B:$XFD,MATCH("Vay dài hạn",balance_sheet!$A:$A,0),MATCH(G$25,balance_sheet!$B$1:$XFD$1,0)),"") | H38: =IFERROR(INDEX(balance_sheet!$B:$XFD,MATCH("Vay dài hạn",balance_sheet!$A:$A,0),MATCH(H$25,balance_sheet!$B$1:$XFD$1,0)),"") | I38: =IFERROR(INDEX(balance_sheet!$B:$XFD,MATCH("Vay dài hạn",balance_sheet!$A:$A,0),MATCH(I$25,balance_sheet!$B$1:$XFD$1,0)),"")
A39: Nợ dài hạn | B39: =IFERROR(INDEX(balance_sheet!$B:$XFD,MATCH("Nợ dài hạn",balance_sheet!$A:$A,0),MATCH(B$25,balance_sheet!$B$1:$XFD$1,0)),"") | C39: =IFERROR(INDEX(balance_sheet!$B:$XFD,MATCH("Nợ dài hạn",balance_sheet!$A:$A,0),MATCH(C$25,balance_sheet!$B$1:$XFD$1,0)),"") | D39: =IFERROR(INDEX(balance_sheet!$B:$XFD,MATCH("Nợ dài hạn",balance_sheet!$A:$A,0),MATCH(D$25,balance_sheet!$B$1:$XFD$1,0)),"") | E39: =IFERROR(INDEX(balance_sheet!$B:$XFD,MATCH("Nợ dài hạn",balance_sheet!$A:$A,0),MATCH(E$25,balance_sheet!$B$1:$XFD$1,0)),"") | F39: =IFERROR(INDEX(balance_sheet!$B:$XFD,MATCH("Nợ dài hạn",balance_sheet!$A:$A,0),MATCH(F$25,balance_sheet!$B$1:$XFD$1,0)),"") | G39: =IFERROR(INDEX(balance_sheet!$B:$XFD,MATCH("Nợ dài hạn",balance_sheet!$A:$A,0),MATCH(G$25,balance_sheet!$B$1:$XFD$1,0)),"") | H39: =IFERROR(INDEX(balance_sheet!$B:$XFD,MATCH("Nợ dài hạn",balance_sheet!$A:$A,0),MATCH(H$25,balance_sheet!$B$1:$XFD$1,0)),"") | I39: =IFERROR(INDEX(balance_sheet!$B:$XFD,MATCH("Nợ dài hạn",balance_sheet!$A:$A,0),MATCH(I$25,balance_sheet!$B$1:$XFD$1,0)),"")
A40: NỢ PHẢI TRẢ | B40: =IFERROR(INDEX(balance_sheet!$B:$XFD,MATCH("NỢ PHẢI TRẢ",balance_sheet!$A:$A,0),MATCH(B$25,balance_sheet!$B$1:$XFD$1,0)),"") | C40: =IFERROR(INDEX(balance_sheet!$B:$XFD,MATCH("NỢ PHẢI TRẢ",balance_sheet!$A:$A,0),MATCH(C$25,balance_sheet!$B$1:$XFD$1,0)),"") | D40: =IFERROR(INDEX(balance_sheet!$B:$XFD,MATCH("NỢ PHẢI TRẢ",balance_sheet!$A:$A,0),MATCH(D$25,balance_sheet!$B$1:$XFD$1,0)),"") | E40: =IFERROR(INDEX(balance_sheet!$B:$XFD,MATCH("NỢ PHẢI TRẢ",balance_sheet!$A:$A,0),MATCH(E$25,balance_sheet!$B$1:$XFD$1,0)),"") | F40: =IFERROR(INDEX(balance_sheet!$B:$XFD,MATCH("NỢ PHẢI TRẢ",balance_sheet!$A:$A,0),MATCH(F$25,balance_sheet!$B$1:$XFD$1,0)),"") | G40: =IFERROR(INDEX(balance_sheet!$B:$XFD,MATCH("NỢ PHẢI TRẢ",balance_sheet!$A:$A,0),MATCH(G$25,balance_sheet!$B$1:$XFD$1,0)),"") | H40: =IFERROR(INDEX(balance_sheet!$B:$XFD,MATCH("NỢ PHẢI TRẢ",balance_sheet!$A:$A,0),MATCH(H$25,balance_sheet!$B$1:$XFD$1,0)),"") | I40: =IFERROR(INDEX(balance_sheet!$B:$XFD,MATCH("NỢ PHẢI TRẢ",balance_sheet!$A:$A,0),MATCH(I$25,balance_sheet!$B$1:$XFD$1,0)),"")
A41: Vốn chủ sở hữu | B41: =IFERROR(INDEX(balance_sheet!$B:$XFD,MATCH("Vốn chủ sở hữu",balance_sheet!$A:$A,0),MATCH(B$25,balance_sheet!$B$1:$XFD$1,0)),"") | C41: =IFERROR(INDEX(balance_sheet!$B:$XFD,MATCH("Vốn chủ sở hữu",balance_sheet!$A:$A,0),MATCH(C$25,balance_sheet!$B$1:$XFD$1,0)),"") | D41: =IFERROR(INDEX(balance_sheet!$B:$XFD,MATCH("Vốn chủ sở hữu",balance_sheet!$A:$A,0),MATCH(D$25,balance_sheet!$B$1:$XFD$1,0)),"") | E41: =IFERROR(INDEX(balance_sheet!$B:$XFD,MATCH("Vốn chủ sở hữu",balance_sheet!$A:$A,0),MATCH(E$25,balance_sheet!$B$1:$XFD$1,0)),"") | F41: =IFERROR(INDEX(balance_sheet!$B:$XFD,MATCH("Vốn chủ sở hữu",balance_sheet!$A:$A,0),MATCH(F$25,balance_sheet!$B$1:$XFD$1,0)),"") | G41: =IFERROR(INDEX(balance_sheet!$B:$XFD,MATCH("Vốn chủ sở hữu",balance_sheet!$A:$A,0),MATCH(G$25,balance_sheet!$B$1:$XFD$1,0)),"") | H41: =IFERROR(INDEX(balance_sheet!$B:$XFD,MATCH("Vốn chủ sở hữu",balance_sheet!$A:$A,0),MATCH(H$25,balance_sheet!$B$1:$XFD$1,0)),"") | I41: =IFERROR(INDEX(balance_sheet!$B:$XFD,MATCH("Vốn chủ sở hữu",balance_sheet!$A:$A,0),MATCH(I$25,balance_sheet!$B$1:$XFD$1,0)),"")
...
