Workbook

Sheet balance_sheet
A1: item | B1: 2018-Q1 | C1: 2018-Q2 | D1: 2018-Q3 | E1: 2018-Q4 | F1: 2024-Q3 | G1: 2024-Q4 | H1: 2025-Q1 | I1: 2025-Q2 | J1: 2025-Q3 | K1: 2025-Q4 | L1: 2026-Q1 | M1: 2026-Q2
A2: TÀI SẢN NGẮN HẠN | B2: 3105829275580 | C2: 3238036134159 | D2: 3717638543591 | E2: 4301904075538 | F2: 46537938169842 | G2: 49394749963613 | H2: 52968968277078 | I2: 61740702018288 | J2: 78382769920190 | K2: 76612765855403 | L2: 85027423981731 | M2: 97180152540672
A3: Tiền và tương đương tiền | B3: 478702782868 | C3: 1207244147840 | D3: 778882643315 | E3: 905429385691 | F3: 3265767728843 | G3: 2864601041636 | H3: 2310027768246 | I3: 2997602183062 | J3: 5291517936798 | K3: 3108078221717 | L3: 5493172934162 | M3: 6154505245964
A4: Tiền | B4: 478702782868 | C4: 907244147840 | D4: 778882643315 | E4: 905429385691 | F4: 3265767728843 | G4: 2864601041636 | H4: 2273027768246 | I4: 2910602183062 | J4: 5130517936798 | K4: 3108078221717 | L4: 5326172934162 | M4: 6154505245964
A5: Các khoản tương đương tiền | B5: 0 | C5: 300000000000 | D5: 0 | E5: 0 | F5: 0 | G5: 0 | H5: 37000000000 | I5: 87000000000 | J5: 161000000000 | K5: 0 | L5: 167000000000 | M5: 0
A6: Các tài sản tài chính ghi nhận thông qua lãi lỗ (FVTPL) | B6: 0 | C6: 0 | D6: 0 | E6: 0 | F6: 0 | G6: 17278163500 | H6: 33872594500 | I6: 51182161900 | J6: 38832202200 | K6: 38923020900 | L6: 55937732900 | M6: 295964797150
A7: Dự phòng suy giảm giá trị tài sản tài chính và tài sản thế chấp | B7: 0 | C7: 0 | D7: 0 | E7: 0 | F7: -9727352788 | G7: -10806072274 | H7: -11506571201 | I7: -12345953462 | J7: -11866416736 | K7: -12757948678 | L7: -11783320309 | M7: -10253768528
A8: Tổng các khoản phải thu | B8: 63851022629 | C8: 98881050080 | D8: 75931321237 | E8: 112392910182 | F8: 2203073674403 | G8: 656597329458 | H8: 996008362522 | I8: 874079299667 | J8: 787897805756 | K8: 727456098295 | L8: 1011891732598 | M8: 2958224791790
A9: Phải thu khách hàng (Trước năm 2016) | B9: 0 | C9: 0 | D9: 0 | E9: 0 | F9: 0 | G9: 0 | H9: 0 | I9: 0 | J9: 0 | K9: 0 | L9: 0 | M9: 0
A10: Trả trước người bán | B10: 933517735 | C10: 2954771613 | D10: 12413614766 | E10: 777927372 | F10: 8701139638 | G10: 1949853033 | H10: 3435219019 | I10: 6902531025 | J10: 3596683895 | K10: 5729878954 | L10: 11052033343 | M10: 6790687225
A11: Phải thu nội bộ | B11: 0 | C11: 0 | D11: 0 | E11: 0 | F11: 0 | G11: 0 | H11: 0 | I11: 0 | J11: 0 | K11: 0 | L11: 0 | M11: 0
A12: Phải thu về XDCB (Trước năm 2016) | B12: 0 | C12: 0 | D12: 0 | E12: 0 | F12: 0 | G12: 0 | H12: 0 | I12: 0 | J12: 0 | K12: 0 | L12: 0 | M12: 0
A13: Phải thu khác | B13: 120084360 | C13: 418422238 | D13: 1329833 | E13: 4844100000 | F13: 1558793428622 | G13: 22076558945 | H13: 286954331576 | I13: 244187804555 | J13: 210474055456 | K13: 2271195630 | L13: 5519758032 | M13: 13292610728
... A21: Thuế và các khoản khác phải thu Nhà nước | B21: 0 | C21: 0 | D21: 0 | E21: 0 | F21: 0 | G21: 0 | H21: 0 | I21: 0 | J21: 0 | K21: 0 | L21: 0 | M21: 0
A22: Tài sản ngắn hạn khác
A23: TÀI SẢN DÀI HẠN | B23: 17789368432 | C23: 42171933041 | D23: 43002163354 | E23: 49147334360 | F23: 3330054972010 | G23: 3849383856581 | H23: 3360594808902 | I23: 3393485968453 | J23: 3390212189913 | K23: 4019491143606 | L23: 3637467753045 | M23: 3411907280610
A24: Phải thu dài hạn | B24: 0 | C24: 0 | D24: 0 | E24: 0 | F24: 0 | G24: 0 | H24: 0 | I24: 0 | J24: 0 | K24: 0 | L24: 0 | M24: 0
A25: Phải thu khách hàng dài hạn | B25: 0 | C25: 0 | D25: 0 | E25: 0 | F25: 0 | G25: 0 | H25: 0 | I25: 0 | J25: 0 | K25: 0 | L25: 0 | M25: 0
A26: Phải thu nội bộ dài hạn (Trước năm 2016) | B26: 0 | C26: 0 | D26: 0 | E26: 0 | F26: 0 | G26: 0 | H26: 0 | I26: 0 | J26: 0 | K26: 0 | L26: 0 | M26: 0
A27: Phải thu dài hạn khác (Trước năm 2016) | B27: 0 | C27: 0 | D27: 0 | E27: 0 | F27: 0 | G27: 0 | H27: 0 | I27: 0 | J27: 0 | K27: 0 | L27: 0 | M27: 0
A28: Dự phòng phải thu dài hạn (Trước năm 2016) | B28: 0 | C28: 0 | D28: 0 | E28: 0 | F28: 0 | G28: 0 | H28: 0 | I28: 0 | J28: 0 | K28: 0 | L28: 0 | M28: 0
A29: Tài sản cố định | B29: 6885610501 | C29: 6528739692 | D29: 5846348327 | E29: 37111999508 | F29: 47000960029 | G29: 50740739690 | H29: 50059922585 | I29: 67889896187 | J29: 65675916039 | K29: 107181206706 | L29: 99261590948 | M29: 103445113819
A30: GTCL TSCĐ hữu hình | B30: 2058427709 | C30: 1906079678 | D30: 1753731647 | E30: 23568693328 | F30: 36875524953 | G30: 39993555777 | H30: 40602366921 | I30: 36928419675 | J30: 37233603012 | K30: 33220423249 | L30: 29637344161 | M30: 33373987097
A31: Nguyên giá TSCĐ hữu hình | B31: 5345839388 | C31: 5345839388 | D31: 5345839388 | E31: 27624998111 | F31: 110167904200 | G31: 117475687200 | H31: 121971999900 | I31: 122197849900 | J31: 126511586020 | K31: 126797126020 | L31: 126797126020 | M31: 134206292060
A32: Khấu hao lũy kế TSCĐ hữu hình | B32: -3287411679 | C32: -3439759710 | D32: -3592107741 | E32: -4056304783 | F32: -73292379247 | G32: -77482131423 | H32: -81369632979 | I32: -85269430225 | J32: -89277983008 | K32: -93576702771 | L32: -97159781859 | M32: -100832304963
A33: GTCL Tài sản thuê tài chính | B33: 0 | C33: 0 | D33: 0 | E33: 0 | F33: 0 | G33: 0 | H33: 0 | I33: 0 | J33: 0 | K33: 0 | L33: 0 | M33: 0
A34: Nguyên giá tài sản thuê tài chính | B34: 0 | C34: 0 | D34: 0 | E34: 0 | F34: 0 | G34: 0 | H34: 0 | I34: 0 | J34: 0 | K34: 0 | L34: 0 | M34: 0
... A91: TỔNG CỘNG NGUỒN VỐN | B91: 3123618644012 | C91: 3280208067200 | D91: 3760640706945 | E91: 4351051409898 | F91: 49867993141852 | G91: 53244133820194 | H91: 56329563085980 | I91: 65134187986741 | J91: 81772982110103 | K91: 80632256999009 | L91: 88664891734776 | M91: 100592059821282
A92: Cổ phiếu ưu đãi
A93: Các khoản đầu tư nắm giữ đến ngày đáo hạn (HTM) | B93: 209840307126 | C93: 109840307126 | D93: 109840307126 | E93: 500000000000 | F93: 2031105785348 | G93: 2232105785348 | H93: 2854426333293 | I93: 2800679117067 | J93: 3451358569122 | K93: 3657418739619 | L93: 1405918739619 | M93: 1588198577180
A94: Phải thu về hoạt động giao dịch chứng khoán (Trước năm 2016) | B94: 0 | C94: 0 | D94: 0 | E94: 0 | F94: 0 | G94: 0 | H94: 0 | I94: 0 | J94: 0 | K94: 0 | L94: 0 | M94: 0
A95: Vốn kinh doanh ở các đơn vị trực thuộc (Trước năm 2016) | B95: 0 | C95: 0 | D95: 0 | E95: 0 | F95: 0 | G95: 0 | H95: 0 | I95: 0 | J95: 0 | K95: 0 | L95: 0 | M95: 0
A96: Phải trả hoạt động giao dịch chứng khoán | B96: 1352668955 | C96: 142450960958 | D96: 0 | E96: 4935967989 | F96: 82795997063 | G96: 30358344178 | H96: 45950131687 | I96: 71989880958 | J96: 1383113176263 | K96: 51121802352 | L96: 63272414917 | M96: 134533283705
A97: Phải trả cổ tức, gốc và lãi trái phiếu (Trước năm 2016) | B97: 0 | C97: 0 | D97: 0 | E97: 0 | F97: 0 | G97: 0 | H97: 0 | I97: 0 | J97: 0 | K97: 0 | L97: 0 | M97: 0
A98: Phải trả tổ chức phát hành chứng khoán (Trước năm 2016) | B98: 0 | C98: 0 | D98: 0 | E98: 0 | F98: 0 | G98: 0 | H98: 0 | I98: 0 | J98: 0 | K98: 0 | L98: 0 | M98: 0
A99: Quỹ bảo vệ Nhà đầu tư | B99: 0 | C99: 0 | D99: 0 | E99: 47200000 | F99: 30553500 | G99: 30553500 | H99: 30553500 | I99: 30553500 | J99: 30553500 | K99: 30553500 | L99: 30553500 | M99: 30553500
A100: Tài sản thiếu chờ xử lý (Trước năm 2016) | B100: 0 | C100: 0 | D100: 0 | E100: 0 | F100: 0 | G100: 0 | H100: 0 | I100: 0 | J100: 0 | K100: 0 | L100: 0 | M100: 0
A101: Phải thu về cho vay ngắn hạn (Trước năm 2016) | B101: 0 | C101: 0 | D101: 0 | E101: 0 | F101: 0 | G101: 0 | H101: 0 | I101: 0 | J101: 0 | K101: 0 | L101: 0 | M101: 0
A102: Giao dịch mua bán lại trái phiếu chính phủ | B102: 0 | C102: 0 | D102: 0 | E102: 0 | F102: 0 | G102: 0 | H102: 0 | I102: 0 | J102: 0 | K102: 0 | L102: 0 | M102: 0
A103: Trả trước người bán dài hạn (Trước năm 2016) | B103: 0 | C103: 0 | D103: 0 | E103: 0 | F103: 0 | G103: 0 | H103: 0 | I103: 0 | J103: 0 | K103: 0 | L103: 0 | M103: 0
...

Sheet income_statement
A1: item | B1: 2018-Q1 | C1: 2018-Q2 | D1: 2018-Q3 | E1: 2018-Q4 | F1: 2024-Q3 | G1: 2024-Q4 | H1: 2025-Q1 | I1: 2025-Q2 | J1: 2025-Q3 | K1: 2025-Q4 | L1: 2026-Q1 | M1: 2026-Q2
A2: DOANH THU HOẠT ĐỘNG | B2: 183979907085 | C2: 196095954109 | D2: 591012271327 | E2: 899082911755 | F2: 1844805107025 | G2: 1843230736579 | H2: 2028164685825 | I2: 2659998744458 | J2: 3164274146538 | K2: 3364988937829 | L2: 2783203426368 | M2: 3744618689735
A3: Các khoản giảm trừ doanh thu | B3: 0 | C3: 0 | D3: 0 | E3: 0 | F3: 0 | G3: 0 | H3: 0 | I3: 0 | J3: 0 | K3: 0 | L3: 0 | M3: 0
A4: Doanh thu thuần về hoạt động kinh doanh | B4: 183979907085 | C4: 196095954109 | D4: 591012271327 | E4: 899082911755 | F4: 1844805107025 | G4: 1843230736579 | H4: 2028164685825 | I4: 2659998744458 | J4: 3164274146538 | K4: 3364988937829 | L4: 2783203426368 | M4: 3744618689735
A5: CHI PHÍ HOẠT ĐỘNG | B5: -45918786469 | C5: -39279894530 | D5: -19134519228 | E5: -28147877069 | F5: -140001708018 | G5: -251453839072 | H5: -127056494784 | I5: -219102604818 | J5: -403418061247 | K5: -463977528886 | L5: -432669955217 | M5: -494598914337
A6: LỢI NHUẬN GỘP | B6: 138061120616 | C6: 156816059579 | D6: 571877752099 | E6: 870935034686 | F6: 1704803399007 | G6: 1591776897507 | H6: 1901108191041 | I6: 2440896139640 | J6: 2760856085291 | K6: 2901011408943 | L6: 2350533471151 | M6: 3250019775398
A7: CHI PHÍ QUẢN LÝ CÔNG TY CHỨNG KHOÁN | B7: -35930659945 | C7: -47912732838 | D7: -42471628725 | E7: -44442663101 | F7: -136461459136 | G7: -190531149547 | H7: -137726487123 | I7: -147960661005 | J7: -170652269576 | K7: -202636046006 | L7: -161180842697 | M7: -140103237495
A8: KẾT QUẢ HOẠT ĐỘNG | B8: 94761145261 | C8: 101633467224 | D8: 521763473804 | E8: 815691208722 | F8: 1096495486270 | G8: 932813189265 | H8: 1310685315274 | I8: 1733125373166 | J8: 2023925521519 | K8: 2041387739975 | L8: 1458655329949 | M8: 2096645870954
A9: CHI PHÍ THUẾ THU NHẬP DOANH NGHIỆP | B9: 94585551102 | C9: 100160288490 | D9: 521758473804 | E9: 819222503944 | F9: 1097052077972 | G9: 932794977555 | H9: 1309844216298 | I9: 1733101500233 | J9: 2024406838686 | K9: 2041348186392 | L9: 1458425492628 | M9: 2096955197698
A10: Chi phí thuế thu nhập hiện hành | B10: -20503832658 | C10: -19071172762 | D10: -102764972323 | E10: -164016979768 | F10: -218319529056 | G10: -191336745520 | H10: -298212624523 | I10: -311831947363 | J10: -404977243039 | K10: -407835810486 | L10: -311488840262 | M10: -409747556919
A11: Chi phí thuế thu nhập hoãn lại | B11: 0 | C11: 0 | D11: 0 | E11: 0 | F11: -1090886538 | G11: 4777750010 | H11: -980698254 | I11: -1195722986 | J11: 95806942 | K11: -433646792 | L11: 696777126 | M11: 4685963689
A12: LỢI NHUẬN KẾ TOÁN SAU THUẾ | B12: 74081718444 | C12: 81089115728 | D12: 418993501481 | E12: 655205524176 | F12: 877641662378 | G12: 746235982045 | H12: 1010650893521 | I12: 1420073829884 | J12: 1619525402589 | K12: 1633078729114 | L12: 1147633429492 | M12: 1691893604468
A13: Lợi nhuận thuần phân bổ cho lợi ích của cổ đông không kiểm soát | B13: 0 | C13: 0 | D13: 0 | E13: 0 | F13: 0 | G13: 0 | H13: 0 | I13: 0 | J13: 0 | K13: 0 | L13: 0 | M13: 0
... A80: THU NHẬP (LỖ) TOÀN DIỆN KHÁC SAU THUẾ | B80: 0 | C80: 0 | D80: 0 | E80: 0 | F80: 68204994067 | G80: -38412600007 | H80: -12925053029 | I80: -28251217798 | J80: 65429803590 | K80: -11816909692 | L80: -12093836311 | M80: -1489140611

Sheet cash_flow
A1: item | B1: 2018-Q1 | C1: 2018-Q2 | D1: 2018-Q3 | E1: 2018-Q4 | F1: 2024-Q3 | G1: 2024-Q4 | H1: 2025-Q1 | I1: 2025-Q2 | J1: 2025-Q3 | K1: 2025-Q4 | L1: 2026-Q1 | M1: 2026-Q2
A2: LỢI NHUẬN TRƯỚC THUẾ | B2: 94585551102 | C2: 100160288490 | D2: 518217725295 | E2: 819222503944 | F2: 1097052077972 | G2: 932794977555 | H2: 1309844216298 | I2: 1733101500233 | J2: 2024406838686 | K2: 2041351186392 | L2: 1458425492628 | M2: 2096955197698
A3: Khấu hao tài sản cố định | B3: 984844420 | C3: 908120809 | D3: 682391365 | E3: 1269971542 | F3: 5613191511 | G3: 5743274339 | H3: 5177129805 | I3: 5850112621 | J3: 6527716268 | K3: 7318877349 | L3: 7919615758 | M3: 7875394766
A4: Các khoản dự phòng | B4: 0 | C4: 0 | D4: 0 | E4: 0 | F4: 2697643051 | G4: -631280514 | H4: 716998927 | I4: -700498927 | J4: 16500000 | K4: -6600000 | L4: 0 | M4: 0
A5: Lãi, lỗ chênh lệch tỷ giá hối đoái chưa thực hiện | B5: 0 | C5: 0 | D5: 0 | E5: 0 | F5: 0 | G5: 0 | H5: 0 | I5: 0 | J5: 0 | K5: 0 | L5: 0 | M5: 0
A6: Lãi, lỗ hoạt động đầu tư | B6: -6452601242 | C6: 6452601242 | D6: -179453024519 | E6: 179453024519 | F6: 0 | G6: 0 | H6: 0 | I6: 0 | J6: 0 | K6: 0 | L6: 0 | M6: 0
A7: Chi phí lãi vay | B7: 7797705524 | C7: 7626654631 | D7: 7916424520 | E7: 11456449670 | F7: 454532798330 | G7: 416133486235 | H7: 402089293017 | I7: 497334006930 | J7: 536214064771 | K7: 619374013780 | L7: 688724696403 | M7: 888967633276
A8: Dự thu lãi và cổ tức | B8: -8196307117 | C8: 3237486491 | D8: -2971611922 | E8: -19932729096 | F8: -22641118223 | G8: -81370495655 | H8: -472346382145 | I8: -106356410802 | J8: 51840614844 | K8: -159789185881 | L8: -646129761926 | M8: -393244396659
A9: Lợi nhuận từ hoạt động kinh doanh trước thay đổi vốn lưu động | B9: -338334362638 | C9: 685613597889 | D9: -347530998622 | E9: -710076868446 | F9: 2313492907820 | G9: -3131141523946 | H9: -4482890413341 | I9: -8496074642332 | J9: -13263997284885 | K9: -2822108061606 | L9: -6872671353632 | M9: -11536382348883
A10: (-) Tăng, (+) giảm các khoản phải thu khác | B10: 132130137040 | C10: -298337878 | D10: -300189967844 | E10: 295764290082 | F10: -1503891251796 | G10: 1543468156282 | H10: -266433544858 | I10: 39294256699 | J10: 37094960786 | K10: 206069664767 | L10: -8570716791 | M10: -3511506578
A11: Tăng/giảm hàng tồn kho (Trước năm 2016) | B11: 0 | C11: 0 | D11: 0 | E11: 0 | F11: 0 | G11: 0 | H11: 0 | I11: 0 | J11: 0 | K11: 0 | L11: 0 | M11: 0
A12: (+) Tăng, (-) giảm các khoản phải trả, phải nộp khác | B12: 14454280719 | C12: 135816784996 | D12: -97012707557 | E12: 76758579837 | F12: 1645816470460 | G12: 806871788374 | H12: 114150383285 | I12: -1965691353 | J12: 1409067278680 | K12: -1435683465105 | L12: 19009008228 | M12: 344396056120
A13: Tăng/giảm chi phí trả trước | B13: 0 | C13: -3160760381 | D13: 10700658903 | E13: -9900956165 | F13: -17051800466 | G13: 14330031888 | H13: -30854847211 | I13: 33957808035 | J13: 16415989355 | K13: 11701598623 | L13: -64459467595 | M13: -29128720345
... A49: Tiền mặt, tiền gửi ngân hàng kỳ | B49: 478702782868 | C49: 907244147840 | D49: 778882643315 | E49: 905429385691 | F49: 3265767728843 | G49: 2864601041636 | H49: 2273027768246 | I49: 2910602183062 | J49: 5130517936798 | K49: 3108078221717 | L49: 5326172934162 | M49: 6154505245964
A50: Tiền gửi ngân hàng cho hoạt động CTCK
A51: Các khoản tương đương tiền
A52: Ảnh hưởng của thay đổi tỷ giá hối đoái quy đổi ngoại tệ
A53: Tiền thu bán chứng khoán môi giới cho khách hàng | B53: 5920075218205 | C53: 10730133094415 | D53: 8058525941120 | E53: 14108622864872 | F53: 112520012185222 | G53: 91526868176106 | H53: 48299768588252 | I53: 188068900792582 | J53: 260780853291467 | K53: 240896925667002 | L53: 229667292803035 | M53: 195679101327756
A54: Tiền chi mua chứng khoán môi giới cho khách hàng | B54: -7375428674833 | C54: -11415928171739 | D54: -4649976888638 | E54: -11356745400644 | F54: -118237820347227 | G54: -129630632144442 | H54: -56329482442643 | I54: -227319267322220 | J54: -303429003111004 | K54: -256895363008217 | L54: -258298866169193 | M54: -246221730680806
A55: Tiền thu bán chứng khoán ủy thác của khách hàng | B55: 0 | C55: 0 | D55: 0 | E55: 0 | F55: 0 | G55: 0 | H55: 0 | I55: 0 | J55: 0 | K55: 0 | L55: 0 | M55: 0
A56: Tiền chi bán chứng khoán ủy thác của khách hàng | B56: -4838583912085 | C56: 4838583912085 | D56: 0 | E56: 0 | F56: 0 | G56: 0 | H56: 0 | I56: 0 | J56: 0 | K56: 0 | L56: 0 | M56: 0
A57: Thu tiền từ tài khoản vãng lai của khách hàng (Trước năm 2016) | B57: 0 | C57: 18557656657265 | D57: -18557656657265 | E57: 0 | F57: 0 | G57: 0 | H57: 0 | I57: 0 | J57: 0 | K57: 0 | L57: 0 | M57: 0
A58: Chi tiền từ tài khoản vãng lai của khách hàng (Trước năm 2016) | B58: 0 | C58: -16205300244857 | D58: -11182826049295 | E58: 27388126294152 | F58: 0 | G58: 0 | H58: 0 | I58: 0 | J58: 0 | K58: 0 | L58: 0 | M58: 0
A59: Thu vay Quỹ Hỗ trợ thanh toán | B59: 0 | C59: 0 | D59: 0 | E59: 0 | F59: 0 | G59: 0 | H59: 0 | I59: 0 | J59: 0 | K59: 0 | L59: 0 | M59: 0
A60: Chi trả vay Quỹ Hỗ trợ thanh toán | B60: 0 | C60: 0 | D60: 0 | E60: 0 | F60: 0 | G60: 0 | H60: 0 | I60: 0 | J60: 0 | K60: 0 | L60: 0 | M60: 0
A61: Nhận tiền gửi để thanh toán giao dịch chứng khoán của khách hàng | B61: 6680123610987 | C61: -6680123610987 | D61: 26414706271253 | E61: 18091765815448 | F61: 146035202953049 | G61: 195446462572917 | H61: 75360296265900 | I61: 311228333521497 | J61: 435057092242924 | K61: 376587178344379 | L61: 369409013782727 | M61: 358514676963077
A62: Nhận tiền gửi của Nhà đầu tư cho hoạt động ủy thác đầu tư của khách hàng | B62: 0 | C62: 0 | D62: 0 | E62: 0 | F62: 0 | G62: 43719133278 | H62: 45659051710 | I62: -45659051710 | J62: 0 | K62: 25613581008 | L62: 6364832859 | M62: -6364832859
A63: Chi trả phí lưu ký chứng khoán của khách hàng | B63: -2353507581 | C63: -2814124647 | D63: -2503925778 | E63: -1790969569 | F63: -11486555148 | G63: -11163468261 | H63: -3794194904 | I63: -24862673382 | J63: -14420621869 | K63: -17739189976 | L63: -18078497044 | M63: -19586607345
A64: Thu lỗi giao dịch chứng khoán | B64: 0 | C64: 0 | D64: 0 | E64: 0 | F64: 0 | G64: 0 | H64: 0 | I64: 0 | J64: 0 | K64: 0 | L64: 0 | M64: 0
... A75: Tiền gửi của tổ chức phát hành | B75: 552559701554 | C75: 8931676653 | D75: 208361969906 | E75: 938077574583 | F75: 4293695969 | G75: 44613698630 | H75: 35009400 | I75: 0 | J75: 0 | K75: 49373986618 | L75: 0 | M75: 0
A76: Trong đó: có kỳ hạn
A77: Tiền gửi của NĐT về GDCK theo phương thức NHTM quản lý (Trước năm 2016) | B77: 0 | C77: 0 | D77: 0 | E77: 0 | F77: 0 | G77: 0 | H77: 0 | I77: 0 | J77: 0 | K77: 0 | L77: 0 | M77: 0
A78: Trong đó: có kỳ hạn (Trước năm 2016) | B78: 0 | C78: 0 | D78: 0 | E78: 0 | F78: 0 | G78: 0 | H78: 0 | I78: 0 | J78: 0 | K78: 0 | L78: 0 | M78: 0
A79: Các khoản tương đương tiền
A80: Ảnh hưởng của thay đổi tỷ giá hối đoái quy đổi ngoại tệ
A81: TIỀN VÀ CÁC KHOẢN TƯƠNG ĐƯƠNG TIỀN CUỐI KỲ CỦA KHÁCH HÀNG | B81: 1186694102469 | C81: 465273589103 | D81: 744960510633 | E81: 1334969895448 | F81: 8006921852278 | G81: 10024246349048 | H81: 14833545581986 | I81: 11849786662404 | J81: 12762472660272 | K81: 10702593296252 | L81: 10360816794093 | M81: 9046562592920
A82: Tiền gửi ngân hàng cuối kỳ | B82: 1186694102469 | C82: 465273589103 | D82: 744960510633 | E82: 1334969895448 | F82: 8006921852278 | G82: 10024246349048 | H82: 14833545581986 | I82: 11849786662404 | J82: 12762472660272 | K82: 10702593296252 | L82: 10360816794093 | M82: 9046562592920
A83: Tiền gửi của NĐT về GDCK theo phương thức CTCK quản lý
A84: Trong đó: có kỳ hạn
A85: Tiền gửi của NĐT về GDCK theo phương thức NHTM quản lý (Trước năm 2016)
...

Sheet chi_so_tai_chinh
A1: Chỉ tiêu | B1: =balance_sheet!B1 | C1: =balance_sheet!C1 | D1: =balance_sheet!D1 | E1: =balance_sheet!E1 | F1: =balance_sheet!F1 | G1: =balance_sheet!G1 | H1: =balance_sheet!H1 | I1: =balance_sheet!I1
A2: ROE | B2: =IFERROR(B$48/((B$36+#REF!)/2),"n/a") | C2: =IFERROR(C$48/((C$36+B$36)/2),"n/a") | D2: =IFERROR(D$48/((D$36+C$36)/2),"n/a") | E2: =IFERROR(E$48/((E$36+D$36)/2),"n/a") | F2: =IFERROR(F$48/((F$36+E$36)/2),"n/a") | G2: =IFERROR(G$48/((G$36+F$36)/2),"n/a") | H2: =IFERROR(H$48/((H$36+G$36)/2),"n/a") | I2: =IFERROR(I$48/((I$36+H$36)/2),"n/a")
A3: ROA | B3: =IFERROR(B$47/((B$28+#REF!)/2),"n/a") | C3: =IFERROR(C$47/((C$28+B$28)/2),"n/a") | D3: =IFERROR(D$47/((D$28+C$28)/2),"n/a") | E3: =IFERROR(E$47/((E$28+D$28)/2),"n/a") | F3: =IFERROR(F$47/((F$28+E$28)/2),"n/a") | G3: =IFERROR(G$47/((G$28+F$28)/2),"n/a") | H3: =IFERROR(H$47/((H$28+G$28)/2),"n/a") | I3: =IFERROR(I$47/((I$28+H$28)/2),"n/a")
A4: Tăng trưởng LN Cổ đông Cty mẹ QQ | B4: =IFERROR((B$48-#REF!)/ABS(#REF!),"n/a") | C4: =IFERROR((C$48-B$48)/ABS(B$48),"n/a") | D4: =IFERROR((D$48-C$48)/ABS(C$48),"n/a") | E4: =IFERROR((E$48-D$48)/ABS(D$48),"n/a") | F4: =IFERROR((F$48-E$48)/ABS(E$48),"n/a") | G4: =IFERROR((G$48-F$48)/ABS(F$48),"n/a") | H4: =IFERROR((H$48-G$48)/ABS(G$48),"n/a") | I4: =IFERROR((I$48-H$48)/ABS(H$48),"n/a")
A5: Tăng trưởng LN Cổ đông Cty mẹ YY | F5: =IFERROR((F$48-B$48)/ABS(B$48),"n/a") | G5: =IFERROR((G$48-C$48)/ABS(C$48),"n/a") | H5: =IFERROR((H$48-D$48)/ABS(D$48),"n/a") | I5: =IFERROR((I$48-E$48)/ABS(E$48),"n/a")
A6: Tăng trưởng Doanh thu thuần QQ | B6: =IFERROR((B$40-#REF!)/ABS(#REF!),"n/a") | C6: =IFERROR((C$40-B$40)/ABS(B$40),"n/a") | D6: =IFERROR((D$40-C$40)/ABS(C$40),"n/a") | E6: =IFERROR((E$40-D$40)/ABS(D$40),"n/a") | F6: =IFERROR((F$40-E$40)/ABS(E$40),"n/a") | G6: =IFERROR((G$40-F$40)/ABS(F$40),"n/a") | H6: =IFERROR((H$40-G$40)/ABS(G$40),"n/a") | I6: =IFERROR((I$40-H$40)/ABS(H$40),"n/a")
A7: Tăng trưởng Doanh thu thuần YY | F7: =IFERROR((F$40-B$40)/ABS(B$40),"n/a") | G7: =IFERROR((G$40-C$40)/ABS(C$40),"n/a") | H7: =IFERROR((H$40-D$40)/ABS(D$40),"n/a") | I7: =IFERROR((I$40-E$40)/ABS(E$40),"n/a")
A8: Biên lợi nhuận gộp | B8: =IFERROR(B$42/B$40,"n/a") | C8: =IFERROR(C$42/C$40,"n/a") | D8: =IFERROR(D$42/D$40,"n/a") | E8: =IFERROR(E$42/E$40,"n/a") | F8: =IFERROR(F$42/F$40,"n/a") | G8: =IFERROR(G$42/G$40,"n/a") | H8: =IFERROR(H$42/H$40,"n/a") | I8: =IFERROR(I$42/I$40,"n/a")
A9: Biên lợi nhuận ròng | B9: =IFERROR(B$47/B$40,"n/a") | C9: =IFERROR(C$47/C$40,"n/a") | D9: =IFERROR(D$47/D$40,"n/a") | E9: =IFERROR(E$47/E$40,"n/a") | F9: =IFERROR(F$47/F$40,"n/a") | G9: =IFERROR(G$47/G$40,"n/a") | H9: =IFERROR(H$47/H$40,"n/a") | I9: =IFERROR(I$47/I$40,"n/a")
A10: D/E (Nợ vay / Vốn chủ sở hữu) | B10: =IFERROR((B$31+B$33)/B$36,"n/a") | C10: =IFERROR((C$31+C$33)/C$36,"n/a") | D10: =IFERROR((D$31+D$33)/D$36,"n/a") | E10: =IFERROR((E$31+E$33)/E$36,"n/a") | F10: =IFERROR((F$31+F$33)/F$36,"n/a") | G10: =IFERROR((G$31+G$33)/G$36,"n/a") | H10: =IFERROR((H$31+H$33)/H$36,"n/a") | I10: =IFERROR((I$31+I$33)/I$36,"n/a")
A11: - Nợ vay dài hạn/Vốn chủ sở hữu | B11: =IFERROR(B$33/B$36,"n/a") | C11: =IFERROR(C$33/C$36,"n/a") | D11: =IFERROR(D$33/D$36,"n/a") | E11: =IFERROR(E$33/E$36,"n/a") | F11: =IFERROR(F$33/F$36,"n/a") | G11: =IFERROR(G$33/G$36,"n/a") | H11: =IFERROR(H$33/H$36,"n/a") | I11: =IFERROR(I$33/I$36,"n/a")
A12: - Nợ vay ngắn hạn/Vốn chủ sở hữu | B12: =IFERROR(B$31/B$36,"n/a") | C12: =IFERROR(C$31/C$36,"n/a") | D12: =IFERROR(D$31/D$36,"n/a") | E12: =IFERROR(E$31/E$36,"n/a") | F12: =IFERROR(F$31/F$36,"n/a") | G12: =IFERROR(G$31/G$36,"n/a") | H12: =IFERROR(H$31/H$36,"n/a") | I12: =IFERROR(I$31/I$36,"n/a")
A13: Nợ phải trả/Vốn chủ sở hữu | B13: =IFERROR(B$35/B$36,"n/a") | C13: =IFERROR(C$35/C$36,"n/a") | D13: =IFERROR(D$35/D$36,"n/a") | E13: =IFERROR(E$35/E$36,"n/a") | F13: =IFERROR(F$35/F$36,"n/a") | G13: =IFERROR(G$35/G$36,"n/a") | H13: =IFERROR(H$35/H$36,"n/a") | I13: =IFERROR(I$35/I$36,"n/a")
A14: - Nợ dài hạn/Vốn chủ sở hữu | B14: =IFERROR(B$34/B$36,"n/a") | C14: =IFERROR(C$34/C$36,"n/a") | D14: =IFERROR(D$34/D$36,"n/a") | E14: =IFERROR(E$34/E$36,"n/a") | F14: =IFERROR(F$34/F$36,"n/a") | G14: =IFERROR(G$34/G$36,"n/a") | H14: =IFERROR(H$34/H$36,"n/a") | I14: =IFERROR(I$34/I$36,"n/a")
A15: - Nợ ngắn hạn/Vốn chủ sở hữu | B15: =IFERROR(B$32/B$36,"n/a") | C15: =IFERROR(C$32/C$36,"n/a") | D15: =IFERROR(D$32/D$36,"n/a") | E15: =IFERROR(E$32/E$36,"n/a") | F15: =IFERROR(F$32/F$36,"n/a") | G15: =IFERROR(G$32/G$36,"n/a") | H15: =IFERROR(H$32/H$36,"n/a") | I15: =IFERROR(I$32/I$36,"n/a")
A16: Chi phí bán hàng, quản lý/LN gộp | B16: =IFERROR((ABS(B$43)+ABS(B$44))/B$42,"n/a") | C16: =IFERROR((ABS(C$43)+ABS(C$44))/C$42,"n/a") | D16: =IFERROR((ABS(D$43)+ABS(D$44))/D$42,"n/a") | E16: =IFERROR((ABS(E$43)+ABS(E$44))/E$42,"n/a") | F16: =IFERROR((ABS(F$43)+ABS(F$44))/F$42,"n/a") | G16: =IFERROR((ABS(G$43)+ABS(G$44))/G$42,"n/a") | H16: =IFERROR((ABS(H$43)+ABS(H$44))/H$42,"n/a") | I16: =IFERROR((ABS(I$43)+ABS(I$44))/I$42,"n/a")
A17: Chi phí lãi vay/LN từ hoạt động kinh doanh | B17: =IFERROR(ABS(B$46)/B$45,"n/a") | C17: =IFERROR(ABS(C$46)/C$45,"n/a") | D17: =IFERROR(ABS(D$46)/D$45,"n/a") | E17: =IFERROR(ABS(E$46)/E$45,"n/a") | F17: =IFERROR(ABS(F$46)/F$45,"n/a") | G17: =IFERROR(ABS(G$46)/G$45,"n/a") | H17: =IFERROR(ABS(H$46)/H$45,"n/a") | I17: =IFERROR(ABS(I$46)/I$45,"n/a")
A18: Số ngày phải trả (DPO) | B18: =IFERROR(((B$30+#REF!)/2)/ABS(B$41)*365,"n/a") | C18: =IFERROR(((C$30+B$30)/2)/ABS(C$41)*365,"n/a") | D18: =IFERROR(((D$30+C$30)/2)/ABS(D$41)*365,"n/a") | E18: =IFERROR(((E$30+D$30)/2)/ABS(E$41)*365,"n/a") | F18: =IFERROR(((F$30+E$30)/2)/ABS(F$41)*365,"n/a") | G18: =IFERROR(((G$30+F$30)/2)/ABS(G$41)*365,"n/a") | H18: =IFERROR(((H$30+G$30)/2)/ABS(H$41)*365,"n/a") | I18: =IFERROR(((I$30+H$30)/2)/ABS(I$41)*365,"n/a")
A19: Tiền và tương đương tiền/Tài sản | B19: =IFERROR(B$25/B$28,"n/a") | C19: =IFERROR(C$25/C$28,"n/a") | D19: =IFERROR(D$25/D$28,"n/a") | E19: =IFERROR(E$25/E$28,"n/a") | F19: =IFERROR(F$25/F$28,"n/a") | G19: =IFERROR(G$25/G$28,"n/a") | H19: =IFERROR(H$25/H$28,"n/a") | I19: =IFERROR(I$25/I$28,"n/a")
A21: II. DỮ LIỆU TRÍCH XUẤT (tự động dò theo tên khoản mục)
A22: Khoản mục | B22: =balance_sheet!B1 | C22: =balance_sheet!C1 | D22: =balance_sheet!D1 | E22: =balance_sheet!E1 | F22: =balance_sheet!F1 | G22: =balance_sheet!G1 | H22: =balance_sheet!H1 | I22: =balance_sheet!I1
A23: CĐKT
A24: Tài sản
A25: Tiền và tương đương tiền | B25: =IFERROR(INDEX(balance_sheet!$B:$XFD,MATCH("Tiền và tương đương tiền",balance_sheet!$A:$A,0),MATCH(B$22,balance_sheet!$B$1:$XFD$1,0)),"") | C25: =IFERROR(INDEX(balance_sheet!$B:$XFD,MATCH("Tiền và tương đương tiền",balance_sheet!$A:$A,0),MATCH(C$22,balance_sheet!$B$1:$XFD$1,0)),"") | D25: =IFERROR(INDEX(balance_sheet!$B:$XFD,MATCH("Tiền và tương đương tiền",balance_sheet!$A:$A,0),MATCH(D$22,balance_sheet!$B$1:$XFD$1,0)),"") | E25: =IFERROR(INDEX(balance_sheet!$B:$XFD,MATCH("Tiền và tương đương tiền",balance_sheet!$A:$A,0),MATCH(E$22,balance_sheet!$B$1:$XFD$1,0)),"") | F25: =IFERROR(INDEX(balance_sheet!$B:$XFD,MATCH("Tiền và tương đương tiền",balance_sheet!$A:$A,0),MATCH(F$22,balance_sheet!$B$1:$XFD$1,0)),"") | G25: =IFERROR(INDEX(balance_sheet!$B:$XFD,MATCH("Tiền và tương đương tiền",balance_sheet!$A:$A,0),MATCH(G$22,balance_sheet!$B$1:$XFD$1,0)),"") | H25: =IFERROR(INDEX(balance_sheet!$B:$XFD,MATCH("Tiền và tương đương tiền",balance_sheet!$A:$A,0),MATCH(H$22,balance_sheet!$B$1:$XFD$1,0)),"") | I25: =IFERROR(INDEX(balance_sheet!$B:$XFD,MATCH("Tiền và tương đương tiền",balance_sheet!$A:$A,0),MATCH(I$22,balance_sheet!$B$1:$XFD$1,0)),"")
A26: Phải thu khách hàng | B26: n/a | C26: n/a | D26: n/a | E26: n/a | F26: n/a | G26: n/a | H26: n/a | I26: n/a
A27: Hàng tồn kho, ròng | B27: n/a | C27: n/a | D27: n/a | E27: n/a | F27: n/a | G27: n/a | H27: n/a | I27: n/a
A28: TỔNG CỘNG TÀI SẢN | B28: =IFERROR(INDEX(balance_sheet!$B:$XFD,MATCH("TỔNG CỘNG TÀI SẢN",balance_sheet!$A:$A,0),MATCH(B$22,balance_sheet!$B$1:$XFD$1,0)),"") | C28: =IFERROR(INDEX(balance_sheet!$B:$XFD,MATCH("TỔNG CỘNG TÀI SẢN",balance_sheet!$A:$A,0),MATCH(C$22,balance_sheet!$B$1:$XFD$1,0)),"") | D28: =IFERROR(INDEX(balance_sheet!$B:$XFD,MATCH("TỔNG CỘNG TÀI SẢN",balance_sheet!$A:$A,0),MATCH(D$22,balance_sheet!$B$1:$XFD$1,0)),"") | E28: =IFERROR(INDEX(balance_sheet!$B:$XFD,MATCH("TỔNG CỘNG TÀI SẢN",balance_sheet!$A:$A,0),MATCH(E$22,balance_sheet!$B$1:$XFD$1,0)),"") | F28: =IFERROR(INDEX(balance_sheet!$B:$XFD,MATCH("TỔNG CỘNG TÀI SẢN",balance_sheet!$A:$A,0),MATCH(F$22,balance_sheet!$B$1:$XFD$1,0)),"") | G28: =IFERROR(INDEX(balance_sheet!$B:$XFD,MATCH("TỔNG CỘNG TÀI SẢN",balance_sheet!$A:$A,0),MATCH(G$22,balance_sheet!$B$1:$XFD$1,0)),"") | H28: =IFERROR(INDEX(balance_sheet!$B:$XFD,MATCH("TỔNG CỘNG TÀI SẢN",balance_sheet!$A:$A,0),MATCH(H$22,balance_sheet!$B$1:$XFD$1,0)),"") | I28: =IFERROR(INDEX(balance_sheet!$B:$XFD,MATCH("TỔNG CỘNG TÀI SẢN",balance_sheet!$A:$A,0),MATCH(I$22,balance_sheet!$B$1:$XFD$1,0)),"")
A29: Nguồn vốn
A30: Phải trả người bán ngắn hạn | B30: =IFERROR(INDEX(balance_sheet!$B:$XFD,MATCH("Phải trả người bán ngắn hạn",balance_sheet!$A:$A,0),MATCH(B$22,balance_sheet!$B$1:$XFD$1,0)),"") | C30: =IFERROR(INDEX(balance_sheet!$B:$XFD,MATCH("Phải trả người bán ngắn hạn",balance_sheet!$A:$A,0),MATCH(C$22,balance_sheet!$B$1:$XFD$1,0)),"") | D30: =IFERROR(INDEX(balance_sheet!$B:$XFD,MATCH("Phải trả người bán ngắn hạn",balance_sheet!$A:$A,0),MATCH(D$22,balance_sheet!$B$1:$XFD$1,0)),"") | E30: =IFERROR(INDEX(balance_sheet!$B:$XFD,MATCH("Phải trả người bán ngắn hạn",balance_sheet!$A:$A,0),MATCH(E$22,balance_sheet!$B$1:$XFD$1,0)),"") | F30: =IFERROR(INDEX(balance_sheet!$B:$XFD,MATCH("Phải trả người bán ngắn hạn",balance_sheet!$A:$A,0),MATCH(F$22,balance_sheet!$B$1:$XFD$1,0)),"") | G30: =IFERROR(INDEX(balance_sheet!$B:$XFD,MATCH("Phải trả người bán ngắn hạn",balance_sheet!$A:$A,0),MATCH(G$22,balance_sheet!$B$1:$XFD$1,0)),"") | H30: =IFERROR(INDEX(balance_sheet!$B:$XFD,MATCH("Phải trả người bán ngắn hạn",balance_sheet!$A:$A,0),MATCH(H$22,balance_sheet!$B$1:$XFD$1,0)),"") | I30: =IFERROR(INDEX(balance_sheet!$B:$XFD,MATCH("Phải trả người bán ngắn hạn",balance_sheet!$A:$A,0),MATCH(I$22,balance_sheet!$B$1:$XFD$1,0)),"")
A31: Vay ngắn hạn | B31: =IFERROR(INDEX(balance_sheet!$B:$XFD,MATCH("Vay ngắn hạn",balance_sheet!$A:$A,0),MATCH(B$22,balance_sheet!$B$1:$XFD$1,0)),"") | C31: =IFERROR(INDEX(balance_sheet!$B:$XFD,MATCH("Vay ngắn hạn",balance_sheet!$A:$A,0),MATCH(C$22,balance_sheet!$B$1:$XFD$1,0)),"") | D31: =IFERROR(INDEX(balance_sheet!$B:$XFD,MATCH("Vay ngắn hạn",balance_sheet!$A:$A,0),MATCH(D$22,balance_sheet!$B$1:$XFD$1,0)),"") | E31: =IFERROR(INDEX(balance_sheet!$B:$XFD,MATCH("Vay ngắn hạn",balance_sheet!$A:$A,0),MATCH(E$22,balance_sheet!$B$1:$XFD$1,0)),"") | F31: =IFERROR(INDEX(balance_sheet!$B:$XFD,MATCH("Vay ngắn hạn",balance_sheet!$A:$A,0),MATCH(F$22,balance_sheet!$B$1:$XFD$1,0)),"") | G31: =IFERROR(INDEX(balance_sheet!$B:$XFD,MATCH("Vay ngắn hạn",balance_sheet!$A:$A,0),MATCH(G$22,balance_sheet!$B$1:$XFD$1,0)),"") | H31: =IFERROR(INDEX(balance_sheet!$B:$XFD,MATCH("Vay ngắn hạn",balance_sheet!$A:$A,0),MATCH(H$22,balance_sheet!$B$1:$XFD$1,0)),"") | I31: =IFERROR(INDEX(balance_sheet!$B:$XFD,MATCH("Vay ngắn hạn",balance_sheet!$A:$A,0),MATCH(I$22,balance_sheet!$B$1:$XFD$1,0)),"")
A32: Nợ phải trả ngắn hạn | B32: =IFERROR(INDEX(balance_sheet!$B:$XFD,MATCH("Nợ phải trả ngắn hạn",balance_sheet!$A:$A,0),MATCH(B$22,balance_sheet!$B$1:$XFD$1,0)),"") | C32: =IFERROR(INDEX(balance_sheet!$B:$XFD,MATCH("Nợ phải trả ngắn hạn",balance_sheet!$A:$A,0),MATCH(C$22,balance_sheet!$B$1:$XFD$1,0)),"") | D32: =IFERROR(INDEX(balance_sheet!$B:$XFD,MATCH("Nợ phải trả ngắn hạn",balance_sheet!$A:$A,0),MATCH(D$22,balance_sheet!$B$1:$XFD$1,0)),"") | E32: =IFERROR(INDEX(balance_sheet!$B:$XFD,MATCH("Nợ phải trả ngắn hạn",balance_sheet!$A:$A,0),MATCH(E$22,balance_sheet!$B$1:$XFD$1,0)),"") | F32: =IFERROR(INDEX(balance_sheet!$B:$XFD,MATCH("Nợ phải trả ngắn hạn",balance_sheet!$A:$A,0),MATCH(F$22,balance_sheet!$B$1:$XFD$1,0)),"") | G32: =IFERROR(INDEX(balance_sheet!$B:$XFD,MATCH("Nợ phải trả ngắn hạn",balance_sheet!$A:$A,0),MATCH(G$22,balance_sheet!$B$1:$XFD$1,0)),"") | H32: =IFERROR(INDEX(balance_sheet!$B:$XFD,MATCH("Nợ phải trả ngắn hạn",balance_sheet!$A:$A,0),MATCH(H$22,balance_sheet!$B$1:$XFD$1,0)),"") | I32: =IFERROR(INDEX(balance_sheet!$B:$XFD,MATCH("Nợ phải trả ngắn hạn",balance_sheet!$A:$A,0),MATCH(I$22,balance_sheet!$B$1:$XFD$1,0)),"")
A33: Vay dài hạn | B33: =IFERROR(INDEX(balance_sheet!$B:$XFD,MATCH("Vay dài hạn",balance_sheet!$A:$A,0),MATCH(B$22,balance_sheet!$B$1:$XFD$1,0)),"") | C33: =IFERROR(INDEX(balance_sheet!$B:$XFD,MATCH("Vay dài hạn",balance_sheet!$A:$A,0),MATCH(C$22,balance_sheet!$B$1:$XFD$1,0)),"") | D33: =IFERROR(INDEX(balance_sheet!$B:$XFD,MATCH("Vay dài hạn",balance_sheet!$A:$A,0),MATCH(D$22,balance_sheet!$B$1:$XFD$1,0)),"") | E33: =IFERROR(INDEX(balance_sheet!$B:$XFD,MATCH("Vay dài hạn",balance_sheet!$A:$A,0),MATCH(E$22,balance_sheet!$B$1:$XFD$1,0)),"") | F33: =IFERROR(INDEX(balance_sheet!$B:$XFD,MATCH("Vay dài hạn",balance_sheet!$A:$A,0),MATCH(F$22,balance_sheet!$B$1:$XFD$1,0)),"") | G33: =IFERROR(INDEX(balance_sheet!$B:$XFD,MATCH("Vay dài hạn",balance_sheet!$A:$A,0),MATCH(G$22,balance_sheet!$B$1:$XFD$1,0)),"") | H33: =IFERROR(INDEX(balance_sheet!$B:$XFD,MATCH("Vay dài hạn",balance_sheet!$A:$A,0),MATCH(H$22,balance_sheet!$B$1:$XFD$1,0)),"") | I33: =IFERROR(INDEX(balance_sheet!$B:$XFD,MATCH("Vay dài hạn",balance_sheet!$A:$A,0),MATCH(I$22,balance_sheet!$B$1:$XFD$1,0)),"")
A34: Nợ phải trả dài hạn | B34: =IFERROR(INDEX(balance_sheet!$B:$XFD,MATCH("Nợ phải trả dài hạn",balance_sheet!$A:$A,0),MATCH(B$22,balance_sheet!$B$1:$XFD$1,0)),"") | C34: =IFERROR(INDEX(balance_sheet!$B:$XFD,MATCH("Nợ phải trả dài hạn",balance_sheet!$A:$A,0),MATCH(C$22,balance_sheet!$B$1:$XFD$1,0)),"") | D34: =IFERROR(INDEX(balance_sheet!$B:$XFD,MATCH("Nợ phải trả dài hạn",balance_sheet!$A:$A,0),MATCH(D$22,balance_sheet!$B$1:$XFD$1,0)),"") | E34: =IFERROR(INDEX(balance_sheet!$B:$XFD,MATCH("Nợ phải trả dài hạn",balance_sheet!$A:$A,0),MATCH(E$22,balance_sheet!$B$1:$XFD$1,0)),"") | F34: =IFERROR(INDEX(balance_sheet!$B:$XFD,MATCH("Nợ phải trả dài hạn",balance_sheet!$A:$A,0),MATCH(F$22,balance_sheet!$B$1:$XFD$1,0)),"") | G34: =IFERROR(INDEX(balance_sheet!$B:$XFD,MATCH("Nợ phải trả dài hạn",balance_sheet!$A:$A,0),MATCH(G$22,balance_sheet!$B$1:$XFD$1,0)),"") | H34: =IFERROR(INDEX(balance_sheet!$B:$XFD,MATCH("Nợ phải trả dài hạn",balance_sheet!$A:$A,0),MATCH(H$22,balance_sheet!$B$1:$XFD$1,0)),"") | I34: =IFERROR(INDEX(balance_sheet!$B:$XFD,MATCH("Nợ phải trả dài hạn",balance_sheet!$A:$A,0),MATCH(I$22,balance_sheet!$B$1:$XFD$1,0)),"")
A35: NỢ PHẢI TRẢ | B35: =IFERROR(INDEX(balance_sheet!$B:$XFD,MATCH("NỢ PHẢI TRẢ",balance_sheet!$A:$A,0),MATCH(B$22,balance_sheet!$B$1:$XFD$1,0)),"") | C35: =IFERROR(INDEX(balance_sheet!$B:$XFD,MATCH("NỢ PHẢI TRẢ",balance_sheet!$A:$A,0),MATCH(C$22,balance_sheet!$B$1:$XFD$1,0)),"") | D35: =IFERROR(INDEX(balance_sheet!$B:$XFD,MATCH("NỢ PHẢI TRẢ",balance_sheet!$A:$A,0),MATCH(D$22,balance_sheet!$B$1:$XFD$1,0)),"") | E35: =IFERROR(INDEX(balance_sheet!$B:$XFD,MATCH("NỢ PHẢI TRẢ",balance_sheet!$A:$A,0),MATCH(E$22,balance_sheet!$B$1:$XFD$1,0)),"") | F35: =IFERROR(INDEX(balance_sheet!$B:$XFD,MATCH("NỢ PHẢI TRẢ",balance_sheet!$A:$A,0),MATCH(F$22,balance_sheet!$B$1:$XFD$1,0)),"") | G35: =IFERROR(INDEX(balance_sheet!$B:$XFD,MATCH("NỢ PHẢI TRẢ",balance_sheet!$A:$A,0),MATCH(G$22,balance_sheet!$B$1:$XFD$1,0)),"") | H35: =IFERROR(INDEX(balance_sheet!$B:$XFD,MATCH("NỢ PHẢI TRẢ",balance_sheet!$A:$A,0),MATCH(H$22,balance_sheet!$B$1:$XFD$1,0)),"") | I35: =IFERROR(INDEX(balance_sheet!$B:$XFD,MATCH("NỢ PHẢI TRẢ",balance_sheet!$A:$A,0),MATCH(I$22,balance_sheet!$B$1:$XFD$1,0)),"")
A36: Vốn chủ sở hữu | B36: =IFERROR(INDEX(balance_sheet!$B:$XFD,MATCH("Vốn chủ sở hữu",balance_sheet!$A:$A,0),MATCH(B$22,balance_sheet!$B$1:$XFD$1,0)),"") | C36: =IFERROR(INDEX(balance_sheet!$B:$XFD,MATCH("Vốn chủ sở hữu",balance_sheet!$A:$A,0),MATCH(C$22,balance_sheet!$B$1:$XFD$1,0)),"") | D36: =IFERROR(INDEX(balance_sheet!$B:$XFD,MATCH("Vốn chủ sở hữu",balance_sheet!$A:$A,0),MATCH(D$22,balance_sheet!$B$1:$XFD$1,0)),"") | E36: =IFERROR(INDEX(balance_sheet!$B:$XFD,MATCH("Vốn chủ sở hữu",balance_sheet!$A:$A,0),MATCH(E$22,balance_sheet!$B$1:$XFD$1,0)),"") | F36: =IFERROR(INDEX(balance_sheet!$B:$XFD,MATCH("Vốn chủ sở hữu",balance_sheet!$A:$A,0),MATCH(F$22,balance_sheet!$B$1:$XFD$1,0)),"") | G36: =IFERROR(INDEX(balance_sheet!$B:$XFD,MATCH("Vốn chủ sở hữu",balance_sheet!$A:$A,0),MATCH(G$22,balance_sheet!$B$1:$XFD$1,0)),"") | H36: =IFERROR(INDEX(balance_sheet!$B:$XFD,MATCH("Vốn chủ sở hữu",balance_sheet!$A:$A,0),MATCH(H$22,balance_sheet!$B$1:$XFD$1,0)),"") | I36: =IFERROR(INDEX(balance_sheet!$B:$XFD,MATCH("Vốn chủ sở hữu",balance_sheet!$A:$A,0),MATCH(I$22,balance_sheet!$B$1:$XFD$1,0)),"")
A37: Tăng VCSH/LN cổ đông cty mẹ | B37: =(B36-#REF!)/B48 | C37: =(C36-B36)/C48 | D37: =(D36-C36)/D48 | E37: =(E36-D36)/E48 | F37: =(F36-E36)/F48 | G37: =(G36-F36)/G48 | H37: =(H36-G36)/H48 | I37: =(I36-H36)/I48
A38: Lợi ích cổ đông không kiểm soát | B38: =IFERROR(INDEX(balance_sheet!$B:$XFD,MATCH("Lợi ích cổ đông không kiểm soát",balance_sheet!$A:$A,0),MATCH(B$22,balance_sheet!$B$1:$XFD$1,0)),"") | C38: =IFERROR(INDEX(balance_sheet!$B:$XFD,MATCH("Lợi ích cổ đông không kiểm soát",balance_sheet!$A:$A,0),MATCH(C$22,balance_sheet!$B$1:$XFD$1,0)),"") | D38: =IFERROR(INDEX(balance_sheet!$B:$XFD,MATCH("Lợi ích cổ đông không kiểm soát",balance_sheet!$A:$A,0),MATCH(D$22,balance_sheet!$B$1:$XFD$1,0)),"") | E38: =IFERROR(INDEX(balance_sheet!$B:$XFD,MATCH("Lợi ích cổ đông không kiểm soát",balance_sheet!$A:$A,0),MATCH(E$22,balance_sheet!$B$1:$XFD$1,0)),"") | F38: =IFERROR(INDEX(balance_sheet!$B:$XFD,MATCH("Lợi ích cổ đông không kiểm soát",balance_sheet!$A:$A,0),MATCH(F$22,balance_sheet!$B$1:$XFD$1,0)),"") | G38: =IFERROR(INDEX(balance_sheet!$B:$XFD,MATCH("Lợi ích cổ đông không kiểm soát",balance_sheet!$A:$A,0),MATCH(G$22,balance_sheet!$B$1:$XFD$1,0)),"") | H38: =IFERROR(INDEX(balance_sheet!$B:$XFD,MATCH("Lợi ích cổ đông không kiểm soát",balance_sheet!$A:$A,0),MATCH(H$22,balance_sheet!$B$1:$XFD$1,0)),"") | I38: =IFERROR(INDEX(balance_sheet!$B:$XFD,MATCH("Lợi ích cổ đông không kiểm soát",balance_sheet!$A:$A,0),MATCH(I$22,balance_sheet!$B$1:$XFD$1,0)),"")
A39: Kết quả hoạt động kinh doanh
A40: Doanh thu thuần về hoạt động kinh doanh | B40: =IFERROR(INDEX(income_statement!$B:$XFD,MATCH("Doanh thu thuần về hoạt động kinh doanh",income_statement!$A:$A,0),MATCH(B$22,income_statement!$B$1:$XFD$1,0)),"") | C40: =IFERROR(INDEX(income_statement!$B:$XFD,MATCH("Doanh thu thuần về hoạt động kinh doanh",income_statement!$A:$A,0),MATCH(C$22,income_statement!$B$1:$XFD$1,0)),"") | D40: =IFERROR(INDEX(income_statement!$B:$XFD,MATCH("Doanh thu thuần về hoạt động kinh doanh",income_statement!$A:$A,0),MATCH(D$22,income_statement!$B$1:$XFD$1,0)),"") | E40: =IFERROR(INDEX(income_statement!$B:$XFD,MATCH("Doanh thu thuần về hoạt động kinh doanh",income_statement!$A:$A,0),MATCH(E$22,income_statement!$B$1:$XFD$1,0)),"") | F40: =IFERROR(INDEX(income_statement!$B:$XFD,MATCH("Doanh thu thuần về hoạt động kinh doanh",income_statement!$A:$A,0),MATCH(F$22,income_statement!$B$1:$XFD$1,0)),"") | G40: =IFERROR(INDEX(income_statement!$B:$XFD,MATCH("Doanh thu thuần về hoạt động kinh doanh",income_statement!$A:$A,0),MATCH(G$22,income_statement!$B$1:$XFD$1,0)),"") | H40: =IFERROR(INDEX(income_statement!$B:$XFD,MATCH("Doanh thu thuần về hoạt động kinh doanh",income_statement!$A:$A,0),MATCH(H$22,income_statement!$B$1:$XFD$1,0)),"") | I40: =IFERROR(INDEX(income_statement!$B:$XFD,MATCH("Doanh thu thuần về hoạt động kinh doanh",income_statement!$A:$A,0),MATCH(I$22,income_statement!$B$1:$XFD$1,0)),"")
A41: CHI PHÍ HOẠT ĐỘNG | B41: =IFERROR(INDEX(income_statement!$B:$XFD,MATCH("CHI PHÍ HOẠT ĐỘNG",income_statement!$A:$A,0),MATCH(B$22,income_statement!$B$1:$XFD$1,0)),"") | C41: =IFERROR(INDEX(income_statement!$B:$XFD,MATCH("CHI PHÍ HOẠT ĐỘNG",income_statement!$A:$A,0),MATCH(C$22,income_statement!$B$1:$XFD$1,0)),"") | D41: =IFERROR(INDEX(income_statement!$B:$XFD,MATCH("CHI PHÍ HOẠT ĐỘNG",income_statement!$A:$A,0),MATCH(D$22,income_statement!$B$1:$XFD$1,0)),"") | E41: =IFERROR(INDEX(income_statement!$B:$XFD,MATCH("CHI PHÍ HOẠT ĐỘNG",income_statement!$A:$A,0),MATCH(E$22,income_statement!$B$1:$XFD$1,0)),"") | F41: =IFERROR(INDEX(income_statement!$B:$XFD,MATCH("CHI PHÍ HOẠT ĐỘNG",income_statement!$A:$A,0),MATCH(F$22,income_statement!$B$1:$XFD$1,0)),"") | G41: =IFERROR(INDEX(income_statement!$B:$XFD,MATCH("CHI PHÍ HOẠT ĐỘNG",income_statement!$A:$A,0),MATCH(G$22,income_statement!$B$1:$XFD$1,0)),"") | H41: =IFERROR(INDEX(income_statement!$B:$XFD,MATCH("CHI PHÍ HOẠT ĐỘNG",income_statement!$A:$A,0),MATCH(H$22,income_statement!$B$1:$XFD$1,0)),"") | I41: =IFERROR(INDEX(income_statement!$B:$XFD,MATCH("CHI PHÍ HOẠT ĐỘNG",income_statement!$A:$A,0),MATCH(I$22,income_statement!$B$1:$XFD$1,0)),"")
...
