Workbook

Sheet balance_sheet
A1: item | B1: 2018-Q1 | C1: 2018-Q2 | D1: 2018-Q3 | E1: 2018-Q4 | F1: 2024-Q3 | G1: 2024-Q4 | H1: 2025-Q1 | I1: 2025-Q2 | J1: 2025-Q3 | K1: 2025-Q4 | L1: 2026-Q1 | M1: 2026-Q2
A2: TÀI SẢN NGẮN HẠN | B2: 3872677138687 | C2: 4233070851415 | D2: 4491049840793 | E2: 5280216054578 | F2: 13535308084055 | G2: 15692597267632 | H2: 15949659613642 | I2: 15713933648138 | J2: 15664103070660 | K2: 18614031193890 | L2: 18163447994797 | M2: 19478579795452
A3: Tiền và tương đương tiền | B3: 81899944010 | C3: 96738062787 | D3: 117587302131 | E3: 206721179629 | F3: 1396669666014 | G3: 1122712392130 | H3: 256848695849 | I3: 346404312952 | J3: 584695579192 | K3: 522025257031 | L3: 923543256525 | M3: 608657296667
A4: Tiền | B4: 81899944010 | C4: 96738062787 | D4: 117587302131 | E4: 206721179629 | F4: 996669666014 | G4: 1022712392130 | H4: 256848695849 | I4: 339404312952 | J4: 542695579192 | K4: 438425257031 | L4: 494094441452 | M4: 599130683660
A5: Các khoản tương đương tiền | B5: 0 | C5: 0 | D5: 0 | E5: 0 | F5: 400000000000 | G5: 100000000000 | H5: 0 | I5: 7000000000 | J5: 42000000000 | K5: 83600000000 | L5: 429448815073 | M5: 9526613007
A6: Đầu tư ngắn hạn | B6: 0 | C6: 0 | D6: 0 | E6: 0 | F6: 0 | G6: 0 | H6: 0 | I6: 98921673893 | J6: 99289134416 | K6: 97918137408 | L6: 99074794328 | M6: 99074794328
A7: Đầu tư ngắn hạn
A8: Dự phòng giảm giá | B8: 0 | C8: 0 | D8: 0 | E8: 0 | F8: 0 | G8: 0 | H8: 0 | I8: 0 | J8: 0 | K8: 0 | L8: 0 | M8: 0
A9: Các khoản phải thu | B9: 108604897949 | C9: 125498489397 | D9: 171250035910 | E9: 175780393688 | F9: 278283783093 | G9: 401134922152 | H9: 304632445702 | I9: 166359422956 | J9: 259873714991 | K9: 153980309545 | L9: 147751795669 | M9: 203761182255
A10: Phải thu khách hàng | B10: 52858316685 | C10: 43292478993 | D10: 68342873558 | E10: 79066643790 | F10: 124556827222 | G10: 70851635761 | H10: 104257111442 | I10: 55983103364 | J10: 106384593691 | K10: 48760415990 | L10: 70317151861 | M10: 46832069007
A11: Trả trước người bán | B11: 44366799350 | C11: 50739682013 | D11: 55978181269 | E11: 57981679200 | F11: 93239686351 | G11: 253102611434 | H11: 117957363803 | I11: 52739479784 | J11: 58899696598 | K11: 38085152243 | L11: 31524838891 | M11: 113056995549
A12: Phải thu nội bộ | B12: 0 | C12: 0 | D12: 0 | E12: 0 | F12: 0 | G12: 0 | H12: 0 | I12: 0 | J12: 0 | K12: 0 | L12: 0 | M12: 0
A13: Phải thu hợp đồng xây dựng đang thực hiện | B13: 0 | C13: 0 | D13: 0 | E13: 0 | F13: 0 | G13: 0 | H13: 0 | I13: 0 | J13: 0 | K13: 0 | L13: 0 | M13: 0
A14: Phải thu khác | B14: 11323958943 | C14: 30841097634 | D14: 46706677475 | E14: 36637359679 | F14: 28470072863 | G14: 64867442121 | H14: 70657918746 | I14: 86021100245 | J14: 82869872822 | K14: 90681158676 | L14: 77663271162 | M14: 75756807090
A15: Dự phòng nợ khó đòi | B15: 0 | C15: 0 | D15: 0 | E15: 0 | F15: -8345709869 | G15: -28518444279 | H15: -28518444279 | I15: -28518444279 | J15: -28531587387 | K15: -31918617346 | L15: -31918617346 | M15: -31918617346
A16: Hàng tồn kho, ròng | B16: 3607975543026 | C16: 3936094231986 | D16: 4124177973673 | E16: 4815524650057 | F16: 10801601688892 | G16: 13015170477311 | H16: 13647265729372 | I16: 13708719465746 | J16: 12448786823997 | K16: 15835334529837 | L16: 13419012225443 | M16: 15186576809971
A17: Hàng tồn kho | B17: 3607975543026 | C17: 3936094231986 | D17: 4124177973673 | E17: 4815524650057 | F17: 10849406684029 | G17: 13074586927914 | H17: 13705778487258 | I17: 13753709950595 | J17: 12494991997766 | K17: 15881309718303 | L17: 13461111273984 | M17: 16603412089455
A18: Dự phòng giảm giá hàng tồn kho | B18: 0 | C18: 0 | D18: 0 | E18: 0 | F18: -47804995137 | G18: -59416450603 | H18: -58512757886 | I18: -44990484849 | J18: -46205173769 | K18: -45975188466 | L18: -42099048541 | M18: -1416835279484
A19: Tài sản lưu động khác | B19: 0 | C19: 0 | D19: 0 | E19: 0 | F19: 0 | G19: 0 | H19: 0 | I19: 0 | J19: 0 | K19: 0 | L19: 170838603 | M19: 171335736
... A22: Phải thu thuế khác | B22: 10422410433 | C22: 845037306 | D22: 3037388526 | E22: 7220318076 | F22: 0 | G22: 0 | H22: 0 | I22: 0 | J22: 2721855013 | K22: 106008324 | L22: 11499299 | M22: 11499299
A23: Tài sản lưu động khác
A24: TÀI SẢN DÀI HẠN | B24: 815719289943 | C24: 940610834341 | D24: 990183116721 | E24: 1022969076235 | F24: 1427177199972 | G24: 1515133510053 | H24: 1469657699207 | I24: 1439843389653 | J24: 1386604619560 | K24: 1549599053151 | L24: 1529337560992 | M24: 2117254018864
A25: Phải thu dài hạn | B25: 46243189214 | C25: 49007477674 | D25: 51390752399 | E25: 57498444869 | F25: 113559945788 | G25: 115599492454 | H25: 118129206365 | I25: 117815539075 | J25: 118147518870 | K25: 121168536356 | L25: 120511022383 | M25: 124008434823
A26: Phải thu khách hàng dài hạn | B26: 0 | C26: 0 | D26: 0 | E26: 0 | F26: 0 | G26: 0 | H26: 0 | I26: 0 | J26: 0 | K26: 0 | L26: 0 | M26: 0
A27: Phải thu nội bộ dài hạn | B27: 0 | C27: 0 | D27: 0 | E27: 0 | F27: 0 | G27: 0 | H27: 0 | I27: 0 | J27: 0 | K27: 0 | L27: 0 | M27: 0
A28: Phải thu dài hạn khác | B28: 46243189214 | C28: 49007477674 | D28: 51390752399 | E28: 57498444869 | F28: 113559945788 | G28: 115599492454 | H28: 118129206365 | I28: 117815539075 | J28: 118147518870 | K28: 121168536356 | L28: 120511022383 | M28: 124008434823
A29: Dự phòng phải thu dài hạn | B29: 0 | C29: 0 | D29: 0 | E29: 0 | F29: 0 | G29: 0 | H29: 0 | I29: 0 | J29: 0 | K29: 0 | L29: 0 | M29: 0
A30: Tài sản cố định | B30: 668852820114 | C30: 683360736408 | D30: 684360427987 | E30: 719287274744 | F30: 862234627072 | G30: 857118818527 | H30: 871957813290 | I30: 853355575866 | J30: 864837183955 | K30: 855770473476 | L30: 914701489275 | M30: 919855138482
A31: GTCL TSCĐ hữu hình | B31: 208184182822 | C31: 223173751581 | D31: 224935778959 | E31: 225960569846 | F31: 249140405046 | G31: 248430247930 | H31: 267030503900 | I31: 252699361405 | J31: 242298081088 | K31: 236245161003 | L31: 246222148323 | M31: 252907423029
A32: Nguyên giá TSCĐ hữu hình | B32: 408320249245 | C32: 430114267619 | D32: 442861017336 | E32: 454178423940 | F32: 783123886981 | G32: 796271142120 | H32: 831295971071 | I32: 833097801697 | J32: 839052084137 | K32: 845032678156 | L32: 870508552693 | M32: 890202651648
A33: Khấu hao lũy kế TSCĐ hữu hình | B33: -200136066423 | C33: -206940516038 | D33: -217925238377 | E33: -228217854094 | F33: -533983481935 | G33: -547840894190 | H33: -564265467171 | I33: -580398440292 | J33: -596754003049 | K33: -608787517153 | L33: -624286404370 | M33: -637295228619
A34: GTCL tài sản thuê tài chính | B34: 0 | C34: 0 | D34: 0 | E34: 0 | F34: 0 | G34: 0 | H34: 0 | I34: 0 | J34: 0 | K34: 0 | L34: 0 | M34: 0
A35: Nguyên giá tài sản thuê tài chính | B35: 0 | C35: 0 | D35: 0 | E35: 0 | F35: 0 | G35: 0 | H35: 0 | I35: 0 | J35: 0 | K35: 0 | L35: 0 | M35: 0
... A72: Vay dài hạn | B72: 78184314000 | C72: 51641789000 | D72: 18474524000 | E72: 7800000000 | F72: 0 | G72: 0 | H72: 0 | I72: 0 | J72: 0 | K72: 0 | L72: 0 | M72: 0
A73: Thuế thu nhập hoãn lại
A74: Dự phòng trợ cấp thôi việc | B74: 0 | C74: 0 | D74: 0 | E74: 0 | F74: 0 | G74: 0 | H74: 0 | I74: 0 | J74: 0 | K74: 0 | L74: 0 | M74: 0
A75: Dự phòng các khoản nợ dài hạn | B75: 7076317000 | C75: 7076317000 | D75: 7076317000 | E75: 7076317000 | F75: 9202074000 | G75: 10363745750 | H75: 10363745750 | I75: 10363745750 | J75: 10146317500 | K75: 12682630000 | L75: 12609554498 | M75: 10399728000
A76: Doanh thu chưa thực hiện | B76: 0 | C76: 0 | D76: 0 | E76: 0 | F76: 0 | G76: 0 | H76: 0 | I76: 0 | J76: 0 | K76: 0 | L76: 0 | M76: 0
A77: Quỹ phát triển khoa học công nghệ | B77: 0 | C77: 0 | D77: 0 | E77: 0 | F77: 0 | G77: 0 | H77: 0 | I77: 0 | J77: 0 | K77: 0 | L77: 0 | M77: 0
A78: Vốn chủ sở hữu | B78: 3198903738511 | C78: 3366712063296 | D78: 3382261329245 | E78: 3745313018202 | F78: 10524432015303 | G78: 11255306630522 | H78: 11730291418447 | I78: 11969384669261 | J78: 11992021944618 | K78: 13274913459412 | L78: 14401169673756 | M78: 13456531361466
...

Sheet income_statement
A1: item | B1: 2018-Q1 | C1: 2018-Q2 | D1: 2018-Q3 | E1: 2018-Q4 | F1: 2024-Q3 | G1: 2024-Q4 | H1: 2025-Q1 | I1: 2025-Q2 | J1: 2025-Q3 | K1: 2025-Q4 | L1: 2026-Q1 | M1: 2026-Q2
A2: Doanh thu bán hàng và cung cấp dịch vụ | B2: 4166588283379 | C2: 3238175968274 | D2: 3178369955454 | E2: 4095665398691 | F2: 7225789054822 | G2: 8698354347717 | H2: 9759650683046 | I2: 7664650341452 | J2: 8235605818836 | K2: 9750682769282 | L2: 17366657543714 | M2: 8564483128740
A3: Các khoản giảm trừ doanh thu | B3: -27135169850 | C3: -20736205018 | D3: -27520745080 | E3: -32271741000 | F3: -96177851976 | G3: -117666403375 | H3: -124554268544 | I3: -82200767315 | J3: -100101386950 | K3: -127690260415 | L3: -121426544426 | M3: -100517281627
A4: Doanh thu thuần | B4: 4139453113529 | C4: 3217439763256 | D4: 3150849210374 | E4: 4063393657691 | F4: 7129611202846 | G4: 8580687944342 | H4: 9635096414502 | I4: 7582449574137 | J4: 8135504431886 | K4: 9622992508867 | L4: 17245230999288 | M4: 8463965847113
A5: Giá vốn hàng bán | B5: -3369430601006 | C5: -2634537690306 | D5: -2550829399062 | E5: -3237254493017 | F5: -5879029148365 | G5: -6788226293053 | H5: -7586766309432 | I5: -5953476887712 | J5: -6528295097135 | K5: -7223656327099 | L5: -13804325099087 | M5: -9130797397247
A6: Lợi nhuận gộp | B6: 770022512523 | C6: 582902072950 | D6: 600019811312 | E6: 826139164674 | F6: 1250582054481 | G6: 1792461651289 | H6: 2048330105070 | I6: 1628972686425 | J6: 1607209334751 | K6: 2399336181768 | L6: 3440905900201 | M6: -666831550134
A7: Doanh thu hoạt động tài chính | B7: 5994175297 | C7: 188751093 | D7: 145838562 | E7: 517262139 | F7: 24894603085 | G7: 28464720237 | H7: 37651295970 | I7: 24247252211 | J7: 28316452524 | K7: 46088225683 | L7: 52416783827 | M7: -28651796771
A8: Chi phí tài chính | B8: -13983492084 | C8: -13733866715 | D8: -17407413734 | E8: -21221091678 | F8: -12977217232 | G8: -42880802744 | H8: -37041222735 | I8: -46383324153 | J8: -30542311945 | K8: -39201911986 | L8: -55085199262 | M8: -61012258081
A9: Chi phí lãi vay | B9: -13553130698 | C9: -11225839714 | D9: -15315285497 | E9: -21014783481 | F9: -6438807781 | G9: -22299606340 | H9: -28848391611 | I9: -32672703171 | J9: -24063535984 | K9: -33497968561 | L9: -50571525907 | M9: -56853927524
A10: Chi phí bán hàng | B10: -281595451271 | C10: -268913495241 | D10: -268067364057 | E10: -351492758857 | F10: -766263429454 | G10: -706245531150 | H10: -1005693098938 | I10: -855377092177 | J10: -757519233823 | K10: -704112549569 | L10: -1352019120210 | M10: -226715965082
A11: Chi phí quản lý doanh nghiệp | B11: -60606184051 | C11: -73696045394 | D11: -93015229413 | E11: -118550695082 | F11: -181399247814 | G11: -208079390615 | H11: -193730064073 | I11: -203474925240 | J11: -240445601201 | K11: -186745261351 | L11: -222121791475 | M11: -38196890403
A12: Lãi/(lỗ) từ hoạt động kinh doanh | B12: 419831560414 | C12: 226747416693 | D12: 221675642670 | E12: 335391881196 | F12: 314836763066 | G12: 863720647017 | H12: 849517015294 | I12: 547984597066 | J12: 607018640306 | K12: 1515364684545 | L12: 1864096573081 | M12: -1021408460471
A13: Thu nhập khác | B13: 1057572840 | C13: 1263333256 | D13: 393502391 | E13: 1923401015 | F13: 4025704624 | G13: 1763875043 | H13: 5101406769 | I13: 3881275230 | J13: 21994473824 | K13: 10211754257 | L13: 3581632251 | M13: 19910198560
... A26: Lãi/(lỗ) từ công ty liên doanh (từ năm 2015) | B26: 0 | C26: 0 | D26: 0 | E26: 0 | F26: 0 | G26: 0 | H26: 0 | I26: 0 | J26: 0 | K26: 0 | L26: 0 | M26: 0

Sheet cash_flow
A1: item | B1: 2018-Q1 | C1: 2018-Q2 | D1: 2018-Q3 | E1: 2018-Q4 | F1: 2024-Q3 | G1: 2024-Q4 | H1: 2025-Q1 | I1: 2025-Q2 | J1: 2025-Q3 | K1: 2025-Q4 | L1: 2026-Q1 | M1: 2026-Q2
A2: Lợi nhuận/(lỗ) trước thuế | B2: 420754514350 | C2: 227534526488 | D2: 221139298315 | E2: 336121933968 | F2: 318019249970 | G2: 864116691201 | H2: 854237258705 | I2: 547392819568 | J2: 625753181461 | K2: 1520456231057 | L2: 1864810619071 | M2: -1002555514834
A3: Khấu hao TSCĐ và BĐSĐT | B3: 9947182144 | C3: 10126744458 | D3: 11260742472 | E3: 10766979013 | F3: 20042779427 | G3: 20381735643 | H3: 22196706619 | I3: 21536874400 | J3: 21021081735 | K3: 20536795649 | L3: 18518277954 | M3: 18961959338
A4: Chi phí dự phòng | B4: 0 | C4: 0 | D4: 0 | E4: 0 | F4: 6380258406 | G4: 30432377395 | H4: -903692717 | I4: -7385664894 | J4: -5126204365 | K4: 5720321082 | L4: -3949215427 | M4: 2671197738793
A5: Lãi/lỗ chênh lệch tỷ giá hối đoái do đánh giá lại các khoản mục tiền tệ có gốc ngoại tệ | B5: 0 | C5: 963264840 | D5: 0 | E5: -1132306183 | F5: 917038623 | G5: 549042768 | H5: -1061047483 | I5: -838658117 | J5: 1505334971 | K5: -2039977941 | L5: -2187343 | M5: 35131536
A6: Lãi/(lỗ) từ thanh lý tài sản cố định | B6: 0 | C6: 0 | D6: 0 | E6: 0 | F6: 0 | G6: 0 | H6: 0 | I6: 0 | J6: 0 | K6: 0 | L6: 0 | M6: 0
A7: (Lãi)/lỗ từ hoạt động đầu tư | B7: -5894368533 | C7: -304669627 | D7: -4127190626 | E7: 2919284209 | F7: -5251469580 | G7: -26204259443 | H7: -28318857249 | I7: -14347632727 | J7: -25115163203 | K7: -42463294522 | L7: -42831359789 | M7: 25367024738
A8: Chi phí lãi vay | B8: 13553130698 | C8: 11225839714 | D8: 15879373171 | E8: 20450698807 | F8: 6438807781 | G8: 22299606340 | H8: 28848391611 | I8: 32672703171 | J8: 24063535984 | K8: 33497968561 | L8: 50571525907 | M8: 56853927524
A9: Thu lãi và cổ tức | B9: 0 | C9: 0 | D9: 0 | E9: 0 | F9: 0 | G9: 0 | H9: 0 | I9: 0 | J9: 0 | K9: 0 | L9: 0 | M9: 0
A10: Lợi nhuận/(lỗ) từ hoạt động kinh doanh trước những thay đổi vốn lưu động | B10: 438360458659 | C10: 249545705873 | D10: 244152223332 | E10: 369126589814 | F10: 346546664627 | G10: 911575193904 | H10: 874998759486 | I10: 579030441401 | J10: 642101766583 | K10: 1535708043886 | L10: 1887117660373 | M10: 1769860267095
A11: (Tăng)/giảm các khoản phải thu | B11: -12071458695 | C11: -30568872418 | D11: -32167599110 | E11: -11229815791 | F11: -79665892558 | G11: -140267237683 | H11: 94192407236 | I11: 109276110403 | J11: -64205154963 | K11: 96427786102 | L11: -49803118650 | M11: -60341880860
A12: (Tăng)/giảm hàng tồn kho | B12: -206016316402 | C12: -328118688960 | D12: -188083741687 | E12: -843967969317 | F12: -1094975965705 | G12: -2225180243885 | H12: -631191559344 | I12: -54068071480 | J12: 1264854560972 | K12: -3386317720537 | L12: 2420198444319 | M12: -2173591971738
A13: Tăng/(giảm) các khoản phải trả | B13: 40949743548 | C13: 19195141980 | D13: 6540959029 | E13: 345517358989 | F13: 474266842052 | G13: 8092632104 | H13: -207454890349 | I13: -329568580575 | J13: 37369383510 | K13: 130627589253 | L13: -59653053842 | M13: -910114273243
... A42: (Tăng)/giảm chứng khoán kinh doanh | B42: 0 | C42: 0 | D42: 0 | E42: 0 | F42: 0 | G42: 0 | H42: 0 | I42: -98921673893 | J42: -367460523 | K42: 1370997008 | L42: -1156656920 | M42: 0

Sheet chi_so_tai_chinh
A1: Chỉ tiêu | B1: =balance_sheet!B1 | C1: =balance_sheet!C1 | D1: =balance_sheet!D1 | E1: =balance_sheet!E1 | F1: =balance_sheet!F1 | G1: =balance_sheet!G1 | H1: =balance_sheet!H1 | I1: =balance_sheet!I1
A2: ROE (LNST CĐ Cty mẹ / VCSH bình quân) | B2: =IFERROR(B$54/((B$41+#REF!)/2),"n/a") | C2: =IFERROR(C$54/((C$41+B$41)/2),"n/a") | D2: =IFERROR(D$54/((D$41+C$41)/2),"n/a") | E2: =IFERROR(E$54/((E$41+D$41)/2),"n/a") | F2: =IFERROR(F$54/((F$41+E$41)/2),"n/a") | G2: =IFERROR(G$54/((G$41+F$41)/2),"n/a") | H2: =IFERROR(H$54/((H$41+G$41)/2),"n/a") | I2: =IFERROR(I$54/((I$41+H$41)/2),"n/a")
A3: ROA (LNST / Tổng tài sản bình quân) | B3: =IFERROR(B$53/((B$33+#REF!)/2),"n/a") | C3: =IFERROR(C$53/((C$33+B$33)/2),"n/a") | D3: =IFERROR(D$53/((D$33+C$33)/2),"n/a") | E3: =IFERROR(E$53/((E$33+D$33)/2),"n/a") | F3: =IFERROR(F$53/((F$33+E$33)/2),"n/a") | G3: =IFERROR(G$53/((G$33+F$33)/2),"n/a") | H3: =IFERROR(H$53/((H$33+G$33)/2),"n/a") | I3: =IFERROR(I$53/((I$33+H$33)/2),"n/a")
A4: Tăng trưởng LN Cổ đông Cty mẹ QQ | B4: =IFERROR((B$54-#REF!)/ABS(#REF!),"n/a") | C4: =IFERROR((C$54-B$54)/ABS(B$54),"n/a") | D4: =IFERROR((D$54-C$54)/ABS(C$54),"n/a") | E4: =IFERROR((E$54-D$54)/ABS(D$54),"n/a") | F4: =IFERROR((F$54-E$54)/ABS(E$54),"n/a") | G4: =IFERROR((G$54-F$54)/ABS(F$54),"n/a") | H4: =IFERROR((H$54-G$54)/ABS(G$54),"n/a") | I4: =IFERROR((I$54-H$54)/ABS(H$54),"n/a")
A5: Tăng trưởng LN Cổ đông Cty mẹ YY | F5: =IFERROR((F$54-B$54)/ABS(B$54),"n/a") | G5: =IFERROR((G$54-C$54)/ABS(C$54),"n/a") | H5: =IFERROR((H$54-D$54)/ABS(D$54),"n/a") | I5: =IFERROR((I$54-E$54)/ABS(E$54),"n/a")
A6: Tăng trưởng Doanh thu thuần QQ | B6: =IFERROR((B$45-#REF!)/ABS(#REF!),"n/a") | C6: =IFERROR((C$45-B$45)/ABS(B$45),"n/a") | D6: =IFERROR((D$45-C$45)/ABS(C$45),"n/a") | E6: =IFERROR((E$45-D$45)/ABS(D$45),"n/a") | F6: =IFERROR((F$45-E$45)/ABS(E$45),"n/a") | G6: =IFERROR((G$45-F$45)/ABS(F$45),"n/a") | H6: =IFERROR((H$45-G$45)/ABS(G$45),"n/a") | I6: =IFERROR((I$45-H$45)/ABS(H$45),"n/a")
A7: Tăng trưởng Doanh thu thuần YY | F7: =IFERROR((F$45-B$45)/ABS(B$45),"n/a") | G7: =IFERROR((G$45-C$45)/ABS(C$45),"n/a") | H7: =IFERROR((H$45-D$45)/ABS(D$45),"n/a") | I7: =IFERROR((I$45-E$45)/ABS(E$45),"n/a")
A8: Biên lợi nhuận gộp | B8: =IFERROR(B$47/B$45,"n/a") | C8: =IFERROR(C$47/C$45,"n/a") | D8: =IFERROR(D$47/D$45,"n/a") | E8: =IFERROR(E$47/E$45,"n/a") | F8: =IFERROR(F$47/F$45,"n/a") | G8: =IFERROR(G$47/G$45,"n/a") | H8: =IFERROR(H$47/H$45,"n/a") | I8: =IFERROR(I$47/I$45,"n/a")
A9: Biên lợi nhuận ròng | B9: =IFERROR(B$54/B$45,"n/a") | C9: =IFERROR(C$54/C$45,"n/a") | D9: =IFERROR(D$54/D$45,"n/a") | E9: =IFERROR(E$54/E$45,"n/a") | F9: =IFERROR(F$54/F$45,"n/a") | G9: =IFERROR(G$54/G$45,"n/a") | H9: =IFERROR(H$54/H$45,"n/a") | I9: =IFERROR(I$54/I$45,"n/a")
A10: D/E (Nợ vay / Vốn chủ sở hữu) | B10: =IFERROR((B$36+B$38)/B$41,"n/a") | C10: =IFERROR((C$36+C$38)/C$41,"n/a") | D10: =IFERROR((D$36+D$38)/D$41,"n/a") | E10: =IFERROR((E$36+E$38)/E$41,"n/a") | F10: =IFERROR((F$36+F$38)/F$41,"n/a") | G10: =IFERROR((G$36+G$38)/G$41,"n/a") | H10: =IFERROR((H$36+H$38)/H$41,"n/a") | I10: =IFERROR((I$36+I$38)/I$41,"n/a")
A11: - Nợ vay dài hạn/Vốn chủ sở hữu | B11: =IFERROR(B$38/B$41,"n/a") | C11: =IFERROR(C$38/C$41,"n/a") | D11: =IFERROR(D$38/D$41,"n/a") | E11: =IFERROR(E$38/E$41,"n/a") | F11: =IFERROR(F$38/F$41,"n/a") | G11: =IFERROR(G$38/G$41,"n/a") | H11: =IFERROR(H$38/H$41,"n/a") | I11: =IFERROR(I$38/I$41,"n/a")
A12: - Nợ vay ngắn hạn/Vốn chủ sở hữu | B12: =IFERROR(B$36/B$41,"n/a") | C12: =IFERROR(C$36/C$41,"n/a") | D12: =IFERROR(D$36/D$41,"n/a") | E12: =IFERROR(E$36/E$41,"n/a") | F12: =IFERROR(F$36/F$41,"n/a") | G12: =IFERROR(G$36/G$41,"n/a") | H12: =IFERROR(H$36/H$41,"n/a") | I12: =IFERROR(I$36/I$41,"n/a")
A13: Nợ phải trả/Vốn chủ sở hữu | B13: =IFERROR(B$40/B$41,"n/a") | C13: =IFERROR(C$40/C$41,"n/a") | D13: =IFERROR(D$40/D$41,"n/a") | E13: =IFERROR(E$40/E$41,"n/a") | F13: =IFERROR(F$40/F$41,"n/a") | G13: =IFERROR(G$40/G$41,"n/a") | H13: =IFERROR(H$40/H$41,"n/a") | I13: =IFERROR(I$40/I$41,"n/a")
A14: - Nợ dài hạn/Vốn chủ sở hữu | B14: =IFERROR(B$39/B$41,"n/a") | C14: =IFERROR(C$39/C$41,"n/a") | D14: =IFERROR(D$39/D$41,"n/a") | E14: =IFERROR(E$39/E$41,"n/a") | F14: =IFERROR(F$39/F$41,"n/a") | G14: =IFERROR(G$39/G$41,"n/a") | H14: =IFERROR(H$39/H$41,"n/a") | I14: =IFERROR(I$39/I$41,"n/a")
A15: - Nợ ngắn hạn/Vốn chủ sở hữu | B15: =IFERROR(B$37/B$41,"n/a") | C15: =IFERROR(C$37/C$41,"n/a") | D15: =IFERROR(D$37/D$41,"n/a") | E15: =IFERROR(E$37/E$41,"n/a") | F15: =IFERROR(F$37/F$41,"n/a") | G15: =IFERROR(G$37/G$41,"n/a") | H15: =IFERROR(H$37/H$41,"n/a") | I15: =IFERROR(I$37/I$41,"n/a")
A16: Chi phí bán hàng, quản lý/LN gộp | B16: =IFERROR((ABS(B$48)+ABS(B$49))/B$47,"n/a") | C16: =IFERROR((ABS(C$48)+ABS(C$49))/C$47,"n/a") | D16: =IFERROR((ABS(D$48)+ABS(D$49))/D$47,"n/a") | E16: =IFERROR((ABS(E$48)+ABS(E$49))/E$47,"n/a") | F16: =IFERROR((ABS(F$48)+ABS(F$49))/F$47,"n/a") | G16: =IFERROR((ABS(G$48)+ABS(G$49))/G$47,"n/a") | H16: =IFERROR((ABS(H$48)+ABS(H$49))/H$47,"n/a") | I16: =IFERROR((ABS(I$48)+ABS(I$49))/I$47,"n/a")
A17: Chi phí lãi vay/LN từ hoạt động kinh doanh | B17: =IFERROR(ABS(B$51)/B$50,"n/a") | C17: =IFERROR(ABS(C$51)/C$50,"n/a") | D17: =IFERROR(ABS(D$51)/D$50,"n/a") | E17: =IFERROR(ABS(E$51)/E$50,"n/a") | F17: =IFERROR(ABS(F$51)/F$50,"n/a") | G17: =IFERROR(ABS(G$51)/G$50,"n/a") | H17: =IFERROR(ABS(H$51)/H$50,"n/a") | I17: =IFERROR(ABS(I$51)/I$50,"n/a")
A18: Số ngày phải trả (DPO) | B18: =IFERROR(((B$35+#REF!)/2)/ABS(B$46)*365,"n/a") | C18: =IFERROR(((C$35+B$35)/2)/ABS(C$46)*365,"n/a") | D18: =IFERROR(((D$35+C$35)/2)/ABS(D$46)*365,"n/a") | E18: =IFERROR(((E$35+D$35)/2)/ABS(E$46)*365,"n/a") | F18: =IFERROR(((F$35+E$35)/2)/ABS(F$46)*365,"n/a") | G18: =IFERROR(((G$35+F$35)/2)/ABS(G$46)*365,"n/a") | H18: =IFERROR(((H$35+G$35)/2)/ABS(H$46)*365,"n/a") | I18: =IFERROR(((I$35+H$35)/2)/ABS(I$46)*365,"n/a")
A19: Số ngày phải thu (DSO) | B19: =IFERROR(((B$29+#REF!)/2)/B$45*365,"n/a") | C19: =IFERROR(((C$29+B$29)/2)/C$45*365,"n/a") | D19: =IFERROR(((D$29+C$29)/2)/D$45*365,"n/a") | E19: =IFERROR(((E$29+D$29)/2)/E$45*365,"n/a") | F19: =IFERROR(((F$29+E$29)/2)/F$45*365,"n/a") | G19: =IFERROR(((G$29+F$29)/2)/G$45*365,"n/a") | H19: =IFERROR(((H$29+G$29)/2)/H$45*365,"n/a") | I19: =IFERROR(((I$29+H$29)/2)/I$45*365,"n/a")
A20: Số ngày tồn kho (DIO) | B20: =IFERROR(((B$30+#REF!)/2)/ABS(B$46)*365,"n/a") | C20: =IFERROR(((C$30+B$30)/2)/ABS(C$46)*365,"n/a") | D20: =IFERROR(((D$30+C$30)/2)/ABS(D$46)*365,"n/a") | E20: =IFERROR(((E$30+D$30)/2)/ABS(E$46)*365,"n/a") | F20: =IFERROR(((F$30+E$30)/2)/ABS(F$46)*365,"n/a") | G20: =IFERROR(((G$30+F$30)/2)/ABS(G$46)*365,"n/a") | H20: =IFERROR(((H$30+G$30)/2)/ABS(H$46)*365,"n/a") | I20: =IFERROR(((I$30+H$30)/2)/ABS(I$46)*365,"n/a")
A21: Tiền và tương đương tiền/Tài sản | B21: =IFERROR(B$28/B$33,"n/a") | C21: =IFERROR(C$28/C$33,"n/a") | D21: =IFERROR(D$28/D$33,"n/a") | E21: =IFERROR(E$28/E$33,"n/a") | F21: =IFERROR(F$28/F$33,"n/a") | G21: =IFERROR(G$28/G$33,"n/a") | H21: =IFERROR(H$28/H$33,"n/a") | I21: =IFERROR(I$28/I$33,"n/a")
A22: Hàng tồn kho/Tài sản | B22: =IFERROR(B$30/B$33,"n/a") | C22: =IFERROR(C$30/C$33,"n/a") | D22: =IFERROR(D$30/D$33,"n/a") | E22: =IFERROR(E$30/E$33,"n/a") | F22: =IFERROR(F$30/F$33,"n/a") | G22: =IFERROR(G$30/G$33,"n/a") | H22: =IFERROR(H$30/H$33,"n/a") | I22: =IFERROR(I$30/I$33,"n/a")
A24: II. DỮ LIỆU TRÍCH XUẤT (tự động dò theo tên khoản mục)
A25: Khoản mục | B25: =balance_sheet!B1 | C25: =balance_sheet!C1 | D25: =balance_sheet!D1 | E25: =balance_sheet!E1 | F25: =balance_sheet!F1 | G25: =balance_sheet!G1 | H25: =balance_sheet!H1 | I25: =balance_sheet!I1
A26: CĐKT
A27: Tài sản
A28: Tiền và tương đương tiền | B28: =IFERROR(INDEX(balance_sheet!$B:$XFD,MATCH("Tiền và tương đương tiền",balance_sheet!$A:$A,0),MATCH(B$25,balance_sheet!$B$1:$XFD$1,0)),"") | C28: =IFERROR(INDEX(balance_sheet!$B:$XFD,MATCH("Tiền và tương đương tiền",balance_sheet!$A:$A,0),MATCH(C$25,balance_sheet!$B$1:$XFD$1,0)),"") | D28: =IFERROR(INDEX(balance_sheet!$B:$XFD,MATCH("Tiền và tương đương tiền",balance_sheet!$A:$A,0),MATCH(D$25,balance_sheet!$B$1:$XFD$1,0)),"") | E28: =IFERROR(INDEX(balance_sheet!$B:$XFD,MATCH("Tiền và tương đương tiền",balance_sheet!$A:$A,0),MATCH(E$25,balance_sheet!$B$1:$XFD$1,0)),"") | F28: =IFERROR(INDEX(balance_sheet!$B:$XFD,MATCH("Tiền và tương đương tiền",balance_sheet!$A:$A,0),MATCH(F$25,balance_sheet!$B$1:$XFD$1,0)),"") | G28: =IFERROR(INDEX(balance_sheet!$B:$XFD,MATCH("Tiền và tương đương tiền",balance_sheet!$A:$A,0),MATCH(G$25,balance_sheet!$B$1:$XFD$1,0)),"") | H28: =IFERROR(INDEX(balance_sheet!$B:$XFD,MATCH("Tiền và tương đương tiền",balance_sheet!$A:$A,0),MATCH(H$25,balance_sheet!$B$1:$XFD$1,0)),"") | I28: =IFERROR(INDEX(balance_sheet!$B:$XFD,MATCH("Tiền và tương đương tiền",balance_sheet!$A:$A,0),MATCH(I$25,balance_sheet!$B$1:$XFD$1,0)),"")
A29: Phải thu khách hàng | B29: =IFERROR(INDEX(balance_sheet!$B:$XFD,MATCH("Phải thu khách hàng",balance_sheet!$A:$A,0),MATCH(B$25,balance_sheet!$B$1:$XFD$1,0)),"") | C29: =IFERROR(INDEX(balance_sheet!$B:$XFD,MATCH("Phải thu khách hàng",balance_sheet!$A:$A,0),MATCH(C$25,balance_sheet!$B$1:$XFD$1,0)),"") | D29: =IFERROR(INDEX(balance_sheet!$B:$XFD,MATCH("Phải thu khách hàng",balance_sheet!$A:$A,0),MATCH(D$25,balance_sheet!$B$1:$XFD$1,0)),"") | E29: =IFERROR(INDEX(balance_sheet!$B:$XFD,MATCH("Phải thu khách hàng",balance_sheet!$A:$A,0),MATCH(E$25,balance_sheet!$B$1:$XFD$1,0)),"") | F29: =IFERROR(INDEX(balance_sheet!$B:$XFD,MATCH("Phải thu khách hàng",balance_sheet!$A:$A,0),MATCH(F$25,balance_sheet!$B$1:$XFD$1,0)),"") | G29: =IFERROR(INDEX(balance_sheet!$B:$XFD,MATCH("Phải thu khách hàng",balance_sheet!$A:$A,0),MATCH(G$25,balance_sheet!$B$1:$XFD$1,0)),"") | H29: =IFERROR(INDEX(balance_sheet!$B:$XFD,MATCH("Phải thu khách hàng",balance_sheet!$A:$A,0),MATCH(H$25,balance_sheet!$B$1:$XFD$1,0)),"") | I29: =IFERROR(INDEX(balance_sheet!$B:$XFD,MATCH("Phải thu khách hàng",balance_sheet!$A:$A,0),MATCH(I$25,balance_sheet!$B$1:$XFD$1,0)),"")
A30: Hàng tồn kho, ròng | B30: =IFERROR(INDEX(balance_sheet!$B:$XFD,MATCH("Hàng tồn kho, ròng",balance_sheet!$A:$A,0),MATCH(B$25,balance_sheet!$B$1:$XFD$1,0)),"") | C30: =IFERROR(INDEX(balance_sheet!$B:$XFD,MATCH("Hàng tồn kho, ròng",balance_sheet!$A:$A,0),MATCH(C$25,balance_sheet!$B$1:$XFD$1,0)),"") | D30: =IFERROR(INDEX(balance_sheet!$B:$XFD,MATCH("Hàng tồn kho, ròng",balance_sheet!$A:$A,0),MATCH(D$25,balance_sheet!$B$1:$XFD$1,0)),"") | E30: =IFERROR(INDEX(balance_sheet!$B:$XFD,MATCH("Hàng tồn kho, ròng",balance_sheet!$A:$A,0),MATCH(E$25,balance_sheet!$B$1:$XFD$1,0)),"") | F30: =IFERROR(INDEX(balance_sheet!$B:$XFD,MATCH("Hàng tồn kho, ròng",balance_sheet!$A:$A,0),MATCH(F$25,balance_sheet!$B$1:$XFD$1,0)),"") | G30: =IFERROR(INDEX(balance_sheet!$B:$XFD,MATCH("Hàng tồn kho, ròng",balance_sheet!$A:$A,0),MATCH(G$25,balance_sheet!$B$1:$XFD$1,0)),"") | H30: =IFERROR(INDEX(balance_sheet!$B:$XFD,MATCH("Hàng tồn kho, ròng",balance_sheet!$A:$A,0),MATCH(H$25,balance_sheet!$B$1:$XFD$1,0)),"") | I30: =IFERROR(INDEX(balance_sheet!$B:$XFD,MATCH("Hàng tồn kho, ròng",balance_sheet!$A:$A,0),MATCH(I$25,balance_sheet!$B$1:$XFD$1,0)),"")
A31: TÀI SẢN NGẮN HẠN | B31: =IFERROR(INDEX(balance_sheet!$B:$XFD,MATCH("TÀI SẢN NGẮN HẠN",balance_sheet!$A:$A,0),MATCH(B$25,balance_sheet!$B$1:$XFD$1,0)),"") | C31: =IFERROR(INDEX(balance_sheet!$B:$XFD,MATCH("TÀI SẢN NGẮN HẠN",balance_sheet!$A:$A,0),MATCH(C$25,balance_sheet!$B$1:$XFD$1,0)),"") | D31: =IFERROR(INDEX(balance_sheet!$B:$XFD,MATCH("TÀI SẢN NGẮN HẠN",balance_sheet!$A:$A,0),MATCH(D$25,balance_sheet!$B$1:$XFD$1,0)),"") | E31: =IFERROR(INDEX(balance_sheet!$B:$XFD,MATCH("TÀI SẢN NGẮN HẠN",balance_sheet!$A:$A,0),MATCH(E$25,balance_sheet!$B$1:$XFD$1,0)),"") | F31: =IFERROR(INDEX(balance_sheet!$B:$XFD,MATCH("TÀI SẢN NGẮN HẠN",balance_sheet!$A:$A,0),MATCH(F$25,balance_sheet!$B$1:$XFD$1,0)),"") | G31: =IFERROR(INDEX(balance_sheet!$B:$XFD,MATCH("TÀI SẢN NGẮN HẠN",balance_sheet!$A:$A,0),MATCH(G$25,balance_sheet!$B$1:$XFD$1,0)),"") | H31: =IFERROR(INDEX(balance_sheet!$B:$XFD,MATCH("TÀI SẢN NGẮN HẠN",balance_sheet!$A:$A,0),MATCH(H$25,balance_sheet!$B$1:$XFD$1,0)),"") | I31: =IFERROR(INDEX(balance_sheet!$B:$XFD,MATCH("TÀI SẢN NGẮN HẠN",balance_sheet!$A:$A,0),MATCH(I$25,balance_sheet!$B$1:$XFD$1,0)),"")
A32: GTCL tài sản cố định vô hình | B32: =IFERROR(INDEX(balance_sheet!$B:$XFD,MATCH("GTCL tài sản cố định vô hình",balance_sheet!$A:$A,0),MATCH(B$25,balance_sheet!$B$1:$XFD$1,0)),"") | C32: =IFERROR(INDEX(balance_sheet!$B:$XFD,MATCH("GTCL tài sản cố định vô hình",balance_sheet!$A:$A,0),MATCH(C$25,balance_sheet!$B$1:$XFD$1,0)),"") | D32: =IFERROR(INDEX(balance_sheet!$B:$XFD,MATCH("GTCL tài sản cố định vô hình",balance_sheet!$A:$A,0),MATCH(D$25,balance_sheet!$B$1:$XFD$1,0)),"") | E32: =IFERROR(INDEX(balance_sheet!$B:$XFD,MATCH("GTCL tài sản cố định vô hình",balance_sheet!$A:$A,0),MATCH(E$25,balance_sheet!$B$1:$XFD$1,0)),"") | F32: =IFERROR(INDEX(balance_sheet!$B:$XFD,MATCH("GTCL tài sản cố định vô hình",balance_sheet!$A:$A,0),MATCH(F$25,balance_sheet!$B$1:$XFD$1,0)),"") | G32: =IFERROR(INDEX(balance_sheet!$B:$XFD,MATCH("GTCL tài sản cố định vô hình",balance_sheet!$A:$A,0),MATCH(G$25,balance_sheet!$B$1:$XFD$1,0)),"") | H32: =IFERROR(INDEX(balance_sheet!$B:$XFD,MATCH("GTCL tài sản cố định vô hình",balance_sheet!$A:$A,0),MATCH(H$25,balance_sheet!$B$1:$XFD$1,0)),"") | I32: =IFERROR(INDEX(balance_sheet!$B:$XFD,MATCH("GTCL tài sản cố định vô hình",balance_sheet!$A:$A,0),MATCH(I$25,balance_sheet!$B$1:$XFD$1,0)),"")
A33: TỔNG CỘNG TÀI SẢN | B33: =IFERROR(INDEX(balance_sheet!$B:$XFD,MATCH("TỔNG CỘNG TÀI SẢN",balance_sheet!$A:$A,0),MATCH(B$25,balance_sheet!$B$1:$XFD$1,0)),"") | C33: =IFERROR(INDEX(balance_sheet!$B:$XFD,MATCH("TỔNG CỘNG TÀI SẢN",balance_sheet!$A:$A,0),MATCH(C$25,balance_sheet!$B$1:$XFD$1,0)),"") | D33: =IFERROR(INDEX(balance_sheet!$B:$XFD,MATCH("TỔNG CỘNG TÀI SẢN",balance_sheet!$A:$A,0),MATCH(D$25,balance_sheet!$B$1:$XFD$1,0)),"") | E33: =IFERROR(INDEX(balance_sheet!$B:$XFD,MATCH("TỔNG CỘNG TÀI SẢN",balance_sheet!$A:$A,0),MATCH(E$25,balance_sheet!$B$1:$XFD$1,0)),"") | F33: =IFERROR(INDEX(balance_sheet!$B:$XFD,MATCH("TỔNG CỘNG TÀI SẢN",balance_sheet!$A:$A,0),MATCH(F$25,balance_sheet!$B$1:$XFD$1,0)),"") | G33: =IFERROR(INDEX(balance_sheet!$B:$XFD,MATCH("TỔNG CỘNG TÀI SẢN",balance_sheet!$A:$A,0),MATCH(G$25,balance_sheet!$B$1:$XFD$1,0)),"") | H33: =IFERROR(INDEX(balance_sheet!$B:$XFD,MATCH("TỔNG CỘNG TÀI SẢN",balance_sheet!$A:$A,0),MATCH(H$25,balance_sheet!$B$1:$XFD$1,0)),"") | I33: =IFERROR(INDEX(balance_sheet!$B:$XFD,MATCH("TỔNG CỘNG TÀI SẢN",balance_sheet!$A:$A,0),MATCH(I$25,balance_sheet!$B$1:$XFD$1,0)),"")
A34: Nguồn vốn
A35: Phải trả người bán | B35: =IFERROR(INDEX(balance_sheet!$B:$XFD,MATCH("Phải trả người bán",balance_sheet!$A:$A,0),MATCH(B$25,balance_sheet!$B$1:$XFD$1,0)),"") | C35: =IFERROR(INDEX(balance_sheet!$B:$XFD,MATCH("Phải trả người bán",balance_sheet!$A:$A,0),MATCH(C$25,balance_sheet!$B$1:$XFD$1,0)),"") | D35: =IFERROR(INDEX(balance_sheet!$B:$XFD,MATCH("Phải trả người bán",balance_sheet!$A:$A,0),MATCH(D$25,balance_sheet!$B$1:$XFD$1,0)),"") | E35: =IFERROR(INDEX(balance_sheet!$B:$XFD,MATCH("Phải trả người bán",balance_sheet!$A:$A,0),MATCH(E$25,balance_sheet!$B$1:$XFD$1,0)),"") | F35: =IFERROR(INDEX(balance_sheet!$B:$XFD,MATCH("Phải trả người bán",balance_sheet!$A:$A,0),MATCH(F$25,balance_sheet!$B$1:$XFD$1,0)),"") | G35: =IFERROR(INDEX(balance_sheet!$B:$XFD,MATCH("Phải trả người bán",balance_sheet!$A:$A,0),MATCH(G$25,balance_sheet!$B$1:$XFD$1,0)),"") | H35: =IFERROR(INDEX(balance_sheet!$B:$XFD,MATCH("Phải trả người bán",balance_sheet!$A:$A,0),MATCH(H$25,balance_sheet!$B$1:$XFD$1,0)),"") | I35: =IFERROR(INDEX(balance_sheet!$B:$XFD,MATCH("Phải trả người bán",balance_sheet!$A:$A,0),MATCH(I$25,balance_sheet!$B$1:$XFD$1,0)),"")
A36: Vay ngắn hạn | B36: =IFERROR(INDEX(balance_sheet!$B:$XFD,MATCH("Vay ngắn hạn",balance_sheet!$A:$A,0),MATCH(B$25,balance_sheet!$B$1:$XFD$1,0)),"") | C36: =IFERROR(INDEX(balance_sheet!$B:$XFD,MATCH("Vay ngắn hạn",balance_sheet!$A:$A,0),MATCH(C$25,balance_sheet!$B$1:$XFD$1,0)),"") | D36: =IFERROR(INDEX(balance_sheet!$B:$XFD,MATCH("Vay ngắn hạn",balance_sheet!$A:$A,0),MATCH(D$25,balance_sheet!$B$1:$XFD$1,0)),"") | E36: =IFERROR(INDEX(balance_sheet!$B:$XFD,MATCH("Vay ngắn hạn",balance_sheet!$A:$A,0),MATCH(E$25,balance_sheet!$B$1:$XFD$1,0)),"") | F36: =IFERROR(INDEX(balance_sheet!$B:$XFD,MATCH("Vay ngắn hạn",balance_sheet!$A:$A,0),MATCH(F$25,balance_sheet!$B$1:$XFD$1,0)),"") | G36: =IFERROR(INDEX(balance_sheet!$B:$XFD,MATCH("Vay ngắn hạn",balance_sheet!$A:$A,0),MATCH(G$25,balance_sheet!$B$1:$XFD$1,0)),"") | H36: =IFERROR(INDEX(balance_sheet!$B:$XFD,MATCH("Vay ngắn hạn",balance_sheet!$A:$A,0),MATCH(H$25,balance_sheet!$B$1:$XFD$1,0)),"") | I36: =IFERROR(INDEX(balance_sheet!$B:$XFD,MATCH("Vay ngắn hạn",balance_sheet!$A:$A,0),MATCH(I$25,balance_sheet!$B$1:$XFD$1,0)),"")
A37: Nợ ngắn hạn | B37: =IFERROR(INDEX(balance_sheet!$B:$XFD,MATCH("Nợ ngắn hạn",balance_sheet!$A:$A,0),MATCH(B$25,balance_sheet!$B$1:$XFD$1,0)),"") | C37: =IFERROR(INDEX(balance_sheet!$B:$XFD,MATCH("Nợ ngắn hạn",balance_sheet!$A:$A,0),MATCH(C$25,balance_sheet!$B$1:$XFD$1,0)),"") | D37: =IFERROR(INDEX(balance_sheet!$B:$XFD,MATCH("Nợ ngắn hạn",balance_sheet!$A:$A,0),MATCH(D$25,balance_sheet!$B$1:$XFD$1,0)),"") | E37: =IFERROR(INDEX(balance_sheet!$B:$XFD,MATCH("Nợ ngắn hạn",balance_sheet!$A:$A,0),MATCH(E$25,balance_sheet!$B$1:$XFD$1,0)),"") | F37: =IFERROR(INDEX(balance_sheet!$B:$XFD,MATCH("Nợ ngắn hạn",balance_sheet!$A:$A,0),MATCH(F$25,balance_sheet!$B$1:$XFD$1,0)),"") | G37: =IFERROR(INDEX(balance_sheet!$B:$XFD,MATCH("Nợ ngắn hạn",balance_sheet!$A:$A,0),MATCH(G$25,balance_sheet!$B$1:$XFD$1,0)),"") | H37: =IFERROR(INDEX(balance_sheet!$B:$XFD,MATCH("Nợ ngắn hạn",balance_sheet!$A:$A,0),MATCH(H$25,balance_sheet!$B$1:$XFD$1,0)),"") | I37: =IFERROR(INDEX(balance_sheet!$B:$XFD,MATCH("Nợ ngắn hạn",balance_sheet!$A:$A,0),MATCH(I$25,balance_sheet!$B$1:$XFD$1,0)),"")
A38: Vay dài hạn | B38: =IFERROR(INDEX(balance_sheet!$B:$XFD,MATCH("Vay dài hạn",balance_sheet!$A:$A,0),MATCH(B$25,balance_sheet!$B$1:$XFD$1,0)),"") | C38: =IFERROR(INDEX(balance_sheet!$B:$XFD,MATCH("Vay dài hạn",balance_sheet!$A:$A,0),MATCH(C$25,balance_sheet!$B$1:$XFD$1,0)),"") | D38: =IFERROR(INDEX(balance_sheet!$B:$XFD,MATCH("Vay dài hạn",balance_sheet!$A:$A,0),MATCH(D$25,balance_sheet!$B$1:$XFD$1,0)),"") | E38: =IFERROR(INDEX(balance_sheet!$B:$XFD,MATCH("Vay dài hạn",balance_sheet!$A:$A,0),MATCH(E$25,balance_sheet!$B$1:$XFD$1,0)),"") | F38: =IFERROR(INDEX(balance_sheet!$B:$XFD,MATCH("Vay dài hạn",balance_sheet!$A:$A,0),MATCH(F$25,balance_sheet!$B$1:$XFD$1,0)),"") | G38: =IFERROR(INDEX(balance_sheet!$B:$XFD,MATCH("Vay dài hạn",balance_sheet!$A:$A,0),MATCH(G$25,balance_sheet!$B$1:$XFD$1,0)),"") | H38: =IFERROR(INDEX(balance_sheet!$B:$XFD,MATCH("Vay dài hạn",balance_sheet!$A:$A,0),MATCH(H$25,balance_sheet!$B$1:$XFD$1,0)),"") | I38: =IFERROR(INDEX(balance_sheet!$B:$XFD,MATCH("Vay dài hạn",balance_sheet!$A:$A,0),MATCH(I$25,balance_sheet!$B$1:$XFD$1,0)),"")
A39: Nợ dài hạn | B39: =IFERROR(INDEX(balance_sheet!$B:$XFD,MATCH("Nợ dài hạn",balance_sheet!$A:$A,0),MATCH(B$25,balance_sheet!$B$1:$XFD$1,0)),"") | C39: =IFERROR(INDEX(balance_sheet!$B:$XFD,MATCH("Nợ dài hạn",balance_sheet!$A:$A,0),MATCH(C$25,balance_sheet!$B$1:$XFD$1,0)),"") | D39: =IFERROR(INDEX(balance_sheet!$B:$XFD,MATCH("Nợ dài hạn",balance_sheet!$A:$A,0),MATCH(D$25,balance_sheet!$B$1:$XFD$1,0)),"") | E39: =IFERROR(INDEX(balance_sheet!$B:$XFD,MATCH("Nợ dài hạn",balance_sheet!$A:$A,0),MATCH(E$25,balance_sheet!$B$1:$XFD$1,0)),"") | F39: =IFERROR(INDEX(balance_sheet!$B:$XFD,MATCH("Nợ dài hạn",balance_sheet!$A:$A,0),MATCH(F$25,balance_sheet!$B$1:$XFD$1,0)),"") | G39: =IFERROR(INDEX(balance_sheet!$B:$XFD,MATCH("Nợ dài hạn",balance_sheet!$A:$A,0),MATCH(G$25,balance_sheet!$B$1:$XFD$1,0)),"") | H39: =IFERROR(INDEX(balance_sheet!$B:$XFD,MATCH("Nợ dài hạn",balance_sheet!$A:$A,0),MATCH(H$25,balance_sheet!$B$1:$XFD$1,0)),"") | I39: =IFERROR(INDEX(balance_sheet!$B:$XFD,MATCH("Nợ dài hạn",balance_sheet!$A:$A,0),MATCH(I$25,balance_sheet!$B$1:$XFD$1,0)),"")
A40: NỢ PHẢI TRẢ | B40: =IFERROR(INDEX(balance_sheet!$B:$XFD,MATCH("NỢ PHẢI TRẢ",balance_sheet!$A:$A,0),MATCH(B$25,balance_sheet!$B$1:$XFD$1,0)),"") | C40: =IFERROR(INDEX(balance_sheet!$B:$XFD,MATCH("NỢ PHẢI TRẢ",balance_sheet!$A:$A,0),MATCH(C$25,balance_sheet!$B$1:$XFD$1,0)),"") | D40: =IFERROR(INDEX(balance_sheet!$B:$XFD,MATCH("NỢ PHẢI TRẢ",balance_sheet!$A:$A,0),MATCH(D$25,balance_sheet!$B$1:$XFD$1,0)),"") | E40: =IFERROR(INDEX(balance_sheet!$B:$XFD,MATCH("NỢ PHẢI TRẢ",balance_sheet!$A:$A,0),MATCH(E$25,balance_sheet!$B$1:$XFD$1,0)),"") | F40: =IFERROR(INDEX(balance_sheet!$B:$XFD,MATCH("NỢ PHẢI TRẢ",balance_sheet!$A:$A,0),MATCH(F$25,balance_sheet!$B$1:$XFD$1,0)),"") | G40: =IFERROR(INDEX(balance_sheet!$B:$XFD,MATCH("NỢ PHẢI TRẢ",balance_sheet!$A:$A,0),MATCH(G$25,balance_sheet!$B$1:$XFD$1,0)),"") | H40: =IFERROR(INDEX(balance_sheet!$B:$XFD,MATCH("NỢ PHẢI TRẢ",balance_sheet!$A:$A,0),MATCH(H$25,balance_sheet!$B$1:$XFD$1,0)),"") | I40: =IFERROR(INDEX(balance_sheet!$B:$XFD,MATCH("NỢ PHẢI TRẢ",balance_sheet!$A:$A,0),MATCH(I$25,balance_sheet!$B$1:$XFD$1,0)),"")
A41: Vốn chủ sở hữu | B41: =IFERROR(INDEX(balance_sheet!$B:$XFD,MATCH("Vốn chủ sở hữu",balance_sheet!$A:$A,0),MATCH(B$25,balance_sheet!$B$1:$XFD$1,0)),"") | C41: =IFERROR(INDEX(balance_sheet!$B:$XFD,MATCH("Vốn chủ sở hữu",balance_sheet!$A:$A,0),MATCH(C$25,balance_sheet!$B$1:$XFD$1,0)),"") | D41: =IFERROR(INDEX(balance_sheet!$B:$XFD,MATCH("Vốn chủ sở hữu",balance_sheet!$A:$A,0),MATCH(D$25,balance_sheet!$B$1:$XFD$1,0)),"") | E41: =IFERROR(INDEX(balance_sheet!$B:$XFD,MATCH("Vốn chủ sở hữu",balance_sheet!$A:$A,0),MATCH(E$25,balance_sheet!$B$1:$XFD$1,0)),"") | F41: =IFERROR(INDEX(balance_sheet!$B:$XFD,MATCH("Vốn chủ sở hữu",balance_sheet!$A:$A,0),MATCH(F$25,balance_sheet!$B$1:$XFD$1,0)),"") | G41: =IFERROR(INDEX(balance_sheet!$B:$XFD,MATCH("Vốn chủ sở hữu",balance_sheet!$A:$A,0),MATCH(G$25,balance_sheet!$B$1:$XFD$1,0)),"") | H41: =IFERROR(INDEX(balance_sheet!$B:$XFD,MATCH("Vốn chủ sở hữu",balance_sheet!$A:$A,0),MATCH(H$25,balance_sheet!$B$1:$XFD$1,0)),"") | I41: =IFERROR(INDEX(balance_sheet!$B:$XFD,MATCH("Vốn chủ sở hữu",balance_sheet!$A:$A,0),MATCH(I$25,balance_sheet!$B$1:$XFD$1,0)),"")
...
