Workbook

Sheet balance_sheet
A1: item | B1: 2018 | C1: 2019 | D1: 2020 | E1: 2021 | F1: 2022 | G1: 2023 | H1: 2024 | I1: 2025
A2: TÀI SẢN NGẮN HẠN | B2: 5405256600641 | C2: 7333364485251 | D2: 7143929036497 | E2: 9292192238421 | F2: 11966357761798 | G2: 12958118192260 | H2: 15692597267632 | I2: 18614031193890
A3: Tiền và tương đương tiền | B3: 206721179629 | C3: 95224439008 | D3: 422234781061 | E3: 355454838957 | F3: 879548130711 | G3: 896147917336 | H3: 1122712392130 | I3: 522025257031
A4: Tiền | B4: 206721179629 | C4: 95224439008 | D4: 422234781061 | E4: 355454838957 | F4: 879548130711 | G4: 896147917336 | H4: 1022712392130 | I4: 438425257031
A5: Các khoản tương đương tiền | B5: 0 | C5: 0 | D5: 0 | E5: 0 | F5: 0 | G5: 0 | H5: 100000000000 | I5: 83600000000
A6: Đầu tư ngắn hạn | B6: 0 | C6: 0 | D6: 0 | E6: 0 | F6: 0 | G6: 0 | H6: 0 | I6: 97918137408
A7: Đầu tư ngắn hạn | F7: 0 | G7: 0 | H7: 0 | I7: 97918137408
A8: Dự phòng giảm giá | B8: 0 | C8: 0 | D8: 0 | E8: 0 | F8: 0 | G8: 0 | H8: 0 | I8: 0
A9: Các khoản phải thu | B9: 155196257825 | C9: 129688313476 | D9: 98997286429 | E9: 111969758488 | F9: 300880402245 | G9: 215035937840 | H9: 401134922152 | I9: 153980309545
A10: Phải thu khách hàng | B10: 57664060443 | C10: 48292876716 | D10: 67591685619 | E10: 59930655833 | F10: 56532707659 | G10: 69277567110 | H10: 70851635761 | I10: 48760415990
A11: Trả trước người bán | B11: 57981679202 | C11: 74867455343 | D11: 20218946599 | E11: 30659175548 | F11: 68902837213 | G11: 27775617785 | H11: 253102611434 | I11: 38085152243
A12: Phải thu nội bộ | B12: 0 | C12: 0 | D12: 0 | E12: 0 | F12: 0 | G12: 0 | H12: 0 | I12: 0
A13: Phải thu hợp đồng xây dựng đang thực hiện | B13: 0 | C13: 0 | D13: 0 | E13: 0 | F13: 0 | G13: 0 | H13: 0 | I13: 0
A14: Phải thu khác | B14: 39159008338 | C14: 5287941028 | D14: 12261206010 | E14: 22831538994 | F14: 37641170145 | G14: 32980198226 | H14: 64867442121 | I14: 90681158676
A15: Dự phòng nợ khó đòi | B15: 0 | C15: 0 | D15: -1202878846 | E15: -2004798077 | F15: -2862909308 | G15: -5049680837 | H15: -28518444279 | I15: -31918617346
A16: Hàng tồn kho, ròng | B16: 4968145942990 | C16: 7030420371216 | D16: 6545905987056 | E16: 8754741712359 | F16: 10506054932284 | G16: 10940937959289 | H16: 13015170477311 | I16: 15835334529837
A17: Hàng tồn kho | B17: 4968145942990 | C17: 7030420371216 | D17: 6545905987056 | E17: 8754741712359 | F17: 10508065026916 | G17: 10944749006797 | H17: 13074586927914 | I17: 15881309718303
A18: Dự phòng giảm giá hàng tồn kho | B18: 0 | C18: 0 | D18: 0 | E18: 0 | F18: -2010094632 | G18: -3811047508 | H18: -59416450603 | I18: -45975188466
A19: Tài sản lưu động khác | B19: 0 | C19: 0 | D19: 0 | E19: 0 | F19: 0 | G19: 0 | H19: 0 | I19: 0
... A22: Phải thu thuế khác | B22: 8376292470 | C22: 91289736 | D22: 7838524 | E22: 4603175720 | F22: 0 | G22: 0 | H22: 0 | I22: 106008324
A23: Tài sản lưu động khác | F23: 0 | G23: 0 | H23: 0 | I23: 0
A24: TÀI SẢN DÀI HẠN | B24: 1032638955963 | C24: 1269599936565 | D24: 1339217061954 | E24: 1326824308701 | F24: 1370766887448 | G24: 1469439823096 | H24: 1515133510053 | I24: 1549599053151
A25: Phải thu dài hạn | B25: 57498444869 | C25: 70721623109 | D25: 77310617360 | E25: 84131506164 | F25: 93956493011 | G25: 104636239106 | H25: 115599492454 | I25: 121168536356
A26: Phải thu khách hàng dài hạn | B26: 0 | C26: 0 | D26: 0 | E26: 0 | F26: 0 | G26: 0 | H26: 0 | I26: 0
A27: Phải thu nội bộ dài hạn | B27: 0 | C27: 0 | D27: 0 | E27: 0 | F27: 0 | G27: 0 | H27: 0 | I27: 0
A28: Phải thu dài hạn khác | B28: 57498444869 | C28: 70721623109 | D28: 77310617360 | E28: 84131506164 | F28: 93956493011 | G28: 104636239106 | H28: 115599492454 | I28: 121168536356
A29: Dự phòng phải thu dài hạn | B29: 0 | C29: 0 | D29: 0 | E29: 0 | F29: 0 | G29: 0 | H29: 0 | I29: 0
A30: Tài sản cố định | B30: 719287274744 | C30: 923870354474 | D30: 931617117533 | E30: 909985491983 | F30: 882432821075 | G30: 882715109732 | H30: 857118818527 | I30: 855770473476
A31: GTCL TSCĐ hữu hình | B31: 225960569846 | C31: 263827234353 | D31: 281244232172 | E31: 259137188160 | F31: 239734551747 | G31: 256373758673 | H31: 248430247930 | I31: 236245161003
A32: Nguyên giá TSCĐ hữu hình | B32: 454178423940 | C32: 534818699342 | D32: 600464186725 | E32: 633614629426 | F32: 672781337441 | G32: 747570855214 | H32: 796271142120 | I32: 845032678156
A33: Khấu hao lũy kế TSCĐ hữu hình | B33: -228217854094 | C33: -270991464989 | D33: -319219954553 | E33: -374477441266 | F33: -433046785694 | G33: -491197096541 | H33: -547840894190 | I33: -608787517153
A34: GTCL tài sản thuê tài chính | B34: 0 | C34: 0 | D34: 0 | E34: 0 | F34: 0 | G34: 0 | H34: 0 | I34: 0
A35: Nguyên giá tài sản thuê tài chính | B35: 0 | C35: 0 | D35: 0 | E35: 0 | F35: 0 | G35: 0 | H35: 0 | I35: 0
... A72: Vay dài hạn | B72: 7800000000 | C72: 3700000000 | D72: 0 | E72: 0 | F72: 0 | G72: 0 | H72: 0 | I72: 0
A73: Thuế thu nhập hoãn lại | F73: 0 | G73: 0 | H73: 0 | I73: 0
A74: Dự phòng trợ cấp thôi việc | B74: 0 | C74: 0 | D74: 0 | E74: 0 | F74: 0 | G74: 0 | H74: 0 | I74: 0
A75: Dự phòng các khoản nợ dài hạn | B75: 7076317000 | C75: 3661780000 | D75: 8850709000 | E75: 42861489361 | F75: 9746905000 | G75: 9202074000 | H75: 10363745750 | I75: 12682630000
A76: Doanh thu chưa thực hiện | B76: 0 | C76: 0 | D76: 0 | E76: 0 | F76: 0 | G76: 0 | H76: 0 | I76: 0
A77: Quỹ phát triển khoa học công nghệ | B77: 0 | C77: 0 | D77: 0 | E77: 0 | F77: 0 | G77: 0 | H77: 0 | I77: 0
A78: Vốn chủ sở hữu | B78: 3745073427904 | C78: 4577265811347 | D78: 5241861865008 | E78: 6012633980253 | F78: 8444094654850 | G78: 9806180663976 | H78: 11255306630522 | I78: 13274913459412
...

Sheet income_statement
A1: item | B1: 2018 | C1: 2019 | D1: 2020 | E1: 2021 | F1: 2022 | G1: 2023 | H1: 2024 | I1: 2025
A2: Doanh thu bán hàng và cung cấp dịch vụ | B2: 14678799605798 | C2: 17144251446632 | D2: 17681913026177 | E2: 19735646137250 | F2: 34211128942240 | G2: 33481608954953 | H2: 38232401184050 | I2: 35410589612616
A3: Các khoản giảm trừ doanh thu | B3: -107663860948 | C3: -143570366109 | D3: -171124375178 | E3: -188587772416 | F3: -334674383087 | G3: -344679758524 | H3: -409564012665 | I3: -434546683224
A4: Doanh thu thuần | B4: 14571135744850 | C4: 17000681080523 | D4: 17510788650999 | E4: 19547058364834 | F4: 33876454559153 | G4: 33136929196429 | H4: 37822837171385 | I4: 34976042929392
A5: Giá vốn hàng bán | B5: -11792052183391 | C5: -13539967588262 | D5: -14076055770112 | E5: -15948760134458 | F5: -27949348024381 | G5: -27078338249235 | H5: -31149334531193 | I5: -27292194621378
A6: Lợi nhuận gộp | B6: 2779083561459 | C6: 3460713492261 | D6: 3434732880887 | E6: 3598298230376 | F6: 5927106534772 | G6: 6058590947194 | H6: 6673502640192 | I6: 7683848308014
A7: Doanh thu hoạt động tài chính | B7: 6846027091 | C7: 16820020734 | D7: 2368958316 | E7: 16326114795 | F7: 54036974170 | G7: 97825547538 | H7: 75567438524 | I7: 136303226388
A8: Chi phí tài chính | B8: -66345864211 | C8: -133678118497 | D8: -161541087492 | E8: -118252734395 | F8: -141471203463 | G8: -142580680640 | H8: -93616780951 | I8: -153168770819
A9: Chi phí lãi vay | B9: -61109039390 | C9: -115367610418 | D9: -154416694276 | E9: -104380274160 | F9: -94143431408 | G9: -118568804103 | H9: -46775305829 | I9: -119082599327
A10: Chi phí bán hàng | B10: -1170069069426 | C10: -1361807553507 | D10: -1420855653447 | E10: -1687654952494 | F10: -2828208644376 | G10: -2835769469802 | H10: -3207574691174 | I10: -3322701974507
A11: Chi phí quản lý doanh nghiệp | B11: -345868153940 | C11: -475831697930 | D11: -505572794605 | E11: -501819303928 | F11: -673996996684 | G11: -693934934718 | H11: -795749355922 | I11: -824395851865
A12: Lãi/(lỗ) từ hoạt động kinh doanh | B12: 1203646500973 | C12: 1506216143061 | D12: 1349132303659 | E12: 1306897354354 | F12: 2337466664419 | G12: 2484131409572 | H12: 2652129250669 | I12: 3519884937211
A13: Thu nhập khác | B13: 4637809502 | C13: 4760923089 | D13: 5485848150 | E13: 8861354013 | F13: 8582642521 | G13: 11846230257 | H13: 10013781125 | I13: 41188910080
... A26: Lãi/(lỗ) từ công ty liên doanh (từ năm 2015) | B26: 0 | C26: 0 | D26: 0 | E26: 0 | F26: 0 | G26: 0 | H26: 0 | I26: 0

Sheet cash_flow
A1: item | B1: 2018 | C1: 2019 | D1: 2020 | E1: 2021 | F1: 2022 | G1: 2023 | H1: 2024 | I1: 2025
A2: Lợi nhuận/(lỗ) trước thuế | B2: 1205550273121 | C2: 1506712385551 | D2: 1345980468715 | E2: 1279230522031 | F2: 2312327554713 | G2: 2488760002374 | H2: 2651012449308 | I2: 3547839490791
A3: Khấu hao TSCĐ và BĐSĐT | B3: 42101648087 | C3: 61066130585 | D3: 72154867041 | E3: 75118429219 | F3: 79516376971 | G3: 81257091304 | H3: 80821846271 | I3: 85291458403
A4: Chi phí dự phòng | B4: 0 | C4: -3414537000 | D4: 6391807846 | E4: 64942006080 | F4: 2868205863 | G4: 2374779451 | H4: 77722354056 | I4: -7695240894
A5: Lãi/lỗ chênh lệch tỷ giá hối đoái do đánh giá lại các khoản mục tiền tệ có gốc ngoại tệ | B5: -169041343 | C5: -1242529054 | D5: 177425063 | E5: 2504365377 | F5: -8239903282 | G5: -1611805757 | H5: 140360327 | I5: -2434348570
A6: Lãi/(lỗ) từ thanh lý tài sản cố định | B6: 0 | C6: 0 | D6: 0 | E6: 0 | F6: 0 | G6: 0 | H6: 0 | I6: 0
A7: (Lãi)/lỗ từ hoạt động đầu tư | B7: -7406944577 | C7: -1456968019 | D7: 1237319162 | E7: -3225478644 | F7: -21327686776 | G7: -79561268312 | H7: -47046699012 | I7: -110244947701
A8: Chi phí lãi vay | B8: 61109042390 | C8: 115367610418 | D8: 154416694276 | E8: 104380274160 | F8: 94421152974 | G8: 118568804103 | H8: 46775305829 | I8: 119082599327
A9: Thu lãi và cổ tức | B9: 0 | C9: 0 | D9: 0 | E9: 0 | F9: 0 | G9: 0 | H9: 0 | I9: 0
A10: Lợi nhuận/(lỗ) từ hoạt động kinh doanh trước những thay đổi vốn lưu động | B10: 1301184977678 | C10: 1677032092481 | D10: 1580358582103 | E10: 1522950118223 | F10: 2459565700463 | G10: 2609787603163 | H10: 2809425616779 | I10: 3631839011356
A11: (Tăng)/giảm các khoản phải thu | B11: -86037746014 | C11: 12888586942 | D11: 17322807863 | E11: -23111709097 | F11: -52151674870 | G11: 39100711762 | H11: -261742771385 | I11: 235691148778
A12: (Tăng)/giảm hàng tồn kho | B12: -1566186716366 | C12: -2062274428226 | D12: 484514384160 | E12: -2208835725303 | F12: -1753323314557 | G12: -436683979881 | H12: -2129837921117 | I12: -2806722790389
A13: Tăng/(giảm) các khoản phải trả | B13: 412203203546 | C13: 199226464534 | D13: -99651505808 | E13: 354804359041 | F13: 76506711125 | G13: 92449328770 | H13: 273559805376 | I13: -369026498161
... A42: (Tăng)/giảm chứng khoán kinh doanh | B42: 0 | C42: 0 | D42: 0 | E42: 0 | F42: 0 | G42: 0 | H42: 0 | I42: -97918137408

Sheet chi_so_tai_chinh
A1: CHỈ SỐ TÀI CHÍNH — PNJ
A2: I. CHỈ SỐ TÀI CHÍNH
A3: Chỉ tiêu | B3: ='balance_sheet'!B1 | C3: ='balance_sheet'!C1 | D3: ='balance_sheet'!D1 | E3: ='balance_sheet'!E1 | F3: ='balance_sheet'!F1 | G3: ='balance_sheet'!G1 | H3: ='balance_sheet'!H1 | I3: ='balance_sheet'!I1
A4: 1. Khả năng sinh lời
A5: ROE (LNST CĐ Cty mẹ / VCSH bình quân) | B5: n/a | C5: =IFERROR(C$47/((C$32+B$32)/2),"n/a") | D5: =IFERROR(D$47/((D$32+C$32)/2),"n/a") | E5: =IFERROR(E$47/((E$32+D$32)/2),"n/a") | F5: =IFERROR(F$47/((F$32+E$32)/2),"n/a") | G5: =IFERROR(G$47/((G$32+F$32)/2),"n/a") | H5: =IFERROR(H$47/((H$32+G$32)/2),"n/a") | I5: =IFERROR(I$47/((I$32+H$32)/2),"n/a")
A6: ROA (LNST / Tổng tài sản bình quân) | B6: n/a | C6: =IFERROR(C$46/((C$33+B$33)/2),"n/a") | D6: =IFERROR(D$46/((D$33+C$33)/2),"n/a") | E6: =IFERROR(E$46/((E$33+D$33)/2),"n/a") | F6: =IFERROR(F$46/((F$33+E$33)/2),"n/a") | G6: =IFERROR(G$46/((G$33+F$33)/2),"n/a") | H6: =IFERROR(H$46/((H$33+G$33)/2),"n/a") | I6: =IFERROR(I$46/((I$33+H$33)/2),"n/a")
A7: Tăng trưởng LN Cổ đông Cty mẹ | B7: n/a | C7: =IFERROR((C$47-B$47)/ABS(B$47),"n/a") | D7: =IFERROR((D$47-C$47)/ABS(C$47),"n/a") | E7: =IFERROR((E$47-D$47)/ABS(D$47),"n/a") | F7: =IFERROR((F$47-E$47)/ABS(E$47),"n/a") | G7: =IFERROR((G$47-F$47)/ABS(F$47),"n/a") | H7: =IFERROR((H$47-G$47)/ABS(G$47),"n/a") | I7: =IFERROR((I$47-H$47)/ABS(H$47),"n/a")
A8: Tăng trưởng Doanh thu thuần | B8: n/a | C8: =IFERROR((C$39-B$39)/ABS(B$39),"n/a") | D8: =IFERROR((D$39-C$39)/ABS(C$39),"n/a") | E8: =IFERROR((E$39-D$39)/ABS(D$39),"n/a") | F8: =IFERROR((F$39-E$39)/ABS(E$39),"n/a") | G8: =IFERROR((G$39-F$39)/ABS(F$39),"n/a") | H8: =IFERROR((H$39-G$39)/ABS(G$39),"n/a") | I8: =IFERROR((I$39-H$39)/ABS(H$39),"n/a")
A9: 2. Biên lợi nhuận
A10: Biên lợi nhuận gộp | B10: =IFERROR(B$41/B$39,"n/a") | C10: =IFERROR(C$41/C$39,"n/a") | D10: =IFERROR(D$41/D$39,"n/a") | E10: =IFERROR(E$41/E$39,"n/a") | F10: =IFERROR(F$41/F$39,"n/a") | G10: =IFERROR(G$41/G$39,"n/a") | H10: =IFERROR(H$41/H$39,"n/a") | I10: =IFERROR(I$41/I$39,"n/a")
A11: Biên lợi nhuận ròng | B11: =IFERROR(B$46/B$39,"n/a") | C11: =IFERROR(C$46/C$39,"n/a") | D11: =IFERROR(D$46/D$39,"n/a") | E11: =IFERROR(E$46/E$39,"n/a") | F11: =IFERROR(F$46/F$39,"n/a") | G11: =IFERROR(G$46/G$39,"n/a") | H11: =IFERROR(H$46/H$39,"n/a") | I11: =IFERROR(I$46/I$39,"n/a")
A12: 3. Đòn bẩy tài chính
A13: D/E (Nợ vay / Vốn chủ sở hữu) | B13: =IFERROR((B$37+B$38)/B$32,"n/a") | C13: =IFERROR((C$37+C$38)/C$32,"n/a") | D13: =IFERROR((D$37+D$38)/D$32,"n/a") | E13: =IFERROR((E$37+E$38)/E$32,"n/a") | F13: =IFERROR((F$37+F$38)/F$32,"n/a") | G13: =IFERROR((G$37+G$38)/G$32,"n/a") | H13: =IFERROR((H$37+H$38)/H$32,"n/a") | I13: =IFERROR((I$37+I$38)/I$32,"n/a")
A14: - Nợ vay dài hạn/Vốn chủ sở hữu | B14: =IFERROR(B$38/B$32,"n/a") | C14: =IFERROR(C$38/C$32,"n/a") | D14: =IFERROR(D$38/D$32,"n/a") | E14: =IFERROR(E$38/E$32,"n/a") | F14: =IFERROR(F$38/F$32,"n/a") | G14: =IFERROR(G$38/G$32,"n/a") | H14: =IFERROR(H$38/H$32,"n/a") | I14: =IFERROR(I$38/I$32,"n/a")
A15: - Nợ vay ngắn hạn/Vốn chủ sở hữu | B15: =IFERROR(B$37/B$32,"n/a") | C15: =IFERROR(C$37/C$32,"n/a") | D15: =IFERROR(D$37/D$32,"n/a") | E15: =IFERROR(E$37/E$32,"n/a") | F15: =IFERROR(F$37/F$32,"n/a") | G15: =IFERROR(G$37/G$32,"n/a") | H15: =IFERROR(H$37/H$32,"n/a") | I15: =IFERROR(I$37/I$32,"n/a")
A16: Nợ phải trả/Vốn chủ sở hữu | B16: =IFERROR(B$34/B$32,"n/a") | C16: =IFERROR(C$34/C$32,"n/a") | D16: =IFERROR(D$34/D$32,"n/a") | E16: =IFERROR(E$34/E$32,"n/a") | F16: =IFERROR(F$34/F$32,"n/a") | G16: =IFERROR(G$34/G$32,"n/a") | H16: =IFERROR(H$34/H$32,"n/a") | I16: =IFERROR(I$34/I$32,"n/a")
A17: - Nợ dài hạn/Vốn chủ sở hữu | B17: =IFERROR(B$36/B$32,"n/a") | C17: =IFERROR(C$36/C$32,"n/a") | D17: =IFERROR(D$36/D$32,"n/a") | E17: =IFERROR(E$36/E$32,"n/a") | F17: =IFERROR(F$36/F$32,"n/a") | G17: =IFERROR(G$36/G$32,"n/a") | H17: =IFERROR(H$36/H$32,"n/a") | I17: =IFERROR(I$36/I$32,"n/a")
A18: - Nợ ngắn hạn/Vốn chủ sở hữu | B18: =IFERROR(B$35/B$32,"n/a") | C18: =IFERROR(C$35/C$32,"n/a") | D18: =IFERROR(D$35/D$32,"n/a") | E18: =IFERROR(E$35/E$32,"n/a") | F18: =IFERROR(F$35/F$32,"n/a") | G18: =IFERROR(G$35/G$32,"n/a") | H18: =IFERROR(H$35/H$32,"n/a") | I18: =IFERROR(I$35/I$32,"n/a")
A19: 4. Chi phí & khả năng trả lãi
A20: Chi phí bán hàng, quản lý/LN gộp | B20: =IFERROR((ABS(B$42)+ABS(B$43))/B$41,"n/a") | C20: =IFERROR((ABS(C$42)+ABS(C$43))/C$41,"n/a") | D20: =IFERROR((ABS(D$42)+ABS(D$43))/D$41,"n/a") | E20: =IFERROR((ABS(E$42)+ABS(E$43))/E$41,"n/a") | F20: =IFERROR((ABS(F$42)+ABS(F$43))/F$41,"n/a") | G20: =IFERROR((ABS(G$42)+ABS(G$43))/G$41,"n/a") | H20: =IFERROR((ABS(H$42)+ABS(H$43))/H$41,"n/a") | I20: =IFERROR((ABS(I$42)+ABS(I$43))/I$41,"n/a")
A21: Chi phí lãi vay/LN từ hoạt động kinh doanh | B21: =IFERROR(ABS(B$45)/B$44,"n/a") | C21: =IFERROR(ABS(C$45)/C$44,"n/a") | D21: =IFERROR(ABS(D$45)/D$44,"n/a") | E21: =IFERROR(ABS(E$45)/E$44,"n/a") | F21: =IFERROR(ABS(F$45)/F$44,"n/a") | G21: =IFERROR(ABS(G$45)/G$44,"n/a") | H21: =IFERROR(ABS(H$45)/H$44,"n/a") | I21: =IFERROR(ABS(I$45)/I$44,"n/a")
A22: 5. Chu kỳ hoạt động vốn lưu động
A23: Số ngày phải trả (DPO) | B23: n/a | C23: =IFERROR(((C$49+B$49)/2)/ABS(C$40)*365,"n/a") | D23: =IFERROR(((D$49+C$49)/2)/ABS(D$40)*365,"n/a") | E23: =IFERROR(((E$49+D$49)/2)/ABS(E$40)*365,"n/a") | F23: =IFERROR(((F$49+E$49)/2)/ABS(F$40)*365,"n/a") | G23: =IFERROR(((G$49+F$49)/2)/ABS(G$40)*365,"n/a") | H23: =IFERROR(((H$49+G$49)/2)/ABS(H$40)*365,"n/a") | I23: =IFERROR(((I$49+H$49)/2)/ABS(I$40)*365,"n/a")
A24: Số ngày phải thu (DSO) | B24: n/a | C24: =IFERROR(((C$48+B$48)/2)/C$39*365,"n/a") | D24: =IFERROR(((D$48+C$48)/2)/D$39*365,"n/a") | E24: =IFERROR(((E$48+D$48)/2)/E$39*365,"n/a") | F24: =IFERROR(((F$48+E$48)/2)/F$39*365,"n/a") | G24: =IFERROR(((G$48+F$48)/2)/G$39*365,"n/a") | H24: =IFERROR(((H$48+G$48)/2)/H$39*365,"n/a") | I24: =IFERROR(((I$48+H$48)/2)/I$39*365,"n/a")
A25: Số ngày tồn kho (DIO) | B25: n/a | C25: =IFERROR(((C$50+B$50)/2)/ABS(C$40)*365,"n/a") | D25: =IFERROR(((D$50+C$50)/2)/ABS(D$40)*365,"n/a") | E25: =IFERROR(((E$50+D$50)/2)/ABS(E$40)*365,"n/a") | F25: =IFERROR(((F$50+E$50)/2)/ABS(F$40)*365,"n/a") | G25: =IFERROR(((G$50+F$50)/2)/ABS(G$40)*365,"n/a") | H25: =IFERROR(((H$50+G$50)/2)/ABS(H$40)*365,"n/a") | I25: =IFERROR(((I$50+H$50)/2)/ABS(I$40)*365,"n/a")
A26: 6. Cơ cấu tài sản
A27: Tiền và tương đương tiền/Tài sản | B27: =IFERROR(B$51/B$33,"n/a") | C27: =IFERROR(C$51/C$33,"n/a") | D27: =IFERROR(D$51/D$33,"n/a") | E27: =IFERROR(E$51/E$33,"n/a") | F27: =IFERROR(F$51/F$33,"n/a") | G27: =IFERROR(G$51/G$33,"n/a") | H27: =IFERROR(H$51/H$33,"n/a") | I27: =IFERROR(I$51/I$33,"n/a")
A28: Hàng tồn kho/Tài sản | B28: =IFERROR(B$50/B$33,"n/a") | C28: =IFERROR(C$50/C$33,"n/a") | D28: =IFERROR(D$50/D$33,"n/a") | E28: =IFERROR(E$50/E$33,"n/a") | F28: =IFERROR(F$50/F$33,"n/a") | G28: =IFERROR(G$50/G$33,"n/a") | H28: =IFERROR(H$50/H$33,"n/a") | I28: =IFERROR(I$50/I$33,"n/a")
A30: II. DỮ LIỆU TRÍCH XUẤT (tự động dò theo tên khoản mục)
A31: Khoản mục | B31: ='balance_sheet'!B1 | C31: ='balance_sheet'!C1 | D31: ='balance_sheet'!D1 | E31: ='balance_sheet'!E1 | F31: ='balance_sheet'!F1 | G31: ='balance_sheet'!G1 | H31: ='balance_sheet'!H1 | I31: ='balance_sheet'!I1
A32: Vốn chủ sở hữu | B32: =IFERROR(INDEX(balance_sheet!$B:$I,MATCH("Vốn chủ sở hữu",balance_sheet!$A:$A,0),MATCH(B$31,balance_sheet!$B$1:$I$1,0)),"") | C32: =IFERROR(INDEX(balance_sheet!$B:$I,MATCH("Vốn chủ sở hữu",balance_sheet!$A:$A,0),MATCH(C$31,balance_sheet!$B$1:$I$1,0)),"") | D32: =IFERROR(INDEX(balance_sheet!$B:$I,MATCH("Vốn chủ sở hữu",balance_sheet!$A:$A,0),MATCH(D$31,balance_sheet!$B$1:$I$1,0)),"") | E32: =IFERROR(INDEX(balance_sheet!$B:$I,MATCH("Vốn chủ sở hữu",balance_sheet!$A:$A,0),MATCH(E$31,balance_sheet!$B$1:$I$1,0)),"") | F32: =IFERROR(INDEX(balance_sheet!$B:$I,MATCH("Vốn chủ sở hữu",balance_sheet!$A:$A,0),MATCH(F$31,balance_sheet!$B$1:$I$1,0)),"") | G32: =IFERROR(INDEX(balance_sheet!$B:$I,MATCH("Vốn chủ sở hữu",balance_sheet!$A:$A,0),MATCH(G$31,balance_sheet!$B$1:$I$1,0)),"") | H32: =IFERROR(INDEX(balance_sheet!$B:$I,MATCH("Vốn chủ sở hữu",balance_sheet!$A:$A,0),MATCH(H$31,balance_sheet!$B$1:$I$1,0)),"") | I32: =IFERROR(INDEX(balance_sheet!$B:$I,MATCH("Vốn chủ sở hữu",balance_sheet!$A:$A,0),MATCH(I$31,balance_sheet!$B$1:$I$1,0)),"")
A33: TỔNG CỘNG TÀI SẢN | B33: =IFERROR(INDEX(balance_sheet!$B:$I,MATCH("TỔNG CỘNG TÀI SẢN",balance_sheet!$A:$A,0),MATCH(B$31,balance_sheet!$B$1:$I$1,0)),"") | C33: =IFERROR(INDEX(balance_sheet!$B:$I,MATCH("TỔNG CỘNG TÀI SẢN",balance_sheet!$A:$A,0),MATCH(C$31,balance_sheet!$B$1:$I$1,0)),"") | D33: =IFERROR(INDEX(balance_sheet!$B:$I,MATCH("TỔNG CỘNG TÀI SẢN",balance_sheet!$A:$A,0),MATCH(D$31,balance_sheet!$B$1:$I$1,0)),"") | E33: =IFERROR(INDEX(balance_sheet!$B:$I,MATCH("TỔNG CỘNG TÀI SẢN",balance_sheet!$A:$A,0),MATCH(E$31,balance_sheet!$B$1:$I$1,0)),"") | F33: =IFERROR(INDEX(balance_sheet!$B:$I,MATCH("TỔNG CỘNG TÀI SẢN",balance_sheet!$A:$A,0),MATCH(F$31,balance_sheet!$B$1:$I$1,0)),"") | G33: =IFERROR(INDEX(balance_sheet!$B:$I,MATCH("TỔNG CỘNG TÀI SẢN",balance_sheet!$A:$A,0),MATCH(G$31,balance_sheet!$B$1:$I$1,0)),"") | H33: =IFERROR(INDEX(balance_sheet!$B:$I,MATCH("TỔNG CỘNG TÀI SẢN",balance_sheet!$A:$A,0),MATCH(H$31,balance_sheet!$B$1:$I$1,0)),"") | I33: =IFERROR(INDEX(balance_sheet!$B:$I,MATCH("TỔNG CỘNG TÀI SẢN",balance_sheet!$A:$A,0),MATCH(I$31,balance_sheet!$B$1:$I$1,0)),"")
A34: NỢ PHẢI TRẢ | B34: =IFERROR(INDEX(balance_sheet!$B:$I,MATCH("NỢ PHẢI TRẢ",balance_sheet!$A:$A,0),MATCH(B$31,balance_sheet!$B$1:$I$1,0)),"") | C34: =IFERROR(INDEX(balance_sheet!$B:$I,MATCH("NỢ PHẢI TRẢ",balance_sheet!$A:$A,0),MATCH(C$31,balance_sheet!$B$1:$I$1,0)),"") | D34: =IFERROR(INDEX(balance_sheet!$B:$I,MATCH("NỢ PHẢI TRẢ",balance_sheet!$A:$A,0),MATCH(D$31,balance_sheet!$B$1:$I$1,0)),"") | E34: =IFERROR(INDEX(balance_sheet!$B:$I,MATCH("NỢ PHẢI TRẢ",balance_sheet!$A:$A,0),MATCH(E$31,balance_sheet!$B$1:$I$1,0)),"") | F34: =IFERROR(INDEX(balance_sheet!$B:$I,MATCH("NỢ PHẢI TRẢ",balance_sheet!$A:$A,0),MATCH(F$31,balance_sheet!$B$1:$I$1,0)),"") | G34: =IFERROR(INDEX(balance_sheet!$B:$I,MATCH("NỢ PHẢI TRẢ",balance_sheet!$A:$A,0),MATCH(G$31,balance_sheet!$B$1:$I$1,0)),"") | H34: =IFERROR(INDEX(balance_sheet!$B:$I,MATCH("NỢ PHẢI TRẢ",balance_sheet!$A:$A,0),MATCH(H$31,balance_sheet!$B$1:$I$1,0)),"") | I34: =IFERROR(INDEX(balance_sheet!$B:$I,MATCH("NỢ PHẢI TRẢ",balance_sheet!$A:$A,0),MATCH(I$31,balance_sheet!$B$1:$I$1,0)),"")
A35: Nợ ngắn hạn | B35: =IFERROR(INDEX(balance_sheet!$B:$I,MATCH("Nợ ngắn hạn",balance_sheet!$A:$A,0),MATCH(B$31,balance_sheet!$B$1:$I$1,0)),"") | C35: =IFERROR(INDEX(balance_sheet!$B:$I,MATCH("Nợ ngắn hạn",balance_sheet!$A:$A,0),MATCH(C$31,balance_sheet!$B$1:$I$1,0)),"") | D35: =IFERROR(INDEX(balance_sheet!$B:$I,MATCH("Nợ ngắn hạn",balance_sheet!$A:$A,0),MATCH(D$31,balance_sheet!$B$1:$I$1,0)),"") | E35: =IFERROR(INDEX(balance_sheet!$B:$I,MATCH("Nợ ngắn hạn",balance_sheet!$A:$A,0),MATCH(E$31,balance_sheet!$B$1:$I$1,0)),"") | F35: =IFERROR(INDEX(balance_sheet!$B:$I,MATCH("Nợ ngắn hạn",balance_sheet!$A:$A,0),MATCH(F$31,balance_sheet!$B$1:$I$1,0)),"") | G35: =IFERROR(INDEX(balance_sheet!$B:$I,MATCH("Nợ ngắn hạn",balance_sheet!$A:$A,0),MATCH(G$31,balance_sheet!$B$1:$I$1,0)),"") | H35: =IFERROR(INDEX(balance_sheet!$B:$I,MATCH("Nợ ngắn hạn",balance_sheet!$A:$A,0),MATCH(H$31,balance_sheet!$B$1:$I$1,0)),"") | I35: =IFERROR(INDEX(balance_sheet!$B:$I,MATCH("Nợ ngắn hạn",balance_sheet!$A:$A,0),MATCH(I$31,balance_sheet!$B$1:$I$1,0)),"")
A36: Nợ dài hạn | B36: =IFERROR(INDEX(balance_sheet!$B:$I,MATCH("Nợ dài hạn",balance_sheet!$A:$A,0),MATCH(B$31,balance_sheet!$B$1:$I$1,0)),"") | C36: =IFERROR(INDEX(balance_sheet!$B:$I,MATCH("Nợ dài hạn",balance_sheet!$A:$A,0),MATCH(C$31,balance_sheet!$B$1:$I$1,0)),"") | D36: =IFERROR(INDEX(balance_sheet!$B:$I,MATCH("Nợ dài hạn",balance_sheet!$A:$A,0),MATCH(D$31,balance_sheet!$B$1:$I$1,0)),"") | E36: =IFERROR(INDEX(balance_sheet!$B:$I,MATCH("Nợ dài hạn",balance_sheet!$A:$A,0),MATCH(E$31,balance_sheet!$B$1:$I$1,0)),"") | F36: =IFERROR(INDEX(balance_sheet!$B:$I,MATCH("Nợ dài hạn",balance_sheet!$A:$A,0),MATCH(F$31,balance_sheet!$B$1:$I$1,0)),"") | G36: =IFERROR(INDEX(balance_sheet!$B:$I,MATCH("Nợ dài hạn",balance_sheet!$A:$A,0),MATCH(G$31,balance_sheet!$B$1:$I$1,0)),"") | H36: =IFERROR(INDEX(balance_sheet!$B:$I,MATCH("Nợ dài hạn",balance_sheet!$A:$A,0),MATCH(H$31,balance_sheet!$B$1:$I$1,0)),"") | I36: =IFERROR(INDEX(balance_sheet!$B:$I,MATCH("Nợ dài hạn",balance_sheet!$A:$A,0),MATCH(I$31,balance_sheet!$B$1:$I$1,0)),"")
A37: Vay ngắn hạn | B37: =IFERROR(INDEX(balance_sheet!$B:$I,MATCH("Vay ngắn hạn",balance_sheet!$A:$A,0),MATCH(B$31,balance_sheet!$B$1:$I$1,0)),"") | C37: =IFERROR(INDEX(balance_sheet!$B:$I,MATCH("Vay ngắn hạn",balance_sheet!$A:$A,0),MATCH(C$31,balance_sheet!$B$1:$I$1,0)),"") | D37: =IFERROR(INDEX(balance_sheet!$B:$I,MATCH("Vay ngắn hạn",balance_sheet!$A:$A,0),MATCH(D$31,balance_sheet!$B$1:$I$1,0)),"") | E37: =IFERROR(INDEX(balance_sheet!$B:$I,MATCH("Vay ngắn hạn",balance_sheet!$A:$A,0),MATCH(E$31,balance_sheet!$B$1:$I$1,0)),"") | F37: =IFERROR(INDEX(balance_sheet!$B:$I,MATCH("Vay ngắn hạn",balance_sheet!$A:$A,0),MATCH(F$31,balance_sheet!$B$1:$I$1,0)),"") | G37: =IFERROR(INDEX(balance_sheet!$B:$I,MATCH("Vay ngắn hạn",balance_sheet!$A:$A,0),MATCH(G$31,balance_sheet!$B$1:$I$1,0)),"") | H37: =IFERROR(INDEX(balance_sheet!$B:$I,MATCH("Vay ngắn hạn",balance_sheet!$A:$A,0),MATCH(H$31,balance_sheet!$B$1:$I$1,0)),"") | I37: =IFERROR(INDEX(balance_sheet!$B:$I,MATCH("Vay ngắn hạn",balance_sheet!$A:$A,0),MATCH(I$31,balance_sheet!$B$1:$I$1,0)),"")
A38: Vay dài hạn | B38: =IFERROR(INDEX(balance_sheet!$B:$I,MATCH("Vay dài hạn",balance_sheet!$A:$A,0),MATCH(B$31,balance_sheet!$B$1:$I$1,0)),"") | C38: =IFERROR(INDEX(balance_sheet!$B:$I,MATCH("Vay dài hạn",balance_sheet!$A:$A,0),MATCH(C$31,balance_sheet!$B$1:$I$1,0)),"") | D38: =IFERROR(INDEX(balance_sheet!$B:$I,MATCH("Vay dài hạn",balance_sheet!$A:$A,0),MATCH(D$31,balance_sheet!$B$1:$I$1,0)),"") | E38: =IFERROR(INDEX(balance_sheet!$B:$I,MATCH("Vay dài hạn",balance_sheet!$A:$A,0),MATCH(E$31,balance_sheet!$B$1:$I$1,0)),"") | F38: =IFERROR(INDEX(balance_sheet!$B:$I,MATCH("Vay dài hạn",balance_sheet!$A:$A,0),MATCH(F$31,balance_sheet!$B$1:$I$1,0)),"") | G38: =IFERROR(INDEX(balance_sheet!$B:$I,MATCH("Vay dài hạn",balance_sheet!$A:$A,0),MATCH(G$31,balance_sheet!$B$1:$I$1,0)),"") | H38: =IFERROR(INDEX(balance_sheet!$B:$I,MATCH("Vay dài hạn",balance_sheet!$A:$A,0),MATCH(H$31,balance_sheet!$B$1:$I$1,0)),"") | I38: =IFERROR(INDEX(balance_sheet!$B:$I,MATCH("Vay dài hạn",balance_sheet!$A:$A,0),MATCH(I$31,balance_sheet!$B$1:$I$1,0)),"")
A39: Doanh thu thuần | B39: =IFERROR(INDEX(income_statement!$B:$I,MATCH("Doanh thu thuần",income_statement!$A:$A,0),MATCH(B$31,income_statement!$B$1:$I$1,0)),"") | C39: =IFERROR(INDEX(income_statement!$B:$I,MATCH("Doanh thu thuần",income_statement!$A:$A,0),MATCH(C$31,income_statement!$B$1:$I$1,0)),"") | D39: =IFERROR(INDEX(income_statement!$B:$I,MATCH("Doanh thu thuần",income_statement!$A:$A,0),MATCH(D$31,income_statement!$B$1:$I$1,0)),"") | E39: =IFERROR(INDEX(income_statement!$B:$I,MATCH("Doanh thu thuần",income_statement!$A:$A,0),MATCH(E$31,income_statement!$B$1:$I$1,0)),"") | F39: =IFERROR(INDEX(income_statement!$B:$I,MATCH("Doanh thu thuần",income_statement!$A:$A,0),MATCH(F$31,income_statement!$B$1:$I$1,0)),"") | G39: =IFERROR(INDEX(income_statement!$B:$I,MATCH("Doanh thu thuần",income_statement!$A:$A,0),MATCH(G$31,income_statement!$B$1:$I$1,0)),"") | H39: =IFERROR(INDEX(income_statement!$B:$I,MATCH("Doanh thu thuần",income_statement!$A:$A,0),MATCH(H$31,income_statement!$B$1:$I$1,0)),"") | I39: =IFERROR(INDEX(income_statement!$B:$I,MATCH("Doanh thu thuần",income_statement!$A:$A,0),MATCH(I$31,income_statement!$B$1:$I$1,0)),"")
A40: Giá vốn hàng bán | B40: =IFERROR(INDEX(income_statement!$B:$I,MATCH("Giá vốn hàng bán",income_statement!$A:$A,0),MATCH(B$31,income_statement!$B$1:$I$1,0)),"") | C40: =IFERROR(INDEX(income_statement!$B:$I,MATCH("Giá vốn hàng bán",income_statement!$A:$A,0),MATCH(C$31,income_statement!$B$1:$I$1,0)),"") | D40: =IFERROR(INDEX(income_statement!$B:$I,MATCH("Giá vốn hàng bán",income_statement!$A:$A,0),MATCH(D$31,income_statement!$B$1:$I$1,0)),"") | E40: =IFERROR(INDEX(income_statement!$B:$I,MATCH("Giá vốn hàng bán",income_statement!$A:$A,0),MATCH(E$31,income_statement!$B$1:$I$1,0)),"") | F40: =IFERROR(INDEX(income_statement!$B:$I,MATCH("Giá vốn hàng bán",income_statement!$A:$A,0),MATCH(F$31,income_statement!$B$1:$I$1,0)),"") | G40: =IFERROR(INDEX(income_statement!$B:$I,MATCH("Giá vốn hàng bán",income_statement!$A:$A,0),MATCH(G$31,income_statement!$B$1:$I$1,0)),"") | H40: =IFERROR(INDEX(income_statement!$B:$I,MATCH("Giá vốn hàng bán",income_statement!$A:$A,0),MATCH(H$31,income_statement!$B$1:$I$1,0)),"") | I40: =IFERROR(INDEX(income_statement!$B:$I,MATCH("Giá vốn hàng bán",income_statement!$A:$A,0),MATCH(I$31,income_statement!$B$1:$I$1,0)),"")
A41: Lợi nhuận gộp | B41: =IFERROR(INDEX(income_statement!$B:$I,MATCH("Lợi nhuận gộp",income_statement!$A:$A,0),MATCH(B$31,income_statement!$B$1:$I$1,0)),"") | C41: =IFERROR(INDEX(income_statement!$B:$I,MATCH("Lợi nhuận gộp",income_statement!$A:$A,0),MATCH(C$31,income_statement!$B$1:$I$1,0)),"") | D41: =IFERROR(INDEX(income_statement!$B:$I,MATCH("Lợi nhuận gộp",income_statement!$A:$A,0),MATCH(D$31,income_statement!$B$1:$I$1,0)),"") | E41: =IFERROR(INDEX(income_statement!$B:$I,MATCH("Lợi nhuận gộp",income_statement!$A:$A,0),MATCH(E$31,income_statement!$B$1:$I$1,0)),"") | F41: =IFERROR(INDEX(income_statement!$B:$I,MATCH("Lợi nhuận gộp",income_statement!$A:$A,0),MATCH(F$31,income_statement!$B$1:$I$1,0)),"") | G41: =IFERROR(INDEX(income_statement!$B:$I,MATCH("Lợi nhuận gộp",income_statement!$A:$A,0),MATCH(G$31,income_statement!$B$1:$I$1,0)),"") | H41: =IFERROR(INDEX(income_statement!$B:$I,MATCH("Lợi nhuận gộp",income_statement!$A:$A,0),MATCH(H$31,income_statement!$B$1:$I$1,0)),"") | I41: =IFERROR(INDEX(income_statement!$B:$I,MATCH("Lợi nhuận gộp",income_statement!$A:$A,0),MATCH(I$31,income_statement!$B$1:$I$1,0)),"")
...
